Workbook

Sheet Read me
A1: PROJECT XL — student housing near VUB, Brussels
A2: Decision model • illustrative development, not a property valuation
A3: Status | B3: Researched rent guidance; investment costs, student budget and finance remain explicit assumptions. 14 October 2026.
A4: How to use | B4: Edit blue cells on Inputs; Excel recalculates all formulas on opening.
A5: Rent rule | B5: Affordable rent = minimum of student budget, market ceiling and applicable regulatory/comparator ceiling.
A6: Legal caveat | B6: A market average is not a legal rent cap. Reference rent must be obtained for the exact dwelling.
A7: Scenario | B7: Development/major conversion, with land acquisition entered separately.
A8: Model boundaries | B8: Unlevered annual cash flow; debt-service and equity cash flow shown separately; no sale proceeds in payback.
A9: Room choice | B9: Room sizing compares every integer from 12–96 rooms; selects highest recurring cash flow among feasible candidates.
A10: Feasible means | B10: Total cost within budget, positive equity cash flow, DSCR target and assumed site capacity; return target shown separately.
A11: Exclusions | B11: Personal/company income tax, capital gains tax and sale proceeds; acquisition costs and VAT must be validated.
A12: Sources | B12: Source links and dates in Sources; all cost and financing inputs are illustrative unless marked otherwise.

Sheet Inputs
A1: Input | B1: Value | C1: Units | D1: Basis / status
A2: Number of rooms | B2: 40 | C2: rooms | D2: Illustrative baseline
A3: Student monthly housing budget incl. charges | B3: 600 | C3: EUR/month | D3: User can replace with surveyed student budget
A4: Monthly charges paid by student | B4: 100 | C4: EUR/month | D4: Separate from rent; assumed to cover utilities only
A5: Local market rent comparator excl. charges | B5: 500 | C5: EUR/month | D5: Bru Kot room median EUR500 excl. charges; Brussels-wide listing data
A6: Conservative reference-rent planning ceiling | B6: 500 | C6: EUR/month | D6: UNVERIFIED placeholder, NOT a legal cap; replace with address-specific assessment
A7: Chosen base rent excl. charges | B7: 475 | C7: EUR/month | D7: Investor proposal
A8: Occupancy | B8: 0.95 | C8: % | D8: Assumption; all 12 months are billable
A9: Billable months | B9: 12 | C9: months/year | D9: Adjust for 10-month contracts
A10: Land / property acquisition | B10: 900000 | C10: EUR | D10: Land for new build; avoid double counting existing structure
A11: Gross floor area per room incl. common areas | B11: 34 | C11: m²/room | D11: Planning assumption, not minimum legal room area
A12: Build cost per gross m² | B12: 2400 | C12: EUR/m² | D12: Assumed VAT-inclusive; validate with contractor
A13: Furnishing per room | B13: 5000 | C13: EUR/room | D13: Assumption
... A30: Net private room area | B30: 18 | C30: m² | D30: Illustrative design; 12 m² student dwelling minimum is not full planning clearance

Sheet Investment
A1: Measure | B1: Value | C1: Meaning
A2: Affordable base rent | B2: =MAX(0,MIN(Inputs!B3-Inputs!B4,Inputs!B5,Inputs!B6,Inputs!B7)) -> 475 | C2: Student budget and comparator constrained
A3: All-in student monthly payment | B3: =B2+Inputs!B4 -> 575 | C3: Rent + utility charge
A4: Gross floor area | B4: =Inputs!B2*Inputs!B11 -> 1360 | C4: m²
A5: Build cost | B5: =B4*Inputs!B12 -> 3264000 | C5: EUR
A6: Furnishing | B6: =Inputs!B2*Inputs!B13 -> 200000 | C6: EUR
A7: Contingency | B7: =(B5+B6)*Inputs!B15 -> 346400 | C7: EUR
A8: Total project investment | B8: =Inputs!B10+B5+B6+B7+Inputs!B14 -> 4960400 | C8: All-in development capital
A9: Loan | B9: =B8*Inputs!B19 -> 1736140 | C9: EUR
A10: Required equity | B10: =B8-B9 -> 3224260 | C10: EUR
A11: Potential annual base rent | B11: =Inputs!B2*B2*Inputs!B9 -> 228000 | C11: Excludes charges
A12: Collected annual rent | B12: =B11*Inputs!B8 -> 216600 | C12: Vacancy adjusted
A13: Operating expenses | B13: =B12*Inputs!B16 -> 54150 | C13: Year one
A14: Net operating income (NOI) | B14: =B12-B13 -> 162450 | C14: Before debt and income tax
A15: Annual debt service | B15: =IF(B9=0,0,IF(Inputs!B20=0,B9/Inputs!B21,-PMT(Inputs!B20,Inputs!B21,B9))) -> 117083.59 | C15: Principal + interest
A16: Annual equity cash flow | B16: =B14-B15 -> 45366.406 | C16: Before investor income tax
A17: Unlevered net yield | B17: =B14/B8 -> 0.032749375 | C17: NOI / all-in investment
A18: Cash-on-cash equity return | B18: =B16/B10 -> 0.014070331 | C18: Annual equity cash flow / equity
A19: DSCR | B19: =IF(B15=0,999,B14/B15) -> 1.3874702 | C19: NOI / debt service
A20: Static project payback years | B20: =IF(B14>0,B8/B14,999)+Inputs!B28 -> 32.534934 | C20: Includes development delay; no escalation
A21: Static equity payback years | B21: =IF(B16>0,B10/B16,999)+Inputs!B28 -> 73.071533 | C21: Includes development delay; before income tax
A22: Rent needed for required net yield | B22: =B8*Inputs!B25/(Inputs!B2*Inputs!B9*Inputs!B8*(1-Inputs!B16)) -> 652.68421 | C22: Excl. charges; compare with affordable rent
A23: Budget and debt feasibility | B23: =IF(AND(B8<=Inputs!B22,B10<=Inputs!B23,B16>0,B19>=Inputs!B24,Inputs!B2<=Inputs!B29),"PASS","FAIL") -> PASS | C23: Yield target assessed separately
A24: Required net yield met | B24: =IF(B17>=Inputs!B25,"YES","NO") -> NO | C24: Target is not a forecast
A25: NPV excluding terminal value | B25: =NPV(Inputs!B26,'Annual cash flow'!F3:F42)+'Annual cash flow'!F2 -> -2535050.7 | C25: 40-year cash flow range; inactive years set to zero
A26: IRR excluding terminal value | B26: =IFERROR(IRR('Annual cash flow'!F2:F42),"No IRR") -> 0.014088073 | C26: Zero cash flow after horizon
A27: Dynamic project payback | B27: =IFERROR(MATCH(1,'Annual cash flow'!J2:J42,0)-1,"Beyond model horizon") -> 27 | C27: First end-year cumulative unlevered cash flow >= 0
A28: Maximum investment at target yield | B28: =B14/Inputs!B25 -> 3610000
A29: Cost reduction needed for target yield | B29: =MAX(0,B8-B28) -> 1350400
A30: Unlevered yield at ten collected months | B30: =B14*10/Inputs!B9/B8 -> 0.027291146
A31: Legal reference verified? | B31: NO — exact address and dwelling details missing
A32: Dynamic equity payback | B32: =IFERROR(MATCH(1,'Annual cash flow'!L2:L42,0)-1,"Beyond model horizon") -> 32

Sheet Annual cash flow
A1: Year | B1: Operating year | C1: Rent | D1: Operating costs | E1: NOI | F1: Project cash flow | G1: Debt service | H1: Equity cash flow | I1: Cumulative project CF | J1: Payback flag | K1: Cumulative equity CF | L1: Equity payback flag
A2: 0 | B2: =MAX(0,A2-Inputs!B28) -> 0 | C2: =IF(AND(B2>0,B2<=Inputs!B27),Investment!B12*(1+Inputs!B17)^(B2-1),0) -> 0 | D2: =IF(AND(B2>0,B2<=Inputs!B27),Investment!B13*(1+Inputs!B18)^(B2-1),0) -> 0 | E2: =C2-D2 -> 0 | F2: =-Investment!B8 -> -4960400 | G2: =IF(AND(B2>0,B2<=Inputs!B21),Investment!B15,0) -> 0 | H2: =-Investment!B10 -> -3224260 | I2: =F2 -> -4960400 | J2: =IF(I2>=0,1,0) -> 0 | K2: =H2 -> -3224260 | L2: =IF(K2>=0,1,0) -> 0
A3: 1 | B3: =MAX(0,A3-Inputs!B28) -> 0 | C3: =IF(AND(B3>0,B3<=Inputs!B27),Investment!B12*(1+Inputs!B17)^(B3-1),0) -> 0 | D3: =IF(AND(B3>0,B3<=Inputs!B27),Investment!B13*(1+Inputs!B18)^(B3-1),0) -> 0 | E3: =C3-D3 -> 0 | F3: =E3 -> 0 | G3: =IF(AND(B3>0,B3<=Inputs!B21),Investment!B15,0) -> 0 | H3: =E3-G3 -> 0 | I3: =I2+F3 -> -4960400 | J3: =IF(I3>=0,1,0) -> 0 | K3: =K2+H3 -> -3224260 | L3: =IF(K3>=0,1,0) -> 0
A4: 2 | B4: =MAX(0,A4-Inputs!B28) -> 0 | C4: =IF(AND(B4>0,B4<=Inputs!B27),Investment!B12*(1+Inputs!B17)^(B4-1),0) -> 0 | D4: =IF(AND(B4>0,B4<=Inputs!B27),Investment!B13*(1+Inputs!B18)^(B4-1),0) -> 0 | E4: =C4-D4 -> 0 | F4: =E4 -> 0 | G4: =IF(AND(B4>0,B4<=Inputs!B21),Investment!B15,0) -> 0 | H4: =E4-G4 -> 0 | I4: =I3+F4 -> -4960400 | J4: =IF(I4>=0,1,0) -> 0 | K4: =K3+H4 -> -3224260 | L4: =IF(K4>=0,1,0) -> 0
A5: 3 | B5: =MAX(0,A5-Inputs!B28) -> 1 | C5: =IF(AND(B5>0,B5<=Inputs!B27),Investment!B12*(1+Inputs!B17)^(B5-1),0) -> 216600 | D5: =IF(AND(B5>0,B5<=Inputs!B27),Investment!B13*(1+Inputs!B18)^(B5-1),0) -> 54150 | E5: =C5-D5 -> 162450 | F5: =E5 -> 162450 | G5: =IF(AND(B5>0,B5<=Inputs!B21),Investment!B15,0) -> 117083.59 | H5: =E5-G5 -> 45366.406 | I5: =I4+F5 -> -4797950 | J5: =IF(I5>=0,1,0) -> 0 | K5: =K4+H5 -> -3178893.6 | L5: =IF(K5>=0,1,0) -> 0
A6: 4 | B6: =MAX(0,A6-Inputs!B28) -> 2 | C6: =IF(AND(B6>0,B6<=Inputs!B27),Investment!B12*(1+Inputs!B17)^(B6-1),0) -> 220932 | D6: =IF(AND(B6>0,B6<=Inputs!B27),Investment!B13*(1+Inputs!B18)^(B6-1),0) -> 55503.75 | E6: =C6-D6 -> 165428.25 | F6: =E6 -> 165428.25 | G6: =IF(AND(B6>0,B6<=Inputs!B21),Investment!B15,0) -> 117083.59 | H6: =E6-G6 -> 48344.656 | I6: =I5+F6 -> -4632521.8 | J6: =IF(I6>=0,1,0) -> 0 | K6: =K5+H6 -> -3130548.9 | L6: =IF(K6>=0,1,0) -> 0
A7: 5 | B7: =MAX(0,A7-Inputs!B28) -> 3 | C7: =IF(AND(B7>0,B7<=Inputs!B27),Investment!B12*(1+Inputs!B17)^(B7-1),0) -> 225350.64 | D7: =IF(AND(B7>0,B7<=Inputs!B27),Investment!B13*(1+Inputs!B18)^(B7-1),0) -> 56891.344 | E7: =C7-D7 -> 168459.3 | F7: =E7 -> 168459.3 | G7: =IF(AND(B7>0,B7<=Inputs!B21),Investment!B15,0) -> 117083.59 | H7: =E7-G7 -> 51375.702 | I7: =I6+F7 -> -4464062.5 | J7: =IF(I7>=0,1,0) -> 0 | K7: =K6+H7 -> -3079173.2 | L7: =IF(K7>=0,1,0) -> 0
A8: 6 | B8: =MAX(0,A8-Inputs!B28) -> 4 | C8: =IF(AND(B8>0,B8<=Inputs!B27),Investment!B12*(1+Inputs!B17)^(B8-1),0) -> 229857.65 | D8: =IF(AND(B8>0,B8<=Inputs!B27),Investment!B13*(1+Inputs!B18)^(B8-1),0) -> 58313.627 | E8: =C8-D8 -> 171544.03 | F8: =E8 -> 171544.03 | G8: =IF(AND(B8>0,B8<=Inputs!B21),Investment!B15,0) -> 117083.59 | H8: =E8-G8 -> 54460.431 | I8: =I7+F8 -> -4292518.4 | J8: =IF(I8>=0,1,0) -> 0 | K8: =K7+H8 -> -3024712.8 | L8: =IF(K8>=0,1,0) -> 0
A9: 7 | B9: =MAX(0,A9-Inputs!B28) -> 5 | C9: =IF(AND(B9>0,B9<=Inputs!B27),Investment!B12*(1+Inputs!B17)^(B9-1),0) -> 234454.81 | D9: =IF(AND(B9>0,B9<=Inputs!B27),Investment!B13*(1+Inputs!B18)^(B9-1),0) -> 59771.468 | E9: =C9-D9 -> 174683.34 | F9: =E9 -> 174683.34 | G9: =IF(AND(B9>0,B9<=Inputs!B21),Investment!B15,0) -> 117083.59 | H9: =E9-G9 -> 57599.744 | I9: =I8+F9 -> -4117835.1 | J9: =IF(I9>=0,1,0) -> 0 | K9: =K8+H9 -> -2967113.1 | L9: =IF(K9>=0,1,0) -> 0
A10: 8 | B10: =MAX(0,A10-Inputs!B28) -> 6 | C10: =IF(AND(B10>0,B10<=Inputs!B27),Investment!B12*(1+Inputs!B17)^(B10-1),0) -> 239143.9 | D10: =IF(AND(B10>0,B10<=Inputs!B27),Investment!B13*(1+Inputs!B18)^(B10-1),0) -> 61265.755 | E10: =C10-D10 -> 177878.15 | F10: =E10 -> 177878.15 | G10: =IF(AND(B10>0,B10<=Inputs!B21),Investment!B15,0) -> 117083.59 | H10: =E10-G10 -> 60794.553 | I10: =I9+F10 -> -3939956.9 | J10: =IF(I10>=0,1,0) -> 0 | K10: =K9+H10 -> -2906318.5 | L10: =IF(K10>=0,1,0) -> 0
A11: 9 | B11: =MAX(0,A11-Inputs!B28) -> 7 | C11: =IF(AND(B11>0,B11<=Inputs!B27),Investment!B12*(1+Inputs!B17)^(B11-1),0) -> 243926.78 | D11: =IF(AND(B11>0,B11<=Inputs!B27),Investment!B13*(1+Inputs!B18)^(B11-1),0) -> 62797.399 | E11: =C11-D11 -> 181129.38 | F11: =E11 -> 181129.38 | G11: =IF(AND(B11>0,B11<=Inputs!B21),Investment!B15,0) -> 117083.59 | H11: =E11-G11 -> 64045.787 | I11: =I10+F11 -> -3758827.6 | J11: =IF(I11>=0,1,0) -> 0 | K11: =K10+H11 -> -2842272.7 | L11: =IF(K11>=0,1,0) -> 0
A12: 10 | B12: =MAX(0,A12-Inputs!B28) -> 8 | C12: =IF(AND(B12>0,B12<=Inputs!B27),Investment!B12*(1+Inputs!B17)^(B12-1),0) -> 248805.32 | D12: =IF(AND(B12>0,B12<=Inputs!B27),Investment!B13*(1+Inputs!B18)^(B12-1),0) -> 64367.334 | E12: =C12-D12 -> 184437.98 | F12: =E12 -> 184437.98 | G12: =IF(AND(B12>0,B12<=Inputs!B21),Investment!B15,0) -> 117083.59 | H12: =E12-G12 -> 67354.388 | I12: =I11+F12 -> -3574389.6 | J12: =IF(I12>=0,1,0) -> 0 | K12: =K11+H12 -> -2774918.3 | L12: =IF(K12>=0,1,0) -> 0
A13: 11 | B13: =MAX(0,A13-Inputs!B28) -> 9 | C13: =IF(AND(B13>0,B13<=Inputs!B27),Investment!B12*(1+Inputs!B17)^(B13-1),0) -> 253781.42 | D13: =IF(AND(B13>0,B13<=Inputs!B27),Investment!B13*(1+Inputs!B18)^(B13-1),0) -> 65976.517 | E13: =C13-D13 -> 187804.91 | F13: =E13 -> 187804.91 | G13: =IF(AND(B13>0,B13<=Inputs!B21),Investment!B15,0) -> 117083.59 | H13: =E13-G13 -> 70721.311 | I13: =I12+F13 -> -3386584.7 | J13: =IF(I13>=0,1,0) -> 0 | K13: =K12+H13 -> -2704197 | L13: =IF(K13>=0,1,0) -> 0
A14: 12 | B14: =MAX(0,A14-Inputs!B28) -> 10 | C14: =IF(AND(B14>0,B14<=Inputs!B27),Investment!B12*(1+Inputs!B17)^(B14-1),0) -> 258857.05 | D14: =IF(AND(B14>0,B14<=Inputs!B27),Investment!B13*(1+Inputs!B18)^(B14-1),0) -> 67625.93 | E14: =C14-D14 -> 191231.12 | F14: =E14 -> 191231.12 | G14: =IF(AND(B14>0,B14<=Inputs!B21),Investment!B15,0) -> 117083.59 | H14: =E14-G14 -> 74147.526 | I14: =I13+F14 -> -3195353.6 | J14: =IF(I14>=0,1,0) -> 0 | K14: =K13+H14 -> -2630049.5 | L14: =IF(K14>=0,1,0) -> 0
A15: 13 | B15: =MAX(0,A15-Inputs!B28) -> 11 | C15: =IF(AND(B15>0,B15<=Inputs!B27),Investment!B12*(1+Inputs!B17)^(B15-1),0) -> 264034.19 | D15: =IF(AND(B15>0,B15<=Inputs!B27),Investment!B13*(1+Inputs!B18)^(B15-1),0) -> 69316.578 | E15: =C15-D15 -> 194717.61 | F15: =E15 -> 194717.61 | G15: =IF(AND(B15>0,B15<=Inputs!B21),Investment!B15,0) -> 117083.59 | H15: =E15-G15 -> 77634.019 | I15: =I14+F15 -> -3000635.9 | J15: =IF(I15>=0,1,0) -> 0 | K15: =K14+H15 -> -2552415.5 | L15: =IF(K15>=0,1,0) -> 0
A16: 14 | B16: =MAX(0,A16-Inputs!B28) -> 12 | C16: =IF(AND(B16>0,B16<=Inputs!B27),Investment!B12*(1+Inputs!B17)^(B16-1),0) -> 269314.88 | D16: =IF(AND(B16>0,B16<=Inputs!B27),Investment!B13*(1+Inputs!B18)^(B16-1),0) -> 71049.493 | E16: =C16-D16 -> 198265.38 | F16: =E16 -> 198265.38 | G16: =IF(AND(B16>0,B16<=Inputs!B21),Investment!B15,0) -> 117083.59 | H16: =E16-G16 -> 81181.789 | I16: =I15+F16 -> -2802370.6 | J16: =IF(I16>=0,1,0) -> 0 | K16: =K15+H16 -> -2471233.7 | L16: =IF(K16>=0,1,0) -> 0
A17: 15 | B17: =MAX(0,A17-Inputs!B28) -> 13 | C17: =IF(AND(B17>0,B17<=Inputs!B27),Investment!B12*(1+Inputs!B17)^(B17-1),0) -> 274701.17 | D17: =IF(AND(B17>0,B17<=Inputs!B27),Investment!B13*(1+Inputs!B18)^(B17-1),0) -> 72825.73 | E17: =C17-D17 -> 201875.44 | F17: =E17 -> 201875.44 | G17: =IF(AND(B17>0,B17<=Inputs!B21),Investment!B15,0) -> 117083.59 | H17: =E17-G17 -> 84791.849 | I17: =I16+F17 -> -2600495.1 | J17: =IF(I17>=0,1,0) -> 0 | K17: =K16+H17 -> -2386441.8 | L17: =IF(K17>=0,1,0) -> 0
A18: 16 | B18: =MAX(0,A18-Inputs!B28) -> 14 | C18: =IF(AND(B18>0,B18<=Inputs!B27),Investment!B12*(1+Inputs!B17)^(B18-1),0) -> 280195.2 | D18: =IF(AND(B18>0,B18<=Inputs!B27),Investment!B13*(1+Inputs!B18)^(B18-1),0) -> 74646.373 | E18: =C18-D18 -> 205548.82 | F18: =E18 -> 205548.82 | G18: =IF(AND(B18>0,B18<=Inputs!B21),Investment!B15,0) -> 117083.59 | H18: =E18-G18 -> 88465.229 | I18: =I17+F18 -> -2394946.3 | J18: =IF(I18>=0,1,0) -> 0 | K18: =K17+H18 -> -2297976.6 | L18: =IF(K18>=0,1,0) -> 0
A19: 17 | B19: =MAX(0,A19-Inputs!B28) -> 15 | C19: =IF(AND(B19>0,B19<=Inputs!B27),Investment!B12*(1+Inputs!B17)^(B19-1),0) -> 285799.1 | D19: =IF(AND(B19>0,B19<=Inputs!B27),Investment!B13*(1+Inputs!B18)^(B19-1),0) -> 76512.532 | E19: =C19-D19 -> 209286.57 | F19: =E19 -> 209286.57 | G19: =IF(AND(B19>0,B19<=Inputs!B21),Investment!B15,0) -> 117083.59 | H19: =E19-G19 -> 92202.974 | I19: =I18+F19 -> -2185659.7 | J19: =IF(I19>=0,1,0) -> 0 | K19: =K18+H19 -> -2205773.6 | L19: =IF(K19>=0,1,0) -> 0
A20: 18 | B20: =MAX(0,A20-Inputs!B28) -> 16 | C20: =IF(AND(B20>0,B20<=Inputs!B27),Investment!B12*(1+Inputs!B17)^(B20-1),0) -> 291515.08 | D20: =IF(AND(B20>0,B20<=Inputs!B27),Investment!B13*(1+Inputs!B18)^(B20-1),0) -> 78425.346 | E20: =C20-D20 -> 213089.74 | F20: =E20 -> 213089.74 | G20: =IF(AND(B20>0,B20<=Inputs!B21),Investment!B15,0) -> 117083.59 | H20: =E20-G20 -> 96006.142 | I20: =I19+F20 -> -1972570 | J20: =IF(I20>=0,1,0) -> 0 | K20: =K19+H20 -> -2109767.5 | L20: =IF(K20>=0,1,0) -> 0
A21: 19 | B21: =MAX(0,A21-Inputs!B28) -> 17 | C21: =IF(AND(B21>0,B21<=Inputs!B27),Investment!B12*(1+Inputs!B17)^(B21-1),0) -> 297345.38 | D21: =IF(AND(B21>0,B21<=Inputs!B27),Investment!B13*(1+Inputs!B18)^(B21-1),0) -> 80385.979 | E21: =C21-D21 -> 216959.4 | F21: =E21 -> 216959.4 | G21: =IF(AND(B21>0,B21<=Inputs!B21),Investment!B15,0) -> 117083.59 | H21: =E21-G21 -> 99875.81 | I21: =I20+F21 -> -1755610.6 | J21: =IF(I21>=0,1,0) -> 0 | K21: =K20+H21 -> -2009891.7 | L21: =IF(K21>=0,1,0) -> 0
A22: 20 | B22: =MAX(0,A22-Inputs!B28) -> 18 | C22: =IF(AND(B22>0,B22<=Inputs!B27),Investment!B12*(1+Inputs!B17)^(B22-1),0) -> 303292.29 | D22: =IF(AND(B22>0,B22<=Inputs!B27),Investment!B13*(1+Inputs!B18)^(B22-1),0) -> 82395.629 | E22: =C22-D22 -> 220896.66 | F22: =E22 -> 220896.66 | G22: =IF(AND(B22>0,B22<=Inputs!B21),Investment!B15,0) -> 117083.59 | H22: =E22-G22 -> 103813.07 | I22: =I21+F22 -> -1534713.9 | J22: =IF(I22>=0,1,0) -> 0 | K22: =K21+H22 -> -1906078.6 | L22: =IF(K22>=0,1,0) -> 0
A23: 21 | B23: =MAX(0,A23-Inputs!B28) -> 19 | C23: =IF(AND(B23>0,B23<=Inputs!B27),Investment!B12*(1+Inputs!B17)^(B23-1),0) -> 309358.14 | D23: =IF(AND(B23>0,B23<=Inputs!B27),Investment!B13*(1+Inputs!B18)^(B23-1),0) -> 84455.52 | E23: =C23-D23 -> 224902.62 | F23: =E23 -> 224902.62 | G23: =IF(AND(B23>0,B23<=Inputs!B21),Investment!B15,0) -> 117083.59 | H23: =E23-G23 -> 107819.02 | I23: =I22+F23 -> -1309811.3 | J23: =IF(I23>=0,1,0) -> 0 | K23: =K22+H23 -> -1798259.6 | L23: =IF(K23>=0,1,0) -> 0
A24: 22 | B24: =MAX(0,A24-Inputs!B28) -> 20 | C24: =IF(AND(B24>0,B24<=Inputs!B27),Investment!B12*(1+Inputs!B17)^(B24-1),0) -> 315545.3 | D24: =IF(AND(B24>0,B24<=Inputs!B27),Investment!B13*(1+Inputs!B18)^(B24-1),0) -> 86566.908 | E24: =C24-D24 -> 228978.39 | F24: =E24 -> 228978.39 | G24: =IF(AND(B24>0,B24<=Inputs!B21),Investment!B15,0) -> 117083.59 | H24: =E24-G24 -> 111894.8 | I24: =I23+F24 -> -1080832.9 | J24: =IF(I24>=0,1,0) -> 0 | K24: =K23+H24 -> -1686364.8 | L24: =IF(K24>=0,1,0) -> 0
A25: 23 | B25: =MAX(0,A25-Inputs!B28) -> 21 | C25: =IF(AND(B25>0,B25<=Inputs!B27),Investment!B12*(1+Inputs!B17)^(B25-1),0) -> 321856.21 | D25: =IF(AND(B25>0,B25<=Inputs!B27),Investment!B13*(1+Inputs!B18)^(B25-1),0) -> 88731.08 | E25: =C25-D25 -> 233125.13 | F25: =E25 -> 233125.13 | G25: =IF(AND(B25>0,B25<=Inputs!B21),Investment!B15,0) -> 117083.59 | H25: =E25-G25 -> 116041.53 | I25: =I24+F25 -> -847707.79 | J25: =IF(I25>=0,1,0) -> 0 | K25: =K24+H25 -> -1570323.3 | L25: =IF(K25>=0,1,0) -> 0
A26: 24 | B26: =MAX(0,A26-Inputs!B28) -> 22 | C26: =IF(AND(B26>0,B26<=Inputs!B27),Investment!B12*(1+Inputs!B17)^(B26-1),0) -> 328293.33 | D26: =IF(AND(B26>0,B26<=Inputs!B27),Investment!B13*(1+Inputs!B18)^(B26-1),0) -> 90949.357 | E26: =C26-D26 -> 237343.97 | F26: =E26 -> 237343.97 | G26: =IF(AND(B26>0,B26<=Inputs!B21),Investment!B15,0) -> 117083.59 | H26: =E26-G26 -> 120260.38 | I26: =I25+F26 -> -610363.81 | J26: =IF(I26>=0,1,0) -> 0 | K26: =K25+H26 -> -1450062.9 | L26: =IF(K26>=0,1,0) -> 0
A27: 25 | B27: =MAX(0,A27-Inputs!B28) -> 23 | C27: =IF(AND(B27>0,B27<=Inputs!B27),Investment!B12*(1+Inputs!B17)^(B27-1),0) -> 334859.2 | D27: =IF(AND(B27>0,B27<=Inputs!B27),Investment!B13*(1+Inputs!B18)^(B27-1),0) -> 93223.091 | E27: =C27-D27 -> 241636.11 | F27: =E27 -> 241636.11 | G27: =IF(AND(B27>0,B27<=Inputs!B21),Investment!B15,0) -> 117083.59 | H27: =E27-G27 -> 124552.51 | I27: =I26+F27 -> -368727.71 | J27: =IF(I27>=0,1,0) -> 0 | K27: =K26+H27 -> -1325510.4 | L27: =IF(K27>=0,1,0) -> 0
A28: 26 | B28: =MAX(0,A28-Inputs!B28) -> 24 | C28: =IF(AND(B28>0,B28<=Inputs!B27),Investment!B12*(1+Inputs!B17)^(B28-1),0) -> 341556.38 | D28: =IF(AND(B28>0,B28<=Inputs!B27),Investment!B13*(1+Inputs!B18)^(B28-1),0) -> 95553.668 | E28: =C28-D28 -> 246002.71 | F28: =E28 -> 246002.71 | G28: =IF(AND(B28>0,B28<=Inputs!B21),Investment!B15,0) -> 117083.59 | H28: =E28-G28 -> 128919.12 | I28: =I27+F28 -> -122724.99 | J28: =IF(I28>=0,1,0) -> 0 | K28: =K27+H28 -> -1196591.3 | L28: =IF(K28>=0,1,0) -> 0
A29: 27 | B29: =MAX(0,A29-Inputs!B28) -> 25 | C29: =IF(AND(B29>0,B29<=Inputs!B27),Investment!B12*(1+Inputs!B17)^(B29-1),0) -> 348387.51 | D29: =IF(AND(B29>0,B29<=Inputs!B27),Investment!B13*(1+Inputs!B18)^(B29-1),0) -> 97942.51 | E29: =C29-D29 -> 250445 | F29: =E29 -> 250445 | G29: =IF(AND(B29>0,B29<=Inputs!B21),Investment!B15,0) -> 117083.59 | H29: =E29-G29 -> 133361.4 | I29: =I28+F29 -> 127720 | J29: =IF(I29>=0,1,0) -> 1 | K29: =K28+H29 -> -1063229.9 | L29: =IF(K29>=0,1,0) -> 0
A30: 28 | B30: =MAX(0,A30-Inputs!B28) -> 26 | C30: =IF(AND(B30>0,B30<=Inputs!B27),Investment!B12*(1+Inputs!B17)^(B30-1),0) -> 355355.26 | D30: =IF(AND(B30>0,B30<=Inputs!B27),Investment!B13*(1+Inputs!B18)^(B30-1),0) -> 100391.07 | E30: =C30-D30 -> 254964.19 | F30: =E30 -> 254964.19 | G30: =IF(AND(B30>0,B30<=Inputs!B21),Investment!B15,0) -> 0 | H30: =E30-G30 -> 254964.19 | I30: =I29+F30 -> 382684.19 | J30: =IF(I30>=0,1,0) -> 1 | K30: =K29+H30 -> -808265.66 | L30: =IF(K30>=0,1,0) -> 0
A31: 29 | B31: =MAX(0,A31-Inputs!B28) -> 27 | C31: =IF(AND(B31>0,B31<=Inputs!B27),Investment!B12*(1+Inputs!B17)^(B31-1),0) -> 362462.36 | D31: =IF(AND(B31>0,B31<=Inputs!B27),Investment!B13*(1+Inputs!B18)^(B31-1),0) -> 102900.85 | E31: =C31-D31 -> 259561.51 | F31: =E31 -> 259561.51 | G31: =IF(AND(B31>0,B31<=Inputs!B21),Investment!B15,0) -> 0 | H31: =E31-G31 -> 259561.51 | I31: =I30+F31 -> 642245.7 | J31: =IF(I31>=0,1,0) -> 1 | K31: =K30+H31 -> -548704.15 | L31: =IF(K31>=0,1,0) -> 0
A32: 30 | B32: =MAX(0,A32-Inputs!B28) -> 28 | C32: =IF(AND(B32>0,B32<=Inputs!B27),Investment!B12*(1+Inputs!B17)^(B32-1),0) -> 369711.61 | D32: =IF(AND(B32>0,B32<=Inputs!B27),Investment!B13*(1+Inputs!B18)^(B32-1),0) -> 105473.37 | E32: =C32-D32 -> 264238.24 | F32: =E32 -> 264238.24 | G32: =IF(AND(B32>0,B32<=Inputs!B21),Investment!B15,0) -> 0 | H32: =E32-G32 -> 264238.24 | I32: =I31+F32 -> 906483.94 | J32: =IF(I32>=0,1,0) -> 1 | K32: =K31+H32 -> -284465.91 | L32: =IF(K32>=0,1,0) -> 0
A33: 31 | B33: =MAX(0,A33-Inputs!B28) -> 29 | C33: =IF(AND(B33>0,B33<=Inputs!B27),Investment!B12*(1+Inputs!B17)^(B33-1),0) -> 377105.84 | D33: =IF(AND(B33>0,B33<=Inputs!B27),Investment!B13*(1+Inputs!B18)^(B33-1),0) -> 108110.21 | E33: =C33-D33 -> 268995.64 | F33: =E33 -> 268995.64 | G33: =IF(AND(B33>0,B33<=Inputs!B21),Investment!B15,0) -> 0 | H33: =E33-G33 -> 268995.64 | I33: =I32+F33 -> 1175479.6 | J33: =IF(I33>=0,1,0) -> 1 | K33: =K32+H33 -> -15470.273 | L33: =IF(K33>=0,1,0) -> 0
A34: 32 | B34: =MAX(0,A34-Inputs!B28) -> 30 | C34: =IF(AND(B34>0,B34<=Inputs!B27),Investment!B12*(1+Inputs!B17)^(B34-1),0) -> 384647.96 | D34: =IF(AND(B34>0,B34<=Inputs!B27),Investment!B13*(1+Inputs!B18)^(B34-1),0) -> 110812.96 | E34: =C34-D34 -> 273835 | F34: =E34 -> 273835 | G34: =IF(AND(B34>0,B34<=Inputs!B21),Investment!B15,0) -> 0 | H34: =E34-G34 -> 273835 | I34: =I33+F34 -> 1449314.6 | J34: =IF(I34>=0,1,0) -> 1 | K34: =K33+H34 -> 258364.73 | L34: =IF(K34>=0,1,0) -> 1
A35: 33 | B35: =MAX(0,A35-Inputs!B28) -> 31 | C35: =IF(AND(B35>0,B35<=Inputs!B27),Investment!B12*(1+Inputs!B17)^(B35-1),0) -> 0 | D35: =IF(AND(B35>0,B35<=Inputs!B27),Investment!B13*(1+Inputs!B18)^(B35-1),0) -> 0 | E35: =C35-D35 -> 0 | F35: =E35 -> 0 | G35: =IF(AND(B35>0,B35<=Inputs!B21),Investment!B15,0) -> 0 | H35: =E35-G35 -> 0 | I35: =I34+F35 -> 1449314.6 | J35: =IF(I35>=0,1,0) -> 1 | K35: =K34+H35 -> 258364.73 | L35: =IF(K35>=0,1,0) -> 1
A36: 34 | B36: =MAX(0,A36-Inputs!B28) -> 32 | C36: =IF(AND(B36>0,B36<=Inputs!B27),Investment!B12*(1+Inputs!B17)^(B36-1),0) -> 0 | D36: =IF(AND(B36>0,B36<=Inputs!B27),Investment!B13*(1+Inputs!B18)^(B36-1),0) -> 0 | E36: =C36-D36 -> 0 | F36: =E36 -> 0 | G36: =IF(AND(B36>0,B36<=Inputs!B21),Investment!B15,0) -> 0 | H36: =E36-G36 -> 0 | I36: =I35+F36 -> 1449314.6 | J36: =IF(I36>=0,1,0) -> 1 | K36: =K35+H36 -> 258364.73 | L36: =IF(K36>=0,1,0) -> 1
A37: 35 | B37: =MAX(0,A37-Inputs!B28) -> 33 | C37: =IF(AND(B37>0,B37<=Inputs!B27),Investment!B12*(1+Inputs!B17)^(B37-1),0) -> 0 | D37: =IF(AND(B37>0,B37<=Inputs!B27),Investment!B13*(1+Inputs!B18)^(B37-1),0) -> 0 | E37: =C37-D37 -> 0 | F37: =E37 -> 0 | G37: =IF(AND(B37>0,B37<=Inputs!B21),Investment!B15,0) -> 0 | H37: =E37-G37 -> 0 | I37: =I36+F37 -> 1449314.6 | J37: =IF(I37>=0,1,0) -> 1 | K37: =K36+H37 -> 258364.73 | L37: =IF(K37>=0,1,0) -> 1
A38: 36 | B38: =MAX(0,A38-Inputs!B28) -> 34 | C38: =IF(AND(B38>0,B38<=Inputs!B27),Investment!B12*(1+Inputs!B17)^(B38-1),0) -> 0 | D38: =IF(AND(B38>0,B38<=Inputs!B27),Investment!B13*(1+Inputs!B18)^(B38-1),0) -> 0 | E38: =C38-D38 -> 0 | F38: =E38 -> 0 | G38: =IF(AND(B38>0,B38<=Inputs!B21),Investment!B15,0) -> 0 | H38: =E38-G38 -> 0 | I38: =I37+F38 -> 1449314.6 | J38: =IF(I38>=0,1,0) -> 1 | K38: =K37+H38 -> 258364.73 | L38: =IF(K38>=0,1,0) -> 1
A39: 37 | B39: =MAX(0,A39-Inputs!B28) -> 35 | C39: =IF(AND(B39>0,B39<=Inputs!B27),Investment!B12*(1+Inputs!B17)^(B39-1),0) -> 0 | D39: =IF(AND(B39>0,B39<=Inputs!B27),Investment!B13*(1+Inputs!B18)^(B39-1),0) -> 0 | E39: =C39-D39 -> 0 | F39: =E39 -> 0 | G39: =IF(AND(B39>0,B39<=Inputs!B21),Investment!B15,0) -> 0 | H39: =E39-G39 -> 0 | I39: =I38+F39 -> 1449314.6 | J39: =IF(I39>=0,1,0) -> 1 | K39: =K38+H39 -> 258364.73 | L39: =IF(K39>=0,1,0) -> 1
A40: 38 | B40: =MAX(0,A40-Inputs!B28) -> 36 | C40: =IF(AND(B40>0,B40<=Inputs!B27),Investment!B12*(1+Inputs!B17)^(B40-1),0) -> 0 | D40: =IF(AND(B40>0,B40<=Inputs!B27),Investment!B13*(1+Inputs!B18)^(B40-1),0) -> 0 | E40: =C40-D40 -> 0 | F40: =E40 -> 0 | G40: =IF(AND(B40>0,B40<=Inputs!B21),Investment!B15,0) -> 0 | H40: =E40-G40 -> 0 | I40: =I39+F40 -> 1449314.6 | J40: =IF(I40>=0,1,0) -> 1 | K40: =K39+H40 -> 258364.73 | L40: =IF(K40>=0,1,0) -> 1
...

Sheet Room sizing
A1: Rooms | B1: Floor area m² | C1: Total cost | D1: Equity | E1: NOI | F1: Debt service | G1: Equity CF | H1: Net yield | I1: DSCR | J1: Feasible | K1: Rank value
A2: 12 | B2: =A2*Inputs!B11 -> 408 | C2: =Inputs!B10+Inputs!B14+(B2*Inputs!B12+A2*Inputs!B13)*(1+Inputs!B15) -> 2293120 | D2: =C2*(1-Inputs!B19) -> 1490528 | E2: =A2*Investment!B2*Inputs!B9*Inputs!B8*(1-Inputs!B16) -> 48735 | F2: =IF(Inputs!B19=0,0,IF(Inputs!B20=0,C2*Inputs!B19/Inputs!B21,-PMT(Inputs!B20,Inputs!B21,C2*Inputs!B19))) -> 54126.024 | G2: =E2-F2 -> -5391.0244 | H2: =E2/C2 -> 0.021252704 | I2: =IF(F2=0,999,E2/F2) -> 0.90039866 | J2: =IF(AND(C2<=Inputs!B22,D2<=Inputs!B23,G2>0,I2>=Inputs!B24,A2<=Inputs!B29),"YES","NO") -> NO | K2: =IF(J2="YES",G2,-1) -> -1
A3: 13 | B3: =A3*Inputs!B11 -> 442 | C3: =Inputs!B10+Inputs!B14+(B3*Inputs!B12+A3*Inputs!B13)*(1+Inputs!B15) -> 2388380 | D3: =C3*(1-Inputs!B19) -> 1552447 | E3: =A3*Investment!B2*Inputs!B9*Inputs!B8*(1-Inputs!B16) -> 52796.25 | F3: =IF(Inputs!B19=0,0,IF(Inputs!B20=0,C3*Inputs!B19/Inputs!B21,-PMT(Inputs!B20,Inputs!B21,C3*Inputs!B19))) -> 56374.509 | G3: =E3-F3 -> -3578.259 | H3: =E3/C3 -> 0.022105465 | I3: =IF(F3=0,999,E3/F3) -> 0.936527 | J3: =IF(AND(C3<=Inputs!B22,D3<=Inputs!B23,G3>0,I3>=Inputs!B24,A3<=Inputs!B29),"YES","NO") -> NO | K3: =IF(J3="YES",G3,-1) -> -1
A4: 14 | B4: =A4*Inputs!B11 -> 476 | C4: =Inputs!B10+Inputs!B14+(B4*Inputs!B12+A4*Inputs!B13)*(1+Inputs!B15) -> 2483640 | D4: =C4*(1-Inputs!B19) -> 1614366 | E4: =A4*Investment!B2*Inputs!B9*Inputs!B8*(1-Inputs!B16) -> 56857.5 | F4: =IF(Inputs!B19=0,0,IF(Inputs!B20=0,C4*Inputs!B19/Inputs!B21,-PMT(Inputs!B20,Inputs!B21,C4*Inputs!B19))) -> 58622.994 | G4: =E4-F4 -> -1765.4937 | H4: =E4/C4 -> 0.022892811 | I4: =IF(F4=0,999,E4/F4) -> 0.96988394 | J4: =IF(AND(C4<=Inputs!B22,D4<=Inputs!B23,G4>0,I4>=Inputs!B24,A4<=Inputs!B29),"YES","NO") -> NO | K4: =IF(J4="YES",G4,-1) -> -1
A5: 15 | B5: =A5*Inputs!B11 -> 510 | C5: =Inputs!B10+Inputs!B14+(B5*Inputs!B12+A5*Inputs!B13)*(1+Inputs!B15) -> 2578900 | D5: =C5*(1-Inputs!B19) -> 1676285 | E5: =A5*Investment!B2*Inputs!B9*Inputs!B8*(1-Inputs!B16) -> 60918.75 | F5: =IF(Inputs!B19=0,0,IF(Inputs!B20=0,C5*Inputs!B19/Inputs!B21,-PMT(Inputs!B20,Inputs!B21,C5*Inputs!B19))) -> 60871.478 | G5: =E5-F5 -> 47.271707 | H5: =E5/C5 -> 0.02362199 | I5: =IF(F5=0,999,E5/F5) -> 1.0007766 | J5: =IF(AND(C5<=Inputs!B22,D5<=Inputs!B23,G5>0,I5>=Inputs!B24,A5<=Inputs!B29),"YES","NO") -> NO | K5: =IF(J5="YES",G5,-1) -> -1
A6: 16 | B6: =A6*Inputs!B11 -> 544 | C6: =Inputs!B10+Inputs!B14+(B6*Inputs!B12+A6*Inputs!B13)*(1+Inputs!B15) -> 2674160 | D6: =C6*(1-Inputs!B19) -> 1738204 | E6: =A6*Investment!B2*Inputs!B9*Inputs!B8*(1-Inputs!B16) -> 64980 | F6: =IF(Inputs!B19=0,0,IF(Inputs!B20=0,C6*Inputs!B19/Inputs!B21,-PMT(Inputs!B20,Inputs!B21,C6*Inputs!B19))) -> 63119.963 | G6: =E6-F6 -> 1860.0371 | H6: =E6/C6 -> 0.024299219 | I6: =IF(F6=0,999,E6/F6) -> 1.0294683 | J6: =IF(AND(C6<=Inputs!B22,D6<=Inputs!B23,G6>0,I6>=Inputs!B24,A6<=Inputs!B29),"YES","NO") -> NO | K6: =IF(J6="YES",G6,-1) -> -1
A7: 17 | B7: =A7*Inputs!B11 -> 578 | C7: =Inputs!B10+Inputs!B14+(B7*Inputs!B12+A7*Inputs!B13)*(1+Inputs!B15) -> 2769420 | D7: =C7*(1-Inputs!B19) -> 1800123 | E7: =A7*Investment!B2*Inputs!B9*Inputs!B8*(1-Inputs!B16) -> 69041.25 | F7: =IF(Inputs!B19=0,0,IF(Inputs!B20=0,C7*Inputs!B19/Inputs!B21,-PMT(Inputs!B20,Inputs!B21,C7*Inputs!B19))) -> 65368.448 | G7: =E7-F7 -> 3672.8024 | H7: =E7/C7 -> 0.024929859 | I7: =IF(F7=0,999,E7/F7) -> 1.0561862 | J7: =IF(AND(C7<=Inputs!B22,D7<=Inputs!B23,G7>0,I7>=Inputs!B24,A7<=Inputs!B29),"YES","NO") -> NO | K7: =IF(J7="YES",G7,-1) -> -1
A8: 18 | B8: =A8*Inputs!B11 -> 612 | C8: =Inputs!B10+Inputs!B14+(B8*Inputs!B12+A8*Inputs!B13)*(1+Inputs!B15) -> 2864680 | D8: =C8*(1-Inputs!B19) -> 1862042 | E8: =A8*Investment!B2*Inputs!B9*Inputs!B8*(1-Inputs!B16) -> 73102.5 | F8: =IF(Inputs!B19=0,0,IF(Inputs!B20=0,C8*Inputs!B19/Inputs!B21,-PMT(Inputs!B20,Inputs!B21,C8*Inputs!B19))) -> 67616.932 | G8: =E8-F8 -> 5485.5678 | H8: =E8/C8 -> 0.025518557 | I8: =IF(F8=0,999,E8/F8) -> 1.0811271 | J8: =IF(AND(C8<=Inputs!B22,D8<=Inputs!B23,G8>0,I8>=Inputs!B24,A8<=Inputs!B29),"YES","NO") -> NO | K8: =IF(J8="YES",G8,-1) -> -1
A9: 19 | B9: =A9*Inputs!B11 -> 646 | C9: =Inputs!B10+Inputs!B14+(B9*Inputs!B12+A9*Inputs!B13)*(1+Inputs!B15) -> 2959940 | D9: =C9*(1-Inputs!B19) -> 1923961 | E9: =A9*Investment!B2*Inputs!B9*Inputs!B8*(1-Inputs!B16) -> 77163.75 | F9: =IF(Inputs!B19=0,0,IF(Inputs!B20=0,C9*Inputs!B19/Inputs!B21,-PMT(Inputs!B20,Inputs!B21,C9*Inputs!B19))) -> 69865.417 | G9: =E9-F9 -> 7298.3332 | H9: =E9/C9 -> 0.026069363 | I9: =IF(F9=0,999,E9/F9) -> 1.1044627 | J9: =IF(AND(C9<=Inputs!B22,D9<=Inputs!B23,G9>0,I9>=Inputs!B24,A9<=Inputs!B29),"YES","NO") -> NO | K9: =IF(J9="YES",G9,-1) -> -1
A10: 20 | B10: =A10*Inputs!B11 -> 680 | C10: =Inputs!B10+Inputs!B14+(B10*Inputs!B12+A10*Inputs!B13)*(1+Inputs!B15) -> 3055200 | D10: =C10*(1-Inputs!B19) -> 1985880 | E10: =A10*Investment!B2*Inputs!B9*Inputs!B8*(1-Inputs!B16) -> 81225 | F10: =IF(Inputs!B19=0,0,IF(Inputs!B20=0,C10*Inputs!B19/Inputs!B21,-PMT(Inputs!B20,Inputs!B21,C10*Inputs!B19))) -> 72113.901 | G10: =E10-F10 -> 9111.0985 | H10: =E10/C10 -> 0.026585821 | I10: =IF(F10=0,999,E10/F10) -> 1.1263432 | J10: =IF(AND(C10<=Inputs!B22,D10<=Inputs!B23,G10>0,I10>=Inputs!B24,A10<=Inputs!B29),"YES","NO") -> NO | K10: =IF(J10="YES",G10,-1) -> -1
A11: 21 | B11: =A11*Inputs!B11 -> 714 | C11: =Inputs!B10+Inputs!B14+(B11*Inputs!B12+A11*Inputs!B13)*(1+Inputs!B15) -> 3150460 | D11: =C11*(1-Inputs!B19) -> 2047799 | E11: =A11*Investment!B2*Inputs!B9*Inputs!B8*(1-Inputs!B16) -> 85286.25 | F11: =IF(Inputs!B19=0,0,IF(Inputs!B20=0,C11*Inputs!B19/Inputs!B21,-PMT(Inputs!B20,Inputs!B21,C11*Inputs!B19))) -> 74362.386 | G11: =E11-F11 -> 10923.864 | H11: =E11/C11 -> 0.027071047 | I11: =IF(F11=0,999,E11/F11) -> 1.1469004 | J11: =IF(AND(C11<=Inputs!B22,D11<=Inputs!B23,G11>0,I11>=Inputs!B24,A11<=Inputs!B29),"YES","NO") -> NO | K11: =IF(J11="YES",G11,-1) -> -1
A12: 22 | B12: =A12*Inputs!B11 -> 748 | C12: =Inputs!B10+Inputs!B14+(B12*Inputs!B12+A12*Inputs!B13)*(1+Inputs!B15) -> 3245720 | D12: =C12*(1-Inputs!B19) -> 2109718 | E12: =A12*Investment!B2*Inputs!B9*Inputs!B8*(1-Inputs!B16) -> 89347.5 | F12: =IF(Inputs!B19=0,0,IF(Inputs!B20=0,C12*Inputs!B19/Inputs!B21,-PMT(Inputs!B20,Inputs!B21,C12*Inputs!B19))) -> 76610.871 | G12: =E12-F12 -> 12736.629 | H12: =E12/C12 -> 0.02752779 | I12: =IF(F12=0,999,E12/F12) -> 1.1662509 | J12: =IF(AND(C12<=Inputs!B22,D12<=Inputs!B23,G12>0,I12>=Inputs!B24,A12<=Inputs!B29),"YES","NO") -> NO | K12: =IF(J12="YES",G12,-1) -> -1
A13: 23 | B13: =A13*Inputs!B11 -> 782 | C13: =Inputs!B10+Inputs!B14+(B13*Inputs!B12+A13*Inputs!B13)*(1+Inputs!B15) -> 3340980 | D13: =C13*(1-Inputs!B19) -> 2171637 | E13: =A13*Investment!B2*Inputs!B9*Inputs!B8*(1-Inputs!B16) -> 93408.75 | F13: =IF(Inputs!B19=0,0,IF(Inputs!B20=0,C13*Inputs!B19/Inputs!B21,-PMT(Inputs!B20,Inputs!B21,C13*Inputs!B19))) -> 78859.355 | G13: =E13-F13 -> 14549.395 | H13: =E13/C13 -> 0.027958488 | I13: =IF(F13=0,999,E13/F13) -> 1.184498 | J13: =IF(AND(C13<=Inputs!B22,D13<=Inputs!B23,G13>0,I13>=Inputs!B24,A13<=Inputs!B29),"YES","NO") -> NO | K13: =IF(J13="YES",G13,-1) -> -1
A14: 24 | B14: =A14*Inputs!B11 -> 816 | C14: =Inputs!B10+Inputs!B14+(B14*Inputs!B12+A14*Inputs!B13)*(1+Inputs!B15) -> 3436240 | D14: =C14*(1-Inputs!B19) -> 2233556 | E14: =A14*Investment!B2*Inputs!B9*Inputs!B8*(1-Inputs!B16) -> 97470 | F14: =IF(Inputs!B19=0,0,IF(Inputs!B20=0,C14*Inputs!B19/Inputs!B21,-PMT(Inputs!B20,Inputs!B21,C14*Inputs!B19))) -> 81107.84 | G14: =E14-F14 -> 16362.16 | H14: =E14/C14 -> 0.028365306 | I14: =IF(F14=0,999,E14/F14) -> 1.2017334 | J14: =IF(AND(C14<=Inputs!B22,D14<=Inputs!B23,G14>0,I14>=Inputs!B24,A14<=Inputs!B29),"YES","NO") -> YES | K14: =IF(J14="YES",G14,-1) -> 16362.16
A15: 25 | B15: =A15*Inputs!B11 -> 850 | C15: =Inputs!B10+Inputs!B14+(B15*Inputs!B12+A15*Inputs!B13)*(1+Inputs!B15) -> 3531500 | D15: =C15*(1-Inputs!B19) -> 2295475 | E15: =A15*Investment!B2*Inputs!B9*Inputs!B8*(1-Inputs!B16) -> 101531.25 | F15: =IF(Inputs!B19=0,0,IF(Inputs!B20=0,C15*Inputs!B19/Inputs!B21,-PMT(Inputs!B20,Inputs!B21,C15*Inputs!B19))) -> 83356.325 | G15: =E15-F15 -> 18174.925 | H15: =E15/C15 -> 0.028750177 | I15: =IF(F15=0,999,E15/F15) -> 1.2180389 | J15: =IF(AND(C15<=Inputs!B22,D15<=Inputs!B23,G15>0,I15>=Inputs!B24,A15<=Inputs!B29),"YES","NO") -> YES | K15: =IF(J15="YES",G15,-1) -> 18174.925
A16: 26 | B16: =A16*Inputs!B11 -> 884 | C16: =Inputs!B10+Inputs!B14+(B16*Inputs!B12+A16*Inputs!B13)*(1+Inputs!B15) -> 3626760 | D16: =C16*(1-Inputs!B19) -> 2357394 | E16: =A16*Investment!B2*Inputs!B9*Inputs!B8*(1-Inputs!B16) -> 105592.5 | F16: =IF(Inputs!B19=0,0,IF(Inputs!B20=0,C16*Inputs!B19/Inputs!B21,-PMT(Inputs!B20,Inputs!B21,C16*Inputs!B19))) -> 85604.809 | G16: =E16-F16 -> 19987.691 | H16: =E16/C16 -> 0.02911483 | I16: =IF(F16=0,999,E16/F16) -> 1.2334879 | J16: =IF(AND(C16<=Inputs!B22,D16<=Inputs!B23,G16>0,I16>=Inputs!B24,A16<=Inputs!B29),"YES","NO") -> YES | K16: =IF(J16="YES",G16,-1) -> 19987.691
A17: 27 | B17: =A17*Inputs!B11 -> 918 | C17: =Inputs!B10+Inputs!B14+(B17*Inputs!B12+A17*Inputs!B13)*(1+Inputs!B15) -> 3722020 | D17: =C17*(1-Inputs!B19) -> 2419313 | E17: =A17*Investment!B2*Inputs!B9*Inputs!B8*(1-Inputs!B16) -> 109653.75 | F17: =IF(Inputs!B19=0,0,IF(Inputs!B20=0,C17*Inputs!B19/Inputs!B21,-PMT(Inputs!B20,Inputs!B21,C17*Inputs!B19))) -> 87853.294 | G17: =E17-F17 -> 21800.456 | H17: =E17/C17 -> 0.029460817 | I17: =IF(F17=0,999,E17/F17) -> 1.2481461 | J17: =IF(AND(C17<=Inputs!B22,D17<=Inputs!B23,G17>0,I17>=Inputs!B24,A17<=Inputs!B29),"YES","NO") -> YES | K17: =IF(J17="YES",G17,-1) -> 21800.456
A18: 28 | B18: =A18*Inputs!B11 -> 952 | C18: =Inputs!B10+Inputs!B14+(B18*Inputs!B12+A18*Inputs!B13)*(1+Inputs!B15) -> 3817280 | D18: =C18*(1-Inputs!B19) -> 2481232 | E18: =A18*Investment!B2*Inputs!B9*Inputs!B8*(1-Inputs!B16) -> 113715 | F18: =IF(Inputs!B19=0,0,IF(Inputs!B20=0,C18*Inputs!B19/Inputs!B21,-PMT(Inputs!B20,Inputs!B21,C18*Inputs!B19))) -> 90101.779 | G18: =E18-F18 -> 23613.221 | H18: =E18/C18 -> 0.029789536 | I18: =IF(F18=0,999,E18/F18) -> 1.2620728 | J18: =IF(AND(C18<=Inputs!B22,D18<=Inputs!B23,G18>0,I18>=Inputs!B24,A18<=Inputs!B29),"YES","NO") -> YES | K18: =IF(J18="YES",G18,-1) -> 23613.221
A19: 29 | B19: =A19*Inputs!B11 -> 986 | C19: =Inputs!B10+Inputs!B14+(B19*Inputs!B12+A19*Inputs!B13)*(1+Inputs!B15) -> 3912540 | D19: =C19*(1-Inputs!B19) -> 2543151 | E19: =A19*Investment!B2*Inputs!B9*Inputs!B8*(1-Inputs!B16) -> 117776.25 | F19: =IF(Inputs!B19=0,0,IF(Inputs!B20=0,C19*Inputs!B19/Inputs!B21,-PMT(Inputs!B20,Inputs!B21,C19*Inputs!B19))) -> 92350.263 | G19: =E19-F19 -> 25425.987 | H19: =E19/C19 -> 0.030102248 | I19: =IF(F19=0,999,E19/F19) -> 1.2753212 | J19: =IF(AND(C19<=Inputs!B22,D19<=Inputs!B23,G19>0,I19>=Inputs!B24,A19<=Inputs!B29),"YES","NO") -> YES | K19: =IF(J19="YES",G19,-1) -> 25425.987
A20: 30 | B20: =A20*Inputs!B11 -> 1020 | C20: =Inputs!B10+Inputs!B14+(B20*Inputs!B12+A20*Inputs!B13)*(1+Inputs!B15) -> 4007800 | D20: =C20*(1-Inputs!B19) -> 2605070 | E20: =A20*Investment!B2*Inputs!B9*Inputs!B8*(1-Inputs!B16) -> 121837.5 | F20: =IF(Inputs!B19=0,0,IF(Inputs!B20=0,C20*Inputs!B19/Inputs!B21,-PMT(Inputs!B20,Inputs!B21,C20*Inputs!B19))) -> 94598.748 | G20: =E20-F20 -> 27238.752 | H20: =E20/C20 -> 0.030400095 | I20: =IF(F20=0,999,E20/F20) -> 1.2879399 | J20: =IF(AND(C20<=Inputs!B22,D20<=Inputs!B23,G20>0,I20>=Inputs!B24,A20<=Inputs!B29),"YES","NO") -> YES | K20: =IF(J20="YES",G20,-1) -> 27238.752
A21: 31 | B21: =A21*Inputs!B11 -> 1054 | C21: =Inputs!B10+Inputs!B14+(B21*Inputs!B12+A21*Inputs!B13)*(1+Inputs!B15) -> 4103060 | D21: =C21*(1-Inputs!B19) -> 2666989 | E21: =A21*Investment!B2*Inputs!B9*Inputs!B8*(1-Inputs!B16) -> 125898.75 | F21: =IF(Inputs!B19=0,0,IF(Inputs!B20=0,C21*Inputs!B19/Inputs!B21,-PMT(Inputs!B20,Inputs!B21,C21*Inputs!B19))) -> 96847.232 | G21: =E21-F21 -> 29051.518 | H21: =E21/C21 -> 0.030684111 | I21: =IF(F21=0,999,E21/F21) -> 1.2999726 | J21: =IF(AND(C21<=Inputs!B22,D21<=Inputs!B23,G21>0,I21>=Inputs!B24,A21<=Inputs!B29),"YES","NO") -> YES | K21: =IF(J21="YES",G21,-1) -> 29051.518
A22: 32 | B22: =A22*Inputs!B11 -> 1088 | C22: =Inputs!B10+Inputs!B14+(B22*Inputs!B12+A22*Inputs!B13)*(1+Inputs!B15) -> 4198320 | D22: =C22*(1-Inputs!B19) -> 2728908 | E22: =A22*Investment!B2*Inputs!B9*Inputs!B8*(1-Inputs!B16) -> 129960 | F22: =IF(Inputs!B19=0,0,IF(Inputs!B20=0,C22*Inputs!B19/Inputs!B21,-PMT(Inputs!B20,Inputs!B21,C22*Inputs!B19))) -> 99095.717 | G22: =E22-F22 -> 30864.283 | H22: =E22/C22 -> 0.030955239 | I22: =IF(F22=0,999,E22/F22) -> 1.3114593 | J22: =IF(AND(C22<=Inputs!B22,D22<=Inputs!B23,G22>0,I22>=Inputs!B24,A22<=Inputs!B29),"YES","NO") -> YES | K22: =IF(J22="YES",G22,-1) -> 30864.283
A23: 33 | B23: =A23*Inputs!B11 -> 1122 | C23: =Inputs!B10+Inputs!B14+(B23*Inputs!B12+A23*Inputs!B13)*(1+Inputs!B15) -> 4293580 | D23: =C23*(1-Inputs!B19) -> 2790827 | E23: =A23*Investment!B2*Inputs!B9*Inputs!B8*(1-Inputs!B16) -> 134021.25 | F23: =IF(Inputs!B19=0,0,IF(Inputs!B20=0,C23*Inputs!B19/Inputs!B21,-PMT(Inputs!B20,Inputs!B21,C23*Inputs!B19))) -> 101344.2 | G23: =E23-F23 -> 32677.048 | H23: =E23/C23 -> 0.031214336 | I23: =IF(F23=0,999,E23/F23) -> 1.3224363 | J23: =IF(AND(C23<=Inputs!B22,D23<=Inputs!B23,G23>0,I23>=Inputs!B24,A23<=Inputs!B29),"YES","NO") -> YES | K23: =IF(J23="YES",G23,-1) -> 32677.048
A24: 34 | B24: =A24*Inputs!B11 -> 1156 | C24: =Inputs!B10+Inputs!B14+(B24*Inputs!B12+A24*Inputs!B13)*(1+Inputs!B15) -> 4388840 | D24: =C24*(1-Inputs!B19) -> 2852746 | E24: =A24*Investment!B2*Inputs!B9*Inputs!B8*(1-Inputs!B16) -> 138082.5 | F24: =IF(Inputs!B19=0,0,IF(Inputs!B20=0,C24*Inputs!B19/Inputs!B21,-PMT(Inputs!B20,Inputs!B21,C24*Inputs!B19))) -> 103592.69 | G24: =E24-F24 -> 34489.814 | H24: =E24/C24 -> 0.031462186 | I24: =IF(F24=0,999,E24/F24) -> 1.3329368 | J24: =IF(AND(C24<=Inputs!B22,D24<=Inputs!B23,G24>0,I24>=Inputs!B24,A24<=Inputs!B29),"YES","NO") -> YES | K24: =IF(J24="YES",G24,-1) -> 34489.814
A25: 35 | B25: =A25*Inputs!B11 -> 1190 | C25: =Inputs!B10+Inputs!B14+(B25*Inputs!B12+A25*Inputs!B13)*(1+Inputs!B15) -> 4484100 | D25: =C25*(1-Inputs!B19) -> 2914665 | E25: =A25*Investment!B2*Inputs!B9*Inputs!B8*(1-Inputs!B16) -> 142143.75 | F25: =IF(Inputs!B19=0,0,IF(Inputs!B20=0,C25*Inputs!B19/Inputs!B21,-PMT(Inputs!B20,Inputs!B21,C25*Inputs!B19))) -> 105841.17 | G25: =E25-F25 -> 36302.579 | H25: =E25/C25 -> 0.031699505 | I25: =IF(F25=0,999,E25/F25) -> 1.3429911 | J25: =IF(AND(C25<=Inputs!B22,D25<=Inputs!B23,G25>0,I25>=Inputs!B24,A25<=Inputs!B29),"YES","NO") -> YES | K25: =IF(J25="YES",G25,-1) -> 36302.579
A26: 36 | B26: =A26*Inputs!B11 -> 1224 | C26: =Inputs!B10+Inputs!B14+(B26*Inputs!B12+A26*Inputs!B13)*(1+Inputs!B15) -> 4579360 | D26: =C26*(1-Inputs!B19) -> 2976584 | E26: =A26*Investment!B2*Inputs!B9*Inputs!B8*(1-Inputs!B16) -> 146205 | F26: =IF(Inputs!B19=0,0,IF(Inputs!B20=0,C26*Inputs!B19/Inputs!B21,-PMT(Inputs!B20,Inputs!B21,C26*Inputs!B19))) -> 108089.66 | G26: =E26-F26 -> 38115.344 | H26: =E26/C26 -> 0.03192695 | I26: =IF(F26=0,999,E26/F26) -> 1.3526271 | J26: =IF(AND(C26<=Inputs!B22,D26<=Inputs!B23,G26>0,I26>=Inputs!B24,A26<=Inputs!B29),"YES","NO") -> YES | K26: =IF(J26="YES",G26,-1) -> 38115.344
A27: 37 | B27: =A27*Inputs!B11 -> 1258 | C27: =Inputs!B10+Inputs!B14+(B27*Inputs!B12+A27*Inputs!B13)*(1+Inputs!B15) -> 4674620 | D27: =C27*(1-Inputs!B19) -> 3038503 | E27: =A27*Investment!B2*Inputs!B9*Inputs!B8*(1-Inputs!B16) -> 150266.25 | F27: =IF(Inputs!B19=0,0,IF(Inputs!B20=0,C27*Inputs!B19/Inputs!B21,-PMT(Inputs!B20,Inputs!B21,C27*Inputs!B19))) -> 110338.14 | G27: =E27-F27 -> 39928.11 | H27: =E27/C27 -> 0.032145126 | I27: =IF(F27=0,999,E27/F27) -> 1.3618704 | J27: =IF(AND(C27<=Inputs!B22,D27<=Inputs!B23,G27>0,I27>=Inputs!B24,A27<=Inputs!B29),"YES","NO") -> YES | K27: =IF(J27="YES",G27,-1) -> 39928.11
A28: 38 | B28: =A28*Inputs!B11 -> 1292 | C28: =Inputs!B10+Inputs!B14+(B28*Inputs!B12+A28*Inputs!B13)*(1+Inputs!B15) -> 4769880 | D28: =C28*(1-Inputs!B19) -> 3100422 | E28: =A28*Investment!B2*Inputs!B9*Inputs!B8*(1-Inputs!B16) -> 154327.5 | F28: =IF(Inputs!B19=0,0,IF(Inputs!B20=0,C28*Inputs!B19/Inputs!B21,-PMT(Inputs!B20,Inputs!B21,C28*Inputs!B19))) -> 112586.62 | G28: =E28-F28 -> 41740.875 | H28: =E28/C28 -> 0.032354588 | I28: =IF(F28=0,999,E28/F28) -> 1.3707445 | J28: =IF(AND(C28<=Inputs!B22,D28<=Inputs!B23,G28>0,I28>=Inputs!B24,A28<=Inputs!B29),"YES","NO") -> YES | K28: =IF(J28="YES",G28,-1) -> 41740.875
A29: 39 | B29: =A29*Inputs!B11 -> 1326 | C29: =Inputs!B10+Inputs!B14+(B29*Inputs!B12+A29*Inputs!B13)*(1+Inputs!B15) -> 4865140 | D29: =C29*(1-Inputs!B19) -> 3162341 | E29: =A29*Investment!B2*Inputs!B9*Inputs!B8*(1-Inputs!B16) -> 158388.75 | F29: =IF(Inputs!B19=0,0,IF(Inputs!B20=0,C29*Inputs!B19/Inputs!B21,-PMT(Inputs!B20,Inputs!B21,C29*Inputs!B19))) -> 114835.11 | G29: =E29-F29 -> 43553.64 | H29: =E29/C29 -> 0.032555846 | I29: =IF(F29=0,999,E29/F29) -> 1.3792711 | J29: =IF(AND(C29<=Inputs!B22,D29<=Inputs!B23,G29>0,I29>=Inputs!B24,A29<=Inputs!B29),"YES","NO") -> YES | K29: =IF(J29="YES",G29,-1) -> 43553.64
A30: 40 | B30: =A30*Inputs!B11 -> 1360 | C30: =Inputs!B10+Inputs!B14+(B30*Inputs!B12+A30*Inputs!B13)*(1+Inputs!B15) -> 4960400 | D30: =C30*(1-Inputs!B19) -> 3224260 | E30: =A30*Investment!B2*Inputs!B9*Inputs!B8*(1-Inputs!B16) -> 162450 | F30: =IF(Inputs!B19=0,0,IF(Inputs!B20=0,C30*Inputs!B19/Inputs!B21,-PMT(Inputs!B20,Inputs!B21,C30*Inputs!B19))) -> 117083.59 | G30: =E30-F30 -> 45366.406 | H30: =E30/C30 -> 0.032749375 | I30: =IF(F30=0,999,E30/F30) -> 1.3874702 | J30: =IF(AND(C30<=Inputs!B22,D30<=Inputs!B23,G30>0,I30>=Inputs!B24,A30<=Inputs!B29),"YES","NO") -> YES | K30: =IF(J30="YES",G30,-1) -> 45366.406
A31: 41 | B31: =A31*Inputs!B11 -> 1394 | C31: =Inputs!B10+Inputs!B14+(B31*Inputs!B12+A31*Inputs!B13)*(1+Inputs!B15) -> 5055660 | D31: =C31*(1-Inputs!B19) -> 3286179 | E31: =A31*Investment!B2*Inputs!B9*Inputs!B8*(1-Inputs!B16) -> 166511.25 | F31: =IF(Inputs!B19=0,0,IF(Inputs!B20=0,C31*Inputs!B19/Inputs!B21,-PMT(Inputs!B20,Inputs!B21,C31*Inputs!B19))) -> 119332.08 | G31: =E31-F31 -> 47179.171 | H31: =E31/C31 -> 0.032935611 | I31: =IF(F31=0,999,E31/F31) -> 1.3953603 | J31: =IF(AND(C31<=Inputs!B22,D31<=Inputs!B23,G31>0,I31>=Inputs!B24,A31<=Inputs!B29),"YES","NO") -> NO | K31: =IF(J31="YES",G31,-1) -> -1
A32: 42 | B32: =A32*Inputs!B11 -> 1428 | C32: =Inputs!B10+Inputs!B14+(B32*Inputs!B12+A32*Inputs!B13)*(1+Inputs!B15) -> 5150920 | D32: =C32*(1-Inputs!B19) -> 3348098 | E32: =A32*Investment!B2*Inputs!B9*Inputs!B8*(1-Inputs!B16) -> 170572.5 | F32: =IF(Inputs!B19=0,0,IF(Inputs!B20=0,C32*Inputs!B19/Inputs!B21,-PMT(Inputs!B20,Inputs!B21,C32*Inputs!B19))) -> 121580.56 | G32: =E32-F32 -> 48991.937 | H32: =E32/C32 -> 0.033114958 | I32: =IF(F32=0,999,E32/F32) -> 1.4029586 | J32: =IF(AND(C32<=Inputs!B22,D32<=Inputs!B23,G32>0,I32>=Inputs!B24,A32<=Inputs!B29),"YES","NO") -> NO | K32: =IF(J32="YES",G32,-1) -> -1
A33: 43 | B33: =A33*Inputs!B11 -> 1462 | C33: =Inputs!B10+Inputs!B14+(B33*Inputs!B12+A33*Inputs!B13)*(1+Inputs!B15) -> 5246180 | D33: =C33*(1-Inputs!B19) -> 3410017 | E33: =A33*Investment!B2*Inputs!B9*Inputs!B8*(1-Inputs!B16) -> 174633.75 | F33: =IF(Inputs!B19=0,0,IF(Inputs!B20=0,C33*Inputs!B19/Inputs!B21,-PMT(Inputs!B20,Inputs!B21,C33*Inputs!B19))) -> 123829.05 | G33: =E33-F33 -> 50804.702 | H33: =E33/C33 -> 0.033287792 | I33: =IF(F33=0,999,E33/F33) -> 1.410281 | J33: =IF(AND(C33<=Inputs!B22,D33<=Inputs!B23,G33>0,I33>=Inputs!B24,A33<=Inputs!B29),"YES","NO") -> NO | K33: =IF(J33="YES",G33,-1) -> -1
A34: 44 | B34: =A34*Inputs!B11 -> 1496 | C34: =Inputs!B10+Inputs!B14+(B34*Inputs!B12+A34*Inputs!B13)*(1+Inputs!B15) -> 5341440 | D34: =C34*(1-Inputs!B19) -> 3471936 | E34: =A34*Investment!B2*Inputs!B9*Inputs!B8*(1-Inputs!B16) -> 178695 | F34: =IF(Inputs!B19=0,0,IF(Inputs!B20=0,C34*Inputs!B19/Inputs!B21,-PMT(Inputs!B20,Inputs!B21,C34*Inputs!B19))) -> 126077.53 | G34: =E34-F34 -> 52617.467 | H34: =E34/C34 -> 0.033454462 | I34: =IF(F34=0,999,E34/F34) -> 1.4173421 | J34: =IF(AND(C34<=Inputs!B22,D34<=Inputs!B23,G34>0,I34>=Inputs!B24,A34<=Inputs!B29),"YES","NO") -> NO | K34: =IF(J34="YES",G34,-1) -> -1
A35: 45 | B35: =A35*Inputs!B11 -> 1530 | C35: =Inputs!B10+Inputs!B14+(B35*Inputs!B12+A35*Inputs!B13)*(1+Inputs!B15) -> 5436700 | D35: =C35*(1-Inputs!B19) -> 3533855 | E35: =A35*Investment!B2*Inputs!B9*Inputs!B8*(1-Inputs!B16) -> 182756.25 | F35: =IF(Inputs!B19=0,0,IF(Inputs!B20=0,C35*Inputs!B19/Inputs!B21,-PMT(Inputs!B20,Inputs!B21,C35*Inputs!B19))) -> 128326.02 | G35: =E35-F35 -> 54430.233 | H35: =E35/C35 -> 0.033615291 | I35: =IF(F35=0,999,E35/F35) -> 1.4241559 | J35: =IF(AND(C35<=Inputs!B22,D35<=Inputs!B23,G35>0,I35>=Inputs!B24,A35<=Inputs!B29),"YES","NO") -> NO | K35: =IF(J35="YES",G35,-1) -> -1
A36: 46 | B36: =A36*Inputs!B11 -> 1564 | C36: =Inputs!B10+Inputs!B14+(B36*Inputs!B12+A36*Inputs!B13)*(1+Inputs!B15) -> 5531960 | D36: =C36*(1-Inputs!B19) -> 3595774 | E36: =A36*Investment!B2*Inputs!B9*Inputs!B8*(1-Inputs!B16) -> 186817.5 | F36: =IF(Inputs!B19=0,0,IF(Inputs!B20=0,C36*Inputs!B19/Inputs!B21,-PMT(Inputs!B20,Inputs!B21,C36*Inputs!B19))) -> 130574.5 | G36: =E36-F36 -> 56242.998 | H36: =E36/C36 -> 0.03377058 | I36: =IF(F36=0,999,E36/F36) -> 1.4307349 | J36: =IF(AND(C36<=Inputs!B22,D36<=Inputs!B23,G36>0,I36>=Inputs!B24,A36<=Inputs!B29),"YES","NO") -> NO | K36: =IF(J36="YES",G36,-1) -> -1
A37: 47 | B37: =A37*Inputs!B11 -> 1598 | C37: =Inputs!B10+Inputs!B14+(B37*Inputs!B12+A37*Inputs!B13)*(1+Inputs!B15) -> 5627220 | D37: =C37*(1-Inputs!B19) -> 3657693 | E37: =A37*Investment!B2*Inputs!B9*Inputs!B8*(1-Inputs!B16) -> 190878.75 | F37: =IF(Inputs!B19=0,0,IF(Inputs!B20=0,C37*Inputs!B19/Inputs!B21,-PMT(Inputs!B20,Inputs!B21,C37*Inputs!B19))) -> 132822.99 | G37: =E37-F37 -> 58055.763 | H37: =E37/C37 -> 0.033920613 | I37: =IF(F37=0,999,E37/F37) -> 1.4370912 | J37: =IF(AND(C37<=Inputs!B22,D37<=Inputs!B23,G37>0,I37>=Inputs!B24,A37<=Inputs!B29),"YES","NO") -> NO | K37: =IF(J37="YES",G37,-1) -> -1
A38: 48 | B38: =A38*Inputs!B11 -> 1632 | C38: =Inputs!B10+Inputs!B14+(B38*Inputs!B12+A38*Inputs!B13)*(1+Inputs!B15) -> 5722480 | D38: =C38*(1-Inputs!B19) -> 3719612 | E38: =A38*Investment!B2*Inputs!B9*Inputs!B8*(1-Inputs!B16) -> 194940 | F38: =IF(Inputs!B19=0,0,IF(Inputs!B20=0,C38*Inputs!B19/Inputs!B21,-PMT(Inputs!B20,Inputs!B21,C38*Inputs!B19))) -> 135071.47 | G38: =E38-F38 -> 59868.529 | H38: =E38/C38 -> 0.03406565 | I38: =IF(F38=0,999,E38/F38) -> 1.4432359 | J38: =IF(AND(C38<=Inputs!B22,D38<=Inputs!B23,G38>0,I38>=Inputs!B24,A38<=Inputs!B29),"YES","NO") -> NO | K38: =IF(J38="YES",G38,-1) -> -1
A39: 49 | B39: =A39*Inputs!B11 -> 1666 | C39: =Inputs!B10+Inputs!B14+(B39*Inputs!B12+A39*Inputs!B13)*(1+Inputs!B15) -> 5817740 | D39: =C39*(1-Inputs!B19) -> 3781531 | E39: =A39*Investment!B2*Inputs!B9*Inputs!B8*(1-Inputs!B16) -> 199001.25 | F39: =IF(Inputs!B19=0,0,IF(Inputs!B20=0,C39*Inputs!B19/Inputs!B21,-PMT(Inputs!B20,Inputs!B21,C39*Inputs!B19))) -> 137319.96 | G39: =E39-F39 -> 61681.294 | H39: =E39/C39 -> 0.034205937 | I39: =IF(F39=0,999,E39/F39) -> 1.4491794 | J39: =IF(AND(C39<=Inputs!B22,D39<=Inputs!B23,G39>0,I39>=Inputs!B24,A39<=Inputs!B29),"YES","NO") -> NO | K39: =IF(J39="YES",G39,-1) -> -1
A40: 50 | B40: =A40*Inputs!B11 -> 1700 | C40: =Inputs!B10+Inputs!B14+(B40*Inputs!B12+A40*Inputs!B13)*(1+Inputs!B15) -> 5913000 | D40: =C40*(1-Inputs!B19) -> 3843450 | E40: =A40*Investment!B2*Inputs!B9*Inputs!B8*(1-Inputs!B16) -> 203062.5 | F40: =IF(Inputs!B19=0,0,IF(Inputs!B20=0,C40*Inputs!B19/Inputs!B21,-PMT(Inputs!B20,Inputs!B21,C40*Inputs!B19))) -> 139568.44 | G40: =E40-F40 -> 63494.06 | H40: =E40/C40 -> 0.034341705 | I40: =IF(F40=0,999,E40/F40) -> 1.4549314 | J40: =IF(AND(C40<=Inputs!B22,D40<=Inputs!B23,G40>0,I40>=Inputs!B24,A40<=Inputs!B29),"YES","NO") -> NO | K40: =IF(J40="YES",G40,-1) -> -1
...

Sheet Scenarios
A1: Scenario | B1: Rent | C1: Occupancy | D1: Cost multiplier | E1: NOI | F1: Total investment | G1: Net yield | H1: Static project payback incl. delay
A2: Downside | B2: 400 | C2: 0.9 | D2: 1.15 | E2: =Inputs!B2*MIN(B2,Inputs!B3-Inputs!B4,Inputs!B5,Inputs!B6)*Inputs!B9*C2*(1-Inputs!B16) -> 129600 | F2: =Investment!B8*D2 -> 5704460 | G2: =E2/F2 -> 0.022719065 | H2: =F2/E2+Inputs!B28 -> 46.015895
A3: Base | B3: 475 | C3: 0.95 | D3: 1 | E3: =Inputs!B2*MIN(B3,Inputs!B3-Inputs!B4,Inputs!B5,Inputs!B6)*Inputs!B9*C3*(1-Inputs!B16) -> 162450 | F3: =Investment!B8*D3 -> 4960400 | G3: =E3/F3 -> 0.032749375 | H3: =F3/E3+Inputs!B28 -> 32.534934
A4: Upside | B4: 500 | C4: 0.98 | D4: 0.95 | E4: =Inputs!B2*MIN(B4,Inputs!B3-Inputs!B4,Inputs!B5,Inputs!B6)*Inputs!B9*C4*(1-Inputs!B16) -> 176400 | F4: =Investment!B8*D4 -> 4712380 | G4: =E4/F4 -> 0.037433314 | H4: =F4/E4+Inputs!B28 -> 28.714172
A5: VUB all-in match | B5: 349.3 | C5: 0.95 | D5: 1 | E5: =Inputs!B2*MIN(B5,Inputs!B3-Inputs!B4,Inputs!B5,Inputs!B6)*Inputs!B9*C5*(1-Inputs!B16) -> 119460.6 | F5: =Investment!B8*D5 -> 4960400 | G5: =E5/F5 -> 0.024082856 | H5: =F5/E5+Inputs!B28 -> 43.523314

Sheet Sources
A1: Item | B1: Source / URL | C1: Finding | D1: Accessed / status
A2: Private market room benchmark | B2: https://www.brukot.be/en/student-guide/rent-stats | C2: Own listing/residence statistics: student room median EUR500 excluding charges / EUR590 including charges; all housing median EUR550 / EUR650. Brussels-wide, not VUB-specific. | D2: 2026-10-14
A3: VUB standard student room | B3: https://www.vub.be/en/studying-vub/practical-info-for-students/student-housing/practical-housing-information | C3: 2026-27 standard room EUR449.30 all-in. Eligibility and limited availability; not a private investor rent cap. | D3: 2026-10-14
A4: Brussels reference rent rule | B4: https://be.brussels/nl/huisvesting/huren-en-verhuren/huurovereenkomst/referentiehuurprijs | C4: Reference must be disclosed. Above reference by more than 20% presumed excessive, rebuttable; defects can make lower rent excessive. No excessive rent since 1 May 2025. | D4: 2026-10-14
A5: Address-specific reference calculator | B5: https://loyers.brussels/ | C5: Enter actual address and dwelling characteristics; student/shared dwelling treatment needs confirmation. Placeholder in model is NOT verified legal clearance. | D5: 2026-10-14
A6: 2026 quality standards | B6: https://be.brussels/en/housing/new-minimum-quality-standards-2026 | C6: Student accommodation minimum net surface 12 m²; other safety, health, equipment and layout rules apply. Gross project area is a separate planning assumption. | D6: 2026-10-14
A7: Lease steps | B7: https://be.brussels/en/housing/rental/steps-renting-and-leasing | C7: Regional guidance: student lease 12 months; registration required. Cash flow stress tests cover fewer collected months. | D7: 2026-10-14
A8: Investment and financing assumptions | B8: No external quotation | C8: Land EUR900k; fixed costs EUR250k; construction EUR2400/gross m² VAT-inclusive assumption; furnishing EUR5k/room; 10% contingency; financing 4.5% over 25 years. Require quotes. | D8: ASSUMPTIONS
