Workbook

Sheet Read me
A1: BRUSSELS STUDENT HOUSING — DECISION MODEL
A2: Purpose | B2: Compare affordable student rent with investor project returns. All starting values are illustrative assumptions, not quotations.
A3: Use | B3: Edit blue cells on Inputs. Read Results, then Cash flow. Monetary amounts are nominal EUR.
A4: Scope | B4: Unlevered, pre-tax project cash flows. No debt, tax or depreciation. All investment paid at time 0, a conservative simplification.
A5: Timing | B5: Construction months rounded UP to full years. First full rental year follows construction; no partial-year income.
A6: Investment | B6: Includes land, construction, facilities, professional fees, contingency and explicit compliance cost. Subsidy is received at time 0.
A7: Student price | B7: Monthly all-in rent: utilities included. Separate affordability cap is an editable policy target.
A8: Return | B8: NPV at entered discount rate; IRR uses yearly project cash flows; PBP is simple payback from investment, excluding sale proceeds.
A9: Risk | B9: Force-majeure contingency is a scenario allowance, not a probability forecast. Illegal payments are not budgeted; use compliance and delay scenarios.
A10: Affordability over time | B10: Cap tests initial rent only. Annual escalated rent appears in Cash flow; recheck student budgets each year.
A11: Optimization | B11: Exact analytical minimum rent at NPV = 0 for a fixed design. Minimum investment is meaningful only with room capacity, quality and useful-life constraints. No global construction optimum is claimed.
A12: Model limits | B12: 60-year annual horizon; construction <=60 months and life <=50 years. No financial close recommendation without local quotes, tax review and financing terms.
A13: Double counting | B13: Maintenance is expensed cash each year; refurbishment is separate major work. Do not also count a funded reserve withdrawal as a new expense.
... A15: Workbook map | B15: Inputs → Results → Cash flow → Scenarios. Sources, Risks and Prompt explain evidence and next steps. Hidden scenario calculation sheets can be unhidden to audit.

Sheet Inputs
A1: Input | B1: Value | C1: Unit | D1: Basis / assumption
A2: Rooms | B2: 100 | C2: rooms | D2: Illustrative project; minimum capacity constraint
A3: Gross area per room | B3: 30 | C3: m²/room | D3: Includes allocation of common areas
A4: Land / acquisition | B4: 1200000 | C4: EUR | D4: Site-specific quotation needed
A5: Construction cost | B5: 2000 | C5: EUR/m² | D5: Illustrative; VAT inclusion must be checked
A6: Facilities | B6: 400000 | C6: EUR | D6: Furniture and common equipment
A7: Professional fees | B7: 0.1 | C7: share | D7: Of construction + facilities
A8: Force-majeure contingency | B8: 0.1 | C8: share | D8: Of construction + facilities + fees
A9: Compliance / audit cost | B9: 0 | C9: EUR | D9: Legal control costs; no unlawful payments
A10: Initial subsidy | B10: 0 | C10: EUR | D10: Only committed funding should be used
A11: Construction duration | B11: 18 | C11: months | D11: Illustrative, including permitting
A12: Operating useful life | B12: 40 | C12: years | D12: Subject to engineering assessment and refurbishment
A13: Discount rate | B13: 0.06 | C13: annual | D13: Nominal unlevered required return
... A28: Sale costs | B28: 0.02 | C28: share | D28: Of gross terminal value

Sheet Cash flow
A1: Year | B1: Operating year | C1: All-in rent / month | D1: Revenue | E1: Operating costs | F1: Refurbishment | G1: Terminal proceeds | H1: Net cash flow | I1: Discount factor | J1: PV cash flow | K1: Cumulative operating cash | L1: PV revenue per EUR rent | M1: Payback crossing year | N1: Cumulative discounted cash | O1: Discounted crossing year
A2: 0 | B2: =IF(AND(A2>Results!$B$4,A2<=Results!$B$5),A2-Results!$B$4,0) -> 0 | C2: =IF(B2>0,Inputs!$B$16*(1+Inputs!$B$18)^(B2-1),0) -> 0 | D2: =IF(B2>0,Inputs!$B$2*Inputs!$B$14*Inputs!$B$15*C2,0) -> 0 | E2: =IF(B2>0,(Inputs!$B$20+Inputs!$B$21+Inputs!$B$2*Inputs!$B$14*(Inputs!$B$22+Inputs!$B$23)+(Inputs!$B$2*Inputs!$B$3*Inputs!$B$5+Inputs!$B$6)*Inputs!$B$24)*(1+Inputs!$B$19)^(B2-1),0) -> 0 | F2: =IF(AND(B2>0,B2<Inputs!$B$12,MOD(B2,Inputs!$B$25)=0),Inputs!$B$26*(1+Inputs!$B$19)^(B2-1),0) -> 0 | G2: =IF(A2=Results!$B$5,Inputs!$B$27*(1-Inputs!$B$28),0) -> 0 | H2: =-Results!B3 -> -8944000 | I2: =1/(1+Inputs!$B$13)^A2 -> 1 | J2: =H2*I2 -> -8944000 | K2: =-Results!B3 -> -8944000 | L2: =IF(B2>0,Inputs!$B$2*Inputs!$B$14*Inputs!$B$15*(1+Inputs!$B$18)^(B2-1)*I2,0) -> 0 | N2: =J2 -> -8944000
A3: 1 | B3: =IF(AND(A3>Results!$B$4,A3<=Results!$B$5),A3-Results!$B$4,0) -> 0 | C3: =IF(B3>0,Inputs!$B$16*(1+Inputs!$B$18)^(B3-1),0) -> 0 | D3: =IF(B3>0,Inputs!$B$2*Inputs!$B$14*Inputs!$B$15*C3,0) -> 0 | E3: =IF(B3>0,(Inputs!$B$20+Inputs!$B$21+Inputs!$B$2*Inputs!$B$14*(Inputs!$B$22+Inputs!$B$23)+(Inputs!$B$2*Inputs!$B$3*Inputs!$B$5+Inputs!$B$6)*Inputs!$B$24)*(1+Inputs!$B$19)^(B3-1),0) -> 0 | F3: =IF(AND(B3>0,B3<Inputs!$B$12,MOD(B3,Inputs!$B$25)=0),Inputs!$B$26*(1+Inputs!$B$19)^(B3-1),0) -> 0 | G3: =IF(A3=Results!$B$5,Inputs!$B$27*(1-Inputs!$B$28),0) -> 0 | H3: =D3-E3-F3+G3 -> 0 | I3: =1/(1+Inputs!$B$13)^A3 -> 0.94339623 | J3: =H3*I3 -> 0 | K3: =K2+H3-G3 -> -8944000 | L3: =IF(B3>0,Inputs!$B$2*Inputs!$B$14*Inputs!$B$15*(1+Inputs!$B$18)^(B3-1)*I3,0) -> 0 | M3: =IF(AND(K3>=0,K2<0),A3-1-K2/(H3-G3),"") | N3: =N2+J3-G3*I3 -> -8944000 | O3: =IF(AND(N3>=0,N2<0),A3-1-N2/((H3-G3)*I3),"")
A4: 2 | B4: =IF(AND(A4>Results!$B$4,A4<=Results!$B$5),A4-Results!$B$4,0) -> 0 | C4: =IF(B4>0,Inputs!$B$16*(1+Inputs!$B$18)^(B4-1),0) -> 0 | D4: =IF(B4>0,Inputs!$B$2*Inputs!$B$14*Inputs!$B$15*C4,0) -> 0 | E4: =IF(B4>0,(Inputs!$B$20+Inputs!$B$21+Inputs!$B$2*Inputs!$B$14*(Inputs!$B$22+Inputs!$B$23)+(Inputs!$B$2*Inputs!$B$3*Inputs!$B$5+Inputs!$B$6)*Inputs!$B$24)*(1+Inputs!$B$19)^(B4-1),0) -> 0 | F4: =IF(AND(B4>0,B4<Inputs!$B$12,MOD(B4,Inputs!$B$25)=0),Inputs!$B$26*(1+Inputs!$B$19)^(B4-1),0) -> 0 | G4: =IF(A4=Results!$B$5,Inputs!$B$27*(1-Inputs!$B$28),0) -> 0 | H4: =D4-E4-F4+G4 -> 0 | I4: =1/(1+Inputs!$B$13)^A4 -> 0.88999644 | J4: =H4*I4 -> 0 | K4: =K3+H4-G4 -> -8944000 | L4: =IF(B4>0,Inputs!$B$2*Inputs!$B$14*Inputs!$B$15*(1+Inputs!$B$18)^(B4-1)*I4,0) -> 0 | M4: =IF(AND(K4>=0,K3<0),A4-1-K3/(H4-G4),"") | N4: =N3+J4-G4*I4 -> -8944000 | O4: =IF(AND(N4>=0,N3<0),A4-1-N3/((H4-G4)*I4),"")
A5: 3 | B5: =IF(AND(A5>Results!$B$4,A5<=Results!$B$5),A5-Results!$B$4,0) -> 1 | C5: =IF(B5>0,Inputs!$B$16*(1+Inputs!$B$18)^(B5-1),0) -> 600 | D5: =IF(B5>0,Inputs!$B$2*Inputs!$B$14*Inputs!$B$15*C5,0) -> 684000 | E5: =IF(B5>0,(Inputs!$B$20+Inputs!$B$21+Inputs!$B$2*Inputs!$B$14*(Inputs!$B$22+Inputs!$B$23)+(Inputs!$B$2*Inputs!$B$3*Inputs!$B$5+Inputs!$B$6)*Inputs!$B$24)*(1+Inputs!$B$19)^(B5-1),0) -> 268000 | F5: =IF(AND(B5>0,B5<Inputs!$B$12,MOD(B5,Inputs!$B$25)=0),Inputs!$B$26*(1+Inputs!$B$19)^(B5-1),0) -> 0 | G5: =IF(A5=Results!$B$5,Inputs!$B$27*(1-Inputs!$B$28),0) -> 0 | H5: =D5-E5-F5+G5 -> 416000 | I5: =1/(1+Inputs!$B$13)^A5 -> 0.83961928 | J5: =H5*I5 -> 349281.62 | K5: =K4+H5-G5 -> -8528000 | L5: =IF(B5>0,Inputs!$B$2*Inputs!$B$14*Inputs!$B$15*(1+Inputs!$B$18)^(B5-1)*I5,0) -> 957.16598 | M5: =IF(AND(K5>=0,K4<0),A5-1-K4/(H5-G5),"") | N5: =N4+J5-G5*I5 -> -8594718.4 | O5: =IF(AND(N5>=0,N4<0),A5-1-N4/((H5-G5)*I5),"")
A6: 4 | B6: =IF(AND(A6>Results!$B$4,A6<=Results!$B$5),A6-Results!$B$4,0) -> 2 | C6: =IF(B6>0,Inputs!$B$16*(1+Inputs!$B$18)^(B6-1),0) -> 612 | D6: =IF(B6>0,Inputs!$B$2*Inputs!$B$14*Inputs!$B$15*C6,0) -> 697680 | E6: =IF(B6>0,(Inputs!$B$20+Inputs!$B$21+Inputs!$B$2*Inputs!$B$14*(Inputs!$B$22+Inputs!$B$23)+(Inputs!$B$2*Inputs!$B$3*Inputs!$B$5+Inputs!$B$6)*Inputs!$B$24)*(1+Inputs!$B$19)^(B6-1),0) -> 274700 | F6: =IF(AND(B6>0,B6<Inputs!$B$12,MOD(B6,Inputs!$B$25)=0),Inputs!$B$26*(1+Inputs!$B$19)^(B6-1),0) -> 0 | G6: =IF(A6=Results!$B$5,Inputs!$B$27*(1-Inputs!$B$28),0) -> 0 | H6: =D6-E6-F6+G6 -> 422980 | I6: =1/(1+Inputs!$B$13)^A6 -> 0.79209366 | J6: =H6*I6 -> 335039.78 | K6: =K5+H6-G6 -> -8105020 | L6: =IF(B6>0,Inputs!$B$2*Inputs!$B$14*Inputs!$B$15*(1+Inputs!$B$18)^(B6-1)*I6,0) -> 921.04651 | M6: =IF(AND(K6>=0,K5<0),A6-1-K5/(H6-G6),"") | N6: =N5+J6-G6*I6 -> -8259678.6 | O6: =IF(AND(N6>=0,N5<0),A6-1-N5/((H6-G6)*I6),"")
A7: 5 | B7: =IF(AND(A7>Results!$B$4,A7<=Results!$B$5),A7-Results!$B$4,0) -> 3 | C7: =IF(B7>0,Inputs!$B$16*(1+Inputs!$B$18)^(B7-1),0) -> 624.24 | D7: =IF(B7>0,Inputs!$B$2*Inputs!$B$14*Inputs!$B$15*C7,0) -> 711633.6 | E7: =IF(B7>0,(Inputs!$B$20+Inputs!$B$21+Inputs!$B$2*Inputs!$B$14*(Inputs!$B$22+Inputs!$B$23)+(Inputs!$B$2*Inputs!$B$3*Inputs!$B$5+Inputs!$B$6)*Inputs!$B$24)*(1+Inputs!$B$19)^(B7-1),0) -> 281567.5 | F7: =IF(AND(B7>0,B7<Inputs!$B$12,MOD(B7,Inputs!$B$25)=0),Inputs!$B$26*(1+Inputs!$B$19)^(B7-1),0) -> 0 | G7: =IF(A7=Results!$B$5,Inputs!$B$27*(1-Inputs!$B$28),0) -> 0 | H7: =D7-E7-F7+G7 -> 430066.1 | I7: =1/(1+Inputs!$B$13)^A7 -> 0.74725817 | J7: =H7*I7 -> 321370.41 | K7: =K6+H7-G7 -> -7674953.9 | L7: =IF(B7>0,Inputs!$B$2*Inputs!$B$14*Inputs!$B$15*(1+Inputs!$B$18)^(B7-1)*I7,0) -> 886.29004 | M7: =IF(AND(K7>=0,K6<0),A7-1-K6/(H7-G7),"") | N7: =N6+J7-G7*I7 -> -7938308.2 | O7: =IF(AND(N7>=0,N6<0),A7-1-N6/((H7-G7)*I7),"")
A8: 6 | B8: =IF(AND(A8>Results!$B$4,A8<=Results!$B$5),A8-Results!$B$4,0) -> 4 | C8: =IF(B8>0,Inputs!$B$16*(1+Inputs!$B$18)^(B8-1),0) -> 636.7248 | D8: =IF(B8>0,Inputs!$B$2*Inputs!$B$14*Inputs!$B$15*C8,0) -> 725866.27 | E8: =IF(B8>0,(Inputs!$B$20+Inputs!$B$21+Inputs!$B$2*Inputs!$B$14*(Inputs!$B$22+Inputs!$B$23)+(Inputs!$B$2*Inputs!$B$3*Inputs!$B$5+Inputs!$B$6)*Inputs!$B$24)*(1+Inputs!$B$19)^(B8-1),0) -> 288606.69 | F8: =IF(AND(B8>0,B8<Inputs!$B$12,MOD(B8,Inputs!$B$25)=0),Inputs!$B$26*(1+Inputs!$B$19)^(B8-1),0) -> 0 | G8: =IF(A8=Results!$B$5,Inputs!$B$27*(1-Inputs!$B$28),0) -> 0 | H8: =D8-E8-F8+G8 -> 437259.58 | I8: =1/(1+Inputs!$B$13)^A8 -> 0.70496054 | J8: =H8*I8 -> 308250.75 | K8: =K7+H8-G8 -> -7237694.3 | L8: =IF(B8>0,Inputs!$B$2*Inputs!$B$14*Inputs!$B$15*(1+Inputs!$B$18)^(B8-1)*I8,0) -> 852.84513 | M8: =IF(AND(K8>=0,K7<0),A8-1-K7/(H8-G8),"") | N8: =N7+J8-G8*I8 -> -7630057.4 | O8: =IF(AND(N8>=0,N7<0),A8-1-N7/((H8-G8)*I8),"")
A9: 7 | B9: =IF(AND(A9>Results!$B$4,A9<=Results!$B$5),A9-Results!$B$4,0) -> 5 | C9: =IF(B9>0,Inputs!$B$16*(1+Inputs!$B$18)^(B9-1),0) -> 649.4593 | D9: =IF(B9>0,Inputs!$B$2*Inputs!$B$14*Inputs!$B$15*C9,0) -> 740383.6 | E9: =IF(B9>0,(Inputs!$B$20+Inputs!$B$21+Inputs!$B$2*Inputs!$B$14*(Inputs!$B$22+Inputs!$B$23)+(Inputs!$B$2*Inputs!$B$3*Inputs!$B$5+Inputs!$B$6)*Inputs!$B$24)*(1+Inputs!$B$19)^(B9-1),0) -> 295821.85 | F9: =IF(AND(B9>0,B9<Inputs!$B$12,MOD(B9,Inputs!$B$25)=0),Inputs!$B$26*(1+Inputs!$B$19)^(B9-1),0) -> 0 | G9: =IF(A9=Results!$B$5,Inputs!$B$27*(1-Inputs!$B$28),0) -> 0 | H9: =D9-E9-F9+G9 -> 444561.74 | I9: =1/(1+Inputs!$B$13)^A9 -> 0.66505711 | J9: =H9*I9 -> 295658.95 | K9: =K8+H9-G9 -> -6793132.6 | L9: =IF(B9>0,Inputs!$B$2*Inputs!$B$14*Inputs!$B$15*(1+Inputs!$B$18)^(B9-1)*I9,0) -> 820.6623 | M9: =IF(AND(K9>=0,K8<0),A9-1-K8/(H9-G9),"") | N9: =N8+J9-G9*I9 -> -7334398.5 | O9: =IF(AND(N9>=0,N8<0),A9-1-N8/((H9-G9)*I9),"")
A10: 8 | B10: =IF(AND(A10>Results!$B$4,A10<=Results!$B$5),A10-Results!$B$4,0) -> 6 | C10: =IF(B10>0,Inputs!$B$16*(1+Inputs!$B$18)^(B10-1),0) -> 662.44848 | D10: =IF(B10>0,Inputs!$B$2*Inputs!$B$14*Inputs!$B$15*C10,0) -> 755191.27 | E10: =IF(B10>0,(Inputs!$B$20+Inputs!$B$21+Inputs!$B$2*Inputs!$B$14*(Inputs!$B$22+Inputs!$B$23)+(Inputs!$B$2*Inputs!$B$3*Inputs!$B$5+Inputs!$B$6)*Inputs!$B$24)*(1+Inputs!$B$19)^(B10-1),0) -> 303217.4 | F10: =IF(AND(B10>0,B10<Inputs!$B$12,MOD(B10,Inputs!$B$25)=0),Inputs!$B$26*(1+Inputs!$B$19)^(B10-1),0) -> 0 | G10: =IF(A10=Results!$B$5,Inputs!$B$27*(1-Inputs!$B$28),0) -> 0 | H10: =D10-E10-F10+G10 -> 451973.87 | I10: =1/(1+Inputs!$B$13)^A10 -> 0.62741237 | J10: =H10*I10 -> 283574 | K10: =K9+H10-G10 -> -6341158.7 | L10: =IF(B10>0,Inputs!$B$2*Inputs!$B$14*Inputs!$B$15*(1+Inputs!$B$18)^(B10-1)*I10,0) -> 789.69391 | M10: =IF(AND(K10>=0,K9<0),A10-1-K9/(H10-G10),"") | N10: =N9+J10-G10*I10 -> -7050824.5 | O10: =IF(AND(N10>=0,N9<0),A10-1-N9/((H10-G10)*I10),"")
A11: 9 | B11: =IF(AND(A11>Results!$B$4,A11<=Results!$B$5),A11-Results!$B$4,0) -> 7 | C11: =IF(B11>0,Inputs!$B$16*(1+Inputs!$B$18)^(B11-1),0) -> 675.69745 | D11: =IF(B11>0,Inputs!$B$2*Inputs!$B$14*Inputs!$B$15*C11,0) -> 770295.09 | E11: =IF(B11>0,(Inputs!$B$20+Inputs!$B$21+Inputs!$B$2*Inputs!$B$14*(Inputs!$B$22+Inputs!$B$23)+(Inputs!$B$2*Inputs!$B$3*Inputs!$B$5+Inputs!$B$6)*Inputs!$B$24)*(1+Inputs!$B$19)^(B11-1),0) -> 310797.84 | F11: =IF(AND(B11>0,B11<Inputs!$B$12,MOD(B11,Inputs!$B$25)=0),Inputs!$B$26*(1+Inputs!$B$19)^(B11-1),0) -> 0 | G11: =IF(A11=Results!$B$5,Inputs!$B$27*(1-Inputs!$B$28),0) -> 0 | H11: =D11-E11-F11+G11 -> 459497.26 | I11: =1/(1+Inputs!$B$13)^A11 -> 0.59189846 | J11: =H11*I11 -> 271975.72 | K11: =K10+H11-G11 -> -5881661.4 | L11: =IF(B11>0,Inputs!$B$2*Inputs!$B$14*Inputs!$B$15*(1+Inputs!$B$18)^(B11-1)*I11,0) -> 759.89414 | M11: =IF(AND(K11>=0,K10<0),A11-1-K10/(H11-G11),"") | N11: =N10+J11-G11*I11 -> -6778848.8 | O11: =IF(AND(N11>=0,N10<0),A11-1-N10/((H11-G11)*I11),"")
A12: 10 | B12: =IF(AND(A12>Results!$B$4,A12<=Results!$B$5),A12-Results!$B$4,0) -> 8 | C12: =IF(B12>0,Inputs!$B$16*(1+Inputs!$B$18)^(B12-1),0) -> 689.2114 | D12: =IF(B12>0,Inputs!$B$2*Inputs!$B$14*Inputs!$B$15*C12,0) -> 785701 | E12: =IF(B12>0,(Inputs!$B$20+Inputs!$B$21+Inputs!$B$2*Inputs!$B$14*(Inputs!$B$22+Inputs!$B$23)+(Inputs!$B$2*Inputs!$B$3*Inputs!$B$5+Inputs!$B$6)*Inputs!$B$24)*(1+Inputs!$B$19)^(B12-1),0) -> 318567.78 | F12: =IF(AND(B12>0,B12<Inputs!$B$12,MOD(B12,Inputs!$B$25)=0),Inputs!$B$26*(1+Inputs!$B$19)^(B12-1),0) -> 0 | G12: =IF(A12=Results!$B$5,Inputs!$B$27*(1-Inputs!$B$28),0) -> 0 | H12: =D12-E12-F12+G12 -> 467133.21 | I12: =1/(1+Inputs!$B$13)^A12 -> 0.55839478 | J12: =H12*I12 -> 260844.75 | K12: =K11+H12-G12 -> -5414528.2 | L12: =IF(B12>0,Inputs!$B$2*Inputs!$B$14*Inputs!$B$15*(1+Inputs!$B$18)^(B12-1)*I12,0) -> 731.21889 | M12: =IF(AND(K12>=0,K11<0),A12-1-K11/(H12-G12),"") | N12: =N11+J12-G12*I12 -> -6518004 | O12: =IF(AND(N12>=0,N11<0),A12-1-N11/((H12-G12)*I12),"")
A13: 11 | B13: =IF(AND(A13>Results!$B$4,A13<=Results!$B$5),A13-Results!$B$4,0) -> 9 | C13: =IF(B13>0,Inputs!$B$16*(1+Inputs!$B$18)^(B13-1),0) -> 702.99563 | D13: =IF(B13>0,Inputs!$B$2*Inputs!$B$14*Inputs!$B$15*C13,0) -> 801415.02 | E13: =IF(B13>0,(Inputs!$B$20+Inputs!$B$21+Inputs!$B$2*Inputs!$B$14*(Inputs!$B$22+Inputs!$B$23)+(Inputs!$B$2*Inputs!$B$3*Inputs!$B$5+Inputs!$B$6)*Inputs!$B$24)*(1+Inputs!$B$19)^(B13-1),0) -> 326531.98 | F13: =IF(AND(B13>0,B13<Inputs!$B$12,MOD(B13,Inputs!$B$25)=0),Inputs!$B$26*(1+Inputs!$B$19)^(B13-1),0) -> 0 | G13: =IF(A13=Results!$B$5,Inputs!$B$27*(1-Inputs!$B$28),0) -> 0 | H13: =D13-E13-F13+G13 -> 474883.04 | I13: =1/(1+Inputs!$B$13)^A13 -> 0.52678753 | J13: =H13*I13 -> 250162.46 | K13: =K12+H13-G13 -> -4939645.2 | L13: =IF(B13>0,Inputs!$B$2*Inputs!$B$14*Inputs!$B$15*(1+Inputs!$B$18)^(B13-1)*I13,0) -> 703.62572 | M13: =IF(AND(K13>=0,K12<0),A13-1-K12/(H13-G13),"") | N13: =N12+J13-G13*I13 -> -6267841.6 | O13: =IF(AND(N13>=0,N12<0),A13-1-N12/((H13-G13)*I13),"")
A14: 12 | B14: =IF(AND(A14>Results!$B$4,A14<=Results!$B$5),A14-Results!$B$4,0) -> 10 | C14: =IF(B14>0,Inputs!$B$16*(1+Inputs!$B$18)^(B14-1),0) -> 717.05554 | D14: =IF(B14>0,Inputs!$B$2*Inputs!$B$14*Inputs!$B$15*C14,0) -> 817443.32 | E14: =IF(B14>0,(Inputs!$B$20+Inputs!$B$21+Inputs!$B$2*Inputs!$B$14*(Inputs!$B$22+Inputs!$B$23)+(Inputs!$B$2*Inputs!$B$3*Inputs!$B$5+Inputs!$B$6)*Inputs!$B$24)*(1+Inputs!$B$19)^(B14-1),0) -> 334695.28 | F14: =IF(AND(B14>0,B14<Inputs!$B$12,MOD(B14,Inputs!$B$25)=0),Inputs!$B$26*(1+Inputs!$B$19)^(B14-1),0) -> 0 | G14: =IF(A14=Results!$B$5,Inputs!$B$27*(1-Inputs!$B$28),0) -> 0 | H14: =D14-E14-F14+G14 -> 482748.04 | I14: =1/(1+Inputs!$B$13)^A14 -> 0.49696936 | J14: =H14*I14 -> 239910.99 | K14: =K13+H14-G14 -> -4456897.1 | L14: =IF(B14>0,Inputs!$B$2*Inputs!$B$14*Inputs!$B$15*(1+Inputs!$B$18)^(B14-1)*I14,0) -> 677.07381 | M14: =IF(AND(K14>=0,K13<0),A14-1-K13/(H14-G14),"") | N14: =N13+J14-G14*I14 -> -6027930.6 | O14: =IF(AND(N14>=0,N13<0),A14-1-N13/((H14-G14)*I14),"")
... A62: 60 | B62: =IF(AND(A62>Results!$B$4,A62<=Results!$B$5),A62-Results!$B$4,0) -> 0 | C62: =IF(B62>0,Inputs!$B$16*(1+Inputs!$B$18)^(B62-1),0) -> 0 | D62: =IF(B62>0,Inputs!$B$2*Inputs!$B$14*Inputs!$B$15*C62,0) -> 0 | E62: =IF(B62>0,(Inputs!$B$20+Inputs!$B$21+Inputs!$B$2*Inputs!$B$14*(Inputs!$B$22+Inputs!$B$23)+(Inputs!$B$2*Inputs!$B$3*Inputs!$B$5+Inputs!$B$6)*Inputs!$B$24)*(1+Inputs!$B$19)^(B62-1),0) -> 0 | F62: =IF(AND(B62>0,B62<Inputs!$B$12,MOD(B62,Inputs!$B$25)=0),Inputs!$B$26*(1+Inputs!$B$19)^(B62-1),0) -> 0 | G62: =IF(A62=Results!$B$5,Inputs!$B$27*(1-Inputs!$B$28),0) -> 0 | H62: =D62-E62-F62+G62 -> 0 | I62: =1/(1+Inputs!$B$13)^A62 -> 0.030314338 | J62: =H62*I62 -> 0 | K62: =K61+H62-G62 -> 13269258 | L62: =IF(B62>0,Inputs!$B$2*Inputs!$B$14*Inputs!$B$15*(1+Inputs!$B$18)^(B62-1)*I62,0) -> 0 | M62: =IF(AND(K62>=0,K61<0),A62-1-K61/(H62-G62),"") | N62: =N61+J62-G62*I62 -> -2280501.3 | O62: =IF(AND(N62>=0,N61<0),A62-1-N61/((H62-G62)*I62),"")

Sheet Results
A1: Metric | B1: Value | C1: Interpretation
A2: Gross initial investment | B2: =Inputs!$B$4+Inputs!$B$2*Inputs!$B$3*Inputs!$B$5+Inputs!$B$6+(Inputs!$B$2*Inputs!$B$3*Inputs!$B$5+Inputs!$B$6)*Inputs!$B$7+(Inputs!$B$2*Inputs!$B$3*Inputs!$B$5+Inputs!$B$6)*(1+Inputs!$B$7)*Inputs!$B$8+Inputs!$B$9 -> 8944000 | C2: Includes contingency; no subsidy deduction
A3: Investor initial cash | B3: =B2-Inputs!$B$10 -> 8944000 | C3: Gross investment less committed upfront subsidy
A4: Construction years | B4: =ROUNDUP(Inputs!$B$11/12,0) -> 2 | C4: Conservative rounding; full-year operating model
A5: Final cash-flow year | B5: =B4+Inputs!$B$12 -> 42 | C5: Construction + operating life
A6: NPV | B6: =SUM('Cash flow'!J2:J62) -> -2280501.3 | C6: Project NPV including terminal value
A7: IRR | B7: =IFERROR(IRR('Cash flow'!H2:H62),"No IRR") -> 0.042735164 | C7: Annual project IRR; check sign changes
A8: Simple PBP (years) | B8: =IF(COUNT('Cash flow'!M3:M62)>0,MIN('Cash flow'!M3:M62),"Not recovered") -> 21.286046 | C8: From time 0; interpolated annual cash; excludes terminal sale
A9: Student price P | B9: =Inputs!$B$16 -> 600 | C9: Initial monthly all-in rent
A10: Student affordability cap | B10: =Inputs!$B$17 -> 650 | C10: Editable student budget threshold
A11: Required initial rent for NPV = 0 | B11: =MAX(0,(Inputs!$B$16*SUM('Cash flow'!L3:L62)-B6)/SUM('Cash flow'!L3:L62)) -> 714.48412 | C11: Investor break-even price given all other inputs
A12: NPV at affordability cap | B12: =B6+(Inputs!$B$17-Inputs!$B$16)*SUM('Cash flow'!L3:L62) -> -1284511 | C12: Feasibility under student cap
A13: Upfront subsidy needed at cap | B13: =MAX(0,-B12) -> 1284511 | C13: Additional time-0 grant / cost reduction required
A14: Maximum investor capital at cap | B14: =B3+B12 -> 7659489 | C14: PV of future net cash flows at capped rent
A15: Joint feasibility | B15: =IF(B11<=B10,"Feasible under assumptions","Funding / cost gap") -> Funding / cost gap | C15: A positive gap cannot be solved by choosing an arbitrary rent
A16: Recommended student price | B16: =IF(B11<=B10,B11,"No feasible price under cap") -> No feasible price under cap | C16: Lowest price meeting NPV >= 0 at selected discount rate
A17: First full operating year | B17: =B4+1 -> 3 | C17: Minimum safe planning time requires site and permit evidence
A18: Input check | B18: =IF(AND(Inputs!B10<=B2,Inputs!B14>0,B5<=60),"OK","CHECK subsidy, occupancy or horizon") -> OK | C18: Subsidy must not exceed gross investment; positive occupancy required
A19: Discounted PBP (years) | B19: =IF(COUNT('Cash flow'!O3:O62)>0,MIN('Cash flow'!O3:O62),"Not recovered") -> Not recovered | C19: Discounted at project hurdle; excludes terminal sale
A20: Capital per room | B20: =B2/'Inputs'!B2 -> 89440 | C20: Gross investment / room, including allocated common area and land
A21: Shortest construction scenario | B21: =MIN(Scenarios!D2:D4) -> 12 | C21: Months, only within the assumed scenarios; not a validated project schedule
A22: Longest useful-life scenario | B22: =MAX(Scenarios!F2:F4) -> 50 | C22: Operating years, only within scenarios; needs engineering validation
A23: Investment recommendation | B23: =IF(B12>=0,"Proceed to project-specific due diligence","Revise cost / secure subsidy before proceeding") -> Revise cost / secure subsidy before proceeding | C23: Conditional result, not a verified investment decision
A24: Lowest feasible scenario capital | B24: =IF(MAX(Scenarios!K2:K4)<0,"No feasible scenario",MIN(IF(Scenarios!K2>=0,Scenarios!G2,1E+99),IF(Scenarios!K3>=0,Scenarios!G3,1E+99),IF(Scenarios!K4>=0,Scenarios!G4,1E+99))) -> 7855000 | C24: Minimum only among illustrative scenarios meeting NPV >= 0 at affordability cap. Design feasibility and quality must be independently confirmed.

Sheet Sources
A1: Source | B1: URL | C1: Verified / published | D1: Use and limits
A2: Perspective monitoring student housing | B2: https://beecole.brussels/sites/default/files/documents/fr_monitoring_logement_etudiant_final2026.pdf | C2: 2026-10-14 / January 2026 | D2: Official regional report. Reports rising student rents; supports affordability concern, not model cost assumptions.
A3: Brussels rental steps | B3: https://be.brussels/fr/logement/location/les-differentes-etapes-de-la-location | C3: 2026-10-14 | D3: Official guidance: student leases are 12 months. 12 billed months still requires occupancy and lease validation.
A4: Brussels student housing label | B4: https://be.brussels/fr/logement/location/conformite-logement/label-logement-etudiant | C4: 2026-10-14 | D4: Quality label lasts 5 years; quality declaration, student lease and valid energy certificate requested. Does not certify model compliance.
A5: Required project evidence | B5: Not yet provided | C5: Unverified | D5: Site offer; VAT-inclusive bill of quantities; architect/engineer design; planning/fire/energy requirements; staffing and utility quotes; discount rate rationale; student budget survey; insurance; grants; tax and financing terms.

Sheet Prompt
A1: Step | B1: Reusable prompt / deliverable
A2: Role and goal | B2: Act as a decision analyst for student housing in Brussels. Build an auditable Excel project model balancing student affordability and investor returns. Do not invent verified inputs or promise a single correct forecast.
A3: Gather inputs | B3: For each input give value, unit, currency year, source URL/date, confidence and low/base/high range. Gather land price, room count and gross area, construction and facilities quotes, fees, VAT, utilities, fixed and variable operations, fully loaded wages, maintenance, major refurbishment, occupancy, billing months, nominal discount rate, escalation, construction schedule, useful life, subsidy, terminal value and student all-in budget cap. Mark missing project inputs and use clearly labelled illustrative assumptions.
A4: Financial conventions | B4: State unlevered/levered and pre/post-tax basis. Keep real/nominal discounting consistent. Avoid counting utilities, maintenance and renovation twice. Explain whether acquisition and construction are staged; if simplified upfront, say so. Use full monthly or dated cash flows if schedule detail permits.
A5: Required outputs | B5: Compute project NPV, annual IRR with sign-change warning, simple and discounted payback excluding residual sale; report initial and future student all-in price P, gross capital and investor funding. Show no-payback and no-feasible-price outcomes explicitly.
A6: Optimization | B6: For each technically feasible design hold minimum room capacity, code compliance and service quality fixed. Minimize student price subject to NPV >= 0 and P <= affordability cap. Compare design alternatives for lowest feasible capital, fastest evidenced delivery and longest evidenced useful life, including lifecycle refurbishment. Present Pareto tradeoffs rather than independently minimizing everything. If infeasible, quantify subsidy/cost-reduction gap and explain why.
A7: Risk and corruption | B7: Use low/base/high cost, occupancy, timing and discount-rate scenarios. Separate contingency from expected-event loss; apply probability only with evidence. Treat corruption as a governance risk via legal audit, procurement controls and delay/overrun stress, never as a planned illegal payment.
A8: Results and pitfalls | B8: Provide a conditional recommendation, assumptions that drive it, sensitivity, sources and unanswered questions. Warn about optimistic occupancy, nominal/real mismatch, VAT, rent/charge mixing, unsupported terminal values, planning delays, missed refurbishment, IRR ambiguity and optimization without constraints. Never infer engineering lifetime or legal compliance from a spreadsheet.
A9: Delivery | B9: Deliver model.xlsx with editable inputs, live formulas, annual cash flows, financial results, scenarios, checks and source register. Include enough code to reproduce and audit calculations.

Sheet Risks
A1: Pitfall / missing evidence | B1: Effect | C1: Action
A2: Site and construction quotes missing | B2: Capital estimate may be materially wrong | C2: Obtain tender with VAT, fees, land and utility connections
A3: Force majeure | B3: Cost increase and opening delay | C3: Stress cost +20%, delay +12 months; review insurance and contingency
A4: Corruption / procurement misconduct | B4: Delay, legal cost, contract failure | C4: Transparent tenders, independent audit, conflicts register; no illicit payment provision
A5: Life and schedule unverified | B5: Longer use or early opening can inflate valuation | C5: Engineering survey and permit critical path; compare scenario bounds, not factual min/max
A6: Discount rate / inflation | B6: Incorrect return hurdle | C6: Use matching nominal cash flows and nominal project discount rate
A7: Terminal value | B7: Sale assumption can dominate return | C7: Base case zero; sensitivity only with evidence
A8: Affordability cap | B8: Policy target can differ from student capacity | C8: Survey disposable budget and utilities; track future rent
A9: Tax and debt excluded | B9: Project IRR differs from equity IRR | C9: Extend after structure is known; no investment advice implied

Sheet Scenarios
A1: Scenario | B1: Construction factor | C1: Occupancy | D1: Duration months | E1: Discount rate | F1: Life years | G1: Gross capital | H1: NPV | I1: IRR | J1: Required P | K1: NPV at cap | L1: Extra subsidy | M1: PBP
A2: Base | B2: 1 | C2: =Inputs!B14 -> 0.95 | D2: =Inputs!B11 -> 18 | E2: =Inputs!B13 -> 0.06 | F2: =Inputs!B12 -> 40 | G2: ='S1 results'!B2 -> 8944000 | H2: ='S1 results'!B6 -> -2280501.3 | I2: ='S1 results'!B7 -> 0.042735164 | J2: ='S1 results'!B11 -> 714.48412 | K2: ='S1 results'!B12 -> -1284511 | L2: ='S1 results'!B13 -> 1284511 | M2: ='S1 results'!B8 -> 21.286046
A3: Lower-cost / fast | B3: 0.85 | C3: 0.98 | D3: 12 | E3: 0.05 | F3: 50 | G3: ='S2 results'!B2 -> 7855000 | H3: ='S2 results'!B6 -> 1858249.8 | I3: ='S2 results'!B7 -> 0.061996771 | J3: ='S2 results'!B11 -> 534.95933 | K3: ='S2 results'!B12 -> 3286779 | L3: ='S2 results'!B13 -> 0 | M3: ='S2 results'!B8 -> 17.37363
A4: Delay / overrun | B4: 1.2 | C4: 0.85 | D4: 30 | E4: 0.08 | F4: 30 | G4: ='S3 results'!B2 -> 10396000 | H4: ='S3 results'!B6 -> -6924346.9 | I4: ='S3 results'!B7 -> 0.010158838 | J4: ='S3 results'!B11 -> 1225.7368 | K4: ='S3 results'!B12 -> -6371051.4 | L4: ='S3 results'!B13 -> 6371051.4 | M4: ='S3 results'!B8 -> 28.732717
A5: Scenario interpretation | B5: All three are illustrative. Fastest = 12 months and longest = 50 years ONLY among these assumptions; not engineering estimates.
A6: Decision | B6: Base capital and minimum rent depend on a fixed 100-room design. A cheaper scenario is not proven technically achievable.

Sheet S1 inputs
A1: Input | B1: Value | C1: Unit | D1: Basis / assumption
A2: Rooms | B2: =Inputs!B2 -> 100 | C2: rooms | D2: Illustrative project; minimum capacity constraint
A3: Gross area per room | B3: =Inputs!B3 -> 30 | C3: m²/room | D3: Includes allocation of common areas
A4: Land / acquisition | B4: =Inputs!B4 -> 1200000 | C4: EUR | D4: Site-specific quotation needed
A5: Construction cost | B5: =Inputs!B5*Scenarios!B2 -> 2000 | C5: EUR/m² | D5: Illustrative; VAT inclusion must be checked
A6: Facilities | B6: =Inputs!B6 -> 400000 | C6: EUR | D6: Furniture and common equipment
A7: Professional fees | B7: =Inputs!B7 -> 0.1 | C7: share | D7: Of construction + facilities
A8: Force-majeure contingency | B8: =Inputs!B8 -> 0.1 | C8: share | D8: Of construction + facilities + fees
A9: Compliance / audit cost | B9: =Inputs!B9 -> 0 | C9: EUR | D9: Legal control costs; no unlawful payments
A10: Initial subsidy | B10: =Inputs!B10 -> 0 | C10: EUR | D10: Only committed funding should be used
A11: Construction duration | B11: =Scenarios!D2 -> 18 | C11: months | D11: Illustrative, including permitting
A12: Operating useful life | B12: =Scenarios!F2 -> 40 | C12: years | D12: Subject to engineering assessment and refurbishment
A13: Discount rate | B13: =Scenarios!E2 -> 0.06 | C13: annual | D13: Nominal unlevered required return
A14: Occupancy | B14: =Scenarios!C2 -> 0.95 | C14: share | D14: Average paying occupancy
A15: Rent / billing months | B15: =Inputs!B15 -> 12 | C15: months/year | D15: Check lease structure
A16: Student monthly all-in rent | B16: =Inputs!B16 -> 600 | C16: EUR/month | D16: Illustrative initial rent
A17: Affordability cap | B17: =Inputs!B17 -> 650 | C17: EUR/month | D17: Policy assumption; validate student budget
A18: Rent escalation | B18: =Inputs!B18 -> 0.02 | C18: annual | D18: Scenario assumption, not entitlement to index
A19: Operating cost escalation | B19: =Inputs!B19 -> 0.025 | C19: annual | D19: Nominal assumption
A20: Fixed operations | B20: =Inputs!B20 -> 30000 | C20: EUR/year | D20: Excludes wages, maintenance, utilities
A21: Wages incl. employer costs | B21: =Inputs!B21 -> 60000 | C21: EUR/year | D21: Illustrative annual staffing
A22: Variable operations | B22: =Inputs!B22 -> 300 | C22: EUR/occupied room/year | D22: Cleaning/administration, excludes utilities
A23: Utilities | B23: =Inputs!B23 -> 900 | C23: EUR/occupied room/year | D23: All-in rent model
A24: Maintenance reserve | B24: =Inputs!B24 -> 0.01 | C24: share/year | D24: Of construction + facilities; treated as annual cash expense
A25: Refurbishment interval | B25: =Inputs!B25 -> 15 | C25: operating years | D25: Every N years, before final operating year
A26: Refurbishment cost | B26: =Inputs!B26 -> 300000 | C26: EUR/event | D26: Today-price cost, escalates with operating costs
... A28: Sale costs | B28: =Inputs!B28 -> 0.02 | C28: share | D28: Of gross terminal value

Sheet S1 results
A1: Metric | B1: Value | C1: Interpretation
A2: Gross initial investment | B2: ='S1 inputs'!$B$4+'S1 inputs'!$B$2*'S1 inputs'!$B$3*'S1 inputs'!$B$5+'S1 inputs'!$B$6+('S1 inputs'!$B$2*'S1 inputs'!$B$3*'S1 inputs'!$B$5+'S1 inputs'!$B$6)*'S1 inputs'!$B$7+('S1 inputs'!$B$2*'S1 inputs'!$B$3*'S1 inputs'!$B$5+'S1 inputs'!$B$6)*(1+'S1 inputs'!$B$7)*'S1 inputs'!$B$8+'S1 inputs'!$B$9 -> 8944000 | C2: Includes contingency; no subsidy deduction
A3: Investor initial cash | B3: =B2-'S1 inputs'!$B$10 -> 8944000 | C3: Gross investment less committed upfront subsidy
A4: Construction years | B4: =ROUNDUP('S1 inputs'!$B$11/12,0) -> 2 | C4: Conservative rounding; full-year operating model
A5: Final cash-flow year | B5: =B4+'S1 inputs'!$B$12 -> 42 | C5: Construction + operating life
A6: NPV | B6: =SUM('S1 cash flow'!J2:J62) -> -2280501.3 | C6: Project NPV including terminal value
A7: IRR | B7: =IFERROR(IRR('S1 cash flow'!H2:H62),"No IRR") -> 0.042735164 | C7: Annual project IRR; check sign changes
A8: Simple PBP (years) | B8: =IF(COUNT('S1 cash flow'!M3:M62)>0,MIN('S1 cash flow'!M3:M62),"Not recovered") -> 21.286046 | C8: From time 0; interpolated annual cash; excludes terminal sale
A9: Student price P | B9: ='S1 inputs'!$B$16 -> 600 | C9: Initial monthly all-in rent
A10: Student affordability cap | B10: ='S1 inputs'!$B$17 -> 650 | C10: Editable student budget threshold
A11: Required initial rent for NPV = 0 | B11: =MAX(0,('S1 inputs'!$B$16*SUM('S1 cash flow'!L3:L62)-B6)/SUM('S1 cash flow'!L3:L62)) -> 714.48412 | C11: Investor break-even price given all other inputs
A12: NPV at affordability cap | B12: =B6+('S1 inputs'!$B$17-'S1 inputs'!$B$16)*SUM('S1 cash flow'!L3:L62) -> -1284511 | C12: Feasibility under student cap
A13: Upfront subsidy needed at cap | B13: =MAX(0,-B12) -> 1284511 | C13: Additional time-0 grant / cost reduction required
A14: Maximum investor capital at cap | B14: =B3+B12 -> 7659489 | C14: PV of future net cash flows at capped rent
A15: Joint feasibility | B15: =IF(B11<=B10,"Feasible under assumptions","Funding / cost gap") -> Funding / cost gap | C15: A positive gap cannot be solved by choosing an arbitrary rent
A16: Recommended student price | B16: =IF(B11<=B10,B11,"No feasible price under cap") -> No feasible price under cap | C16: Lowest price meeting NPV >= 0 at selected discount rate
A17: First full operating year | B17: =B4+1 -> 3 | C17: Minimum safe planning time requires site and permit evidence
A18: Input check | B18: =IF(AND('S1 inputs'!B10<=B2,'S1 inputs'!B14>0,B5<=60),"OK","CHECK subsidy, occupancy or horizon") -> OK | C18: Subsidy must not exceed gross investment; positive occupancy required
A19: Discounted PBP (years) | B19: =IF(COUNT('S1 cash flow'!O3:O62)>0,MIN('S1 cash flow'!O3:O62),"Not recovered") -> Not recovered | C19: Discounted at project hurdle; excludes terminal sale
A20: Capital per room | B20: =B2/'S1 inputs'!B2 -> 89440 | C20: Gross investment / room, including allocated common area and land

Sheet S1 cash flow
A1: Year | B1: Operating year | C1: All-in rent / month | D1: Revenue | E1: Operating costs | F1: Refurbishment | G1: Terminal proceeds | H1: Net cash flow | I1: Discount factor | J1: PV cash flow | K1: Cumulative operating cash | L1: PV revenue per EUR rent | M1: Payback crossing year | N1: Cumulative discounted cash | O1: Discounted crossing year
A2: 0 | B2: =IF(AND(A2>'S1 results'!$B$4,A2<='S1 results'!$B$5),A2-'S1 results'!$B$4,0) -> 0 | C2: =IF(B2>0,'S1 inputs'!$B$16*(1+'S1 inputs'!$B$18)^(B2-1),0) -> 0 | D2: =IF(B2>0,'S1 inputs'!$B$2*'S1 inputs'!$B$14*'S1 inputs'!$B$15*C2,0) -> 0 | E2: =IF(B2>0,('S1 inputs'!$B$20+'S1 inputs'!$B$21+'S1 inputs'!$B$2*'S1 inputs'!$B$14*('S1 inputs'!$B$22+'S1 inputs'!$B$23)+('S1 inputs'!$B$2*'S1 inputs'!$B$3*'S1 inputs'!$B$5+'S1 inputs'!$B$6)*'S1 inputs'!$B$24)*(1+'S1 inputs'!$B$19)^(B2-1),0) -> 0 | F2: =IF(AND(B2>0,B2<'S1 inputs'!$B$12,MOD(B2,'S1 inputs'!$B$25)=0),'S1 inputs'!$B$26*(1+'S1 inputs'!$B$19)^(B2-1),0) -> 0 | G2: =IF(A2='S1 results'!$B$5,'S1 inputs'!$B$27*(1-'S1 inputs'!$B$28),0) -> 0 | H2: =-'S1 results'!B3 -> -8944000 | I2: =1/(1+'S1 inputs'!$B$13)^A2 -> 1 | J2: =H2*I2 -> -8944000 | K2: =-'S1 results'!B3 -> -8944000 | L2: =IF(B2>0,'S1 inputs'!$B$2*'S1 inputs'!$B$14*'S1 inputs'!$B$15*(1+'S1 inputs'!$B$18)^(B2-1)*I2,0) -> 0 | N2: =J2 -> -8944000
A3: 1 | B3: =IF(AND(A3>'S1 results'!$B$4,A3<='S1 results'!$B$5),A3-'S1 results'!$B$4,0) -> 0 | C3: =IF(B3>0,'S1 inputs'!$B$16*(1+'S1 inputs'!$B$18)^(B3-1),0) -> 0 | D3: =IF(B3>0,'S1 inputs'!$B$2*'S1 inputs'!$B$14*'S1 inputs'!$B$15*C3,0) -> 0 | E3: =IF(B3>0,('S1 inputs'!$B$20+'S1 inputs'!$B$21+'S1 inputs'!$B$2*'S1 inputs'!$B$14*('S1 inputs'!$B$22+'S1 inputs'!$B$23)+('S1 inputs'!$B$2*'S1 inputs'!$B$3*'S1 inputs'!$B$5+'S1 inputs'!$B$6)*'S1 inputs'!$B$24)*(1+'S1 inputs'!$B$19)^(B3-1),0) -> 0 | F3: =IF(AND(B3>0,B3<'S1 inputs'!$B$12,MOD(B3,'S1 inputs'!$B$25)=0),'S1 inputs'!$B$26*(1+'S1 inputs'!$B$19)^(B3-1),0) -> 0 | G3: =IF(A3='S1 results'!$B$5,'S1 inputs'!$B$27*(1-'S1 inputs'!$B$28),0) -> 0 | H3: =D3-E3-F3+G3 -> 0 | I3: =1/(1+'S1 inputs'!$B$13)^A3 -> 0.94339623 | J3: =H3*I3 -> 0 | K3: =K2+H3-G3 -> -8944000 | L3: =IF(B3>0,'S1 inputs'!$B$2*'S1 inputs'!$B$14*'S1 inputs'!$B$15*(1+'S1 inputs'!$B$18)^(B3-1)*I3,0) -> 0 | M3: =IF(AND(K3>=0,K2<0),A3-1-K2/(H3-G3),"") | N3: =N2+J3-G3*I3 -> -8944000 | O3: =IF(AND(N3>=0,N2<0),A3-1-N2/((H3-G3)*I3),"")
A4: 2 | B4: =IF(AND(A4>'S1 results'!$B$4,A4<='S1 results'!$B$5),A4-'S1 results'!$B$4,0) -> 0 | C4: =IF(B4>0,'S1 inputs'!$B$16*(1+'S1 inputs'!$B$18)^(B4-1),0) -> 0 | D4: =IF(B4>0,'S1 inputs'!$B$2*'S1 inputs'!$B$14*'S1 inputs'!$B$15*C4,0) -> 0 | E4: =IF(B4>0,('S1 inputs'!$B$20+'S1 inputs'!$B$21+'S1 inputs'!$B$2*'S1 inputs'!$B$14*('S1 inputs'!$B$22+'S1 inputs'!$B$23)+('S1 inputs'!$B$2*'S1 inputs'!$B$3*'S1 inputs'!$B$5+'S1 inputs'!$B$6)*'S1 inputs'!$B$24)*(1+'S1 inputs'!$B$19)^(B4-1),0) -> 0 | F4: =IF(AND(B4>0,B4<'S1 inputs'!$B$12,MOD(B4,'S1 inputs'!$B$25)=0),'S1 inputs'!$B$26*(1+'S1 inputs'!$B$19)^(B4-1),0) -> 0 | G4: =IF(A4='S1 results'!$B$5,'S1 inputs'!$B$27*(1-'S1 inputs'!$B$28),0) -> 0 | H4: =D4-E4-F4+G4 -> 0 | I4: =1/(1+'S1 inputs'!$B$13)^A4 -> 0.88999644 | J4: =H4*I4 -> 0 | K4: =K3+H4-G4 -> -8944000 | L4: =IF(B4>0,'S1 inputs'!$B$2*'S1 inputs'!$B$14*'S1 inputs'!$B$15*(1+'S1 inputs'!$B$18)^(B4-1)*I4,0) -> 0 | M4: =IF(AND(K4>=0,K3<0),A4-1-K3/(H4-G4),"") | N4: =N3+J4-G4*I4 -> -8944000 | O4: =IF(AND(N4>=0,N3<0),A4-1-N3/((H4-G4)*I4),"")
A5: 3 | B5: =IF(AND(A5>'S1 results'!$B$4,A5<='S1 results'!$B$5),A5-'S1 results'!$B$4,0) -> 1 | C5: =IF(B5>0,'S1 inputs'!$B$16*(1+'S1 inputs'!$B$18)^(B5-1),0) -> 600 | D5: =IF(B5>0,'S1 inputs'!$B$2*'S1 inputs'!$B$14*'S1 inputs'!$B$15*C5,0) -> 684000 | E5: =IF(B5>0,('S1 inputs'!$B$20+'S1 inputs'!$B$21+'S1 inputs'!$B$2*'S1 inputs'!$B$14*('S1 inputs'!$B$22+'S1 inputs'!$B$23)+('S1 inputs'!$B$2*'S1 inputs'!$B$3*'S1 inputs'!$B$5+'S1 inputs'!$B$6)*'S1 inputs'!$B$24)*(1+'S1 inputs'!$B$19)^(B5-1),0) -> 268000 | F5: =IF(AND(B5>0,B5<'S1 inputs'!$B$12,MOD(B5,'S1 inputs'!$B$25)=0),'S1 inputs'!$B$26*(1+'S1 inputs'!$B$19)^(B5-1),0) -> 0 | G5: =IF(A5='S1 results'!$B$5,'S1 inputs'!$B$27*(1-'S1 inputs'!$B$28),0) -> 0 | H5: =D5-E5-F5+G5 -> 416000 | I5: =1/(1+'S1 inputs'!$B$13)^A5 -> 0.83961928 | J5: =H5*I5 -> 349281.62 | K5: =K4+H5-G5 -> -8528000 | L5: =IF(B5>0,'S1 inputs'!$B$2*'S1 inputs'!$B$14*'S1 inputs'!$B$15*(1+'S1 inputs'!$B$18)^(B5-1)*I5,0) -> 957.16598 | M5: =IF(AND(K5>=0,K4<0),A5-1-K4/(H5-G5),"") | N5: =N4+J5-G5*I5 -> -8594718.4 | O5: =IF(AND(N5>=0,N4<0),A5-1-N4/((H5-G5)*I5),"")
A6: 4 | B6: =IF(AND(A6>'S1 results'!$B$4,A6<='S1 results'!$B$5),A6-'S1 results'!$B$4,0) -> 2 | C6: =IF(B6>0,'S1 inputs'!$B$16*(1+'S1 inputs'!$B$18)^(B6-1),0) -> 612 | D6: =IF(B6>0,'S1 inputs'!$B$2*'S1 inputs'!$B$14*'S1 inputs'!$B$15*C6,0) -> 697680 | E6: =IF(B6>0,('S1 inputs'!$B$20+'S1 inputs'!$B$21+'S1 inputs'!$B$2*'S1 inputs'!$B$14*('S1 inputs'!$B$22+'S1 inputs'!$B$23)+('S1 inputs'!$B$2*'S1 inputs'!$B$3*'S1 inputs'!$B$5+'S1 inputs'!$B$6)*'S1 inputs'!$B$24)*(1+'S1 inputs'!$B$19)^(B6-1),0) -> 274700 | F6: =IF(AND(B6>0,B6<'S1 inputs'!$B$12,MOD(B6,'S1 inputs'!$B$25)=0),'S1 inputs'!$B$26*(1+'S1 inputs'!$B$19)^(B6-1),0) -> 0 | G6: =IF(A6='S1 results'!$B$5,'S1 inputs'!$B$27*(1-'S1 inputs'!$B$28),0) -> 0 | H6: =D6-E6-F6+G6 -> 422980 | I6: =1/(1+'S1 inputs'!$B$13)^A6 -> 0.79209366 | J6: =H6*I6 -> 335039.78 | K6: =K5+H6-G6 -> -8105020 | L6: =IF(B6>0,'S1 inputs'!$B$2*'S1 inputs'!$B$14*'S1 inputs'!$B$15*(1+'S1 inputs'!$B$18)^(B6-1)*I6,0) -> 921.04651 | M6: =IF(AND(K6>=0,K5<0),A6-1-K5/(H6-G6),"") | N6: =N5+J6-G6*I6 -> -8259678.6 | O6: =IF(AND(N6>=0,N5<0),A6-1-N5/((H6-G6)*I6),"")
A7: 5 | B7: =IF(AND(A7>'S1 results'!$B$4,A7<='S1 results'!$B$5),A7-'S1 results'!$B$4,0) -> 3 | C7: =IF(B7>0,'S1 inputs'!$B$16*(1+'S1 inputs'!$B$18)^(B7-1),0) -> 624.24 | D7: =IF(B7>0,'S1 inputs'!$B$2*'S1 inputs'!$B$14*'S1 inputs'!$B$15*C7,0) -> 711633.6 | E7: =IF(B7>0,('S1 inputs'!$B$20+'S1 inputs'!$B$21+'S1 inputs'!$B$2*'S1 inputs'!$B$14*('S1 inputs'!$B$22+'S1 inputs'!$B$23)+('S1 inputs'!$B$2*'S1 inputs'!$B$3*'S1 inputs'!$B$5+'S1 inputs'!$B$6)*'S1 inputs'!$B$24)*(1+'S1 inputs'!$B$19)^(B7-1),0) -> 281567.5 | F7: =IF(AND(B7>0,B7<'S1 inputs'!$B$12,MOD(B7,'S1 inputs'!$B$25)=0),'S1 inputs'!$B$26*(1+'S1 inputs'!$B$19)^(B7-1),0) -> 0 | G7: =IF(A7='S1 results'!$B$5,'S1 inputs'!$B$27*(1-'S1 inputs'!$B$28),0) -> 0 | H7: =D7-E7-F7+G7 -> 430066.1 | I7: =1/(1+'S1 inputs'!$B$13)^A7 -> 0.74725817 | J7: =H7*I7 -> 321370.41 | K7: =K6+H7-G7 -> -7674953.9 | L7: =IF(B7>0,'S1 inputs'!$B$2*'S1 inputs'!$B$14*'S1 inputs'!$B$15*(1+'S1 inputs'!$B$18)^(B7-1)*I7,0) -> 886.29004 | M7: =IF(AND(K7>=0,K6<0),A7-1-K6/(H7-G7),"") | N7: =N6+J7-G7*I7 -> -7938308.2 | O7: =IF(AND(N7>=0,N6<0),A7-1-N6/((H7-G7)*I7),"")
A8: 6 | B8: =IF(AND(A8>'S1 results'!$B$4,A8<='S1 results'!$B$5),A8-'S1 results'!$B$4,0) -> 4 | C8: =IF(B8>0,'S1 inputs'!$B$16*(1+'S1 inputs'!$B$18)^(B8-1),0) -> 636.7248 | D8: =IF(B8>0,'S1 inputs'!$B$2*'S1 inputs'!$B$14*'S1 inputs'!$B$15*C8,0) -> 725866.27 | E8: =IF(B8>0,('S1 inputs'!$B$20+'S1 inputs'!$B$21+'S1 inputs'!$B$2*'S1 inputs'!$B$14*('S1 inputs'!$B$22+'S1 inputs'!$B$23)+('S1 inputs'!$B$2*'S1 inputs'!$B$3*'S1 inputs'!$B$5+'S1 inputs'!$B$6)*'S1 inputs'!$B$24)*(1+'S1 inputs'!$B$19)^(B8-1),0) -> 288606.69 | F8: =IF(AND(B8>0,B8<'S1 inputs'!$B$12,MOD(B8,'S1 inputs'!$B$25)=0),'S1 inputs'!$B$26*(1+'S1 inputs'!$B$19)^(B8-1),0) -> 0 | G8: =IF(A8='S1 results'!$B$5,'S1 inputs'!$B$27*(1-'S1 inputs'!$B$28),0) -> 0 | H8: =D8-E8-F8+G8 -> 437259.58 | I8: =1/(1+'S1 inputs'!$B$13)^A8 -> 0.70496054 | J8: =H8*I8 -> 308250.75 | K8: =K7+H8-G8 -> -7237694.3 | L8: =IF(B8>0,'S1 inputs'!$B$2*'S1 inputs'!$B$14*'S1 inputs'!$B$15*(1+'S1 inputs'!$B$18)^(B8-1)*I8,0) -> 852.84513 | M8: =IF(AND(K8>=0,K7<0),A8-1-K7/(H8-G8),"") | N8: =N7+J8-G8*I8 -> -7630057.4 | O8: =IF(AND(N8>=0,N7<0),A8-1-N7/((H8-G8)*I8),"")
A9: 7 | B9: =IF(AND(A9>'S1 results'!$B$4,A9<='S1 results'!$B$5),A9-'S1 results'!$B$4,0) -> 5 | C9: =IF(B9>0,'S1 inputs'!$B$16*(1+'S1 inputs'!$B$18)^(B9-1),0) -> 649.4593 | D9: =IF(B9>0,'S1 inputs'!$B$2*'S1 inputs'!$B$14*'S1 inputs'!$B$15*C9,0) -> 740383.6 | E9: =IF(B9>0,('S1 inputs'!$B$20+'S1 inputs'!$B$21+'S1 inputs'!$B$2*'S1 inputs'!$B$14*('S1 inputs'!$B$22+'S1 inputs'!$B$23)+('S1 inputs'!$B$2*'S1 inputs'!$B$3*'S1 inputs'!$B$5+'S1 inputs'!$B$6)*'S1 inputs'!$B$24)*(1+'S1 inputs'!$B$19)^(B9-1),0) -> 295821.85 | F9: =IF(AND(B9>0,B9<'S1 inputs'!$B$12,MOD(B9,'S1 inputs'!$B$25)=0),'S1 inputs'!$B$26*(1+'S1 inputs'!$B$19)^(B9-1),0) -> 0 | G9: =IF(A9='S1 results'!$B$5,'S1 inputs'!$B$27*(1-'S1 inputs'!$B$28),0) -> 0 | H9: =D9-E9-F9+G9 -> 444561.74 | I9: =1/(1+'S1 inputs'!$B$13)^A9 -> 0.66505711 | J9: =H9*I9 -> 295658.95 | K9: =K8+H9-G9 -> -6793132.6 | L9: =IF(B9>0,'S1 inputs'!$B$2*'S1 inputs'!$B$14*'S1 inputs'!$B$15*(1+'S1 inputs'!$B$18)^(B9-1)*I9,0) -> 820.6623 | M9: =IF(AND(K9>=0,K8<0),A9-1-K8/(H9-G9),"") | N9: =N8+J9-G9*I9 -> -7334398.5 | O9: =IF(AND(N9>=0,N8<0),A9-1-N8/((H9-G9)*I9),"")
A10: 8 | B10: =IF(AND(A10>'S1 results'!$B$4,A10<='S1 results'!$B$5),A10-'S1 results'!$B$4,0) -> 6 | C10: =IF(B10>0,'S1 inputs'!$B$16*(1+'S1 inputs'!$B$18)^(B10-1),0) -> 662.44848 | D10: =IF(B10>0,'S1 inputs'!$B$2*'S1 inputs'!$B$14*'S1 inputs'!$B$15*C10,0) -> 755191.27 | E10: =IF(B10>0,('S1 inputs'!$B$20+'S1 inputs'!$B$21+'S1 inputs'!$B$2*'S1 inputs'!$B$14*('S1 inputs'!$B$22+'S1 inputs'!$B$23)+('S1 inputs'!$B$2*'S1 inputs'!$B$3*'S1 inputs'!$B$5+'S1 inputs'!$B$6)*'S1 inputs'!$B$24)*(1+'S1 inputs'!$B$19)^(B10-1),0) -> 303217.4 | F10: =IF(AND(B10>0,B10<'S1 inputs'!$B$12,MOD(B10,'S1 inputs'!$B$25)=0),'S1 inputs'!$B$26*(1+'S1 inputs'!$B$19)^(B10-1),0) -> 0 | G10: =IF(A10='S1 results'!$B$5,'S1 inputs'!$B$27*(1-'S1 inputs'!$B$28),0) -> 0 | H10: =D10-E10-F10+G10 -> 451973.87 | I10: =1/(1+'S1 inputs'!$B$13)^A10 -> 0.62741237 | J10: =H10*I10 -> 283574 | K10: =K9+H10-G10 -> -6341158.7 | L10: =IF(B10>0,'S1 inputs'!$B$2*'S1 inputs'!$B$14*'S1 inputs'!$B$15*(1+'S1 inputs'!$B$18)^(B10-1)*I10,0) -> 789.69391 | M10: =IF(AND(K10>=0,K9<0),A10-1-K9/(H10-G10),"") | N10: =N9+J10-G10*I10 -> -7050824.5 | O10: =IF(AND(N10>=0,N9<0),A10-1-N9/((H10-G10)*I10),"")
A11: 9 | B11: =IF(AND(A11>'S1 results'!$B$4,A11<='S1 results'!$B$5),A11-'S1 results'!$B$4,0) -> 7 | C11: =IF(B11>0,'S1 inputs'!$B$16*(1+'S1 inputs'!$B$18)^(B11-1),0) -> 675.69745 | D11: =IF(B11>0,'S1 inputs'!$B$2*'S1 inputs'!$B$14*'S1 inputs'!$B$15*C11,0) -> 770295.09 | E11: =IF(B11>0,('S1 inputs'!$B$20+'S1 inputs'!$B$21+'S1 inputs'!$B$2*'S1 inputs'!$B$14*('S1 inputs'!$B$22+'S1 inputs'!$B$23)+('S1 inputs'!$B$2*'S1 inputs'!$B$3*'S1 inputs'!$B$5+'S1 inputs'!$B$6)*'S1 inputs'!$B$24)*(1+'S1 inputs'!$B$19)^(B11-1),0) -> 310797.84 | F11: =IF(AND(B11>0,B11<'S1 inputs'!$B$12,MOD(B11,'S1 inputs'!$B$25)=0),'S1 inputs'!$B$26*(1+'S1 inputs'!$B$19)^(B11-1),0) -> 0 | G11: =IF(A11='S1 results'!$B$5,'S1 inputs'!$B$27*(1-'S1 inputs'!$B$28),0) -> 0 | H11: =D11-E11-F11+G11 -> 459497.26 | I11: =1/(1+'S1 inputs'!$B$13)^A11 -> 0.59189846 | J11: =H11*I11 -> 271975.72 | K11: =K10+H11-G11 -> -5881661.4 | L11: =IF(B11>0,'S1 inputs'!$B$2*'S1 inputs'!$B$14*'S1 inputs'!$B$15*(1+'S1 inputs'!$B$18)^(B11-1)*I11,0) -> 759.89414 | M11: =IF(AND(K11>=0,K10<0),A11-1-K10/(H11-G11),"") | N11: =N10+J11-G11*I11 -> -6778848.8 | O11: =IF(AND(N11>=0,N10<0),A11-1-N10/((H11-G11)*I11),"")
A12: 10 | B12: =IF(AND(A12>'S1 results'!$B$4,A12<='S1 results'!$B$5),A12-'S1 results'!$B$4,0) -> 8 | C12: =IF(B12>0,'S1 inputs'!$B$16*(1+'S1 inputs'!$B$18)^(B12-1),0) -> 689.2114 | D12: =IF(B12>0,'S1 inputs'!$B$2*'S1 inputs'!$B$14*'S1 inputs'!$B$15*C12,0) -> 785701 | E12: =IF(B12>0,('S1 inputs'!$B$20+'S1 inputs'!$B$21+'S1 inputs'!$B$2*'S1 inputs'!$B$14*('S1 inputs'!$B$22+'S1 inputs'!$B$23)+('S1 inputs'!$B$2*'S1 inputs'!$B$3*'S1 inputs'!$B$5+'S1 inputs'!$B$6)*'S1 inputs'!$B$24)*(1+'S1 inputs'!$B$19)^(B12-1),0) -> 318567.78 | F12: =IF(AND(B12>0,B12<'S1 inputs'!$B$12,MOD(B12,'S1 inputs'!$B$25)=0),'S1 inputs'!$B$26*(1+'S1 inputs'!$B$19)^(B12-1),0) -> 0 | G12: =IF(A12='S1 results'!$B$5,'S1 inputs'!$B$27*(1-'S1 inputs'!$B$28),0) -> 0 | H12: =D12-E12-F12+G12 -> 467133.21 | I12: =1/(1+'S1 inputs'!$B$13)^A12 -> 0.55839478 | J12: =H12*I12 -> 260844.75 | K12: =K11+H12-G12 -> -5414528.2 | L12: =IF(B12>0,'S1 inputs'!$B$2*'S1 inputs'!$B$14*'S1 inputs'!$B$15*(1+'S1 inputs'!$B$18)^(B12-1)*I12,0) -> 731.21889 | M12: =IF(AND(K12>=0,K11<0),A12-1-K11/(H12-G12),"") | N12: =N11+J12-G12*I12 -> -6518004 | O12: =IF(AND(N12>=0,N11<0),A12-1-N11/((H12-G12)*I12),"")
A13: 11 | B13: =IF(AND(A13>'S1 results'!$B$4,A13<='S1 results'!$B$5),A13-'S1 results'!$B$4,0) -> 9 | C13: =IF(B13>0,'S1 inputs'!$B$16*(1+'S1 inputs'!$B$18)^(B13-1),0) -> 702.99563 | D13: =IF(B13>0,'S1 inputs'!$B$2*'S1 inputs'!$B$14*'S1 inputs'!$B$15*C13,0) -> 801415.02 | E13: =IF(B13>0,('S1 inputs'!$B$20+'S1 inputs'!$B$21+'S1 inputs'!$B$2*'S1 inputs'!$B$14*('S1 inputs'!$B$22+'S1 inputs'!$B$23)+('S1 inputs'!$B$2*'S1 inputs'!$B$3*'S1 inputs'!$B$5+'S1 inputs'!$B$6)*'S1 inputs'!$B$24)*(1+'S1 inputs'!$B$19)^(B13-1),0) -> 326531.98 | F13: =IF(AND(B13>0,B13<'S1 inputs'!$B$12,MOD(B13,'S1 inputs'!$B$25)=0),'S1 inputs'!$B$26*(1+'S1 inputs'!$B$19)^(B13-1),0) -> 0 | G13: =IF(A13='S1 results'!$B$5,'S1 inputs'!$B$27*(1-'S1 inputs'!$B$28),0) -> 0 | H13: =D13-E13-F13+G13 -> 474883.04 | I13: =1/(1+'S1 inputs'!$B$13)^A13 -> 0.52678753 | J13: =H13*I13 -> 250162.46 | K13: =K12+H13-G13 -> -4939645.2 | L13: =IF(B13>0,'S1 inputs'!$B$2*'S1 inputs'!$B$14*'S1 inputs'!$B$15*(1+'S1 inputs'!$B$18)^(B13-1)*I13,0) -> 703.62572 | M13: =IF(AND(K13>=0,K12<0),A13-1-K12/(H13-G13),"") | N13: =N12+J13-G13*I13 -> -6267841.6 | O13: =IF(AND(N13>=0,N12<0),A13-1-N12/((H13-G13)*I13),"")
A14: 12 | B14: =IF(AND(A14>'S1 results'!$B$4,A14<='S1 results'!$B$5),A14-'S1 results'!$B$4,0) -> 10 | C14: =IF(B14>0,'S1 inputs'!$B$16*(1+'S1 inputs'!$B$18)^(B14-1),0) -> 717.05554 | D14: =IF(B14>0,'S1 inputs'!$B$2*'S1 inputs'!$B$14*'S1 inputs'!$B$15*C14,0) -> 817443.32 | E14: =IF(B14>0,('S1 inputs'!$B$20+'S1 inputs'!$B$21+'S1 inputs'!$B$2*'S1 inputs'!$B$14*('S1 inputs'!$B$22+'S1 inputs'!$B$23)+('S1 inputs'!$B$2*'S1 inputs'!$B$3*'S1 inputs'!$B$5+'S1 inputs'!$B$6)*'S1 inputs'!$B$24)*(1+'S1 inputs'!$B$19)^(B14-1),0) -> 334695.28 | F14: =IF(AND(B14>0,B14<'S1 inputs'!$B$12,MOD(B14,'S1 inputs'!$B$25)=0),'S1 inputs'!$B$26*(1+'S1 inputs'!$B$19)^(B14-1),0) -> 0 | G14: =IF(A14='S1 results'!$B$5,'S1 inputs'!$B$27*(1-'S1 inputs'!$B$28),0) -> 0 | H14: =D14-E14-F14+G14 -> 482748.04 | I14: =1/(1+'S1 inputs'!$B$13)^A14 -> 0.49696936 | J14: =H14*I14 -> 239910.99 | K14: =K13+H14-G14 -> -4456897.1 | L14: =IF(B14>0,'S1 inputs'!$B$2*'S1 inputs'!$B$14*'S1 inputs'!$B$15*(1+'S1 inputs'!$B$18)^(B14-1)*I14,0) -> 677.07381 | M14: =IF(AND(K14>=0,K13<0),A14-1-K13/(H14-G14),"") | N14: =N13+J14-G14*I14 -> -6027930.6 | O14: =IF(AND(N14>=0,N13<0),A14-1-N13/((H14-G14)*I14),"")
... A62: 60 | B62: =IF(AND(A62>'S1 results'!$B$4,A62<='S1 results'!$B$5),A62-'S1 results'!$B$4,0) -> 0 | C62: =IF(B62>0,'S1 inputs'!$B$16*(1+'S1 inputs'!$B$18)^(B62-1),0) -> 0 | D62: =IF(B62>0,'S1 inputs'!$B$2*'S1 inputs'!$B$14*'S1 inputs'!$B$15*C62,0) -> 0 | E62: =IF(B62>0,('S1 inputs'!$B$20+'S1 inputs'!$B$21+'S1 inputs'!$B$2*'S1 inputs'!$B$14*('S1 inputs'!$B$22+'S1 inputs'!$B$23)+('S1 inputs'!$B$2*'S1 inputs'!$B$3*'S1 inputs'!$B$5+'S1 inputs'!$B$6)*'S1 inputs'!$B$24)*(1+'S1 inputs'!$B$19)^(B62-1),0) -> 0 | F62: =IF(AND(B62>0,B62<'S1 inputs'!$B$12,MOD(B62,'S1 inputs'!$B$25)=0),'S1 inputs'!$B$26*(1+'S1 inputs'!$B$19)^(B62-1),0) -> 0 | G62: =IF(A62='S1 results'!$B$5,'S1 inputs'!$B$27*(1-'S1 inputs'!$B$28),0) -> 0 | H62: =D62-E62-F62+G62 -> 0 | I62: =1/(1+'S1 inputs'!$B$13)^A62 -> 0.030314338 | J62: =H62*I62 -> 0 | K62: =K61+H62-G62 -> 13269258 | L62: =IF(B62>0,'S1 inputs'!$B$2*'S1 inputs'!$B$14*'S1 inputs'!$B$15*(1+'S1 inputs'!$B$18)^(B62-1)*I62,0) -> 0 | M62: =IF(AND(K62>=0,K61<0),A62-1-K61/(H62-G62),"") | N62: =N61+J62-G62*I62 -> -2280501.3 | O62: =IF(AND(N62>=0,N61<0),A62-1-N61/((H62-G62)*I62),"")

Sheet S2 inputs
A1: Input | B1: Value | C1: Unit | D1: Basis / assumption
A2: Rooms | B2: =Inputs!B2 -> 100 | C2: rooms | D2: Illustrative project; minimum capacity constraint
A3: Gross area per room | B3: =Inputs!B3 -> 30 | C3: m²/room | D3: Includes allocation of common areas
A4: Land / acquisition | B4: =Inputs!B4 -> 1200000 | C4: EUR | D4: Site-specific quotation needed
A5: Construction cost | B5: =Inputs!B5*Scenarios!B3 -> 1700 | C5: EUR/m² | D5: Illustrative; VAT inclusion must be checked
A6: Facilities | B6: =Inputs!B6 -> 400000 | C6: EUR | D6: Furniture and common equipment
A7: Professional fees | B7: =Inputs!B7 -> 0.1 | C7: share | D7: Of construction + facilities
A8: Force-majeure contingency | B8: =Inputs!B8 -> 0.1 | C8: share | D8: Of construction + facilities + fees
A9: Compliance / audit cost | B9: =Inputs!B9 -> 0 | C9: EUR | D9: Legal control costs; no unlawful payments
A10: Initial subsidy | B10: =Inputs!B10 -> 0 | C10: EUR | D10: Only committed funding should be used
A11: Construction duration | B11: =Scenarios!D3 -> 12 | C11: months | D11: Illustrative, including permitting
A12: Operating useful life | B12: =Scenarios!F3 -> 50 | C12: years | D12: Subject to engineering assessment and refurbishment
A13: Discount rate | B13: =Scenarios!E3 -> 0.05 | C13: annual | D13: Nominal unlevered required return
A14: Occupancy | B14: =Scenarios!C3 -> 0.98 | C14: share | D14: Average paying occupancy
A15: Rent / billing months | B15: =Inputs!B15 -> 12 | C15: months/year | D15: Check lease structure
A16: Student monthly all-in rent | B16: =Inputs!B16 -> 600 | C16: EUR/month | D16: Illustrative initial rent
A17: Affordability cap | B17: =Inputs!B17 -> 650 | C17: EUR/month | D17: Policy assumption; validate student budget
A18: Rent escalation | B18: =Inputs!B18 -> 0.02 | C18: annual | D18: Scenario assumption, not entitlement to index
A19: Operating cost escalation | B19: =Inputs!B19 -> 0.025 | C19: annual | D19: Nominal assumption
A20: Fixed operations | B20: =Inputs!B20 -> 30000 | C20: EUR/year | D20: Excludes wages, maintenance, utilities
A21: Wages incl. employer costs | B21: =Inputs!B21 -> 60000 | C21: EUR/year | D21: Illustrative annual staffing
A22: Variable operations | B22: =Inputs!B22 -> 300 | C22: EUR/occupied room/year | D22: Cleaning/administration, excludes utilities
A23: Utilities | B23: =Inputs!B23 -> 900 | C23: EUR/occupied room/year | D23: All-in rent model
A24: Maintenance reserve | B24: =Inputs!B24 -> 0.01 | C24: share/year | D24: Of construction + facilities; treated as annual cash expense
A25: Refurbishment interval | B25: =Inputs!B25 -> 15 | C25: operating years | D25: Every N years, before final operating year
A26: Refurbishment cost | B26: =Inputs!B26 -> 300000 | C26: EUR/event | D26: Today-price cost, escalates with operating costs
... A28: Sale costs | B28: =Inputs!B28 -> 0.02 | C28: share | D28: Of gross terminal value

Sheet S2 results
A1: Metric | B1: Value | C1: Interpretation
A2: Gross initial investment | B2: ='S2 inputs'!$B$4+'S2 inputs'!$B$2*'S2 inputs'!$B$3*'S2 inputs'!$B$5+'S2 inputs'!$B$6+('S2 inputs'!$B$2*'S2 inputs'!$B$3*'S2 inputs'!$B$5+'S2 inputs'!$B$6)*'S2 inputs'!$B$7+('S2 inputs'!$B$2*'S2 inputs'!$B$3*'S2 inputs'!$B$5+'S2 inputs'!$B$6)*(1+'S2 inputs'!$B$7)*'S2 inputs'!$B$8+'S2 inputs'!$B$9 -> 7855000 | C2: Includes contingency; no subsidy deduction
A3: Investor initial cash | B3: =B2-'S2 inputs'!$B$10 -> 7855000 | C3: Gross investment less committed upfront subsidy
A4: Construction years | B4: =ROUNDUP('S2 inputs'!$B$11/12,0) -> 1 | C4: Conservative rounding; full-year operating model
A5: Final cash-flow year | B5: =B4+'S2 inputs'!$B$12 -> 51 | C5: Construction + operating life
A6: NPV | B6: =SUM('S2 cash flow'!J2:J62) -> 1858249.8 | C6: Project NPV including terminal value
A7: IRR | B7: =IFERROR(IRR('S2 cash flow'!H2:H62),"No IRR") -> 0.061996771 | C7: Annual project IRR; check sign changes
A8: Simple PBP (years) | B8: =IF(COUNT('S2 cash flow'!M3:M62)>0,MIN('S2 cash flow'!M3:M62),"Not recovered") -> 17.37363 | C8: From time 0; interpolated annual cash; excludes terminal sale
A9: Student price P | B9: ='S2 inputs'!$B$16 -> 600 | C9: Initial monthly all-in rent
A10: Student affordability cap | B10: ='S2 inputs'!$B$17 -> 650 | C10: Editable student budget threshold
A11: Required initial rent for NPV = 0 | B11: =MAX(0,('S2 inputs'!$B$16*SUM('S2 cash flow'!L3:L62)-B6)/SUM('S2 cash flow'!L3:L62)) -> 534.95933 | C11: Investor break-even price given all other inputs
A12: NPV at affordability cap | B12: =B6+('S2 inputs'!$B$17-'S2 inputs'!$B$16)*SUM('S2 cash flow'!L3:L62) -> 3286779 | C12: Feasibility under student cap
A13: Upfront subsidy needed at cap | B13: =MAX(0,-B12) -> 0 | C13: Additional time-0 grant / cost reduction required
A14: Maximum investor capital at cap | B14: =B3+B12 -> 11141779 | C14: PV of future net cash flows at capped rent
A15: Joint feasibility | B15: =IF(B11<=B10,"Feasible under assumptions","Funding / cost gap") -> Feasible under assumptions | C15: A positive gap cannot be solved by choosing an arbitrary rent
A16: Recommended student price | B16: =IF(B11<=B10,B11,"No feasible price under cap") -> 534.95933 | C16: Lowest price meeting NPV >= 0 at selected discount rate
A17: First full operating year | B17: =B4+1 -> 2 | C17: Minimum safe planning time requires site and permit evidence
A18: Input check | B18: =IF(AND('S2 inputs'!B10<=B2,'S2 inputs'!B14>0,B5<=60),"OK","CHECK subsidy, occupancy or horizon") -> OK | C18: Subsidy must not exceed gross investment; positive occupancy required
A19: Discounted PBP (years) | B19: =IF(COUNT('S2 cash flow'!O3:O62)>0,MIN('S2 cash flow'!O3:O62),"Not recovered") -> 33.145566 | C19: Discounted at project hurdle; excludes terminal sale
A20: Capital per room | B20: =B2/'S2 inputs'!B2 -> 78550 | C20: Gross investment / room, including allocated common area and land

Sheet S2 cash flow
A1: Year | B1: Operating year | C1: All-in rent / month | D1: Revenue | E1: Operating costs | F1: Refurbishment | G1: Terminal proceeds | H1: Net cash flow | I1: Discount factor | J1: PV cash flow | K1: Cumulative operating cash | L1: PV revenue per EUR rent | M1: Payback crossing year | N1: Cumulative discounted cash | O1: Discounted crossing year
A2: 0 | B2: =IF(AND(A2>'S2 results'!$B$4,A2<='S2 results'!$B$5),A2-'S2 results'!$B$4,0) -> 0 | C2: =IF(B2>0,'S2 inputs'!$B$16*(1+'S2 inputs'!$B$18)^(B2-1),0) -> 0 | D2: =IF(B2>0,'S2 inputs'!$B$2*'S2 inputs'!$B$14*'S2 inputs'!$B$15*C2,0) -> 0 | E2: =IF(B2>0,('S2 inputs'!$B$20+'S2 inputs'!$B$21+'S2 inputs'!$B$2*'S2 inputs'!$B$14*('S2 inputs'!$B$22+'S2 inputs'!$B$23)+('S2 inputs'!$B$2*'S2 inputs'!$B$3*'S2 inputs'!$B$5+'S2 inputs'!$B$6)*'S2 inputs'!$B$24)*(1+'S2 inputs'!$B$19)^(B2-1),0) -> 0 | F2: =IF(AND(B2>0,B2<'S2 inputs'!$B$12,MOD(B2,'S2 inputs'!$B$25)=0),'S2 inputs'!$B$26*(1+'S2 inputs'!$B$19)^(B2-1),0) -> 0 | G2: =IF(A2='S2 results'!$B$5,'S2 inputs'!$B$27*(1-'S2 inputs'!$B$28),0) -> 0 | H2: =-'S2 results'!B3 -> -7855000 | I2: =1/(1+'S2 inputs'!$B$13)^A2 -> 1 | J2: =H2*I2 -> -7855000 | K2: =-'S2 results'!B3 -> -7855000 | L2: =IF(B2>0,'S2 inputs'!$B$2*'S2 inputs'!$B$14*'S2 inputs'!$B$15*(1+'S2 inputs'!$B$18)^(B2-1)*I2,0) -> 0 | N2: =J2 -> -7855000
A3: 1 | B3: =IF(AND(A3>'S2 results'!$B$4,A3<='S2 results'!$B$5),A3-'S2 results'!$B$4,0) -> 0 | C3: =IF(B3>0,'S2 inputs'!$B$16*(1+'S2 inputs'!$B$18)^(B3-1),0) -> 0 | D3: =IF(B3>0,'S2 inputs'!$B$2*'S2 inputs'!$B$14*'S2 inputs'!$B$15*C3,0) -> 0 | E3: =IF(B3>0,('S2 inputs'!$B$20+'S2 inputs'!$B$21+'S2 inputs'!$B$2*'S2 inputs'!$B$14*('S2 inputs'!$B$22+'S2 inputs'!$B$23)+('S2 inputs'!$B$2*'S2 inputs'!$B$3*'S2 inputs'!$B$5+'S2 inputs'!$B$6)*'S2 inputs'!$B$24)*(1+'S2 inputs'!$B$19)^(B3-1),0) -> 0 | F3: =IF(AND(B3>0,B3<'S2 inputs'!$B$12,MOD(B3,'S2 inputs'!$B$25)=0),'S2 inputs'!$B$26*(1+'S2 inputs'!$B$19)^(B3-1),0) -> 0 | G3: =IF(A3='S2 results'!$B$5,'S2 inputs'!$B$27*(1-'S2 inputs'!$B$28),0) -> 0 | H3: =D3-E3-F3+G3 -> 0 | I3: =1/(1+'S2 inputs'!$B$13)^A3 -> 0.95238095 | J3: =H3*I3 -> 0 | K3: =K2+H3-G3 -> -7855000 | L3: =IF(B3>0,'S2 inputs'!$B$2*'S2 inputs'!$B$14*'S2 inputs'!$B$15*(1+'S2 inputs'!$B$18)^(B3-1)*I3,0) -> 0 | M3: =IF(AND(K3>=0,K2<0),A3-1-K2/(H3-G3),"") | N3: =N2+J3-G3*I3 -> -7855000 | O3: =IF(AND(N3>=0,N2<0),A3-1-N2/((H3-G3)*I3),"")
A4: 2 | B4: =IF(AND(A4>'S2 results'!$B$4,A4<='S2 results'!$B$5),A4-'S2 results'!$B$4,0) -> 1 | C4: =IF(B4>0,'S2 inputs'!$B$16*(1+'S2 inputs'!$B$18)^(B4-1),0) -> 600 | D4: =IF(B4>0,'S2 inputs'!$B$2*'S2 inputs'!$B$14*'S2 inputs'!$B$15*C4,0) -> 705600 | E4: =IF(B4>0,('S2 inputs'!$B$20+'S2 inputs'!$B$21+'S2 inputs'!$B$2*'S2 inputs'!$B$14*('S2 inputs'!$B$22+'S2 inputs'!$B$23)+('S2 inputs'!$B$2*'S2 inputs'!$B$3*'S2 inputs'!$B$5+'S2 inputs'!$B$6)*'S2 inputs'!$B$24)*(1+'S2 inputs'!$B$19)^(B4-1),0) -> 262600 | F4: =IF(AND(B4>0,B4<'S2 inputs'!$B$12,MOD(B4,'S2 inputs'!$B$25)=0),'S2 inputs'!$B$26*(1+'S2 inputs'!$B$19)^(B4-1),0) -> 0 | G4: =IF(A4='S2 results'!$B$5,'S2 inputs'!$B$27*(1-'S2 inputs'!$B$28),0) -> 0 | H4: =D4-E4-F4+G4 -> 443000 | I4: =1/(1+'S2 inputs'!$B$13)^A4 -> 0.90702948 | J4: =H4*I4 -> 401814.06 | K4: =K3+H4-G4 -> -7412000 | L4: =IF(B4>0,'S2 inputs'!$B$2*'S2 inputs'!$B$14*'S2 inputs'!$B$15*(1+'S2 inputs'!$B$18)^(B4-1)*I4,0) -> 1066.6667 | M4: =IF(AND(K4>=0,K3<0),A4-1-K3/(H4-G4),"") | N4: =N3+J4-G4*I4 -> -7453185.9 | O4: =IF(AND(N4>=0,N3<0),A4-1-N3/((H4-G4)*I4),"")
A5: 3 | B5: =IF(AND(A5>'S2 results'!$B$4,A5<='S2 results'!$B$5),A5-'S2 results'!$B$4,0) -> 2 | C5: =IF(B5>0,'S2 inputs'!$B$16*(1+'S2 inputs'!$B$18)^(B5-1),0) -> 612 | D5: =IF(B5>0,'S2 inputs'!$B$2*'S2 inputs'!$B$14*'S2 inputs'!$B$15*C5,0) -> 719712 | E5: =IF(B5>0,('S2 inputs'!$B$20+'S2 inputs'!$B$21+'S2 inputs'!$B$2*'S2 inputs'!$B$14*('S2 inputs'!$B$22+'S2 inputs'!$B$23)+('S2 inputs'!$B$2*'S2 inputs'!$B$3*'S2 inputs'!$B$5+'S2 inputs'!$B$6)*'S2 inputs'!$B$24)*(1+'S2 inputs'!$B$19)^(B5-1),0) -> 269165 | F5: =IF(AND(B5>0,B5<'S2 inputs'!$B$12,MOD(B5,'S2 inputs'!$B$25)=0),'S2 inputs'!$B$26*(1+'S2 inputs'!$B$19)^(B5-1),0) -> 0 | G5: =IF(A5='S2 results'!$B$5,'S2 inputs'!$B$27*(1-'S2 inputs'!$B$28),0) -> 0 | H5: =D5-E5-F5+G5 -> 450547 | I5: =1/(1+'S2 inputs'!$B$13)^A5 -> 0.8638376 | J5: =H5*I5 -> 389199.44 | K5: =K4+H5-G5 -> -6961453 | L5: =IF(B5>0,'S2 inputs'!$B$2*'S2 inputs'!$B$14*'S2 inputs'!$B$15*(1+'S2 inputs'!$B$18)^(B5-1)*I5,0) -> 1036.1905 | M5: =IF(AND(K5>=0,K4<0),A5-1-K4/(H5-G5),"") | N5: =N4+J5-G5*I5 -> -7063986.5 | O5: =IF(AND(N5>=0,N4<0),A5-1-N4/((H5-G5)*I5),"")
