Workbook

Sheet Leeswijzer
A1: Studentenhuisvesting | haalbaarheid en rendement
A2: Doel: transparant rekenmodel op basis van de aangeleverde notities.
A3: Alle bedragen en percentages behalve de genoemde 8 + 2 maanden zijn fictieve voorbeelden.
A4: Valuta: EUR. Bedragen moeten consequent exclusief of inclusief niet-recupereerbare btw worden ingevoerd.
A5: Blauwe cellen op Invoer zijn aanpasbaar. Zwarte cellen bevatten formules.
A6: Keuze 1 = 12 maanden studentenhuur; keuze 2 = 8 maanden studentenhuur + 2 maanden Airbnb; keuze 3 = vrije mix.
A7: De resterende maanden leveren geen kamerinkomsten op; bezettingsgraden verwerken leegstand binnen actieve maanden.
A8: Exchange en wissels: verwerk leegstand in studentenbezetting; tel dezelfde leegstand niet nogmaals als kosten.
A9: Grond, aankoop bestaand gebouw en nieuwbouw zijn afzonderlijke posten. Vul overlappende bedragen niet dubbel in.
A10: Opstart en aanvangsonderhoud zijn eenmalig. Jaarlijkse exploitatie, onderhoud en vastgoedbelasting zijn terugkerend.
A11: Diensten: was, schoonmaak, afhaalpunt (interpretatie onduidelijke tekst) en bagageopslag.
A12: Diensten worden per verhuurde kamermaand geraamd, ook bij Airbnb; pas besteding aan de werkelijke vraag aan.
... A23: Code: build_model.py bewaart de basis; improve_model.py genereert deze uitgebreide versie.

Sheet Invoer
A1: Aanpasbare aannames | fictief voorbeeld
A3: Parameter | B3: Waarde | C3: Eenheid | D3: Toelichting
A4: Verhuurscenario | B4: 2 | C4: 1 / 2 / 3 | D4: 1: student 12m; 2: student 8m + Airbnb 2m; 3: vrije mix
A5: Aantal kamers | B5: 10 | C5: kamers | D5: Identieke kamers als vereenvoudiging
A6: Studentenhuur | B6: 600 | C6: EUR/kamer/maand | D6: Fictief startbedrag
A7: Jaarlijkse huurverhoging | B7: 0.02 | C7: % | D7: Niet gespecificeerd in notities
A8: Studentmaanden vrije mix | B8: 8 | C8: maanden | D8: Alleen gebruikt bij keuze 3
A9: Airbnb-maanden vrije mix | B9: 2 | C9: maanden | D9: Alleen gebruikt bij keuze 3
A10: Bezetting studentenhuur | B10: 0.95 | C10: % | D10: Inclusief exchange en gaten tussen huurders
A11: Airbnb-nachtprijs | B11: 75 | C11: EUR/kamer/nacht | D11: Fictief
A12: Airbnb-bezetting | B12: 0.6 | C12: % | D12: Binnen voor Airbnb beschikbare maanden
A13: Dagen per maand | B13: 30 | C13: dagen | D13: Vaste rekenconventie
A14: Jaarlijkse groei Airbnb-prijs | B14: 0.02 | C14: % | D14: Fictief
A15: Gemiddeld Airbnb-verblijf | B15: 4 | C15: nachten | D15: Bepaalt aantal schoonmaakwissels
... A40: Verkoopkosten | B40: 0.03 | C40: % verkoopwaarde | D40: Fictief

Sheet Samenvatting
A1: Studentenhuisvesting | investeringsbeslissing
A3: Scenario | B3: =Invoer!$B$4 -> 2
A4: Studentmaanden | B4: =IF(B3=1,12,IF(B3=2,8,Invoer!$B$8)) -> 8
A5: Airbnb-maanden | B5: =IF(B3=1,0,IF(B3=2,2,Invoer!$B$9)) -> 2
A6: Niet ingeplande maanden | B6: =12-B4-B5 -> 2
A7: Controle kalender | B7: =IF(AND(B4>=0,B5>=0,B4+B5<=12),"OK","FOUT: totaal > 12 maanden") -> OK
A8: Initiële investering | B8: =Invoer!$B$18+Invoer!$B$19+Invoer!$B$20+Invoer!$B$21+Invoer!$B$22+Invoer!$B$23 -> 635000
A9: Omzet jaar 1 | B9: =Kasstromen!C13 -> 75240
A10: Kosten jaar 1 | B10: =Kasstromen!C24 -> 29834.8
A11: Operationele kasstroom jaar 1 | B11: =Kasstromen!C25 -> 45405.2
A12: Aanvangsrendement | B12: =IFERROR(B11/B8,0) -> 0.071504252
A13: Netto contante waarde | B13: =NPV(Invoer!$B$38,Kasstromen!C28:V28)+Kasstromen!B28 -> 107911.16
A14: Intern rendement (IRR) | B14: =IFERROR(IRR(Kasstromen!B28:V28),"Niet berekenbaar") -> 0.084908399
A15: Terugverdientijd incl. verkoop (jaar) | B15: =IFERROR(MATCH(1,Kasstromen!B31:V31,0)-1,"Niet binnen 20 jaar") -> 13
A16: Netto verkoopopbrengst jaar 20 | B16: =Kasstromen!V27 -> 710150.6
A17: Rekenhorizon | B17: 20
A21: Let op: fictieve invoer. NCW en IRR omvatten de verkoop aan het einde van jaar 20.
A22: Leegstand verlaagt omzet; vaste kosten lopen door. Kosten staan positief, investering negatief.
A23: Bij een kalenderfout eerst de vrije mix corrigeren; resultaten zijn dan niet bruikbaar.

Sheet Kasstromen
A1: Kasstromen | EUR | eindejaarsconventie
A3: Jaar | B3: 0 | C3: 1 | D3: 2 | E3: 3 | F3: 4 | G3: 5 | H3: 6 | I3: 7 | J3: 8 | K3: 9 | L3: 10 | M3: 11 | N3: 12 | O3: 13 | P3: 14 | Q3: 15 | R3: 16 | S3: 17 | T3: 18 | U3: 19 | V3: 20
A4: Bezet: student-kamermaanden | B4: 0 | C4: =Invoer!$B$5*Samenvatting!$B$4*Invoer!$B$10 -> 76 | D4: =Invoer!$B$5*Samenvatting!$B$4*Invoer!$B$10 -> 76 | E4: =Invoer!$B$5*Samenvatting!$B$4*Invoer!$B$10 -> 76 | F4: =Invoer!$B$5*Samenvatting!$B$4*Invoer!$B$10 -> 76 | G4: =Invoer!$B$5*Samenvatting!$B$4*Invoer!$B$10 -> 76 | H4: =Invoer!$B$5*Samenvatting!$B$4*Invoer!$B$10 -> 76 | I4: =Invoer!$B$5*Samenvatting!$B$4*Invoer!$B$10 -> 76 | J4: =Invoer!$B$5*Samenvatting!$B$4*Invoer!$B$10 -> 76 | ... V4: =Invoer!$B$5*Samenvatting!$B$4*Invoer!$B$10 -> 76
A5: Bezet: Airbnb-kamernachten | B5: 0 | C5: =Invoer!$B$5*Samenvatting!$B$5*Invoer!$B$13*Invoer!$B$12 -> 360 | D5: =Invoer!$B$5*Samenvatting!$B$5*Invoer!$B$13*Invoer!$B$12 -> 360 | E5: =Invoer!$B$5*Samenvatting!$B$5*Invoer!$B$13*Invoer!$B$12 -> 360 | F5: =Invoer!$B$5*Samenvatting!$B$5*Invoer!$B$13*Invoer!$B$12 -> 360 | G5: =Invoer!$B$5*Samenvatting!$B$5*Invoer!$B$13*Invoer!$B$12 -> 360 | H5: =Invoer!$B$5*Samenvatting!$B$5*Invoer!$B$13*Invoer!$B$12 -> 360 | I5: =Invoer!$B$5*Samenvatting!$B$5*Invoer!$B$13*Invoer!$B$12 -> 360 | J5: =Invoer!$B$5*Samenvatting!$B$5*Invoer!$B$13*Invoer!$B$12 -> 360 | ... V5: =Invoer!$B$5*Samenvatting!$B$5*Invoer!$B$13*Invoer!$B$12 -> 360
A6: Bezet: totale kamermaanden | B6: 0 | C6: =C4+C5/Invoer!$B$13 -> 88 | D6: =D4+D5/Invoer!$B$13 -> 88 | E6: =E4+E5/Invoer!$B$13 -> 88 | F6: =F4+F5/Invoer!$B$13 -> 88 | G6: =G4+G5/Invoer!$B$13 -> 88 | H6: =H4+H5/Invoer!$B$13 -> 88 | I6: =I4+I5/Invoer!$B$13 -> 88 | J6: =J4+J5/Invoer!$B$13 -> 88 | ... V6: =V4+V5/Invoer!$B$13 -> 88
A7: Studentenhuur | B7: 0 | C7: =C4*Invoer!$B$6*(1+Invoer!$B$7)^(C$3-1) -> 45600 | D7: =D4*Invoer!$B$6*(1+Invoer!$B$7)^(D$3-1) -> 46512 | E7: =E4*Invoer!$B$6*(1+Invoer!$B$7)^(E$3-1) -> 47442.24 | F7: =F4*Invoer!$B$6*(1+Invoer!$B$7)^(F$3-1) -> 48391.085 | G7: =G4*Invoer!$B$6*(1+Invoer!$B$7)^(G$3-1) -> 49358.906 | H7: =H4*Invoer!$B$6*(1+Invoer!$B$7)^(H$3-1) -> 50346.085 | I7: =I4*Invoer!$B$6*(1+Invoer!$B$7)^(I$3-1) -> 51353.006 | J7: =J4*Invoer!$B$6*(1+Invoer!$B$7)^(J$3-1) -> 52380.066 | ... V7: =V4*Invoer!$B$6*(1+Invoer!$B$7)^(V$3-1) -> 66430.589
A8: Airbnb-overnachtingen | B8: 0 | C8: =C5*Invoer!$B$11*(1+Invoer!$B$14)^(C$3-1) -> 27000 | D8: =D5*Invoer!$B$11*(1+Invoer!$B$14)^(D$3-1) -> 27540 | E8: =E5*Invoer!$B$11*(1+Invoer!$B$14)^(E$3-1) -> 28090.8 | F8: =F5*Invoer!$B$11*(1+Invoer!$B$14)^(F$3-1) -> 28652.616 | G8: =G5*Invoer!$B$11*(1+Invoer!$B$14)^(G$3-1) -> 29225.668 | H8: =H5*Invoer!$B$11*(1+Invoer!$B$14)^(H$3-1) -> 29810.182 | I8: =I5*Invoer!$B$11*(1+Invoer!$B$14)^(I$3-1) -> 30406.385 | J8: =J5*Invoer!$B$11*(1+Invoer!$B$14)^(J$3-1) -> 31014.513 | ... V8: =V5*Invoer!$B$11*(1+Invoer!$B$14)^(V$3-1) -> 39333.902
A9: Wasdiensten | B9: 0 | C9: =C6*Invoer!$B$29*(1+Invoer!$B$37)^(C$3-1) -> 880 | D9: =D6*Invoer!$B$29*(1+Invoer!$B$37)^(D$3-1) -> 897.6 | E9: =E6*Invoer!$B$29*(1+Invoer!$B$37)^(E$3-1) -> 915.552 | F9: =F6*Invoer!$B$29*(1+Invoer!$B$37)^(F$3-1) -> 933.86304 | G9: =G6*Invoer!$B$29*(1+Invoer!$B$37)^(G$3-1) -> 952.5403 | H9: =H6*Invoer!$B$29*(1+Invoer!$B$37)^(H$3-1) -> 971.59111 | I9: =I6*Invoer!$B$29*(1+Invoer!$B$37)^(I$3-1) -> 991.02293 | J9: =J6*Invoer!$B$29*(1+Invoer!$B$37)^(J$3-1) -> 1010.8434 | ... V9: =V6*Invoer!$B$29*(1+Invoer!$B$37)^(V$3-1) -> 1281.9938
A10: Schoonmaakdiensten | B10: 0 | C10: =C6*Invoer!$B$31*(1+Invoer!$B$37)^(C$3-1) -> 1320 | D10: =D6*Invoer!$B$31*(1+Invoer!$B$37)^(D$3-1) -> 1346.4 | E10: =E6*Invoer!$B$31*(1+Invoer!$B$37)^(E$3-1) -> 1373.328 | F10: =F6*Invoer!$B$31*(1+Invoer!$B$37)^(F$3-1) -> 1400.7946 | G10: =G6*Invoer!$B$31*(1+Invoer!$B$37)^(G$3-1) -> 1428.8105 | H10: =H6*Invoer!$B$31*(1+Invoer!$B$37)^(H$3-1) -> 1457.3867 | I10: =I6*Invoer!$B$31*(1+Invoer!$B$37)^(I$3-1) -> 1486.5344 | J10: =J6*Invoer!$B$31*(1+Invoer!$B$37)^(J$3-1) -> 1516.2651 | ... V10: =V6*Invoer!$B$31*(1+Invoer!$B$37)^(V$3-1) -> 1922.9907
A11: Afhaalpunt | B11: 0 | C11: =C6*Invoer!$B$33*(1+Invoer!$B$37)^(C$3-1) -> 176 | D11: =D6*Invoer!$B$33*(1+Invoer!$B$37)^(D$3-1) -> 179.52 | E11: =E6*Invoer!$B$33*(1+Invoer!$B$37)^(E$3-1) -> 183.1104 | F11: =F6*Invoer!$B$33*(1+Invoer!$B$37)^(F$3-1) -> 186.77261 | G11: =G6*Invoer!$B$33*(1+Invoer!$B$37)^(G$3-1) -> 190.50806 | H11: =H6*Invoer!$B$33*(1+Invoer!$B$37)^(H$3-1) -> 194.31822 | I11: =I6*Invoer!$B$33*(1+Invoer!$B$37)^(I$3-1) -> 198.20459 | J11: =J6*Invoer!$B$33*(1+Invoer!$B$37)^(J$3-1) -> 202.16868 | ... V11: =V6*Invoer!$B$33*(1+Invoer!$B$37)^(V$3-1) -> 256.39877
A12: Bagageopslag | B12: 0 | C12: =C6*Invoer!$B$35*(1+Invoer!$B$37)^(C$3-1) -> 264 | D12: =D6*Invoer!$B$35*(1+Invoer!$B$37)^(D$3-1) -> 269.28 | E12: =E6*Invoer!$B$35*(1+Invoer!$B$37)^(E$3-1) -> 274.6656 | F12: =F6*Invoer!$B$35*(1+Invoer!$B$37)^(F$3-1) -> 280.15891 | G12: =G6*Invoer!$B$35*(1+Invoer!$B$37)^(G$3-1) -> 285.76209 | H12: =H6*Invoer!$B$35*(1+Invoer!$B$37)^(H$3-1) -> 291.47733 | I12: =I6*Invoer!$B$35*(1+Invoer!$B$37)^(I$3-1) -> 297.30688 | J12: =J6*Invoer!$B$35*(1+Invoer!$B$37)^(J$3-1) -> 303.25302 | ... V12: =V6*Invoer!$B$35*(1+Invoer!$B$37)^(V$3-1) -> 384.59815
A13: Totale omzet | B13: 0 | C13: =SUM(C7:C12) -> 75240 | D13: =SUM(D7:D12) -> 76744.8 | E13: =SUM(E7:E12) -> 78279.696 | F13: =SUM(F7:F12) -> 79845.29 | G13: =SUM(G7:G12) -> 81442.196 | H13: =SUM(H7:H12) -> 83071.04 | I13: =SUM(I7:I12) -> 84732.46 | J13: =SUM(J7:J12) -> 86427.11 | ... V13: =SUM(V7:V12) -> 109610.47
A15: Vaste exploitatiekosten | B15: 0 | C15: =Invoer!$B$24*(1+Invoer!$B$28)^(C$3-1) -> 12000 | D15: =Invoer!$B$24*(1+Invoer!$B$28)^(D$3-1) -> 12240 | E15: =Invoer!$B$24*(1+Invoer!$B$28)^(E$3-1) -> 12484.8 | F15: =Invoer!$B$24*(1+Invoer!$B$28)^(F$3-1) -> 12734.496 | G15: =Invoer!$B$24*(1+Invoer!$B$28)^(G$3-1) -> 12989.186 | H15: =Invoer!$B$24*(1+Invoer!$B$28)^(H$3-1) -> 13248.97 | I15: =Invoer!$B$24*(1+Invoer!$B$28)^(I$3-1) -> 13513.949 | J15: =Invoer!$B$24*(1+Invoer!$B$28)^(J$3-1) -> 13784.228 | ... V15: =Invoer!$B$24*(1+Invoer!$B$28)^(V$3-1) -> 17481.734
A16: Onderhoud | B16: 0 | C16: =Invoer!$B$25*(1+Invoer!$B$28)^(C$3-1) -> 6000 | D16: =Invoer!$B$25*(1+Invoer!$B$28)^(D$3-1) -> 6120 | E16: =Invoer!$B$25*(1+Invoer!$B$28)^(E$3-1) -> 6242.4 | F16: =Invoer!$B$25*(1+Invoer!$B$28)^(F$3-1) -> 6367.248 | G16: =Invoer!$B$25*(1+Invoer!$B$28)^(G$3-1) -> 6494.593 | H16: =Invoer!$B$25*(1+Invoer!$B$28)^(H$3-1) -> 6624.4848 | I16: =Invoer!$B$25*(1+Invoer!$B$28)^(I$3-1) -> 6756.9745 | J16: =Invoer!$B$25*(1+Invoer!$B$28)^(J$3-1) -> 6892.114 | ... V16: =Invoer!$B$25*(1+Invoer!$B$28)^(V$3-1) -> 8740.867
A17: Vastgoedbelasting | B17: 0 | C17: =Invoer!$B$26*(1+Invoer!$B$28)^(C$3-1) -> 2000 | D17: =Invoer!$B$26*(1+Invoer!$B$28)^(D$3-1) -> 2040 | E17: =Invoer!$B$26*(1+Invoer!$B$28)^(E$3-1) -> 2080.8 | F17: =Invoer!$B$26*(1+Invoer!$B$28)^(F$3-1) -> 2122.416 | G17: =Invoer!$B$26*(1+Invoer!$B$28)^(G$3-1) -> 2164.8643 | H17: =Invoer!$B$26*(1+Invoer!$B$28)^(H$3-1) -> 2208.1616 | I17: =Invoer!$B$26*(1+Invoer!$B$28)^(I$3-1) -> 2252.3248 | J17: =Invoer!$B$26*(1+Invoer!$B$28)^(J$3-1) -> 2297.3713 | ... V17: =Invoer!$B$26*(1+Invoer!$B$28)^(V$3-1) -> 2913.6223
A18: Vastgoedbeheer | B18: 0 | C18: =C13*Invoer!$B$27 -> 6019.2 | D18: =D13*Invoer!$B$27 -> 6139.584 | E18: =E13*Invoer!$B$27 -> 6262.3757 | F18: =F13*Invoer!$B$27 -> 6387.6232 | G18: =G13*Invoer!$B$27 -> 6515.3757 | H18: =H13*Invoer!$B$27 -> 6645.6832 | I18: =I13*Invoer!$B$27 -> 6778.5968 | J18: =J13*Invoer!$B$27 -> 6914.1688 | ... V18: =V13*Invoer!$B$27 -> 8768.8378
A19: Airbnb-platform | B19: 0 | C19: =C8*Invoer!$B$16 -> 810 | D19: =D8*Invoer!$B$16 -> 826.2 | E19: =E8*Invoer!$B$16 -> 842.724 | F19: =F8*Invoer!$B$16 -> 859.57848 | G19: =G8*Invoer!$B$16 -> 876.77005 | H19: =H8*Invoer!$B$16 -> 894.30545 | I19: =I8*Invoer!$B$16 -> 912.19156 | J19: =J8*Invoer!$B$16 -> 930.43539 | ... V19: =V8*Invoer!$B$16 -> 1180.017
A20: Airbnb-wissels / schoonmaak | B20: 0 | C20: =C5/Invoer!$B$15*Invoer!$B$17*(1+Invoer!$B$28)^(C$3-1) -> 1800 | D20: =D5/Invoer!$B$15*Invoer!$B$17*(1+Invoer!$B$28)^(D$3-1) -> 1836 | E20: =E5/Invoer!$B$15*Invoer!$B$17*(1+Invoer!$B$28)^(E$3-1) -> 1872.72 | F20: =F5/Invoer!$B$15*Invoer!$B$17*(1+Invoer!$B$28)^(F$3-1) -> 1910.1744 | G20: =G5/Invoer!$B$15*Invoer!$B$17*(1+Invoer!$B$28)^(G$3-1) -> 1948.3779 | H20: =H5/Invoer!$B$15*Invoer!$B$17*(1+Invoer!$B$28)^(H$3-1) -> 1987.3454 | I20: =I5/Invoer!$B$15*Invoer!$B$17*(1+Invoer!$B$28)^(I$3-1) -> 2027.0924 | J20: =J5/Invoer!$B$15*Invoer!$B$17*(1+Invoer!$B$28)^(J$3-1) -> 2067.6342 | ... V20: =V5/Invoer!$B$15*Invoer!$B$17*(1+Invoer!$B$28)^(V$3-1) -> 2622.2601
A21: Was: directe kosten | B21: 0 | C21: =C9*Invoer!$B$30 -> 352 | D21: =D9*Invoer!$B$30 -> 359.04 | E21: =E9*Invoer!$B$30 -> 366.2208 | F21: =F9*Invoer!$B$30 -> 373.54522 | G21: =G9*Invoer!$B$30 -> 381.01612 | H21: =H9*Invoer!$B$30 -> 388.63644 | I21: =I9*Invoer!$B$30 -> 396.40917 | J21: =J9*Invoer!$B$30 -> 404.33736 | ... V21: =V9*Invoer!$B$30 -> 512.79753
A22: Schoonmaak: directe kosten | B22: 0 | C22: =C10*Invoer!$B$32 -> 792 | D22: =D10*Invoer!$B$32 -> 807.84 | E22: =E10*Invoer!$B$32 -> 823.9968 | F22: =F10*Invoer!$B$32 -> 840.47674 | G22: =G10*Invoer!$B$32 -> 857.28627 | H22: =H10*Invoer!$B$32 -> 874.432 | I22: =I10*Invoer!$B$32 -> 891.92064 | J22: =J10*Invoer!$B$32 -> 909.75905 | ... V22: =V10*Invoer!$B$32 -> 1153.7944
A23: Afhaalpunt + bagage: directe kosten | B23: 0 | C23: =C11*Invoer!$B$34+C12*Invoer!$B$36 -> 61.6 | D23: =D11*Invoer!$B$34+D12*Invoer!$B$36 -> 62.832 | E23: =E11*Invoer!$B$34+E12*Invoer!$B$36 -> 64.08864 | F23: =F11*Invoer!$B$34+F12*Invoer!$B$36 -> 65.370413 | G23: =G11*Invoer!$B$34+G12*Invoer!$B$36 -> 66.677821 | H23: =H11*Invoer!$B$34+H12*Invoer!$B$36 -> 68.011377 | I23: =I11*Invoer!$B$34+I12*Invoer!$B$36 -> 69.371605 | J23: =J11*Invoer!$B$34+J12*Invoer!$B$36 -> 70.759037 | ... V23: =V11*Invoer!$B$34+V12*Invoer!$B$36 -> 89.739568
A24: Totale kosten | B24: 0 | C24: =SUM(C15:C23) -> 29834.8 | D24: =SUM(D15:D23) -> 30431.496 | E24: =SUM(E15:E23) -> 31040.126 | F24: =SUM(F15:F23) -> 31660.928 | G24: =SUM(G15:G23) -> 32294.147 | H24: =SUM(H15:H23) -> 32940.03 | I24: =SUM(I15:I23) -> 33598.831 | J24: =SUM(J15:J23) -> 34270.807 | ... V24: =SUM(V15:V23) -> 43463.67
A25: Operationele kasstroom | B25: 0 | C25: =C13-C24 -> 45405.2 | D25: =D13-D24 -> 46313.304 | E25: =E13-E24 -> 47239.57 | F25: =F13-F24 -> 48184.361 | G25: =G13-G24 -> 49148.049 | H25: =H13-H24 -> 50131.01 | I25: =I13-I24 -> 51133.63 | J25: =J13-J24 -> 52156.302 | ... V25: =V13-V24 -> 66146.803
A26: Investering | B26: =-Samenvatting!B8 -> -635000 | C26: =0 -> 0 | D26: =0 -> 0 | E26: =0 -> 0 | F26: =0 -> 0 | G26: =0 -> 0 | H26: =0 -> 0 | I26: =0 -> 0 | J26: =0 -> 0 | ... V26: =0 -> 0
A27: Netto verkoopopbrengst | B27: 0 | C27: =IF(C$3=20,(Invoer!$B$18+Invoer!$B$19+Invoer!$B$20)*(1+Invoer!$B$39)^C$3*(1-Invoer!$B$40),0) -> 0 | D27: =IF(D$3=20,(Invoer!$B$18+Invoer!$B$19+Invoer!$B$20)*(1+Invoer!$B$39)^D$3*(1-Invoer!$B$40),0) -> 0 | E27: =IF(E$3=20,(Invoer!$B$18+Invoer!$B$19+Invoer!$B$20)*(1+Invoer!$B$39)^E$3*(1-Invoer!$B$40),0) -> 0 | F27: =IF(F$3=20,(Invoer!$B$18+Invoer!$B$19+Invoer!$B$20)*(1+Invoer!$B$39)^F$3*(1-Invoer!$B$40),0) -> 0 | G27: =IF(G$3=20,(Invoer!$B$18+Invoer!$B$19+Invoer!$B$20)*(1+Invoer!$B$39)^G$3*(1-Invoer!$B$40),0) -> 0 | H27: =IF(H$3=20,(Invoer!$B$18+Invoer!$B$19+Invoer!$B$20)*(1+Invoer!$B$39)^H$3*(1-Invoer!$B$40),0) -> 0 | I27: =IF(I$3=20,(Invoer!$B$18+Invoer!$B$19+Invoer!$B$20)*(1+Invoer!$B$39)^I$3*(1-Invoer!$B$40),0) -> 0 | J27: =IF(J$3=20,(Invoer!$B$18+Invoer!$B$19+Invoer!$B$20)*(1+Invoer!$B$39)^J$3*(1-Invoer!$B$40),0) -> 0 | ... V27: =IF(V$3=20,(Invoer!$B$18+Invoer!$B$19+Invoer!$B$20)*(1+Invoer!$B$39)^V$3*(1-Invoer!$B$40),0) -> 710150.6
A28: Netto kasstroom | B28: =-Samenvatting!B8 -> -635000 | C28: =SUM(C25:C27) -> 45405.2 | D28: =SUM(D25:D27) -> 46313.304 | E28: =SUM(E25:E27) -> 47239.57 | F28: =SUM(F25:F27) -> 48184.361 | G28: =SUM(G25:G27) -> 49148.049 | H28: =SUM(H25:H27) -> 50131.01 | I28: =SUM(I25:I27) -> 51133.63 | J28: =SUM(J25:J27) -> 52156.302 | ... V28: =SUM(V25:V27) -> 776297.41
A29: Contante waarde kasstroom | B29: =-Samenvatting!B8 -> -635000 | C29: =C28/(1+Invoer!$B$38)^C$3 -> 42434.766 | D29: =D28/(1+Invoer!$B$38)^D$3 -> 40451.833 | E29: =E28/(1+Invoer!$B$38)^E$3 -> 38561.561 | F29: =F28/(1+Invoer!$B$38)^F$3 -> 36759.619 | G29: =G28/(1+Invoer!$B$38)^G$3 -> 35041.879 | H29: =H28/(1+Invoer!$B$38)^H$3 -> 33404.408 | I29: =I28/(1+Invoer!$B$38)^I$3 -> 31843.455 | J29: =J28/(1+Invoer!$B$38)^J$3 -> 30355.443 | ... V29: =V28/(1+Invoer!$B$38)^V$3 -> 200610
A30: Cumulatieve kasstroom | B30: =-Samenvatting!B8 -> -635000 | C30: =B30+C28 -> -589594.8 | D30: =C30+D28 -> -543281.5 | E30: =D30+E28 -> -496041.93 | F30: =E30+F28 -> -447857.56 | G30: =F30+G28 -> -398709.52 | H30: =G30+H28 -> -348578.51 | I30: =H30+I28 -> -297444.88 | J30: =I30+J28 -> -245288.57 | ... V30: =U30+V28 -> 1178377.5
A31: Terugverdiend (1=ja) | B31: =IF(B30>=0,1,0) -> 0 | C31: =IF(C30>=0,1,0) -> 0 | D31: =IF(D30>=0,1,0) -> 0 | E31: =IF(E30>=0,1,0) -> 0 | F31: =IF(F30>=0,1,0) -> 0 | G31: =IF(G30>=0,1,0) -> 0 | H31: =IF(H30>=0,1,0) -> 0 | I31: =IF(I30>=0,1,0) -> 0 | ... V31: =IF(V30>=0,1,0) -> 1

Sheet Scenariovergelijking
A1: Vergelijking | identieke investering en aannames
A3: Scenario | B3: 12 maanden student | C3: 8 student + 2 Airbnb | D3: Vrije mix
A4: Studentmaanden | B4: 12 | C4: 8 | D4: =Invoer!$B$8 -> 8
A5: Airbnb-maanden | B5: 0 | C5: 2 | D5: =Invoer!$B$9 -> 2
A6: Niet ingeplande maanden | B6: =12-B4-B5 -> 0 | C6: =12-C4-C5 -> 2 | D6: =12-D4-D5 -> 2
A7: Omzet jaar 1 | B7: =(Invoer!$B$5*B$4*Invoer!$B$10*Invoer!$B$6*(1+Invoer!$B$7)^(1-1)+Invoer!$B$5*B$5*Invoer!$B$13*Invoer!$B$12*Invoer!$B$11*(1+Invoer!$B$14)^(1-1)+(Invoer!$B$5*(B$4*Invoer!$B$10+B$5*Invoer!$B$12))*(Invoer!$B$29+Invoer!$B$31+Invoer!$B$33+Invoer!$B$35)*(1+Invoer!$B$37)^(1-1)) -> 71820 | C7: =(Invoer!$B$5*C$4*Invoer!$B$10*Invoer!$B$6*(1+Invoer!$B$7)^(1-1)+Invoer!$B$5*C$5*Invoer!$B$13*Invoer!$B$12*Invoer!$B$11*(1+Invoer!$B$14)^(1-1)+(Invoer!$B$5*(C$4*Invoer!$B$10+C$5*Invoer!$B$12))*(Invoer!$B$29+Invoer!$B$31+Invoer!$B$33+Invoer!$B$35)*(1+Invoer!$B$37)^(1-1)) -> 75240 | D7: =(Invoer!$B$5*D$4*Invoer!$B$10*Invoer!$B$6*(1+Invoer!$B$7)^(1-1)+Invoer!$B$5*D$5*Invoer!$B$13*Invoer!$B$12*Invoer!$B$11*(1+Invoer!$B$14)^(1-1)+(Invoer!$B$5*(D$4*Invoer!$B$10+D$5*Invoer!$B$12))*(Invoer!$B$29+Invoer!$B$31+Invoer!$B$33+Invoer!$B$35)*(1+Invoer!$B$37)^(1-1)) -> 75240
A8: Kosten jaar 1 | B8: =((Invoer!$B$24+Invoer!$B$25+Invoer!$B$26+(Invoer!$B$5*B$5*Invoer!$B$13*Invoer!$B$12)/Invoer!$B$15*Invoer!$B$17 )*(1+Invoer!$B$28)^(1-1)+(Invoer!$B$5*B$5*Invoer!$B$13*Invoer!$B$12*Invoer!$B$11*(1+Invoer!$B$14)^(1-1))*Invoer!$B$16+(Invoer!$B$5*B$4*Invoer!$B$10*Invoer!$B$6*(1+Invoer!$B$7)^(1-1)+Invoer!$B$5*B$5*Invoer!$B$13*Invoer!$B$12*Invoer!$B$11*(1+Invoer!$B$14)^(1-1)+(Invoer!$B$5*(B$4*Invoer!$B$10+B$5*Invoer!$B$12))*(Invoer!$B$29+Invoer!$B$31+Invoer!$B$33+Invoer!$B$35)*(1+Invoer!$B$37)^(1-1))*Invoer!$B$27+(Invoer!$B$5*(B$4*Invoer!$B$10+B$5*Invoer!$B$12))*(Invoer!$B$29*Invoer!$B$30+Invoer!$B$31*Invoer!$B$32+Invoer!$B$33*Invoer!$B$34+Invoer!$B$35*Invoer!$B$36)*(1+Invoer!$B$37)^(1-1)) -> 27307.4 | C8: =((Invoer!$B$24+Invoer!$B$25+Invoer!$B$26+(Invoer!$B$5*C$5*Invoer!$B$13*Invoer!$B$12)/Invoer!$B$15*Invoer!$B$17 )*(1+Invoer!$B$28)^(1-1)+(Invoer!$B$5*C$5*Invoer!$B$13*Invoer!$B$12*Invoer!$B$11*(1+Invoer!$B$14)^(1-1))*Invoer!$B$16+(Invoer!$B$5*C$4*Invoer!$B$10*Invoer!$B$6*(1+Invoer!$B$7)^(1-1)+Invoer!$B$5*C$5*Invoer!$B$13*Invoer!$B$12*Invoer!$B$11*(1+Invoer!$B$14)^(1-1)+(Invoer!$B$5*(C$4*Invoer!$B$10+C$5*Invoer!$B$12))*(Invoer!$B$29+Invoer!$B$31+Invoer!$B$33+Invoer!$B$35)*(1+Invoer!$B$37)^(1-1))*Invoer!$B$27+(Invoer!$B$5*(C$4*Invoer!$B$10+C$5*Invoer!$B$12))*(Invoer!$B$29*Invoer!$B$30+Invoer!$B$31*Invoer!$B$32+Invoer!$B$33*Invoer!$B$34+Invoer!$B$35*Invoer!$B$36)*(1+Invoer!$B$37)^(1-1)) -> 29834.8 | D8: =((Invoer!$B$24+Invoer!$B$25+Invoer!$B$26+(Invoer!$B$5*D$5*Invoer!$B$13*Invoer!$B$12)/Invoer!$B$15*Invoer!$B$17 )*(1+Invoer!$B$28)^(1-1)+(Invoer!$B$5*D$5*Invoer!$B$13*Invoer!$B$12*Invoer!$B$11*(1+Invoer!$B$14)^(1-1))*Invoer!$B$16+(Invoer!$B$5*D$4*Invoer!$B$10*Invoer!$B$6*(1+Invoer!$B$7)^(1-1)+Invoer!$B$5*D$5*Invoer!$B$13*Invoer!$B$12*Invoer!$B$11*(1+Invoer!$B$14)^(1-1)+(Invoer!$B$5*(D$4*Invoer!$B$10+D$5*Invoer!$B$12))*(Invoer!$B$29+Invoer!$B$31+Invoer!$B$33+Invoer!$B$35)*(1+Invoer!$B$37)^(1-1))*Invoer!$B$27+(Invoer!$B$5*(D$4*Invoer!$B$10+D$5*Invoer!$B$12))*(Invoer!$B$29*Invoer!$B$30+Invoer!$B$31*Invoer!$B$32+Invoer!$B$33*Invoer!$B$34+Invoer!$B$35*Invoer!$B$36)*(1+Invoer!$B$37)^(1-1)) -> 29834.8
A9: Operationele kasstroom jaar 1 | B9: =B7-B8 -> 44512.6 | C9: =C7-C8 -> 45405.2 | D9: =D7-D8 -> 45405.2
A10: Netto contante waarde | B10: =NPV(Invoer!$B$38,B18:B37)+B17 -> 96914.274 | C10: =NPV(Invoer!$B$38,C18:C37)+C17 -> 107911.16 | D10: =NPV(Invoer!$B$38,D18:D37)+D17 -> 107911.16
A11: IRR incl. verkoop | B11: =IFERROR(IRR(B17:B37),"Niet berekenbaar") -> 0.083396274 | C11: =IFERROR(IRR(C17:C37),"Niet berekenbaar") -> 0.084908399 | D11: =IFERROR(IRR(D17:D37),"Niet berekenbaar") -> 0.084908399
A12: Cumulatieve kasstroom na 20 jaar | B12: =SUM(B17:B37) -> 1156689.7 | C12: =SUM(C17:C37) -> 1178377.5 | D12: =SUM(D17:D37) -> 1178377.5
A13: Kalendercontrole | B13: =IF(B4+B5<=12,"OK","FOUT: totaal > 12 maanden") -> OK | C13: =IF(C4+C5<=12,"OK","FOUT: totaal > 12 maanden") -> OK | D13: =IF(D4+D5<=12,"OK","FOUT: totaal > 12 maanden") -> OK
A16: Jaar / netto kasstroom
A17: 0 | B17: =-Samenvatting!B8 -> -635000 | C17: =-Samenvatting!B8 -> -635000 | D17: =-Samenvatting!B8 -> -635000
A18: 1 | B18: =(Invoer!$B$5*B$4*Invoer!$B$10*Invoer!$B$6*(1+Invoer!$B$7)^($A18-1)+Invoer!$B$5*B$5*Invoer!$B$13*Invoer!$B$12*Invoer!$B$11*(1+Invoer!$B$14)^($A18-1)+(Invoer!$B$5*(B$4*Invoer!$B$10+B$5*Invoer!$B$12))*(Invoer!$B$29+Invoer!$B$31+Invoer!$B$33+Invoer!$B$35)*(1+Invoer!$B$37)^($A18-1))-((Invoer!$B$24+Invoer!$B$25+Invoer!$B$26+(Invoer!$B$5*B$5*Invoer!$B$13*Invoer!$B$12)/Invoer!$B$15*Invoer!$B$17 )*(1+Invoer!$B$28)^($A18-1)+(Invoer!$B$5*B$5*Invoer!$B$13*Invoer!$B$12*Invoer!$B$11*(1+Invoer!$B$14)^($A18-1))*Invoer!$B$16+(Invoer!$B$5*B$4*Invoer!$B$10*Invoer!$B$6*(1+Invoer!$B$7)^($A18-1)+Invoer!$B$5*B$5*Invoer!$B$13*Invoer!$B$12*Invoer!$B$11*(1+Invoer!$B$14)^($A18-1)+(Invoer!$B$5*(B$4*Invoer!$B$10+B$5*Invoer!$B$12))*(Invoer!$B$29+Invoer!$B$31+Invoer!$B$33+Invoer!$B$35)*(1+Invoer!$B$37)^($A18-1))*Invoer!$B$27+(Invoer!$B$5*(B$4*Invoer!$B$10+B$5*Invoer!$B$12))*(Invoer!$B$29*Invoer!$B$30+Invoer!$B$31*Invoer!$B$32+Invoer!$B$33*Invoer!$B$34+Invoer!$B$35*Invoer!$B$36)*(1+Invoer!$B$37)^($A18-1))+IF($A18=20,Kasstromen!$V$27,0) -> 44512.6 | C18: =(Invoer!$B$5*C$4*Invoer!$B$10*Invoer!$B$6*(1+Invoer!$B$7)^($A18-1)+Invoer!$B$5*C$5*Invoer!$B$13*Invoer!$B$12*Invoer!$B$11*(1+Invoer!$B$14)^($A18-1)+(Invoer!$B$5*(C$4*Invoer!$B$10+C$5*Invoer!$B$12))*(Invoer!$B$29+Invoer!$B$31+Invoer!$B$33+Invoer!$B$35)*(1+Invoer!$B$37)^($A18-1))-((Invoer!$B$24+Invoer!$B$25+Invoer!$B$26+(Invoer!$B$5*C$5*Invoer!$B$13*Invoer!$B$12)/Invoer!$B$15*Invoer!$B$17 )*(1+Invoer!$B$28)^($A18-1)+(Invoer!$B$5*C$5*Invoer!$B$13*Invoer!$B$12*Invoer!$B$11*(1+Invoer!$B$14)^($A18-1))*Invoer!$B$16+(Invoer!$B$5*C$4*Invoer!$B$10*Invoer!$B$6*(1+Invoer!$B$7)^($A18-1)+Invoer!$B$5*C$5*Invoer!$B$13*Invoer!$B$12*Invoer!$B$11*(1+Invoer!$B$14)^($A18-1)+(Invoer!$B$5*(C$4*Invoer!$B$10+C$5*Invoer!$B$12))*(Invoer!$B$29+Invoer!$B$31+Invoer!$B$33+Invoer!$B$35)*(1+Invoer!$B$37)^($A18-1))*Invoer!$B$27+(Invoer!$B$5*(C$4*Invoer!$B$10+C$5*Invoer!$B$12))*(Invoer!$B$29*Invoer!$B$30+Invoer!$B$31*Invoer!$B$32+Invoer!$B$33*Invoer!$B$34+Invoer!$B$35*Invoer!$B$36)*(1+Invoer!$B$37)^($A18-1))+IF($A18=20,Kasstromen!$V$27,0) -> 45405.2 | D18: =(Invoer!$B$5*D$4*Invoer!$B$10*Invoer!$B$6*(1+Invoer!$B$7)^($A18-1)+Invoer!$B$5*D$5*Invoer!$B$13*Invoer!$B$12*Invoer!$B$11*(1+Invoer!$B$14)^($A18-1)+(Invoer!$B$5*(D$4*Invoer!$B$10+D$5*Invoer!$B$12))*(Invoer!$B$29+Invoer!$B$31+Invoer!$B$33+Invoer!$B$35)*(1+Invoer!$B$37)^($A18-1))-((Invoer!$B$24+Invoer!$B$25+Invoer!$B$26+(Invoer!$B$5*D$5*Invoer!$B$13*Invoer!$B$12)/Invoer!$B$15*Invoer!$B$17 )*(1+Invoer!$B$28)^($A18-1)+(Invoer!$B$5*D$5*Invoer!$B$13*Invoer!$B$12*Invoer!$B$11*(1+Invoer!$B$14)^($A18-1))*Invoer!$B$16+(Invoer!$B$5*D$4*Invoer!$B$10*Invoer!$B$6*(1+Invoer!$B$7)^($A18-1)+Invoer!$B$5*D$5*Invoer!$B$13*Invoer!$B$12*Invoer!$B$11*(1+Invoer!$B$14)^($A18-1)+(Invoer!$B$5*(D$4*Invoer!$B$10+D$5*Invoer!$B$12))*(Invoer!$B$29+Invoer!$B$31+Invoer!$B$33+Invoer!$B$35)*(1+Invoer!$B$37)^($A18-1))*Invoer!$B$27+(Invoer!$B$5*(D$4*Invoer!$B$10+D$5*Invoer!$B$12))*(Invoer!$B$29*Invoer!$B$30+Invoer!$B$31*Invoer!$B$32+Invoer!$B$33*Invoer!$B$34+Invoer!$B$35*Invoer!$B$36)*(1+Invoer!$B$37)^($A18-1))+IF($A18=20,Kasstromen!$V$27,0) -> 45405.2
A19: 2 | B19: =(Invoer!$B$5*B$4*Invoer!$B$10*Invoer!$B$6*(1+Invoer!$B$7)^($A19-1)+Invoer!$B$5*B$5*Invoer!$B$13*Invoer!$B$12*Invoer!$B$11*(1+Invoer!$B$14)^($A19-1)+(Invoer!$B$5*(B$4*Invoer!$B$10+B$5*Invoer!$B$12))*(Invoer!$B$29+Invoer!$B$31+Invoer!$B$33+Invoer!$B$35)*(1+Invoer!$B$37)^($A19-1))-((Invoer!$B$24+Invoer!$B$25+Invoer!$B$26+(Invoer!$B$5*B$5*Invoer!$B$13*Invoer!$B$12)/Invoer!$B$15*Invoer!$B$17 )*(1+Invoer!$B$28)^($A19-1)+(Invoer!$B$5*B$5*Invoer!$B$13*Invoer!$B$12*Invoer!$B$11*(1+Invoer!$B$14)^($A19-1))*Invoer!$B$16+(Invoer!$B$5*B$4*Invoer!$B$10*Invoer!$B$6*(1+Invoer!$B$7)^($A19-1)+Invoer!$B$5*B$5*Invoer!$B$13*Invoer!$B$12*Invoer!$B$11*(1+Invoer!$B$14)^($A19-1)+(Invoer!$B$5*(B$4*Invoer!$B$10+B$5*Invoer!$B$12))*(Invoer!$B$29+Invoer!$B$31+Invoer!$B$33+Invoer!$B$35)*(1+Invoer!$B$37)^($A19-1))*Invoer!$B$27+(Invoer!$B$5*(B$4*Invoer!$B$10+B$5*Invoer!$B$12))*(Invoer!$B$29*Invoer!$B$30+Invoer!$B$31*Invoer!$B$32+Invoer!$B$33*Invoer!$B$34+Invoer!$B$35*Invoer!$B$36)*(1+Invoer!$B$37)^($A19-1))+IF($A19=20,Kasstromen!$V$27,0) -> 45402.852 | C19: =(Invoer!$B$5*C$4*Invoer!$B$10*Invoer!$B$6*(1+Invoer!$B$7)^($A19-1)+Invoer!$B$5*C$5*Invoer!$B$13*Invoer!$B$12*Invoer!$B$11*(1+Invoer!$B$14)^($A19-1)+(Invoer!$B$5*(C$4*Invoer!$B$10+C$5*Invoer!$B$12))*(Invoer!$B$29+Invoer!$B$31+Invoer!$B$33+Invoer!$B$35)*(1+Invoer!$B$37)^($A19-1))-((Invoer!$B$24+Invoer!$B$25+Invoer!$B$26+(Invoer!$B$5*C$5*Invoer!$B$13*Invoer!$B$12)/Invoer!$B$15*Invoer!$B$17 )*(1+Invoer!$B$28)^($A19-1)+(Invoer!$B$5*C$5*Invoer!$B$13*Invoer!$B$12*Invoer!$B$11*(1+Invoer!$B$14)^($A19-1))*Invoer!$B$16+(Invoer!$B$5*C$4*Invoer!$B$10*Invoer!$B$6*(1+Invoer!$B$7)^($A19-1)+Invoer!$B$5*C$5*Invoer!$B$13*Invoer!$B$12*Invoer!$B$11*(1+Invoer!$B$14)^($A19-1)+(Invoer!$B$5*(C$4*Invoer!$B$10+C$5*Invoer!$B$12))*(Invoer!$B$29+Invoer!$B$31+Invoer!$B$33+Invoer!$B$35)*(1+Invoer!$B$37)^($A19-1))*Invoer!$B$27+(Invoer!$B$5*(C$4*Invoer!$B$10+C$5*Invoer!$B$12))*(Invoer!$B$29*Invoer!$B$30+Invoer!$B$31*Invoer!$B$32+Invoer!$B$33*Invoer!$B$34+Invoer!$B$35*Invoer!$B$36)*(1+Invoer!$B$37)^($A19-1))+IF($A19=20,Kasstromen!$V$27,0) -> 46313.304 | D19: =(Invoer!$B$5*D$4*Invoer!$B$10*Invoer!$B$6*(1+Invoer!$B$7)^($A19-1)+Invoer!$B$5*D$5*Invoer!$B$13*Invoer!$B$12*Invoer!$B$11*(1+Invoer!$B$14)^($A19-1)+(Invoer!$B$5*(D$4*Invoer!$B$10+D$5*Invoer!$B$12))*(Invoer!$B$29+Invoer!$B$31+Invoer!$B$33+Invoer!$B$35)*(1+Invoer!$B$37)^($A19-1))-((Invoer!$B$24+Invoer!$B$25+Invoer!$B$26+(Invoer!$B$5*D$5*Invoer!$B$13*Invoer!$B$12)/Invoer!$B$15*Invoer!$B$17 )*(1+Invoer!$B$28)^($A19-1)+(Invoer!$B$5*D$5*Invoer!$B$13*Invoer!$B$12*Invoer!$B$11*(1+Invoer!$B$14)^($A19-1))*Invoer!$B$16+(Invoer!$B$5*D$4*Invoer!$B$10*Invoer!$B$6*(1+Invoer!$B$7)^($A19-1)+Invoer!$B$5*D$5*Invoer!$B$13*Invoer!$B$12*Invoer!$B$11*(1+Invoer!$B$14)^($A19-1)+(Invoer!$B$5*(D$4*Invoer!$B$10+D$5*Invoer!$B$12))*(Invoer!$B$29+Invoer!$B$31+Invoer!$B$33+Invoer!$B$35)*(1+Invoer!$B$37)^($A19-1))*Invoer!$B$27+(Invoer!$B$5*(D$4*Invoer!$B$10+D$5*Invoer!$B$12))*(Invoer!$B$29*Invoer!$B$30+Invoer!$B$31*Invoer!$B$32+Invoer!$B$33*Invoer!$B$34+Invoer!$B$35*Invoer!$B$36)*(1+Invoer!$B$37)^($A19-1))+IF($A19=20,Kasstromen!$V$27,0) -> 46313.304
A20: 3 | B20: =(Invoer!$B$5*B$4*Invoer!$B$10*Invoer!$B$6*(1+Invoer!$B$7)^($A20-1)+Invoer!$B$5*B$5*Invoer!$B$13*Invoer!$B$12*Invoer!$B$11*(1+Invoer!$B$14)^($A20-1)+(Invoer!$B$5*(B$4*Invoer!$B$10+B$5*Invoer!$B$12))*(Invoer!$B$29+Invoer!$B$31+Invoer!$B$33+Invoer!$B$35)*(1+Invoer!$B$37)^($A20-1))-((Invoer!$B$24+Invoer!$B$25+Invoer!$B$26+(Invoer!$B$5*B$5*Invoer!$B$13*Invoer!$B$12)/Invoer!$B$15*Invoer!$B$17 )*(1+Invoer!$B$28)^($A20-1)+(Invoer!$B$5*B$5*Invoer!$B$13*Invoer!$B$12*Invoer!$B$11*(1+Invoer!$B$14)^($A20-1))*Invoer!$B$16+(Invoer!$B$5*B$4*Invoer!$B$10*Invoer!$B$6*(1+Invoer!$B$7)^($A20-1)+Invoer!$B$5*B$5*Invoer!$B$13*Invoer!$B$12*Invoer!$B$11*(1+Invoer!$B$14)^($A20-1)+(Invoer!$B$5*(B$4*Invoer!$B$10+B$5*Invoer!$B$12))*(Invoer!$B$29+Invoer!$B$31+Invoer!$B$33+Invoer!$B$35)*(1+Invoer!$B$37)^($A20-1))*Invoer!$B$27+(Invoer!$B$5*(B$4*Invoer!$B$10+B$5*Invoer!$B$12))*(Invoer!$B$29*Invoer!$B$30+Invoer!$B$31*Invoer!$B$32+Invoer!$B$33*Invoer!$B$34+Invoer!$B$35*Invoer!$B$36)*(1+Invoer!$B$37)^($A20-1))+IF($A20=20,Kasstromen!$V$27,0) -> 46310.909 | C20: =(Invoer!$B$5*C$4*Invoer!$B$10*Invoer!$B$6*(1+Invoer!$B$7)^($A20-1)+Invoer!$B$5*C$5*Invoer!$B$13*Invoer!$B$12*Invoer!$B$11*(1+Invoer!$B$14)^($A20-1)+(Invoer!$B$5*(C$4*Invoer!$B$10+C$5*Invoer!$B$12))*(Invoer!$B$29+Invoer!$B$31+Invoer!$B$33+Invoer!$B$35)*(1+Invoer!$B$37)^($A20-1))-((Invoer!$B$24+Invoer!$B$25+Invoer!$B$26+(Invoer!$B$5*C$5*Invoer!$B$13*Invoer!$B$12)/Invoer!$B$15*Invoer!$B$17 )*(1+Invoer!$B$28)^($A20-1)+(Invoer!$B$5*C$5*Invoer!$B$13*Invoer!$B$12*Invoer!$B$11*(1+Invoer!$B$14)^($A20-1))*Invoer!$B$16+(Invoer!$B$5*C$4*Invoer!$B$10*Invoer!$B$6*(1+Invoer!$B$7)^($A20-1)+Invoer!$B$5*C$5*Invoer!$B$13*Invoer!$B$12*Invoer!$B$11*(1+Invoer!$B$14)^($A20-1)+(Invoer!$B$5*(C$4*Invoer!$B$10+C$5*Invoer!$B$12))*(Invoer!$B$29+Invoer!$B$31+Invoer!$B$33+Invoer!$B$35)*(1+Invoer!$B$37)^($A20-1))*Invoer!$B$27+(Invoer!$B$5*(C$4*Invoer!$B$10+C$5*Invoer!$B$12))*(Invoer!$B$29*Invoer!$B$30+Invoer!$B$31*Invoer!$B$32+Invoer!$B$33*Invoer!$B$34+Invoer!$B$35*Invoer!$B$36)*(1+Invoer!$B$37)^($A20-1))+IF($A20=20,Kasstromen!$V$27,0) -> 47239.57 | D20: =(Invoer!$B$5*D$4*Invoer!$B$10*Invoer!$B$6*(1+Invoer!$B$7)^($A20-1)+Invoer!$B$5*D$5*Invoer!$B$13*Invoer!$B$12*Invoer!$B$11*(1+Invoer!$B$14)^($A20-1)+(Invoer!$B$5*(D$4*Invoer!$B$10+D$5*Invoer!$B$12))*(Invoer!$B$29+Invoer!$B$31+Invoer!$B$33+Invoer!$B$35)*(1+Invoer!$B$37)^($A20-1))-((Invoer!$B$24+Invoer!$B$25+Invoer!$B$26+(Invoer!$B$5*D$5*Invoer!$B$13*Invoer!$B$12)/Invoer!$B$15*Invoer!$B$17 )*(1+Invoer!$B$28)^($A20-1)+(Invoer!$B$5*D$5*Invoer!$B$13*Invoer!$B$12*Invoer!$B$11*(1+Invoer!$B$14)^($A20-1))*Invoer!$B$16+(Invoer!$B$5*D$4*Invoer!$B$10*Invoer!$B$6*(1+Invoer!$B$7)^($A20-1)+Invoer!$B$5*D$5*Invoer!$B$13*Invoer!$B$12*Invoer!$B$11*(1+Invoer!$B$14)^($A20-1)+(Invoer!$B$5*(D$4*Invoer!$B$10+D$5*Invoer!$B$12))*(Invoer!$B$29+Invoer!$B$31+Invoer!$B$33+Invoer!$B$35)*(1+Invoer!$B$37)^($A20-1))*Invoer!$B$27+(Invoer!$B$5*(D$4*Invoer!$B$10+D$5*Invoer!$B$12))*(Invoer!$B$29*Invoer!$B$30+Invoer!$B$31*Invoer!$B$32+Invoer!$B$33*Invoer!$B$34+Invoer!$B$35*Invoer!$B$36)*(1+Invoer!$B$37)^($A20-1))+IF($A20=20,Kasstromen!$V$27,0) -> 47239.57
A21: 4 | B21: =(Invoer!$B$5*B$4*Invoer!$B$10*Invoer!$B$6*(1+Invoer!$B$7)^($A21-1)+Invoer!$B$5*B$5*Invoer!$B$13*Invoer!$B$12*Invoer!$B$11*(1+Invoer!$B$14)^($A21-1)+(Invoer!$B$5*(B$4*Invoer!$B$10+B$5*Invoer!$B$12))*(Invoer!$B$29+Invoer!$B$31+Invoer!$B$33+Invoer!$B$35)*(1+Invoer!$B$37)^($A21-1))-((Invoer!$B$24+Invoer!$B$25+Invoer!$B$26+(Invoer!$B$5*B$5*Invoer!$B$13*Invoer!$B$12)/Invoer!$B$15*Invoer!$B$17 )*(1+Invoer!$B$28)^($A21-1)+(Invoer!$B$5*B$5*Invoer!$B$13*Invoer!$B$12*Invoer!$B$11*(1+Invoer!$B$14)^($A21-1))*Invoer!$B$16+(Invoer!$B$5*B$4*Invoer!$B$10*Invoer!$B$6*(1+Invoer!$B$7)^($A21-1)+Invoer!$B$5*B$5*Invoer!$B$13*Invoer!$B$12*Invoer!$B$11*(1+Invoer!$B$14)^($A21-1)+(Invoer!$B$5*(B$4*Invoer!$B$10+B$5*Invoer!$B$12))*(Invoer!$B$29+Invoer!$B$31+Invoer!$B$33+Invoer!$B$35)*(1+Invoer!$B$37)^($A21-1))*Invoer!$B$27+(Invoer!$B$5*(B$4*Invoer!$B$10+B$5*Invoer!$B$12))*(Invoer!$B$29*Invoer!$B$30+Invoer!$B$31*Invoer!$B$32+Invoer!$B$33*Invoer!$B$34+Invoer!$B$35*Invoer!$B$36)*(1+Invoer!$B$37)^($A21-1))+IF($A21=20,Kasstromen!$V$27,0) -> 47237.127 | C21: =(Invoer!$B$5*C$4*Invoer!$B$10*Invoer!$B$6*(1+Invoer!$B$7)^($A21-1)+Invoer!$B$5*C$5*Invoer!$B$13*Invoer!$B$12*Invoer!$B$11*(1+Invoer!$B$14)^($A21-1)+(Invoer!$B$5*(C$4*Invoer!$B$10+C$5*Invoer!$B$12))*(Invoer!$B$29+Invoer!$B$31+Invoer!$B$33+Invoer!$B$35)*(1+Invoer!$B$37)^($A21-1))-((Invoer!$B$24+Invoer!$B$25+Invoer!$B$26+(Invoer!$B$5*C$5*Invoer!$B$13*Invoer!$B$12)/Invoer!$B$15*Invoer!$B$17 )*(1+Invoer!$B$28)^($A21-1)+(Invoer!$B$5*C$5*Invoer!$B$13*Invoer!$B$12*Invoer!$B$11*(1+Invoer!$B$14)^($A21-1))*Invoer!$B$16+(Invoer!$B$5*C$4*Invoer!$B$10*Invoer!$B$6*(1+Invoer!$B$7)^($A21-1)+Invoer!$B$5*C$5*Invoer!$B$13*Invoer!$B$12*Invoer!$B$11*(1+Invoer!$B$14)^($A21-1)+(Invoer!$B$5*(C$4*Invoer!$B$10+C$5*Invoer!$B$12))*(Invoer!$B$29+Invoer!$B$31+Invoer!$B$33+Invoer!$B$35)*(1+Invoer!$B$37)^($A21-1))*Invoer!$B$27+(Invoer!$B$5*(C$4*Invoer!$B$10+C$5*Invoer!$B$12))*(Invoer!$B$29*Invoer!$B$30+Invoer!$B$31*Invoer!$B$32+Invoer!$B$33*Invoer!$B$34+Invoer!$B$35*Invoer!$B$36)*(1+Invoer!$B$37)^($A21-1))+IF($A21=20,Kasstromen!$V$27,0) -> 48184.361 | D21: =(Invoer!$B$5*D$4*Invoer!$B$10*Invoer!$B$6*(1+Invoer!$B$7)^($A21-1)+Invoer!$B$5*D$5*Invoer!$B$13*Invoer!$B$12*Invoer!$B$11*(1+Invoer!$B$14)^($A21-1)+(Invoer!$B$5*(D$4*Invoer!$B$10+D$5*Invoer!$B$12))*(Invoer!$B$29+Invoer!$B$31+Invoer!$B$33+Invoer!$B$35)*(1+Invoer!$B$37)^($A21-1))-((Invoer!$B$24+Invoer!$B$25+Invoer!$B$26+(Invoer!$B$5*D$5*Invoer!$B$13*Invoer!$B$12)/Invoer!$B$15*Invoer!$B$17 )*(1+Invoer!$B$28)^($A21-1)+(Invoer!$B$5*D$5*Invoer!$B$13*Invoer!$B$12*Invoer!$B$11*(1+Invoer!$B$14)^($A21-1))*Invoer!$B$16+(Invoer!$B$5*D$4*Invoer!$B$10*Invoer!$B$6*(1+Invoer!$B$7)^($A21-1)+Invoer!$B$5*D$5*Invoer!$B$13*Invoer!$B$12*Invoer!$B$11*(1+Invoer!$B$14)^($A21-1)+(Invoer!$B$5*(D$4*Invoer!$B$10+D$5*Invoer!$B$12))*(Invoer!$B$29+Invoer!$B$31+Invoer!$B$33+Invoer!$B$35)*(1+Invoer!$B$37)^($A21-1))*Invoer!$B$27+(Invoer!$B$5*(D$4*Invoer!$B$10+D$5*Invoer!$B$12))*(Invoer!$B$29*Invoer!$B$30+Invoer!$B$31*Invoer!$B$32+Invoer!$B$33*Invoer!$B$34+Invoer!$B$35*Invoer!$B$36)*(1+Invoer!$B$37)^($A21-1))+IF($A21=20,Kasstromen!$V$27,0) -> 48184.361
A22: 5 | B22: =(Invoer!$B$5*B$4*Invoer!$B$10*Invoer!$B$6*(1+Invoer!$B$7)^($A22-1)+Invoer!$B$5*B$5*Invoer!$B$13*Invoer!$B$12*Invoer!$B$11*(1+Invoer!$B$14)^($A22-1)+(Invoer!$B$5*(B$4*Invoer!$B$10+B$5*Invoer!$B$12))*(Invoer!$B$29+Invoer!$B$31+Invoer!$B$33+Invoer!$B$35)*(1+Invoer!$B$37)^($A22-1))-((Invoer!$B$24+Invoer!$B$25+Invoer!$B$26+(Invoer!$B$5*B$5*Invoer!$B$13*Invoer!$B$12)/Invoer!$B$15*Invoer!$B$17 )*(1+Invoer!$B$28)^($A22-1)+(Invoer!$B$5*B$5*Invoer!$B$13*Invoer!$B$12*Invoer!$B$11*(1+Invoer!$B$14)^($A22-1))*Invoer!$B$16+(Invoer!$B$5*B$4*Invoer!$B$10*Invoer!$B$6*(1+Invoer!$B$7)^($A22-1)+Invoer!$B$5*B$5*Invoer!$B$13*Invoer!$B$12*Invoer!$B$11*(1+Invoer!$B$14)^($A22-1)+(Invoer!$B$5*(B$4*Invoer!$B$10+B$5*Invoer!$B$12))*(Invoer!$B$29+Invoer!$B$31+Invoer!$B$33+Invoer!$B$35)*(1+Invoer!$B$37)^($A22-1))*Invoer!$B$27+(Invoer!$B$5*(B$4*Invoer!$B$10+B$5*Invoer!$B$12))*(Invoer!$B$29*Invoer!$B$30+Invoer!$B$31*Invoer!$B$32+Invoer!$B$33*Invoer!$B$34+Invoer!$B$35*Invoer!$B$36)*(1+Invoer!$B$37)^($A22-1))+IF($A22=20,Kasstromen!$V$27,0) -> 48181.87 | C22: =(Invoer!$B$5*C$4*Invoer!$B$10*Invoer!$B$6*(1+Invoer!$B$7)^($A22-1)+Invoer!$B$5*C$5*Invoer!$B$13*Invoer!$B$12*Invoer!$B$11*(1+Invoer!$B$14)^($A22-1)+(Invoer!$B$5*(C$4*Invoer!$B$10+C$5*Invoer!$B$12))*(Invoer!$B$29+Invoer!$B$31+Invoer!$B$33+Invoer!$B$35)*(1+Invoer!$B$37)^($A22-1))-((Invoer!$B$24+Invoer!$B$25+Invoer!$B$26+(Invoer!$B$5*C$5*Invoer!$B$13*Invoer!$B$12)/Invoer!$B$15*Invoer!$B$17 )*(1+Invoer!$B$28)^($A22-1)+(Invoer!$B$5*C$5*Invoer!$B$13*Invoer!$B$12*Invoer!$B$11*(1+Invoer!$B$14)^($A22-1))*Invoer!$B$16+(Invoer!$B$5*C$4*Invoer!$B$10*Invoer!$B$6*(1+Invoer!$B$7)^($A22-1)+Invoer!$B$5*C$5*Invoer!$B$13*Invoer!$B$12*Invoer!$B$11*(1+Invoer!$B$14)^($A22-1)+(Invoer!$B$5*(C$4*Invoer!$B$10+C$5*Invoer!$B$12))*(Invoer!$B$29+Invoer!$B$31+Invoer!$B$33+Invoer!$B$35)*(1+Invoer!$B$37)^($A22-1))*Invoer!$B$27+(Invoer!$B$5*(C$4*Invoer!$B$10+C$5*Invoer!$B$12))*(Invoer!$B$29*Invoer!$B$30+Invoer!$B$31*Invoer!$B$32+Invoer!$B$33*Invoer!$B$34+Invoer!$B$35*Invoer!$B$36)*(1+Invoer!$B$37)^($A22-1))+IF($A22=20,Kasstromen!$V$27,0) -> 49148.049 | D22: =(Invoer!$B$5*D$4*Invoer!$B$10*Invoer!$B$6*(1+Invoer!$B$7)^($A22-1)+Invoer!$B$5*D$5*Invoer!$B$13*Invoer!$B$12*Invoer!$B$11*(1+Invoer!$B$14)^($A22-1)+(Invoer!$B$5*(D$4*Invoer!$B$10+D$5*Invoer!$B$12))*(Invoer!$B$29+Invoer!$B$31+Invoer!$B$33+Invoer!$B$35)*(1+Invoer!$B$37)^($A22-1))-((Invoer!$B$24+Invoer!$B$25+Invoer!$B$26+(Invoer!$B$5*D$5*Invoer!$B$13*Invoer!$B$12)/Invoer!$B$15*Invoer!$B$17 )*(1+Invoer!$B$28)^($A22-1)+(Invoer!$B$5*D$5*Invoer!$B$13*Invoer!$B$12*Invoer!$B$11*(1+Invoer!$B$14)^($A22-1))*Invoer!$B$16+(Invoer!$B$5*D$4*Invoer!$B$10*Invoer!$B$6*(1+Invoer!$B$7)^($A22-1)+Invoer!$B$5*D$5*Invoer!$B$13*Invoer!$B$12*Invoer!$B$11*(1+Invoer!$B$14)^($A22-1)+(Invoer!$B$5*(D$4*Invoer!$B$10+D$5*Invoer!$B$12))*(Invoer!$B$29+Invoer!$B$31+Invoer!$B$33+Invoer!$B$35)*(1+Invoer!$B$37)^($A22-1))*Invoer!$B$27+(Invoer!$B$5*(D$4*Invoer!$B$10+D$5*Invoer!$B$12))*(Invoer!$B$29*Invoer!$B$30+Invoer!$B$31*Invoer!$B$32+Invoer!$B$33*Invoer!$B$34+Invoer!$B$35*Invoer!$B$36)*(1+Invoer!$B$37)^($A22-1))+IF($A22=20,Kasstromen!$V$27,0) -> 49148.049
A23: 6 | B23: =(Invoer!$B$5*B$4*Invoer!$B$10*Invoer!$B$6*(1+Invoer!$B$7)^($A23-1)+Invoer!$B$5*B$5*Invoer!$B$13*Invoer!$B$12*Invoer!$B$11*(1+Invoer!$B$14)^($A23-1)+(Invoer!$B$5*(B$4*Invoer!$B$10+B$5*Invoer!$B$12))*(Invoer!$B$29+Invoer!$B$31+Invoer!$B$33+Invoer!$B$35)*(1+Invoer!$B$37)^($A23-1))-((Invoer!$B$24+Invoer!$B$25+Invoer!$B$26+(Invoer!$B$5*B$5*Invoer!$B$13*Invoer!$B$12)/Invoer!$B$15*Invoer!$B$17 )*(1+Invoer!$B$28)^($A23-1)+(Invoer!$B$5*B$5*Invoer!$B$13*Invoer!$B$12*Invoer!$B$11*(1+Invoer!$B$14)^($A23-1))*Invoer!$B$16+(Invoer!$B$5*B$4*Invoer!$B$10*Invoer!$B$6*(1+Invoer!$B$7)^($A23-1)+Invoer!$B$5*B$5*Invoer!$B$13*Invoer!$B$12*Invoer!$B$11*(1+Invoer!$B$14)^($A23-1)+(Invoer!$B$5*(B$4*Invoer!$B$10+B$5*Invoer!$B$12))*(Invoer!$B$29+Invoer!$B$31+Invoer!$B$33+Invoer!$B$35)*(1+Invoer!$B$37)^($A23-1))*Invoer!$B$27+(Invoer!$B$5*(B$4*Invoer!$B$10+B$5*Invoer!$B$12))*(Invoer!$B$29*Invoer!$B$30+Invoer!$B$31*Invoer!$B$32+Invoer!$B$33*Invoer!$B$34+Invoer!$B$35*Invoer!$B$36)*(1+Invoer!$B$37)^($A23-1))+IF($A23=20,Kasstromen!$V$27,0) -> 49145.507 | C23: =(Invoer!$B$5*C$4*Invoer!$B$10*Invoer!$B$6*(1+Invoer!$B$7)^($A23-1)+Invoer!$B$5*C$5*Invoer!$B$13*Invoer!$B$12*Invoer!$B$11*(1+Invoer!$B$14)^($A23-1)+(Invoer!$B$5*(C$4*Invoer!$B$10+C$5*Invoer!$B$12))*(Invoer!$B$29+Invoer!$B$31+Invoer!$B$33+Invoer!$B$35)*(1+Invoer!$B$37)^($A23-1))-((Invoer!$B$24+Invoer!$B$25+Invoer!$B$26+(Invoer!$B$5*C$5*Invoer!$B$13*Invoer!$B$12)/Invoer!$B$15*Invoer!$B$17 )*(1+Invoer!$B$28)^($A23-1)+(Invoer!$B$5*C$5*Invoer!$B$13*Invoer!$B$12*Invoer!$B$11*(1+Invoer!$B$14)^($A23-1))*Invoer!$B$16+(Invoer!$B$5*C$4*Invoer!$B$10*Invoer!$B$6*(1+Invoer!$B$7)^($A23-1)+Invoer!$B$5*C$5*Invoer!$B$13*Invoer!$B$12*Invoer!$B$11*(1+Invoer!$B$14)^($A23-1)+(Invoer!$B$5*(C$4*Invoer!$B$10+C$5*Invoer!$B$12))*(Invoer!$B$29+Invoer!$B$31+Invoer!$B$33+Invoer!$B$35)*(1+Invoer!$B$37)^($A23-1))*Invoer!$B$27+(Invoer!$B$5*(C$4*Invoer!$B$10+C$5*Invoer!$B$12))*(Invoer!$B$29*Invoer!$B$30+Invoer!$B$31*Invoer!$B$32+Invoer!$B$33*Invoer!$B$34+Invoer!$B$35*Invoer!$B$36)*(1+Invoer!$B$37)^($A23-1))+IF($A23=20,Kasstromen!$V$27,0) -> 50131.01 | D23: =(Invoer!$B$5*D$4*Invoer!$B$10*Invoer!$B$6*(1+Invoer!$B$7)^($A23-1)+Invoer!$B$5*D$5*Invoer!$B$13*Invoer!$B$12*Invoer!$B$11*(1+Invoer!$B$14)^($A23-1)+(Invoer!$B$5*(D$4*Invoer!$B$10+D$5*Invoer!$B$12))*(Invoer!$B$29+Invoer!$B$31+Invoer!$B$33+Invoer!$B$35)*(1+Invoer!$B$37)^($A23-1))-((Invoer!$B$24+Invoer!$B$25+Invoer!$B$26+(Invoer!$B$5*D$5*Invoer!$B$13*Invoer!$B$12)/Invoer!$B$15*Invoer!$B$17 )*(1+Invoer!$B$28)^($A23-1)+(Invoer!$B$5*D$5*Invoer!$B$13*Invoer!$B$12*Invoer!$B$11*(1+Invoer!$B$14)^($A23-1))*Invoer!$B$16+(Invoer!$B$5*D$4*Invoer!$B$10*Invoer!$B$6*(1+Invoer!$B$7)^($A23-1)+Invoer!$B$5*D$5*Invoer!$B$13*Invoer!$B$12*Invoer!$B$11*(1+Invoer!$B$14)^($A23-1)+(Invoer!$B$5*(D$4*Invoer!$B$10+D$5*Invoer!$B$12))*(Invoer!$B$29+Invoer!$B$31+Invoer!$B$33+Invoer!$B$35)*(1+Invoer!$B$37)^($A23-1))*Invoer!$B$27+(Invoer!$B$5*(D$4*Invoer!$B$10+D$5*Invoer!$B$12))*(Invoer!$B$29*Invoer!$B$30+Invoer!$B$31*Invoer!$B$32+Invoer!$B$33*Invoer!$B$34+Invoer!$B$35*Invoer!$B$36)*(1+Invoer!$B$37)^($A23-1))+IF($A23=20,Kasstromen!$V$27,0) -> 50131.01
A24: 7 | B24: =(Invoer!$B$5*B$4*Invoer!$B$10*Invoer!$B$6*(1+Invoer!$B$7)^($A24-1)+Invoer!$B$5*B$5*Invoer!$B$13*Invoer!$B$12*Invoer!$B$11*(1+Invoer!$B$14)^($A24-1)+(Invoer!$B$5*(B$4*Invoer!$B$10+B$5*Invoer!$B$12))*(Invoer!$B$29+Invoer!$B$31+Invoer!$B$33+Invoer!$B$35)*(1+Invoer!$B$37)^($A24-1))-((Invoer!$B$24+Invoer!$B$25+Invoer!$B$26+(Invoer!$B$5*B$5*Invoer!$B$13*Invoer!$B$12)/Invoer!$B$15*Invoer!$B$17 )*(1+Invoer!$B$28)^($A24-1)+(Invoer!$B$5*B$5*Invoer!$B$13*Invoer!$B$12*Invoer!$B$11*(1+Invoer!$B$14)^($A24-1))*Invoer!$B$16+(Invoer!$B$5*B$4*Invoer!$B$10*Invoer!$B$6*(1+Invoer!$B$7)^($A24-1)+Invoer!$B$5*B$5*Invoer!$B$13*Invoer!$B$12*Invoer!$B$11*(1+Invoer!$B$14)^($A24-1)+(Invoer!$B$5*(B$4*Invoer!$B$10+B$5*Invoer!$B$12))*(Invoer!$B$29+Invoer!$B$31+Invoer!$B$33+Invoer!$B$35)*(1+Invoer!$B$37)^($A24-1))*Invoer!$B$27+(Invoer!$B$5*(B$4*Invoer!$B$10+B$5*Invoer!$B$12))*(Invoer!$B$29*Invoer!$B$30+Invoer!$B$31*Invoer!$B$32+Invoer!$B$33*Invoer!$B$34+Invoer!$B$35*Invoer!$B$36)*(1+Invoer!$B$37)^($A24-1))+IF($A24=20,Kasstromen!$V$27,0) -> 50128.417 | C24: =(Invoer!$B$5*C$4*Invoer!$B$10*Invoer!$B$6*(1+Invoer!$B$7)^($A24-1)+Invoer!$B$5*C$5*Invoer!$B$13*Invoer!$B$12*Invoer!$B$11*(1+Invoer!$B$14)^($A24-1)+(Invoer!$B$5*(C$4*Invoer!$B$10+C$5*Invoer!$B$12))*(Invoer!$B$29+Invoer!$B$31+Invoer!$B$33+Invoer!$B$35)*(1+Invoer!$B$37)^($A24-1))-((Invoer!$B$24+Invoer!$B$25+Invoer!$B$26+(Invoer!$B$5*C$5*Invoer!$B$13*Invoer!$B$12)/Invoer!$B$15*Invoer!$B$17 )*(1+Invoer!$B$28)^($A24-1)+(Invoer!$B$5*C$5*Invoer!$B$13*Invoer!$B$12*Invoer!$B$11*(1+Invoer!$B$14)^($A24-1))*Invoer!$B$16+(Invoer!$B$5*C$4*Invoer!$B$10*Invoer!$B$6*(1+Invoer!$B$7)^($A24-1)+Invoer!$B$5*C$5*Invoer!$B$13*Invoer!$B$12*Invoer!$B$11*(1+Invoer!$B$14)^($A24-1)+(Invoer!$B$5*(C$4*Invoer!$B$10+C$5*Invoer!$B$12))*(Invoer!$B$29+Invoer!$B$31+Invoer!$B$33+Invoer!$B$35)*(1+Invoer!$B$37)^($A24-1))*Invoer!$B$27+(Invoer!$B$5*(C$4*Invoer!$B$10+C$5*Invoer!$B$12))*(Invoer!$B$29*Invoer!$B$30+Invoer!$B$31*Invoer!$B$32+Invoer!$B$33*Invoer!$B$34+Invoer!$B$35*Invoer!$B$36)*(1+Invoer!$B$37)^($A24-1))+IF($A24=20,Kasstromen!$V$27,0) -> 51133.63 | D24: =(Invoer!$B$5*D$4*Invoer!$B$10*Invoer!$B$6*(1+Invoer!$B$7)^($A24-1)+Invoer!$B$5*D$5*Invoer!$B$13*Invoer!$B$12*Invoer!$B$11*(1+Invoer!$B$14)^($A24-1)+(Invoer!$B$5*(D$4*Invoer!$B$10+D$5*Invoer!$B$12))*(Invoer!$B$29+Invoer!$B$31+Invoer!$B$33+Invoer!$B$35)*(1+Invoer!$B$37)^($A24-1))-((Invoer!$B$24+Invoer!$B$25+Invoer!$B$26+(Invoer!$B$5*D$5*Invoer!$B$13*Invoer!$B$12)/Invoer!$B$15*Invoer!$B$17 )*(1+Invoer!$B$28)^($A24-1)+(Invoer!$B$5*D$5*Invoer!$B$13*Invoer!$B$12*Invoer!$B$11*(1+Invoer!$B$14)^($A24-1))*Invoer!$B$16+(Invoer!$B$5*D$4*Invoer!$B$10*Invoer!$B$6*(1+Invoer!$B$7)^($A24-1)+Invoer!$B$5*D$5*Invoer!$B$13*Invoer!$B$12*Invoer!$B$11*(1+Invoer!$B$14)^($A24-1)+(Invoer!$B$5*(D$4*Invoer!$B$10+D$5*Invoer!$B$12))*(Invoer!$B$29+Invoer!$B$31+Invoer!$B$33+Invoer!$B$35)*(1+Invoer!$B$37)^($A24-1))*Invoer!$B$27+(Invoer!$B$5*(D$4*Invoer!$B$10+D$5*Invoer!$B$12))*(Invoer!$B$29*Invoer!$B$30+Invoer!$B$31*Invoer!$B$32+Invoer!$B$33*Invoer!$B$34+Invoer!$B$35*Invoer!$B$36)*(1+Invoer!$B$37)^($A24-1))+IF($A24=20,Kasstromen!$V$27,0) -> 51133.63
A25: 8 | B25: =(Invoer!$B$5*B$4*Invoer!$B$10*Invoer!$B$6*(1+Invoer!$B$7)^($A25-1)+Invoer!$B$5*B$5*Invoer!$B$13*Invoer!$B$12*Invoer!$B$11*(1+Invoer!$B$14)^($A25-1)+(Invoer!$B$5*(B$4*Invoer!$B$10+B$5*Invoer!$B$12))*(Invoer!$B$29+Invoer!$B$31+Invoer!$B$33+Invoer!$B$35)*(1+Invoer!$B$37)^($A25-1))-((Invoer!$B$24+Invoer!$B$25+Invoer!$B$26+(Invoer!$B$5*B$5*Invoer!$B$13*Invoer!$B$12)/Invoer!$B$15*Invoer!$B$17 )*(1+Invoer!$B$28)^($A25-1)+(Invoer!$B$5*B$5*Invoer!$B$13*Invoer!$B$12*Invoer!$B$11*(1+Invoer!$B$14)^($A25-1))*Invoer!$B$16+(Invoer!$B$5*B$4*Invoer!$B$10*Invoer!$B$6*(1+Invoer!$B$7)^($A25-1)+Invoer!$B$5*B$5*Invoer!$B$13*Invoer!$B$12*Invoer!$B$11*(1+Invoer!$B$14)^($A25-1)+(Invoer!$B$5*(B$4*Invoer!$B$10+B$5*Invoer!$B$12))*(Invoer!$B$29+Invoer!$B$31+Invoer!$B$33+Invoer!$B$35)*(1+Invoer!$B$37)^($A25-1))*Invoer!$B$27+(Invoer!$B$5*(B$4*Invoer!$B$10+B$5*Invoer!$B$12))*(Invoer!$B$29*Invoer!$B$30+Invoer!$B$31*Invoer!$B$32+Invoer!$B$33*Invoer!$B$34+Invoer!$B$35*Invoer!$B$36)*(1+Invoer!$B$37)^($A25-1))+IF($A25=20,Kasstromen!$V$27,0) -> 51130.986 | C25: =(Invoer!$B$5*C$4*Invoer!$B$10*Invoer!$B$6*(1+Invoer!$B$7)^($A25-1)+Invoer!$B$5*C$5*Invoer!$B$13*Invoer!$B$12*Invoer!$B$11*(1+Invoer!$B$14)^($A25-1)+(Invoer!$B$5*(C$4*Invoer!$B$10+C$5*Invoer!$B$12))*(Invoer!$B$29+Invoer!$B$31+Invoer!$B$33+Invoer!$B$35)*(1+Invoer!$B$37)^($A25-1))-((Invoer!$B$24+Invoer!$B$25+Invoer!$B$26+(Invoer!$B$5*C$5*Invoer!$B$13*Invoer!$B$12)/Invoer!$B$15*Invoer!$B$17 )*(1+Invoer!$B$28)^($A25-1)+(Invoer!$B$5*C$5*Invoer!$B$13*Invoer!$B$12*Invoer!$B$11*(1+Invoer!$B$14)^($A25-1))*Invoer!$B$16+(Invoer!$B$5*C$4*Invoer!$B$10*Invoer!$B$6*(1+Invoer!$B$7)^($A25-1)+Invoer!$B$5*C$5*Invoer!$B$13*Invoer!$B$12*Invoer!$B$11*(1+Invoer!$B$14)^($A25-1)+(Invoer!$B$5*(C$4*Invoer!$B$10+C$5*Invoer!$B$12))*(Invoer!$B$29+Invoer!$B$31+Invoer!$B$33+Invoer!$B$35)*(1+Invoer!$B$37)^($A25-1))*Invoer!$B$27+(Invoer!$B$5*(C$4*Invoer!$B$10+C$5*Invoer!$B$12))*(Invoer!$B$29*Invoer!$B$30+Invoer!$B$31*Invoer!$B$32+Invoer!$B$33*Invoer!$B$34+Invoer!$B$35*Invoer!$B$36)*(1+Invoer!$B$37)^($A25-1))+IF($A25=20,Kasstromen!$V$27,0) -> 52156.302 | D25: =(Invoer!$B$5*D$4*Invoer!$B$10*Invoer!$B$6*(1+Invoer!$B$7)^($A25-1)+Invoer!$B$5*D$5*Invoer!$B$13*Invoer!$B$12*Invoer!$B$11*(1+Invoer!$B$14)^($A25-1)+(Invoer!$B$5*(D$4*Invoer!$B$10+D$5*Invoer!$B$12))*(Invoer!$B$29+Invoer!$B$31+Invoer!$B$33+Invoer!$B$35)*(1+Invoer!$B$37)^($A25-1))-((Invoer!$B$24+Invoer!$B$25+Invoer!$B$26+(Invoer!$B$5*D$5*Invoer!$B$13*Invoer!$B$12)/Invoer!$B$15*Invoer!$B$17 )*(1+Invoer!$B$28)^($A25-1)+(Invoer!$B$5*D$5*Invoer!$B$13*Invoer!$B$12*Invoer!$B$11*(1+Invoer!$B$14)^($A25-1))*Invoer!$B$16+(Invoer!$B$5*D$4*Invoer!$B$10*Invoer!$B$6*(1+Invoer!$B$7)^($A25-1)+Invoer!$B$5*D$5*Invoer!$B$13*Invoer!$B$12*Invoer!$B$11*(1+Invoer!$B$14)^($A25-1)+(Invoer!$B$5*(D$4*Invoer!$B$10+D$5*Invoer!$B$12))*(Invoer!$B$29+Invoer!$B$31+Invoer!$B$33+Invoer!$B$35)*(1+Invoer!$B$37)^($A25-1))*Invoer!$B$27+(Invoer!$B$5*(D$4*Invoer!$B$10+D$5*Invoer!$B$12))*(Invoer!$B$29*Invoer!$B$30+Invoer!$B$31*Invoer!$B$32+Invoer!$B$33*Invoer!$B$34+Invoer!$B$35*Invoer!$B$36)*(1+Invoer!$B$37)^($A25-1))+IF($A25=20,Kasstromen!$V$27,0) -> 52156.302
A26: 9 | B26: =(Invoer!$B$5*B$4*Invoer!$B$10*Invoer!$B$6*(1+Invoer!$B$7)^($A26-1)+Invoer!$B$5*B$5*Invoer!$B$13*Invoer!$B$12*Invoer!$B$11*(1+Invoer!$B$14)^($A26-1)+(Invoer!$B$5*(B$4*Invoer!$B$10+B$5*Invoer!$B$12))*(Invoer!$B$29+Invoer!$B$31+Invoer!$B$33+Invoer!$B$35)*(1+Invoer!$B$37)^($A26-1))-((Invoer!$B$24+Invoer!$B$25+Invoer!$B$26+(Invoer!$B$5*B$5*Invoer!$B$13*Invoer!$B$12)/Invoer!$B$15*Invoer!$B$17 )*(1+Invoer!$B$28)^($A26-1)+(Invoer!$B$5*B$5*Invoer!$B$13*Invoer!$B$12*Invoer!$B$11*(1+Invoer!$B$14)^($A26-1))*Invoer!$B$16+(Invoer!$B$5*B$4*Invoer!$B$10*Invoer!$B$6*(1+Invoer!$B$7)^($A26-1)+Invoer!$B$5*B$5*Invoer!$B$13*Invoer!$B$12*Invoer!$B$11*(1+Invoer!$B$14)^($A26-1)+(Invoer!$B$5*(B$4*Invoer!$B$10+B$5*Invoer!$B$12))*(Invoer!$B$29+Invoer!$B$31+Invoer!$B$33+Invoer!$B$35)*(1+Invoer!$B$37)^($A26-1))*Invoer!$B$27+(Invoer!$B$5*(B$4*Invoer!$B$10+B$5*Invoer!$B$12))*(Invoer!$B$29*Invoer!$B$30+Invoer!$B$31*Invoer!$B$32+Invoer!$B$33*Invoer!$B$34+Invoer!$B$35*Invoer!$B$36)*(1+Invoer!$B$37)^($A26-1))+IF($A26=20,Kasstromen!$V$27,0) -> 52153.605 | C26: =(Invoer!$B$5*C$4*Invoer!$B$10*Invoer!$B$6*(1+Invoer!$B$7)^($A26-1)+Invoer!$B$5*C$5*Invoer!$B$13*Invoer!$B$12*Invoer!$B$11*(1+Invoer!$B$14)^($A26-1)+(Invoer!$B$5*(C$4*Invoer!$B$10+C$5*Invoer!$B$12))*(Invoer!$B$29+Invoer!$B$31+Invoer!$B$33+Invoer!$B$35)*(1+Invoer!$B$37)^($A26-1))-((Invoer!$B$24+Invoer!$B$25+Invoer!$B$26+(Invoer!$B$5*C$5*Invoer!$B$13*Invoer!$B$12)/Invoer!$B$15*Invoer!$B$17 )*(1+Invoer!$B$28)^($A26-1)+(Invoer!$B$5*C$5*Invoer!$B$13*Invoer!$B$12*Invoer!$B$11*(1+Invoer!$B$14)^($A26-1))*Invoer!$B$16+(Invoer!$B$5*C$4*Invoer!$B$10*Invoer!$B$6*(1+Invoer!$B$7)^($A26-1)+Invoer!$B$5*C$5*Invoer!$B$13*Invoer!$B$12*Invoer!$B$11*(1+Invoer!$B$14)^($A26-1)+(Invoer!$B$5*(C$4*Invoer!$B$10+C$5*Invoer!$B$12))*(Invoer!$B$29+Invoer!$B$31+Invoer!$B$33+Invoer!$B$35)*(1+Invoer!$B$37)^($A26-1))*Invoer!$B$27+(Invoer!$B$5*(C$4*Invoer!$B$10+C$5*Invoer!$B$12))*(Invoer!$B$29*Invoer!$B$30+Invoer!$B$31*Invoer!$B$32+Invoer!$B$33*Invoer!$B$34+Invoer!$B$35*Invoer!$B$36)*(1+Invoer!$B$37)^($A26-1))+IF($A26=20,Kasstromen!$V$27,0) -> 53199.429 | D26: =(Invoer!$B$5*D$4*Invoer!$B$10*Invoer!$B$6*(1+Invoer!$B$7)^($A26-1)+Invoer!$B$5*D$5*Invoer!$B$13*Invoer!$B$12*Invoer!$B$11*(1+Invoer!$B$14)^($A26-1)+(Invoer!$B$5*(D$4*Invoer!$B$10+D$5*Invoer!$B$12))*(Invoer!$B$29+Invoer!$B$31+Invoer!$B$33+Invoer!$B$35)*(1+Invoer!$B$37)^($A26-1))-((Invoer!$B$24+Invoer!$B$25+Invoer!$B$26+(Invoer!$B$5*D$5*Invoer!$B$13*Invoer!$B$12)/Invoer!$B$15*Invoer!$B$17 )*(1+Invoer!$B$28)^($A26-1)+(Invoer!$B$5*D$5*Invoer!$B$13*Invoer!$B$12*Invoer!$B$11*(1+Invoer!$B$14)^($A26-1))*Invoer!$B$16+(Invoer!$B$5*D$4*Invoer!$B$10*Invoer!$B$6*(1+Invoer!$B$7)^($A26-1)+Invoer!$B$5*D$5*Invoer!$B$13*Invoer!$B$12*Invoer!$B$11*(1+Invoer!$B$14)^($A26-1)+(Invoer!$B$5*(D$4*Invoer!$B$10+D$5*Invoer!$B$12))*(Invoer!$B$29+Invoer!$B$31+Invoer!$B$33+Invoer!$B$35)*(1+Invoer!$B$37)^($A26-1))*Invoer!$B$27+(Invoer!$B$5*(D$4*Invoer!$B$10+D$5*Invoer!$B$12))*(Invoer!$B$29*Invoer!$B$30+Invoer!$B$31*Invoer!$B$32+Invoer!$B$33*Invoer!$B$34+Invoer!$B$35*Invoer!$B$36)*(1+Invoer!$B$37)^($A26-1))+IF($A26=20,Kasstromen!$V$27,0) -> 53199.429
A27: 10 | B27: =(Invoer!$B$5*B$4*Invoer!$B$10*Invoer!$B$6*(1+Invoer!$B$7)^($A27-1)+Invoer!$B$5*B$5*Invoer!$B$13*Invoer!$B$12*Invoer!$B$11*(1+Invoer!$B$14)^($A27-1)+(Invoer!$B$5*(B$4*Invoer!$B$10+B$5*Invoer!$B$12))*(Invoer!$B$29+Invoer!$B$31+Invoer!$B$33+Invoer!$B$35)*(1+Invoer!$B$37)^($A27-1))-((Invoer!$B$24+Invoer!$B$25+Invoer!$B$26+(Invoer!$B$5*B$5*Invoer!$B$13*Invoer!$B$12)/Invoer!$B$15*Invoer!$B$17 )*(1+Invoer!$B$28)^($A27-1)+(Invoer!$B$5*B$5*Invoer!$B$13*Invoer!$B$12*Invoer!$B$11*(1+Invoer!$B$14)^($A27-1))*Invoer!$B$16+(Invoer!$B$5*B$4*Invoer!$B$10*Invoer!$B$6*(1+Invoer!$B$7)^($A27-1)+Invoer!$B$5*B$5*Invoer!$B$13*Invoer!$B$12*Invoer!$B$11*(1+Invoer!$B$14)^($A27-1)+(Invoer!$B$5*(B$4*Invoer!$B$10+B$5*Invoer!$B$12))*(Invoer!$B$29+Invoer!$B$31+Invoer!$B$33+Invoer!$B$35)*(1+Invoer!$B$37)^($A27-1))*Invoer!$B$27+(Invoer!$B$5*(B$4*Invoer!$B$10+B$5*Invoer!$B$12))*(Invoer!$B$29*Invoer!$B$30+Invoer!$B$31*Invoer!$B$32+Invoer!$B$33*Invoer!$B$34+Invoer!$B$35*Invoer!$B$36)*(1+Invoer!$B$37)^($A27-1))+IF($A27=20,Kasstromen!$V$27,0) -> 53196.677 | C27: =(Invoer!$B$5*C$4*Invoer!$B$10*Invoer!$B$6*(1+Invoer!$B$7)^($A27-1)+Invoer!$B$5*C$5*Invoer!$B$13*Invoer!$B$12*Invoer!$B$11*(1+Invoer!$B$14)^($A27-1)+(Invoer!$B$5*(C$4*Invoer!$B$10+C$5*Invoer!$B$12))*(Invoer!$B$29+Invoer!$B$31+Invoer!$B$33+Invoer!$B$35)*(1+Invoer!$B$37)^($A27-1))-((Invoer!$B$24+Invoer!$B$25+Invoer!$B$26+(Invoer!$B$5*C$5*Invoer!$B$13*Invoer!$B$12)/Invoer!$B$15*Invoer!$B$17 )*(1+Invoer!$B$28)^($A27-1)+(Invoer!$B$5*C$5*Invoer!$B$13*Invoer!$B$12*Invoer!$B$11*(1+Invoer!$B$14)^($A27-1))*Invoer!$B$16+(Invoer!$B$5*C$4*Invoer!$B$10*Invoer!$B$6*(1+Invoer!$B$7)^($A27-1)+Invoer!$B$5*C$5*Invoer!$B$13*Invoer!$B$12*Invoer!$B$11*(1+Invoer!$B$14)^($A27-1)+(Invoer!$B$5*(C$4*Invoer!$B$10+C$5*Invoer!$B$12))*(Invoer!$B$29+Invoer!$B$31+Invoer!$B$33+Invoer!$B$35)*(1+Invoer!$B$37)^($A27-1))*Invoer!$B$27+(Invoer!$B$5*(C$4*Invoer!$B$10+C$5*Invoer!$B$12))*(Invoer!$B$29*Invoer!$B$30+Invoer!$B$31*Invoer!$B$32+Invoer!$B$33*Invoer!$B$34+Invoer!$B$35*Invoer!$B$36)*(1+Invoer!$B$37)^($A27-1))+IF($A27=20,Kasstromen!$V$27,0) -> 54263.417 | D27: =(Invoer!$B$5*D$4*Invoer!$B$10*Invoer!$B$6*(1+Invoer!$B$7)^($A27-1)+Invoer!$B$5*D$5*Invoer!$B$13*Invoer!$B$12*Invoer!$B$11*(1+Invoer!$B$14)^($A27-1)+(Invoer!$B$5*(D$4*Invoer!$B$10+D$5*Invoer!$B$12))*(Invoer!$B$29+Invoer!$B$31+Invoer!$B$33+Invoer!$B$35)*(1+Invoer!$B$37)^($A27-1))-((Invoer!$B$24+Invoer!$B$25+Invoer!$B$26+(Invoer!$B$5*D$5*Invoer!$B$13*Invoer!$B$12)/Invoer!$B$15*Invoer!$B$17 )*(1+Invoer!$B$28)^($A27-1)+(Invoer!$B$5*D$5*Invoer!$B$13*Invoer!$B$12*Invoer!$B$11*(1+Invoer!$B$14)^($A27-1))*Invoer!$B$16+(Invoer!$B$5*D$4*Invoer!$B$10*Invoer!$B$6*(1+Invoer!$B$7)^($A27-1)+Invoer!$B$5*D$5*Invoer!$B$13*Invoer!$B$12*Invoer!$B$11*(1+Invoer!$B$14)^($A27-1)+(Invoer!$B$5*(D$4*Invoer!$B$10+D$5*Invoer!$B$12))*(Invoer!$B$29+Invoer!$B$31+Invoer!$B$33+Invoer!$B$35)*(1+Invoer!$B$37)^($A27-1))*Invoer!$B$27+(Invoer!$B$5*(D$4*Invoer!$B$10+D$5*Invoer!$B$12))*(Invoer!$B$29*Invoer!$B$30+Invoer!$B$31*Invoer!$B$32+Invoer!$B$33*Invoer!$B$34+Invoer!$B$35*Invoer!$B$36)*(1+Invoer!$B$37)^($A27-1))+IF($A27=20,Kasstromen!$V$27,0) -> 54263.417
A28: 11 | B28: =(Invoer!$B$5*B$4*Invoer!$B$10*Invoer!$B$6*(1+Invoer!$B$7)^($A28-1)+Invoer!$B$5*B$5*Invoer!$B$13*Invoer!$B$12*Invoer!$B$11*(1+Invoer!$B$14)^($A28-1)+(Invoer!$B$5*(B$4*Invoer!$B$10+B$5*Invoer!$B$12))*(Invoer!$B$29+Invoer!$B$31+Invoer!$B$33+Invoer!$B$35)*(1+Invoer!$B$37)^($A28-1))-((Invoer!$B$24+Invoer!$B$25+Invoer!$B$26+(Invoer!$B$5*B$5*Invoer!$B$13*Invoer!$B$12)/Invoer!$B$15*Invoer!$B$17 )*(1+Invoer!$B$28)^($A28-1)+(Invoer!$B$5*B$5*Invoer!$B$13*Invoer!$B$12*Invoer!$B$11*(1+Invoer!$B$14)^($A28-1))*Invoer!$B$16+(Invoer!$B$5*B$4*Invoer!$B$10*Invoer!$B$6*(1+Invoer!$B$7)^($A28-1)+Invoer!$B$5*B$5*Invoer!$B$13*Invoer!$B$12*Invoer!$B$11*(1+Invoer!$B$14)^($A28-1)+(Invoer!$B$5*(B$4*Invoer!$B$10+B$5*Invoer!$B$12))*(Invoer!$B$29+Invoer!$B$31+Invoer!$B$33+Invoer!$B$35)*(1+Invoer!$B$37)^($A28-1))*Invoer!$B$27+(Invoer!$B$5*(B$4*Invoer!$B$10+B$5*Invoer!$B$12))*(Invoer!$B$29*Invoer!$B$30+Invoer!$B$31*Invoer!$B$32+Invoer!$B$33*Invoer!$B$34+Invoer!$B$35*Invoer!$B$36)*(1+Invoer!$B$37)^($A28-1))+IF($A28=20,Kasstromen!$V$27,0) -> 54260.611 | C28: =(Invoer!$B$5*C$4*Invoer!$B$10*Invoer!$B$6*(1+Invoer!$B$7)^($A28-1)+Invoer!$B$5*C$5*Invoer!$B$13*Invoer!$B$12*Invoer!$B$11*(1+Invoer!$B$14)^($A28-1)+(Invoer!$B$5*(C$4*Invoer!$B$10+C$5*Invoer!$B$12))*(Invoer!$B$29+Invoer!$B$31+Invoer!$B$33+Invoer!$B$35)*(1+Invoer!$B$37)^($A28-1))-((Invoer!$B$24+Invoer!$B$25+Invoer!$B$26+(Invoer!$B$5*C$5*Invoer!$B$13*Invoer!$B$12)/Invoer!$B$15*Invoer!$B$17 )*(1+Invoer!$B$28)^($A28-1)+(Invoer!$B$5*C$5*Invoer!$B$13*Invoer!$B$12*Invoer!$B$11*(1+Invoer!$B$14)^($A28-1))*Invoer!$B$16+(Invoer!$B$5*C$4*Invoer!$B$10*Invoer!$B$6*(1+Invoer!$B$7)^($A28-1)+Invoer!$B$5*C$5*Invoer!$B$13*Invoer!$B$12*Invoer!$B$11*(1+Invoer!$B$14)^($A28-1)+(Invoer!$B$5*(C$4*Invoer!$B$10+C$5*Invoer!$B$12))*(Invoer!$B$29+Invoer!$B$31+Invoer!$B$33+Invoer!$B$35)*(1+Invoer!$B$37)^($A28-1))*Invoer!$B$27+(Invoer!$B$5*(C$4*Invoer!$B$10+C$5*Invoer!$B$12))*(Invoer!$B$29*Invoer!$B$30+Invoer!$B$31*Invoer!$B$32+Invoer!$B$33*Invoer!$B$34+Invoer!$B$35*Invoer!$B$36)*(1+Invoer!$B$37)^($A28-1))+IF($A28=20,Kasstromen!$V$27,0) -> 55348.685 | D28: =(Invoer!$B$5*D$4*Invoer!$B$10*Invoer!$B$6*(1+Invoer!$B$7)^($A28-1)+Invoer!$B$5*D$5*Invoer!$B$13*Invoer!$B$12*Invoer!$B$11*(1+Invoer!$B$14)^($A28-1)+(Invoer!$B$5*(D$4*Invoer!$B$10+D$5*Invoer!$B$12))*(Invoer!$B$29+Invoer!$B$31+Invoer!$B$33+Invoer!$B$35)*(1+Invoer!$B$37)^($A28-1))-((Invoer!$B$24+Invoer!$B$25+Invoer!$B$26+(Invoer!$B$5*D$5*Invoer!$B$13*Invoer!$B$12)/Invoer!$B$15*Invoer!$B$17 )*(1+Invoer!$B$28)^($A28-1)+(Invoer!$B$5*D$5*Invoer!$B$13*Invoer!$B$12*Invoer!$B$11*(1+Invoer!$B$14)^($A28-1))*Invoer!$B$16+(Invoer!$B$5*D$4*Invoer!$B$10*Invoer!$B$6*(1+Invoer!$B$7)^($A28-1)+Invoer!$B$5*D$5*Invoer!$B$13*Invoer!$B$12*Invoer!$B$11*(1+Invoer!$B$14)^($A28-1)+(Invoer!$B$5*(D$4*Invoer!$B$10+D$5*Invoer!$B$12))*(Invoer!$B$29+Invoer!$B$31+Invoer!$B$33+Invoer!$B$35)*(1+Invoer!$B$37)^($A28-1))*Invoer!$B$27+(Invoer!$B$5*(D$4*Invoer!$B$10+D$5*Invoer!$B$12))*(Invoer!$B$29*Invoer!$B$30+Invoer!$B$31*Invoer!$B$32+Invoer!$B$33*Invoer!$B$34+Invoer!$B$35*Invoer!$B$36)*(1+Invoer!$B$37)^($A28-1))+IF($A28=20,Kasstromen!$V$27,0) -> 55348.685
A29: 12 | B29: =(Invoer!$B$5*B$4*Invoer!$B$10*Invoer!$B$6*(1+Invoer!$B$7)^($A29-1)+Invoer!$B$5*B$5*Invoer!$B$13*Invoer!$B$12*Invoer!$B$11*(1+Invoer!$B$14)^($A29-1)+(Invoer!$B$5*(B$4*Invoer!$B$10+B$5*Invoer!$B$12))*(Invoer!$B$29+Invoer!$B$31+Invoer!$B$33+Invoer!$B$35)*(1+Invoer!$B$37)^($A29-1))-((Invoer!$B$24+Invoer!$B$25+Invoer!$B$26+(Invoer!$B$5*B$5*Invoer!$B$13*Invoer!$B$12)/Invoer!$B$15*Invoer!$B$17 )*(1+Invoer!$B$28)^($A29-1)+(Invoer!$B$5*B$5*Invoer!$B$13*Invoer!$B$12*Invoer!$B$11*(1+Invoer!$B$14)^($A29-1))*Invoer!$B$16+(Invoer!$B$5*B$4*Invoer!$B$10*Invoer!$B$6*(1+Invoer!$B$7)^($A29-1)+Invoer!$B$5*B$5*Invoer!$B$13*Invoer!$B$12*Invoer!$B$11*(1+Invoer!$B$14)^($A29-1)+(Invoer!$B$5*(B$4*Invoer!$B$10+B$5*Invoer!$B$12))*(Invoer!$B$29+Invoer!$B$31+Invoer!$B$33+Invoer!$B$35)*(1+Invoer!$B$37)^($A29-1))*Invoer!$B$27+(Invoer!$B$5*(B$4*Invoer!$B$10+B$5*Invoer!$B$12))*(Invoer!$B$29*Invoer!$B$30+Invoer!$B$31*Invoer!$B$32+Invoer!$B$33*Invoer!$B$34+Invoer!$B$35*Invoer!$B$36)*(1+Invoer!$B$37)^($A29-1))+IF($A29=20,Kasstromen!$V$27,0) -> 55345.823 | C29: =(Invoer!$B$5*C$4*Invoer!$B$10*Invoer!$B$6*(1+Invoer!$B$7)^($A29-1)+Invoer!$B$5*C$5*Invoer!$B$13*Invoer!$B$12*Invoer!$B$11*(1+Invoer!$B$14)^($A29-1)+(Invoer!$B$5*(C$4*Invoer!$B$10+C$5*Invoer!$B$12))*(Invoer!$B$29+Invoer!$B$31+Invoer!$B$33+Invoer!$B$35)*(1+Invoer!$B$37)^($A29-1))-((Invoer!$B$24+Invoer!$B$25+Invoer!$B$26+(Invoer!$B$5*C$5*Invoer!$B$13*Invoer!$B$12)/Invoer!$B$15*Invoer!$B$17 )*(1+Invoer!$B$28)^($A29-1)+(Invoer!$B$5*C$5*Invoer!$B$13*Invoer!$B$12*Invoer!$B$11*(1+Invoer!$B$14)^($A29-1))*Invoer!$B$16+(Invoer!$B$5*C$4*Invoer!$B$10*Invoer!$B$6*(1+Invoer!$B$7)^($A29-1)+Invoer!$B$5*C$5*Invoer!$B$13*Invoer!$B$12*Invoer!$B$11*(1+Invoer!$B$14)^($A29-1)+(Invoer!$B$5*(C$4*Invoer!$B$10+C$5*Invoer!$B$12))*(Invoer!$B$29+Invoer!$B$31+Invoer!$B$33+Invoer!$B$35)*(1+Invoer!$B$37)^($A29-1))*Invoer!$B$27+(Invoer!$B$5*(C$4*Invoer!$B$10+C$5*Invoer!$B$12))*(Invoer!$B$29*Invoer!$B$30+Invoer!$B$31*Invoer!$B$32+Invoer!$B$33*Invoer!$B$34+Invoer!$B$35*Invoer!$B$36)*(1+Invoer!$B$37)^($A29-1))+IF($A29=20,Kasstromen!$V$27,0) -> 56455.659 | D29: =(Invoer!$B$5*D$4*Invoer!$B$10*Invoer!$B$6*(1+Invoer!$B$7)^($A29-1)+Invoer!$B$5*D$5*Invoer!$B$13*Invoer!$B$12*Invoer!$B$11*(1+Invoer!$B$14)^($A29-1)+(Invoer!$B$5*(D$4*Invoer!$B$10+D$5*Invoer!$B$12))*(Invoer!$B$29+Invoer!$B$31+Invoer!$B$33+Invoer!$B$35)*(1+Invoer!$B$37)^($A29-1))-((Invoer!$B$24+Invoer!$B$25+Invoer!$B$26+(Invoer!$B$5*D$5*Invoer!$B$13*Invoer!$B$12)/Invoer!$B$15*Invoer!$B$17 )*(1+Invoer!$B$28)^($A29-1)+(Invoer!$B$5*D$5*Invoer!$B$13*Invoer!$B$12*Invoer!$B$11*(1+Invoer!$B$14)^($A29-1))*Invoer!$B$16+(Invoer!$B$5*D$4*Invoer!$B$10*Invoer!$B$6*(1+Invoer!$B$7)^($A29-1)+Invoer!$B$5*D$5*Invoer!$B$13*Invoer!$B$12*Invoer!$B$11*(1+Invoer!$B$14)^($A29-1)+(Invoer!$B$5*(D$4*Invoer!$B$10+D$5*Invoer!$B$12))*(Invoer!$B$29+Invoer!$B$31+Invoer!$B$33+Invoer!$B$35)*(1+Invoer!$B$37)^($A29-1))*Invoer!$B$27+(Invoer!$B$5*(D$4*Invoer!$B$10+D$5*Invoer!$B$12))*(Invoer!$B$29*Invoer!$B$30+Invoer!$B$31*Invoer!$B$32+Invoer!$B$33*Invoer!$B$34+Invoer!$B$35*Invoer!$B$36)*(1+Invoer!$B$37)^($A29-1))+IF($A29=20,Kasstromen!$V$27,0) -> 56455.659
