Workbook

Sheet Report
A1: BRUSSELS | STUDENT HOUSING
A2: Investment committee report • capital allocation • model date 14 October 2026
A4: Use / evidence status | B4: =IF(Assumptions!B5="YES","DEMONSTRATION — hypothetical opportunities","LIVE INPUTS — evidence required") -> DEMONSTRATION — hypothetical opportunities
A5: Mandate | B5: Maximize 10-year discounted unlevered profit within budget; legal readiness is mandatory.
A6: Optimal portfolio NPV | B6: =MAX(Portfolio!N5:N260) -> 188913.04
A7: Winning subset position | B7: =MATCH(B6,Portfolio!N5:N260,0) -> 12
A8: Committed capital | B8: =INDEX(Portfolio!J5:J260,B7) -> 1786750
A9: Remaining capital | B9: =Assumptions!B6-B8 -> 213250
A10: Projects selected | B10: =INDEX(Portfolio!K5:K260,B7) -> 3
A11: Recommendation | B11: =IF(B10=0,"No eligible positive-NPV portfolio — retain capital",IF(Assumptions!B5="YES","Illustration only; obtain actual opportunities and evidence before investment","Selected projects require final due diligence and transaction approval")) -> Illustration only; obtain actual opportunities and evidence before investment
A14: Order | B14: Project | C14: NPV | D14: IRR | E14: All-in capital | F14: Ready (months) | G14: Downside NPV | H14: Compliance | I14: Selection
A15: =IF(1<=COUNTIF(Opportunities!$S$8:$S$15,"ELIGIBLE"),1,"") -> 1 | B15: =IF($A15="","",INDEX(Opportunities!$B$8:$B$15,MATCH($A15,Opportunities!$T$8:$T$15,0))) -> Illustrative conversion A | C15: =IF($A15="","",INDEX(Opportunities!$P$8:$P$15,MATCH($A15,Opportunities!$T$8:$T$15,0))) -> 90896.517 | D15: =IF($A15="","",INDEX(Opportunities!$Q$8:$Q$15,MATCH($A15,Opportunities!$T$8:$T$15,0))) -> 0.10331943 | E15: =IF($A15="","",INDEX(Opportunities!$L$8:$L$15,MATCH($A15,Opportunities!$T$8:$T$15,0))) -> 869500 | F15: =IF($A15="","",INDEX(Opportunities!$H$8:$H$15,MATCH($A15,Opportunities!$T$8:$T$15,0))) -> 12 | G15: =IF($A15="","",INDEX(Opportunities!$R$8:$R$15,MATCH($A15,Opportunities!$T$8:$T$15,0))) -> -103155.23 | H15: =IF($A15="","",INDEX(Opportunities!$M$8:$M$15,MATCH($A15,Opportunities!$T$8:$T$15,0))) -> DEMO PASS | I15: =IF($A15="","",IF(INDEX(Opportunities!$U$8:$U$15,MATCH($A15,Opportunities!$T$8:$T$15,0))=1,"SELECTED","WATCHLIST")) -> SELECTED
A16: =IF(2<=COUNTIF(Opportunities!$S$8:$S$15,"ELIGIBLE"),2,"") -> 2 | B16: =IF($A16="","",INDEX(Opportunities!$B$8:$B$15,MATCH($A16,Opportunities!$T$8:$T$15,0))) -> Illustrative renovation B | C16: =IF($A16="","",INDEX(Opportunities!$P$8:$P$15,MATCH($A16,Opportunities!$T$8:$T$15,0))) -> 76128.402 | D16: =IF($A16="","",INDEX(Opportunities!$Q$8:$Q$15,MATCH($A16,Opportunities!$T$8:$T$15,0))) -> 0.10690125 | E16: =IF($A16="","",INDEX(Opportunities!$L$8:$L$15,MATCH($A16,Opportunities!$T$8:$T$15,0))) -> 585000 | F16: =IF($A16="","",INDEX(Opportunities!$H$8:$H$15,MATCH($A16,Opportunities!$T$8:$T$15,0))) -> 6 | G16: =IF($A16="","",INDEX(Opportunities!$R$8:$R$15,MATCH($A16,Opportunities!$T$8:$T$15,0))) -> -55582.705 | H16: =IF($A16="","",INDEX(Opportunities!$M$8:$M$15,MATCH($A16,Opportunities!$T$8:$T$15,0))) -> DEMO PASS | I16: =IF($A16="","",IF(INDEX(Opportunities!$U$8:$U$15,MATCH($A16,Opportunities!$T$8:$T$15,0))=1,"SELECTED","WATCHLIST")) -> SELECTED
A17: =IF(3<=COUNTIF(Opportunities!$S$8:$S$15,"ELIGIBLE"),3,"") -> 3 | B17: =IF($A17="","",INDEX(Opportunities!$B$8:$B$15,MATCH($A17,Opportunities!$T$8:$T$15,0))) -> Illustrative new build C | C17: =IF($A17="","",INDEX(Opportunities!$P$8:$P$15,MATCH($A17,Opportunities!$T$8:$T$15,0))) -> 54783.715 | D17: =IF($A17="","",INDEX(Opportunities!$Q$8:$Q$15,MATCH($A17,Opportunities!$T$8:$T$15,0))) -> 0.094246244 | E17: =IF($A17="","",INDEX(Opportunities!$L$8:$L$15,MATCH($A17,Opportunities!$T$8:$T$15,0))) -> 1581000 | F17: =IF($A17="","",INDEX(Opportunities!$H$8:$H$15,MATCH($A17,Opportunities!$T$8:$T$15,0))) -> 30 | G17: =IF($A17="","",INDEX(Opportunities!$R$8:$R$15,MATCH($A17,Opportunities!$T$8:$T$15,0))) -> -325708.62 | H17: =IF($A17="","",INDEX(Opportunities!$M$8:$M$15,MATCH($A17,Opportunities!$T$8:$T$15,0))) -> DEMO PASS | I17: =IF($A17="","",IF(INDEX(Opportunities!$U$8:$U$15,MATCH($A17,Opportunities!$T$8:$T$15,0))=1,"SELECTED","WATCHLIST")) -> WATCHLIST
A18: =IF(4<=COUNTIF(Opportunities!$S$8:$S$15,"ELIGIBLE"),4,"") -> 4 | B18: =IF($A18="","",INDEX(Opportunities!$B$8:$B$15,MATCH($A18,Opportunities!$T$8:$T$15,0))) -> Illustrative small asset D | C18: =IF($A18="","",INDEX(Opportunities!$P$8:$P$15,MATCH($A18,Opportunities!$T$8:$T$15,0))) -> 21888.123 | D18: =IF($A18="","",INDEX(Opportunities!$Q$8:$Q$15,MATCH($A18,Opportunities!$T$8:$T$15,0))) -> 0.09882353 | E18: =IF($A18="","",INDEX(Opportunities!$L$8:$L$15,MATCH($A18,Opportunities!$T$8:$T$15,0))) -> 332250 | F18: =IF($A18="","",INDEX(Opportunities!$H$8:$H$15,MATCH($A18,Opportunities!$T$8:$T$15,0))) -> 4 | G18: =IF($A18="","",INDEX(Opportunities!$R$8:$R$15,MATCH($A18,Opportunities!$T$8:$T$15,0))) -> -50757.491 | H18: =IF($A18="","",INDEX(Opportunities!$M$8:$M$15,MATCH($A18,Opportunities!$T$8:$T$15,0))) -> DEMO PASS | I18: =IF($A18="","",IF(INDEX(Opportunities!$U$8:$U$15,MATCH($A18,Opportunities!$T$8:$T$15,0))=1,"SELECTED","WATCHLIST")) -> SELECTED
A19: =IF(5<=COUNTIF(Opportunities!$S$8:$S$15,"ELIGIBLE"),5,"") | B19: =IF($A19="","",INDEX(Opportunities!$B$8:$B$15,MATCH($A19,Opportunities!$T$8:$T$15,0))) | C19: =IF($A19="","",INDEX(Opportunities!$P$8:$P$15,MATCH($A19,Opportunities!$T$8:$T$15,0))) | D19: =IF($A19="","",INDEX(Opportunities!$Q$8:$Q$15,MATCH($A19,Opportunities!$T$8:$T$15,0))) | E19: =IF($A19="","",INDEX(Opportunities!$L$8:$L$15,MATCH($A19,Opportunities!$T$8:$T$15,0))) | F19: =IF($A19="","",INDEX(Opportunities!$H$8:$H$15,MATCH($A19,Opportunities!$T$8:$T$15,0))) | G19: =IF($A19="","",INDEX(Opportunities!$R$8:$R$15,MATCH($A19,Opportunities!$T$8:$T$15,0))) | H19: =IF($A19="","",INDEX(Opportunities!$M$8:$M$15,MATCH($A19,Opportunities!$T$8:$T$15,0))) | I19: =IF($A19="","",IF(INDEX(Opportunities!$U$8:$U$15,MATCH($A19,Opportunities!$T$8:$T$15,0))=1,"SELECTED","WATCHLIST"))
A20: =IF(6<=COUNTIF(Opportunities!$S$8:$S$15,"ELIGIBLE"),6,"") | B20: =IF($A20="","",INDEX(Opportunities!$B$8:$B$15,MATCH($A20,Opportunities!$T$8:$T$15,0))) | C20: =IF($A20="","",INDEX(Opportunities!$P$8:$P$15,MATCH($A20,Opportunities!$T$8:$T$15,0))) | D20: =IF($A20="","",INDEX(Opportunities!$Q$8:$Q$15,MATCH($A20,Opportunities!$T$8:$T$15,0))) | E20: =IF($A20="","",INDEX(Opportunities!$L$8:$L$15,MATCH($A20,Opportunities!$T$8:$T$15,0))) | F20: =IF($A20="","",INDEX(Opportunities!$H$8:$H$15,MATCH($A20,Opportunities!$T$8:$T$15,0))) | G20: =IF($A20="","",INDEX(Opportunities!$R$8:$R$15,MATCH($A20,Opportunities!$T$8:$T$15,0))) | H20: =IF($A20="","",INDEX(Opportunities!$M$8:$M$15,MATCH($A20,Opportunities!$T$8:$T$15,0))) | I20: =IF($A20="","",IF(INDEX(Opportunities!$U$8:$U$15,MATCH($A20,Opportunities!$T$8:$T$15,0))=1,"SELECTED","WATCHLIST"))
A21: =IF(7<=COUNTIF(Opportunities!$S$8:$S$15,"ELIGIBLE"),7,"") | B21: =IF($A21="","",INDEX(Opportunities!$B$8:$B$15,MATCH($A21,Opportunities!$T$8:$T$15,0))) | C21: =IF($A21="","",INDEX(Opportunities!$P$8:$P$15,MATCH($A21,Opportunities!$T$8:$T$15,0))) | D21: =IF($A21="","",INDEX(Opportunities!$Q$8:$Q$15,MATCH($A21,Opportunities!$T$8:$T$15,0))) | E21: =IF($A21="","",INDEX(Opportunities!$L$8:$L$15,MATCH($A21,Opportunities!$T$8:$T$15,0))) | F21: =IF($A21="","",INDEX(Opportunities!$H$8:$H$15,MATCH($A21,Opportunities!$T$8:$T$15,0))) | G21: =IF($A21="","",INDEX(Opportunities!$R$8:$R$15,MATCH($A21,Opportunities!$T$8:$T$15,0))) | H21: =IF($A21="","",INDEX(Opportunities!$M$8:$M$15,MATCH($A21,Opportunities!$T$8:$T$15,0))) | I21: =IF($A21="","",IF(INDEX(Opportunities!$U$8:$U$15,MATCH($A21,Opportunities!$T$8:$T$15,0))=1,"SELECTED","WATCHLIST"))
A22: =IF(8<=COUNTIF(Opportunities!$S$8:$S$15,"ELIGIBLE"),8,"") | B22: =IF($A22="","",INDEX(Opportunities!$B$8:$B$15,MATCH($A22,Opportunities!$T$8:$T$15,0))) | C22: =IF($A22="","",INDEX(Opportunities!$P$8:$P$15,MATCH($A22,Opportunities!$T$8:$T$15,0))) | D22: =IF($A22="","",INDEX(Opportunities!$Q$8:$Q$15,MATCH($A22,Opportunities!$T$8:$T$15,0))) | E22: =IF($A22="","",INDEX(Opportunities!$L$8:$L$15,MATCH($A22,Opportunities!$T$8:$T$15,0))) | F22: =IF($A22="","",INDEX(Opportunities!$H$8:$H$15,MATCH($A22,Opportunities!$T$8:$T$15,0))) | G22: =IF($A22="","",INDEX(Opportunities!$R$8:$R$15,MATCH($A22,Opportunities!$T$8:$T$15,0))) | H22: =IF($A22="","",INDEX(Opportunities!$M$8:$M$15,MATCH($A22,Opportunities!$T$8:$T$15,0))) | I22: =IF($A22="","",IF(INDEX(Opportunities!$U$8:$U$15,MATCH($A22,Opportunities!$T$8:$T$15,0))=1,"SELECTED","WATCHLIST"))
A25: Report inclusion policy
A26: Shortlist shows eligible positive-NPV investments in descending NPV order. Exclusions and raw inputs remain in Opportunities for audit. Portfolio selection respects budget and project count.
A28: Key risks
A29: Rent and occupancy, construction overrun, permit delay, terminal valuation and legal compliance. Downside is a sensitivity, not a probability forecast.
A31: Scope
A32: No source spreadsheet was supplied. Examples are fictional. NPV measures discounted profit; IRR is supplemental. Financing and investor-specific taxes are excluded.
A34: Excluded / incomplete opportunities | B34: =COUNTIF(Opportunities!S8:S15,"EXCLUDE") -> 2
A35: Portfolio downside NPV | B35: =Opportunities!U8*Opportunities!R8+Opportunities!U9*Opportunities!R9+Opportunities!U10*Opportunities!R10+Opportunities!U11*Opportunities!R11+Opportunities!U12*Opportunities!R12+Opportunities!U13*Opportunities!R13+Opportunities!U14*Opportunities!R14+Opportunities!U15*Opportunities!R15 -> -209495.43
A36: Undiscounted portfolio profit | B36: =Opportunities!U8*SUM('Cash flows'!B5:L5)+Opportunities!U9*SUM('Cash flows'!B6:L6)+Opportunities!U10*SUM('Cash flows'!B7:L7)+Opportunities!U11*SUM('Cash flows'!B8:L8)+Opportunities!U12*SUM('Cash flows'!B9:L9)+Opportunities!U13*SUM('Cash flows'!B10:L10)+Opportunities!U14*SUM('Cash flows'!B11:L11)+Opportunities!U15*SUM('Cash flows'!B12:L12) -> 2296579.6
A38: Independent analysis • Institutional report format • No affiliation with Vanguard.

Sheet Guide
A1: How to use this workbook
A2: Editable blue cells • formula-driven analysis • no macros or external links
A4: Step | B4: Instruction
A5: 1. Import | B5: Replace the eight input rows in Opportunities with the supplied spreadsheet. Preserve calculated columns L:U.
A6: 2. Set assumptions | B6: Change budget, required return, delay limit and scenario assumptions. The horizon is fixed at ten years.
A7: 3. Validate compliance | B7: Replace Demo pass by Verified / Unknown / Fail, and cite actual evidence in each evidence row. Switch Demo mode to NO for real evaluation.
A8: 4. Review | B8: Shortlist ranks eligible assets by NPV. Exact enumeration selects the best subset; excluded assets remain in Opportunities.
A9: 5. Rank | B9: Rank uses descending base NPV; ties are resolved by input row order. Portfolio selection maximizes aggregate NPV.
A10: Method | B10: Acquisition plus contingency capital is committed immediately. Rent and operating cost inflation use the same rate; operating costs begin at rental readiness.
A11: Limitations | B11: Annual timing is approximate. Add pre-opening carrying costs to Other capital costs. No leverage, tax, capex phasing or replacement capex is modeled.
A12: Capacity | B12: The model supports exactly eight projects; enumeration covers every subset, including retaining all capital.
A13: Saving | B13: Run python3 build_model.py to rebuild the template. This overwrites user edits; retain a copy before rerunning.
A14: Source status | B14: See Sources for 2026 official requirements. Verify every room and shared facility; project-wide Verified means all spaces passed, with linked evidence.

Sheet Assumptions
A1: Investment assumptions
A2: Blue cells are editable. Unlevered, pre-tax EUR model; all capital committed at time zero.
A4: Parameter | B4: Value | C4: Interpretation
A5: Demo mode (YES / NO) | B5: YES | C5: YES accepts hypothetical demonstration checks; NO requires Verified evidence.
A6: Available capital | B6: 2000000 | C6: EUR; includes all-in acquisition and construction costs
A7: Maximum projects | B7: 3 | C7: Portfolio cap; eight opportunity slots
A8: Discount rate | B8: 0.09 | C8: Required annual unlevered return
A9: Holding period (years) | B9: 10 | C9: Fixed 10 years; cash flow grid is ten years
A10: Annual rent growth | B10: 0.02 | C10: Applied to base rent from acquisition date
A11: Exit capitalization rate | B11: 0.055 | C11: Year 11 stabilized NOI / cap rate
A12: Exit selling costs | B12: 0.03 | C12: Fraction of exit value
A13: Acquisition costs | B13: 0.14 | C13: Planning estimate; replace with transaction-specific tax/legal fees
A14: Construction contingency | B14: 0.15 | C14: Fraction of base renovation budget
A15: Stress rent reduction | B15: 0.1 | C15: Rent haircut for downside case
A16: Stress delay (months) | B16: 6 | C16: Additional delay in downside case
A17: Stress construction uplift | B17: 0.2 | C17: Applied on top of contingency
A18: Maximum acceptable delay | B18: 36 | C18: Months from acquisition to legal rental readiness

Sheet Opportunities
A1: Opportunity universe | eight investment slots
A2: HYPOTHETICAL EXAMPLES ONLY. Replace with your spreadsheet data; no Brussels properties have been sourced.
A7: ID | B7: Project / location | C7: Rooms | D7: Monthly rent / room | E7: Purchase price | F7: Base construction cost | G7: Other capital costs | H7: Months to ready | I7: Occupancy | J7: Operating cost / revenue | K7: Annual fixed costs | L7: All-in capital | M7: Compliance gate | N7: Year 1 NOI | O7: Year 11 NOI | P7: Base NPV | Q7: Base IRR | R7: Downside NPV | S7: Decision | T7: Rank | U7: Portfolio selected
A8: DEMO01 | B8: Illustrative conversion A | C8: 14 | D8: 640 | E8: 500000 | F8: 230000 | G8: 35000 | H8: 12 | I8: 0.95 | J8: 0.24 | K8: 14000 | L8: =IF(B8="",0,E8*(1+Assumptions!$B$13)+F8*(1+Assumptions!$B$14)+G8) -> 869500 | M8: =IF(B8="","EMPTY",IF(COUNTIF(Compliance!D5:D16,"Fail")>0,"FAIL",IF(AND(COUNTIF(Compliance!D5:D16,"Verified")=12,COUNTBLANK(Compliance!E5:E16)=0),"PASS",IF(AND(Assumptions!$B$5="YES",COUNTIF(Compliance!D5:D16,"Demo pass")=12),"DEMO PASS","UNVERIFIED")))) -> DEMO PASS | N8: ='Cash flows'!C5 -> 0 | O8: =C8*D8*12*I8*(1-J8)*(1+Assumptions!$B$10)^10-K8*(1+Assumptions!$B$10)^10 -> 77563.932 | P8: =NPV(Assumptions!$B$8,'Cash flows'!C5:L5)+'Cash flows'!B5 -> 90896.517 | Q8: =IFERROR(IRR('Cash flows'!B5:L5),0) -> 0.10331943 | R8: =NPV(Assumptions!$B$8,'Cash flows'!C18:L18)+'Cash flows'!B18 -> -103155.23 | S8: =IF(B8="","EMPTY",IF(AND(OR(M8="PASS",M8="DEMO PASS"),H8<=Assumptions!$B$18,C8>0,D8>0,E8>0,H8>=0,I8>0,I8<=1,J8>=0,J8<1,F8>=0,G8>=0,K8>=0,P8>0),"ELIGIBLE","EXCLUDE")) -> ELIGIBLE | T8: =IF(S8="ELIGIBLE",1+COUNTIFS($S$8:$S$15,"ELIGIBLE",$P$8:$P$15,">"&P8)+COUNTIFS($S$8:S8,"ELIGIBLE",$P$8:P8,P8)-1,"") -> 1 | U8: =INDEX(Portfolio!B$5:B$260,Report!$B$7) -> 1
A9: DEMO02 | B9: Illustrative renovation B | C9: 10 | D9: 620 | E9: 350000 | F9: 140000 | G9: 25000 | H9: 6 | I9: 0.95 | J9: 0.25 | K9: 10500 | L9: =IF(B9="",0,E9*(1+Assumptions!$B$13)+F9*(1+Assumptions!$B$14)+G9) -> 585000 | M9: =IF(B9="","EMPTY",IF(COUNTIF(Compliance!D17:D28,"Fail")>0,"FAIL",IF(AND(COUNTIF(Compliance!D17:D28,"Verified")=12,COUNTBLANK(Compliance!E17:E28)=0),"PASS",IF(AND(Assumptions!$B$5="YES",COUNTIF(Compliance!D17:D28,"Demo pass")=12),"DEMO PASS","UNVERIFIED")))) -> DEMO PASS | N9: ='Cash flows'!C6 -> 21255 | O9: =C9*D9*12*I9*(1-J9)*(1+Assumptions!$B$10)^10-K9*(1+Assumptions!$B$10)^10 -> 51819.453 | P9: =NPV(Assumptions!$B$8,'Cash flows'!C6:L6)+'Cash flows'!B6 -> 76128.402 | Q9: =IFERROR(IRR('Cash flows'!B6:L6),0) -> 0.10690125 | R9: =NPV(Assumptions!$B$8,'Cash flows'!C19:L19)+'Cash flows'!B19 -> -55582.705 | S9: =IF(B9="","EMPTY",IF(AND(OR(M9="PASS",M9="DEMO PASS"),H9<=Assumptions!$B$18,C9>0,D9>0,E9>0,H9>=0,I9>0,I9<=1,J9>=0,J9<1,F9>=0,G9>=0,K9>=0,P9>0),"ELIGIBLE","EXCLUDE")) -> ELIGIBLE | T9: =IF(S9="ELIGIBLE",1+COUNTIFS($S$8:$S$15,"ELIGIBLE",$P$8:$P$15,">"&P9)+COUNTIFS($S$8:S9,"ELIGIBLE",$P$8:P9,P9)-1,"") -> 2 | U9: =INDEX(Portfolio!C$5:C$260,Report!$B$7) -> 1
A10: DEMO03 | B10: Illustrative new build C | C10: 24 | D10: 680 | E10: 700000 | F10: 620000 | G10: 70000 | H10: 30 | I10: 0.94 | J10: 0.23 | K10: 23500 | L10: =IF(B10="",0,E10*(1+Assumptions!$B$13)+F10*(1+Assumptions!$B$14)+G10) -> 1581000 | M10: =IF(B10="","EMPTY",IF(COUNTIF(Compliance!D29:D40,"Fail")>0,"FAIL",IF(AND(COUNTIF(Compliance!D29:D40,"Verified")=12,COUNTBLANK(Compliance!E29:E40)=0),"PASS",IF(AND(Assumptions!$B$5="YES",COUNTIF(Compliance!D29:D40,"Demo pass")=12),"DEMO PASS","UNVERIFIED")))) -> DEMO PASS | N10: ='Cash flows'!C7 -> 0 | O10: =C10*D10*12*I10*(1-J10)*(1+Assumptions!$B$10)^10-K10*(1+Assumptions!$B$10)^10 -> 144144.86 | P10: =NPV(Assumptions!$B$8,'Cash flows'!C7:L7)+'Cash flows'!B7 -> 54783.715 | Q10: =IFERROR(IRR('Cash flows'!B7:L7),0) -> 0.094246244 | R10: =NPV(Assumptions!$B$8,'Cash flows'!C20:L20)+'Cash flows'!B20 -> -325708.62 | S10: =IF(B10="","EMPTY",IF(AND(OR(M10="PASS",M10="DEMO PASS"),H10<=Assumptions!$B$18,C10>0,D10>0,E10>0,H10>=0,I10>0,I10<=1,J10>=0,J10<1,F10>=0,G10>=0,K10>=0,P10>0),"ELIGIBLE","EXCLUDE")) -> ELIGIBLE | T10: =IF(S10="ELIGIBLE",1+COUNTIFS($S$8:$S$15,"ELIGIBLE",$P$8:$P$15,">"&P10)+COUNTIFS($S$8:S10,"ELIGIBLE",$P$8:P10,P10)-1,"") -> 3 | U10: =INDEX(Portfolio!D$5:D$260,Report!$B$7) -> 0
A11: DEMO04 | B11: Illustrative small asset D | C11: 6 | D11: 590 | E11: 200000 | F11: 75000 | G11: 18000 | H11: 4 | I11: 0.94 | J11: 0.26 | K11: 7000 | L11: =IF(B11="",0,E11*(1+Assumptions!$B$13)+F11*(1+Assumptions!$B$14)+G11) -> 332250 | M11: =IF(B11="","EMPTY",IF(COUNTIF(Compliance!D41:D52,"Fail")>0,"FAIL",IF(AND(COUNTIF(Compliance!D41:D52,"Verified")=12,COUNTBLANK(Compliance!E41:E52)=0),"PASS",IF(AND(Assumptions!$B$5="YES",COUNTIF(Compliance!D41:D52,"Demo pass")=12),"DEMO PASS","UNVERIFIED")))) -> DEMO PASS | N11: ='Cash flows'!C8 -> 15032.725 | O11: =C11*D11*12*I11*(1-J11)*(1+Assumptions!$B$10)^10-K11*(1+Assumptions!$B$10)^10 -> 27487.212 | P11: =NPV(Assumptions!$B$8,'Cash flows'!C8:L8)+'Cash flows'!B8 -> 21888.123 | Q11: =IFERROR(IRR('Cash flows'!B8:L8),0) -> 0.09882353 | R11: =NPV(Assumptions!$B$8,'Cash flows'!C21:L21)+'Cash flows'!B21 -> -50757.491 | S11: =IF(B11="","EMPTY",IF(AND(OR(M11="PASS",M11="DEMO PASS"),H11<=Assumptions!$B$18,C11>0,D11>0,E11>0,H11>=0,I11>0,I11<=1,J11>=0,J11<1,F11>=0,G11>=0,K11>=0,P11>0),"ELIGIBLE","EXCLUDE")) -> ELIGIBLE | T11: =IF(S11="ELIGIBLE",1+COUNTIFS($S$8:$S$15,"ELIGIBLE",$P$8:$P$15,">"&P11)+COUNTIFS($S$8:S11,"ELIGIBLE",$P$8:P11,P11)-1,"") -> 4 | U11: =INDEX(Portfolio!E$5:E$260,Report!$B$7) -> 1
A12: DEMO05 | B12: Illustrative delayed asset E | C12: 16 | D12: 650 | E12: 600000 | F12: 360000 | G12: 45000 | H12: 42 | I12: 0.95 | J12: 0.24 | K12: 16000 | L12: =IF(B12="",0,E12*(1+Assumptions!$B$13)+F12*(1+Assumptions!$B$14)+G12) -> 1143000 | M12: =IF(B12="","EMPTY",IF(COUNTIF(Compliance!D53:D64,"Fail")>0,"FAIL",IF(AND(COUNTIF(Compliance!D53:D64,"Verified")=12,COUNTBLANK(Compliance!E53:E64)=0),"PASS",IF(AND(Assumptions!$B$5="YES",COUNTIF(Compliance!D53:D64,"Demo pass")=12),"DEMO PASS","UNVERIFIED")))) -> DEMO PASS | N12: ='Cash flows'!C9 -> 0 | O12: =C12*D12*12*I12*(1-J12)*(1+Assumptions!$B$10)^10-K12*(1+Assumptions!$B$10)^10 -> 90334.313 | P12: =NPV(Assumptions!$B$8,'Cash flows'!C9:L9)+'Cash flows'!B9 -> -175492.04 | Q12: =IFERROR(IRR('Cash flows'!B9:L9),0) -> 0.070241327 | R12: =NPV(Assumptions!$B$8,'Cash flows'!C22:L22)+'Cash flows'!B22 -> -400400.9 | S12: =IF(B12="","EMPTY",IF(AND(OR(M12="PASS",M12="DEMO PASS"),H12<=Assumptions!$B$18,C12>0,D12>0,E12>0,H12>=0,I12>0,I12<=1,J12>=0,J12<1,F12>=0,G12>=0,K12>=0,P12>0),"ELIGIBLE","EXCLUDE")) -> EXCLUDE | T12: =IF(S12="ELIGIBLE",1+COUNTIFS($S$8:$S$15,"ELIGIBLE",$P$8:$P$15,">"&P12)+COUNTIFS($S$8:S12,"ELIGIBLE",$P$8:P12,P12)-1,"") | U12: =INDEX(Portfolio!F$5:F$260,Report!$B$7) -> 0
A13: DEMO06 | B13: Illustrative compliance failure F | C13: 12 | D13: 660 | E13: 500000 | F13: 175000 | G13: 28000 | H13: 8 | I13: 0.95 | J13: 0.24 | K13: 12000 | L13: =IF(B13="",0,E13*(1+Assumptions!$B$13)+F13*(1+Assumptions!$B$14)+G13) -> 799250 | M13: =IF(B13="","EMPTY",IF(COUNTIF(Compliance!D65:D76,"Fail")>0,"FAIL",IF(AND(COUNTIF(Compliance!D65:D76,"Verified")=12,COUNTBLANK(Compliance!E65:E76)=0),"PASS",IF(AND(Assumptions!$B$5="YES",COUNTIF(Compliance!D65:D76,"Demo pass")=12),"DEMO PASS","UNVERIFIED")))) -> FAIL | N13: ='Cash flows'!C10 -> 18872.96 | O13: =C13*D13*12*I13*(1-J13)*(1+Assumptions!$B$10)^10-K13*(1+Assumptions!$B$10)^10 -> 69018.099 | P13: =NPV(Assumptions!$B$8,'Cash flows'!C10:L10)+'Cash flows'!B10 -> 72646.659 | Q13: =IFERROR(IRR('Cash flows'!B10:L10),0) -> 0.10185409 | R13: =NPV(Assumptions!$B$8,'Cash flows'!C23:L23)+'Cash flows'!B23 -> -95607.999 | S13: =IF(B13="","EMPTY",IF(AND(OR(M13="PASS",M13="DEMO PASS"),H13<=Assumptions!$B$18,C13>0,D13>0,E13>0,H13>=0,I13>0,I13<=1,J13>=0,J13<1,F13>=0,G13>=0,K13>=0,P13>0),"ELIGIBLE","EXCLUDE")) -> EXCLUDE | T13: =IF(S13="ELIGIBLE",1+COUNTIFS($S$8:$S$15,"ELIGIBLE",$P$8:$P$15,">"&P13)+COUNTIFS($S$8:S13,"ELIGIBLE",$P$8:P13,P13)-1,"") | U13: =INDEX(Portfolio!G$5:G$260,Report!$B$7) -> 0
A14: SLOT7 | C14: 0 | D14: 0 | E14: 0 | F14: 0 | G14: 0 | H14: 0 | I14: 0.95 | J14: 0.25 | K14: 0 | L14: =IF(B14="",0,E14*(1+Assumptions!$B$13)+F14*(1+Assumptions!$B$14)+G14) -> 0 | M14: =IF(B14="","EMPTY",IF(COUNTIF(Compliance!D77:D88,"Fail")>0,"FAIL",IF(AND(COUNTIF(Compliance!D77:D88,"Verified")=12,COUNTBLANK(Compliance!E77:E88)=0),"PASS",IF(AND(Assumptions!$B$5="YES",COUNTIF(Compliance!D77:D88,"Demo pass")=12),"DEMO PASS","UNVERIFIED")))) -> EMPTY | N14: ='Cash flows'!C11 -> 0 | O14: =C14*D14*12*I14*(1-J14)*(1+Assumptions!$B$10)^10-K14*(1+Assumptions!$B$10)^10 -> 0 | P14: =NPV(Assumptions!$B$8,'Cash flows'!C11:L11)+'Cash flows'!B11 -> 0 | Q14: =IFERROR(IRR('Cash flows'!B11:L11),0) -> 0 | R14: =NPV(Assumptions!$B$8,'Cash flows'!C24:L24)+'Cash flows'!B24 -> 0 | S14: =IF(B14="","EMPTY",IF(AND(OR(M14="PASS",M14="DEMO PASS"),H14<=Assumptions!$B$18,C14>0,D14>0,E14>0,H14>=0,I14>0,I14<=1,J14>=0,J14<1,F14>=0,G14>=0,K14>=0,P14>0),"ELIGIBLE","EXCLUDE")) -> EMPTY | T14: =IF(S14="ELIGIBLE",1+COUNTIFS($S$8:$S$15,"ELIGIBLE",$P$8:$P$15,">"&P14)+COUNTIFS($S$8:S14,"ELIGIBLE",$P$8:P14,P14)-1,"") | U14: =INDEX(Portfolio!H$5:H$260,Report!$B$7) -> 0
A15: SLOT8 | C15: 0 | D15: 0 | E15: 0 | F15: 0 | G15: 0 | H15: 0 | I15: 0.95 | J15: 0.25 | K15: 0 | L15: =IF(B15="",0,E15*(1+Assumptions!$B$13)+F15*(1+Assumptions!$B$14)+G15) -> 0 | M15: =IF(B15="","EMPTY",IF(COUNTIF(Compliance!D89:D100,"Fail")>0,"FAIL",IF(AND(COUNTIF(Compliance!D89:D100,"Verified")=12,COUNTBLANK(Compliance!E89:E100)=0),"PASS",IF(AND(Assumptions!$B$5="YES",COUNTIF(Compliance!D89:D100,"Demo pass")=12),"DEMO PASS","UNVERIFIED")))) -> EMPTY | N15: ='Cash flows'!C12 -> 0 | O15: =C15*D15*12*I15*(1-J15)*(1+Assumptions!$B$10)^10-K15*(1+Assumptions!$B$10)^10 -> 0 | P15: =NPV(Assumptions!$B$8,'Cash flows'!C12:L12)+'Cash flows'!B12 -> 0 | Q15: =IFERROR(IRR('Cash flows'!B12:L12),0) -> 0 | R15: =NPV(Assumptions!$B$8,'Cash flows'!C25:L25)+'Cash flows'!B25 -> 0 | S15: =IF(B15="","EMPTY",IF(AND(OR(M15="PASS",M15="DEMO PASS"),H15<=Assumptions!$B$18,C15>0,D15>0,E15>0,H15>=0,I15>0,I15<=1,J15>=0,J15<1,F15>=0,G15>=0,K15>=0,P15>0),"ELIGIBLE","EXCLUDE")) -> EMPTY | T15: =IF(S15="ELIGIBLE",1+COUNTIFS($S$8:$S$15,"ELIGIBLE",$P$8:$P$15,">"&P15)+COUNTIFS($S$8:S15,"ELIGIBLE",$P$8:P15,P15)-1,"") | U15: =INDEX(Portfolio!I$5:I$260,Report!$B$7) -> 0

Sheet Compliance
A1: Mandatory requirements | project evidence register
A2: Unknown evidence blocks eligibility. Demo pass is permitted only in explicit demonstration mode.
A4: ID | B4: Control | C4: Minimum / validation needed | D4: Status | E4: Evidence / authority / date
A5: DEMO01 | B5: Planning use | C5: Written confirmation that student housing use and works are lawful | D5: Demo pass | E5: Illustrative only — no evidence
A6: DEMO01 | B6: Rental authorization | C6: Check required planning/letting approvals; DIRL clearance required after a letting prohibition. Ordinary voluntary conformity certificate and quality label are not universal prerequisites. Source S3/S4. | D6: Demo pass | E6: Illustrative only — no evidence
A7: DEMO01 | B7: Minimum room area | C7: Student accommodation: 12 m² for one resident; 18 m² for two. Shared area counted pro rata. Validate legal classification, habitable share and height. Source S2, art. 4. | D7: Demo pass | E7: Illustrative only — no evidence
A8: DEMO01 | B8: Occupancy limits | C8: Shared WC and shower: maximum six users each; kitchen sink and four-ring hob: maximum eight users. Use contractual maximum occupancy. Source S2, art. 5. | D8: Demo pass | E8: Illustrative only — no evidence
A9: DEMO01 | B9: Sanitation | C9: Bath/shower with hot water and drainage; shared facilities accessible and lockable. Source S2, art. 5. | D9: Demo pass | E9: Illustrative only — no evidence
A10: DEMO01 | B10: Kitchen / cooking | C10: Operational cooking equipment in communal kitchen; suitable supply. Source S2, art. 5. | D10: Demo pass | E10: Illustrative only — no evidence
A11: DEMO01 | B11: Daylight / ventilation | C11: Daylight and permanent base ventilation; verify windows, airflow and configuration against S2, art. 3. | D11: Demo pass | E11: Illustrative only — no evidence
A12: DEMO01 | B12: Electrical / gas safety | C12: Safe electrical/gas installation; no type B gas heater in bedroom. Source S1/S2. | D12: Demo pass | E12: Illustrative only — no evidence
A13: DEMO01 | B13: Fire safety | C13: Fire authority requirements, escape routes and detection | D13: Demo pass | E13: Illustrative only — no evidence
A14: DEMO01 | B14: Water / heating / moisture | C14: Water, installed heating, dry structure, sound drainage and no harmful infestation; source S2, arts. 2–5. | D14: Demo pass | E14: Illustrative only — no evidence
A15: DEMO01 | B15: Energy certification | C15: Applicable PEB certificate and required disclosures | D15: Demo pass | E15: Illustrative only — no evidence
... A76: DEMO06 | B76: Accessibility / other rules | C76: Verify access, ceiling heights, structure, mailbox and doorbell, and all case-specific rules. Source S2; confirm municipal requirements. | D76: Unknown | E76: Illustrative only — no evidence
A77: SLOT7 | B77: Planning use | C77: Written confirmation that student housing use and works are lawful | D77: Unknown
A78: SLOT7 | B78: Rental authorization | C78: Check required planning/letting approvals; DIRL clearance required after a letting prohibition. Ordinary voluntary conformity certificate and quality label are not universal prerequisites. Source S3/S4. | D78: Unknown
A79: SLOT7 | B79: Minimum room area | C79: Student accommodation: 12 m² for one resident; 18 m² for two. Shared area counted pro rata. Validate legal classification, habitable share and height. Source S2, art. 4. | D79: Unknown
A80: SLOT7 | B80: Occupancy limits | C80: Shared WC and shower: maximum six users each; kitchen sink and four-ring hob: maximum eight users. Use contractual maximum occupancy. Source S2, art. 5. | D80: Unknown
A81: SLOT7 | B81: Sanitation | C81: Bath/shower with hot water and drainage; shared facilities accessible and lockable. Source S2, art. 5. | D81: Unknown
A82: SLOT7 | B82: Kitchen / cooking | C82: Operational cooking equipment in communal kitchen; suitable supply. Source S2, art. 5. | D82: Unknown
A83: SLOT7 | B83: Daylight / ventilation | C83: Daylight and permanent base ventilation; verify windows, airflow and configuration against S2, art. 3. | D83: Unknown
A84: SLOT7 | B84: Electrical / gas safety | C84: Safe electrical/gas installation; no type B gas heater in bedroom. Source S1/S2. | D84: Unknown
A85: SLOT7 | B85: Fire safety | C85: Fire authority requirements, escape routes and detection | D85: Unknown
A86: SLOT7 | B86: Water / heating / moisture | C86: Water, installed heating, dry structure, sound drainage and no harmful infestation; source S2, arts. 2–5. | D86: Unknown
A87: SLOT7 | B87: Energy certification | C87: Applicable PEB certificate and required disclosures | D87: Unknown
A88: SLOT7 | B88: Accessibility / other rules | C88: Verify access, ceiling heights, structure, mailbox and doorbell, and all case-specific rules. Source S2; confirm municipal requirements. | D88: Unknown
... A100: SLOT8 | B100: Accessibility / other rules | C100: Verify access, ceiling heights, structure, mailbox and doorbell, and all case-specific rules. Source S2; confirm municipal requirements. | D100: Unknown

Sheet Cash flows
A1: Ten-year cash flows | base and downside
A2: Annual approximation: delay reduces operating months. Capital paid at acquisition; terminal sale at year 10.
A4: Project | B4: Year 0 | C4: Year 1 | D4: Year 2 | E4: Year 3 | F4: Year 4 | G4: Year 5 | H4: Year 6 | I4: Year 7 | J4: Year 8 | K4: Year 9 | L4: Year 10
A5: =Opportunities!B8 -> Illustrative conversion A | B5: =-Opportunities!L8 -> -869500 | C5: =(Opportunities!C8*Opportunities!D8*12*Opportunities!I8*(1-Opportunities!J8)-Opportunities!K8)*(1+Assumptions!$B$10)^0*MAX(0,MIN(1,(1*12-(Opportunities!H8))/12)) -> 0 | D5: =(Opportunities!C8*Opportunities!D8*12*Opportunities!I8*(1-Opportunities!J8)-Opportunities!K8)*(1+Assumptions!$B$10)^1*MAX(0,MIN(1,(2*12-(Opportunities!H8))/12)) -> 64902.029 | E5: =(Opportunities!C8*Opportunities!D8*12*Opportunities!I8*(1-Opportunities!J8)-Opportunities!K8)*(1+Assumptions!$B$10)^2*MAX(0,MIN(1,(3*12-(Opportunities!H8))/12)) -> 66200.069 | F5: =(Opportunities!C8*Opportunities!D8*12*Opportunities!I8*(1-Opportunities!J8)-Opportunities!K8)*(1+Assumptions!$B$10)^3*MAX(0,MIN(1,(4*12-(Opportunities!H8))/12)) -> 67524.071 | G5: =(Opportunities!C8*Opportunities!D8*12*Opportunities!I8*(1-Opportunities!J8)-Opportunities!K8)*(1+Assumptions!$B$10)^4*MAX(0,MIN(1,(5*12-(Opportunities!H8))/12)) -> 68874.552 | H5: =(Opportunities!C8*Opportunities!D8*12*Opportunities!I8*(1-Opportunities!J8)-Opportunities!K8)*(1+Assumptions!$B$10)^5*MAX(0,MIN(1,(6*12-(Opportunities!H8))/12)) -> 70252.043 | I5: =(Opportunities!C8*Opportunities!D8*12*Opportunities!I8*(1-Opportunities!J8)-Opportunities!K8)*(1+Assumptions!$B$10)^6*MAX(0,MIN(1,(7*12-(Opportunities!H8))/12)) -> 71657.084 | J5: =(Opportunities!C8*Opportunities!D8*12*Opportunities!I8*(1-Opportunities!J8)-Opportunities!K8)*(1+Assumptions!$B$10)^7*MAX(0,MIN(1,(8*12-(Opportunities!H8))/12)) -> 73090.226 | K5: =(Opportunities!C8*Opportunities!D8*12*Opportunities!I8*(1-Opportunities!J8)-Opportunities!K8)*(1+Assumptions!$B$10)^8*MAX(0,MIN(1,(9*12-(Opportunities!H8))/12)) -> 74552.03 | L5: =(Opportunities!C8*Opportunities!D8*12*Opportunities!I8*(1-Opportunities!J8)-Opportunities!K8)*(1+Assumptions!$B$10)^9*MAX(0,MIN(1,(10*12-(Opportunities!H8))/12))+MAX(0,(Opportunities!O8)/Assumptions!$B$11)*(1-Assumptions!$B$12) -> 1443988.8
A6: =Opportunities!B9 -> Illustrative renovation B | B6: =-Opportunities!L9 -> -585000 | C6: =(Opportunities!C9*Opportunities!D9*12*Opportunities!I9*(1-Opportunities!J9)-Opportunities!K9)*(1+Assumptions!$B$10)^0*MAX(0,MIN(1,(1*12-(Opportunities!H9))/12)) -> 21255 | D6: =(Opportunities!C9*Opportunities!D9*12*Opportunities!I9*(1-Opportunities!J9)-Opportunities!K9)*(1+Assumptions!$B$10)^1*MAX(0,MIN(1,(2*12-(Opportunities!H9))/12)) -> 43360.2 | E6: =(Opportunities!C9*Opportunities!D9*12*Opportunities!I9*(1-Opportunities!J9)-Opportunities!K9)*(1+Assumptions!$B$10)^2*MAX(0,MIN(1,(3*12-(Opportunities!H9))/12)) -> 44227.404 | F6: =(Opportunities!C9*Opportunities!D9*12*Opportunities!I9*(1-Opportunities!J9)-Opportunities!K9)*(1+Assumptions!$B$10)^3*MAX(0,MIN(1,(4*12-(Opportunities!H9))/12)) -> 45111.952 | G6: =(Opportunities!C9*Opportunities!D9*12*Opportunities!I9*(1-Opportunities!J9)-Opportunities!K9)*(1+Assumptions!$B$10)^4*MAX(0,MIN(1,(5*12-(Opportunities!H9))/12)) -> 46014.191 | H6: =(Opportunities!C9*Opportunities!D9*12*Opportunities!I9*(1-Opportunities!J9)-Opportunities!K9)*(1+Assumptions!$B$10)^5*MAX(0,MIN(1,(6*12-(Opportunities!H9))/12)) -> 46934.475 | I6: =(Opportunities!C9*Opportunities!D9*12*Opportunities!I9*(1-Opportunities!J9)-Opportunities!K9)*(1+Assumptions!$B$10)^6*MAX(0,MIN(1,(7*12-(Opportunities!H9))/12)) -> 47873.164 | J6: =(Opportunities!C9*Opportunities!D9*12*Opportunities!I9*(1-Opportunities!J9)-Opportunities!K9)*(1+Assumptions!$B$10)^7*MAX(0,MIN(1,(8*12-(Opportunities!H9))/12)) -> 48830.628 | K6: =(Opportunities!C9*Opportunities!D9*12*Opportunities!I9*(1-Opportunities!J9)-Opportunities!K9)*(1+Assumptions!$B$10)^8*MAX(0,MIN(1,(9*12-(Opportunities!H9))/12)) -> 49807.24 | L6: =(Opportunities!C9*Opportunities!D9*12*Opportunities!I9*(1-Opportunities!J9)-Opportunities!K9)*(1+Assumptions!$B$10)^9*MAX(0,MIN(1,(10*12-(Opportunities!H9))/12))+MAX(0,(Opportunities!O9)/Assumptions!$B$11)*(1-Assumptions!$B$12) -> 964710.1
A7: =Opportunities!B10 -> Illustrative new build C | B7: =-Opportunities!L10 -> -1581000 | C7: =(Opportunities!C10*Opportunities!D10*12*Opportunities!I10*(1-Opportunities!J10)-Opportunities!K10)*(1+Assumptions!$B$10)^0*MAX(0,MIN(1,(1*12-(Opportunities!H10))/12)) -> 0 | D7: =(Opportunities!C10*Opportunities!D10*12*Opportunities!I10*(1-Opportunities!J10)-Opportunities!K10)*(1+Assumptions!$B$10)^1*MAX(0,MIN(1,(2*12-(Opportunities!H10))/12)) -> 0 | E7: =(Opportunities!C10*Opportunities!D10*12*Opportunities!I10*(1-Opportunities!J10)-Opportunities!K10)*(1+Assumptions!$B$10)^2*MAX(0,MIN(1,(3*12-(Opportunities!H10))/12)) -> 61513.126 | F7: =(Opportunities!C10*Opportunities!D10*12*Opportunities!I10*(1-Opportunities!J10)-Opportunities!K10)*(1+Assumptions!$B$10)^3*MAX(0,MIN(1,(4*12-(Opportunities!H10))/12)) -> 125486.78 | G7: =(Opportunities!C10*Opportunities!D10*12*Opportunities!I10*(1-Opportunities!J10)-Opportunities!K10)*(1+Assumptions!$B$10)^4*MAX(0,MIN(1,(5*12-(Opportunities!H10))/12)) -> 127996.51 | H7: =(Opportunities!C10*Opportunities!D10*12*Opportunities!I10*(1-Opportunities!J10)-Opportunities!K10)*(1+Assumptions!$B$10)^5*MAX(0,MIN(1,(6*12-(Opportunities!H10))/12)) -> 130556.44 | I7: =(Opportunities!C10*Opportunities!D10*12*Opportunities!I10*(1-Opportunities!J10)-Opportunities!K10)*(1+Assumptions!$B$10)^6*MAX(0,MIN(1,(7*12-(Opportunities!H10))/12)) -> 133167.57 | J7: =(Opportunities!C10*Opportunities!D10*12*Opportunities!I10*(1-Opportunities!J10)-Opportunities!K10)*(1+Assumptions!$B$10)^7*MAX(0,MIN(1,(8*12-(Opportunities!H10))/12)) -> 135830.92 | K7: =(Opportunities!C10*Opportunities!D10*12*Opportunities!I10*(1-Opportunities!J10)-Opportunities!K10)*(1+Assumptions!$B$10)^8*MAX(0,MIN(1,(9*12-(Opportunities!H10))/12)) -> 138547.54 | L7: =(Opportunities!C10*Opportunities!D10*12*Opportunities!I10*(1-Opportunities!J10)-Opportunities!K10)*(1+Assumptions!$B$10)^9*MAX(0,MIN(1,(10*12-(Opportunities!H10))/12))+MAX(0,(Opportunities!O10)/Assumptions!$B$11)*(1-Assumptions!$B$12) -> 2683509.7
A8: =Opportunities!B11 -> Illustrative small asset D | B8: =-Opportunities!L11 -> -332250 | C8: =(Opportunities!C11*Opportunities!D11*12*Opportunities!I11*(1-Opportunities!J11)-Opportunities!K11)*(1+Assumptions!$B$10)^0*MAX(0,MIN(1,(1*12-(Opportunities!H11))/12)) -> 15032.725 | D8: =(Opportunities!C11*Opportunities!D11*12*Opportunities!I11*(1-Opportunities!J11)-Opportunities!K11)*(1+Assumptions!$B$10)^1*MAX(0,MIN(1,(2*12-(Opportunities!H11))/12)) -> 23000.07 | E8: =(Opportunities!C11*Opportunities!D11*12*Opportunities!I11*(1-Opportunities!J11)-Opportunities!K11)*(1+Assumptions!$B$10)^2*MAX(0,MIN(1,(3*12-(Opportunities!H11))/12)) -> 23460.071 | F8: =(Opportunities!C11*Opportunities!D11*12*Opportunities!I11*(1-Opportunities!J11)-Opportunities!K11)*(1+Assumptions!$B$10)^3*MAX(0,MIN(1,(4*12-(Opportunities!H11))/12)) -> 23929.273 | G8: =(Opportunities!C11*Opportunities!D11*12*Opportunities!I11*(1-Opportunities!J11)-Opportunities!K11)*(1+Assumptions!$B$10)^4*MAX(0,MIN(1,(5*12-(Opportunities!H11))/12)) -> 24407.858 | H8: =(Opportunities!C11*Opportunities!D11*12*Opportunities!I11*(1-Opportunities!J11)-Opportunities!K11)*(1+Assumptions!$B$10)^5*MAX(0,MIN(1,(6*12-(Opportunities!H11))/12)) -> 24896.015 | I8: =(Opportunities!C11*Opportunities!D11*12*Opportunities!I11*(1-Opportunities!J11)-Opportunities!K11)*(1+Assumptions!$B$10)^6*MAX(0,MIN(1,(7*12-(Opportunities!H11))/12)) -> 25393.935 | J8: =(Opportunities!C11*Opportunities!D11*12*Opportunities!I11*(1-Opportunities!J11)-Opportunities!K11)*(1+Assumptions!$B$10)^7*MAX(0,MIN(1,(8*12-(Opportunities!H11))/12)) -> 25901.814 | K8: =(Opportunities!C11*Opportunities!D11*12*Opportunities!I11*(1-Opportunities!J11)-Opportunities!K11)*(1+Assumptions!$B$10)^8*MAX(0,MIN(1,(9*12-(Opportunities!H11))/12)) -> 26419.85 | L8: =(Opportunities!C11*Opportunities!D11*12*Opportunities!I11*(1-Opportunities!J11)-Opportunities!K11)*(1+Assumptions!$B$10)^9*MAX(0,MIN(1,(10*12-(Opportunities!H11))/12))+MAX(0,(Opportunities!O11)/Assumptions!$B$11)*(1-Assumptions!$B$12) -> 511722.72
A9: =Opportunities!B12 -> Illustrative delayed asset E | B9: =-Opportunities!L12 -> -1143000 | C9: =(Opportunities!C12*Opportunities!D12*12*Opportunities!I12*(1-Opportunities!J12)-Opportunities!K12)*(1+Assumptions!$B$10)^0*MAX(0,MIN(1,(1*12-(Opportunities!H12))/12)) -> 0 | D9: =(Opportunities!C12*Opportunities!D12*12*Opportunities!I12*(1-Opportunities!J12)-Opportunities!K12)*(1+Assumptions!$B$10)^1*MAX(0,MIN(1,(2*12-(Opportunities!H12))/12)) -> 0 | E9: =(Opportunities!C12*Opportunities!D12*12*Opportunities!I12*(1-Opportunities!J12)-Opportunities!K12)*(1+Assumptions!$B$10)^2*MAX(0,MIN(1,(3*12-(Opportunities!H12))/12)) -> 0 | F9: =(Opportunities!C12*Opportunities!D12*12*Opportunities!I12*(1-Opportunities!J12)-Opportunities!K12)*(1+Assumptions!$B$10)^3*MAX(0,MIN(1,(4*12-(Opportunities!H12))/12)) -> 39320.728 | G9: =(Opportunities!C12*Opportunities!D12*12*Opportunities!I12*(1-Opportunities!J12)-Opportunities!K12)*(1+Assumptions!$B$10)^4*MAX(0,MIN(1,(5*12-(Opportunities!H12))/12)) -> 80214.285 | H9: =(Opportunities!C12*Opportunities!D12*12*Opportunities!I12*(1-Opportunities!J12)-Opportunities!K12)*(1+Assumptions!$B$10)^5*MAX(0,MIN(1,(6*12-(Opportunities!H12))/12)) -> 81818.57 | I9: =(Opportunities!C12*Opportunities!D12*12*Opportunities!I12*(1-Opportunities!J12)-Opportunities!K12)*(1+Assumptions!$B$10)^6*MAX(0,MIN(1,(7*12-(Opportunities!H12))/12)) -> 83454.942 | J9: =(Opportunities!C12*Opportunities!D12*12*Opportunities!I12*(1-Opportunities!J12)-Opportunities!K12)*(1+Assumptions!$B$10)^7*MAX(0,MIN(1,(8*12-(Opportunities!H12))/12)) -> 85124.041 | K9: =(Opportunities!C12*Opportunities!D12*12*Opportunities!I12*(1-Opportunities!J12)-Opportunities!K12)*(1+Assumptions!$B$10)^8*MAX(0,MIN(1,(9*12-(Opportunities!H12))/12)) -> 86826.521 | L9: =(Opportunities!C12*Opportunities!D12*12*Opportunities!I12*(1-Opportunities!J12)-Opportunities!K12)*(1+Assumptions!$B$10)^9*MAX(0,MIN(1,(10*12-(Opportunities!H12))/12))+MAX(0,(Opportunities!O12)/Assumptions!$B$11)*(1-Assumptions!$B$12) -> 1681731.8
A10: =Opportunities!B13 -> Illustrative compliance failure F | B10: =-Opportunities!L13 -> -799250 | C10: =(Opportunities!C13*Opportunities!D13*12*Opportunities!I13*(1-Opportunities!J13)-Opportunities!K13)*(1+Assumptions!$B$10)^0*MAX(0,MIN(1,(1*12-(Opportunities!H13))/12)) -> 18872.96 | D10: =(Opportunities!C13*Opportunities!D13*12*Opportunities!I13*(1-Opportunities!J13)-Opportunities!K13)*(1+Assumptions!$B$10)^1*MAX(0,MIN(1,(2*12-(Opportunities!H13))/12)) -> 57751.258 | E10: =(Opportunities!C13*Opportunities!D13*12*Opportunities!I13*(1-Opportunities!J13)-Opportunities!K13)*(1+Assumptions!$B$10)^2*MAX(0,MIN(1,(3*12-(Opportunities!H13))/12)) -> 58906.283 | F10: =(Opportunities!C13*Opportunities!D13*12*Opportunities!I13*(1-Opportunities!J13)-Opportunities!K13)*(1+Assumptions!$B$10)^3*MAX(0,MIN(1,(4*12-(Opportunities!H13))/12)) -> 60084.408 | G10: =(Opportunities!C13*Opportunities!D13*12*Opportunities!I13*(1-Opportunities!J13)-Opportunities!K13)*(1+Assumptions!$B$10)^4*MAX(0,MIN(1,(5*12-(Opportunities!H13))/12)) -> 61286.097 | H10: =(Opportunities!C13*Opportunities!D13*12*Opportunities!I13*(1-Opportunities!J13)-Opportunities!K13)*(1+Assumptions!$B$10)^5*MAX(0,MIN(1,(6*12-(Opportunities!H13))/12)) -> 62511.819 | I10: =(Opportunities!C13*Opportunities!D13*12*Opportunities!I13*(1-Opportunities!J13)-Opportunities!K13)*(1+Assumptions!$B$10)^6*MAX(0,MIN(1,(7*12-(Opportunities!H13))/12)) -> 63762.055 | J10: =(Opportunities!C13*Opportunities!D13*12*Opportunities!I13*(1-Opportunities!J13)-Opportunities!K13)*(1+Assumptions!$B$10)^7*MAX(0,MIN(1,(8*12-(Opportunities!H13))/12)) -> 65037.296 | K10: =(Opportunities!C13*Opportunities!D13*12*Opportunities!I13*(1-Opportunities!J13)-Opportunities!K13)*(1+Assumptions!$B$10)^8*MAX(0,MIN(1,(9*12-(Opportunities!H13))/12)) -> 66338.042 | L10: =(Opportunities!C13*Opportunities!D13*12*Opportunities!I13*(1-Opportunities!J13)-Opportunities!K13)*(1+Assumptions!$B$10)^9*MAX(0,MIN(1,(10*12-(Opportunities!H13))/12))+MAX(0,(Opportunities!O13)/Assumptions!$B$11)*(1-Assumptions!$B$12) -> 1284893.1
A11: =Opportunities!B14 | B11: =-Opportunities!L14 -> 0 | C11: =(Opportunities!C14*Opportunities!D14*12*Opportunities!I14*(1-Opportunities!J14)-Opportunities!K14)*(1+Assumptions!$B$10)^0*MAX(0,MIN(1,(1*12-(Opportunities!H14))/12)) -> 0 | D11: =(Opportunities!C14*Opportunities!D14*12*Opportunities!I14*(1-Opportunities!J14)-Opportunities!K14)*(1+Assumptions!$B$10)^1*MAX(0,MIN(1,(2*12-(Opportunities!H14))/12)) -> 0 | E11: =(Opportunities!C14*Opportunities!D14*12*Opportunities!I14*(1-Opportunities!J14)-Opportunities!K14)*(1+Assumptions!$B$10)^2*MAX(0,MIN(1,(3*12-(Opportunities!H14))/12)) -> 0 | F11: =(Opportunities!C14*Opportunities!D14*12*Opportunities!I14*(1-Opportunities!J14)-Opportunities!K14)*(1+Assumptions!$B$10)^3*MAX(0,MIN(1,(4*12-(Opportunities!H14))/12)) -> 0 | G11: =(Opportunities!C14*Opportunities!D14*12*Opportunities!I14*(1-Opportunities!J14)-Opportunities!K14)*(1+Assumptions!$B$10)^4*MAX(0,MIN(1,(5*12-(Opportunities!H14))/12)) -> 0 | H11: =(Opportunities!C14*Opportunities!D14*12*Opportunities!I14*(1-Opportunities!J14)-Opportunities!K14)*(1+Assumptions!$B$10)^5*MAX(0,MIN(1,(6*12-(Opportunities!H14))/12)) -> 0 | I11: =(Opportunities!C14*Opportunities!D14*12*Opportunities!I14*(1-Opportunities!J14)-Opportunities!K14)*(1+Assumptions!$B$10)^6*MAX(0,MIN(1,(7*12-(Opportunities!H14))/12)) -> 0 | J11: =(Opportunities!C14*Opportunities!D14*12*Opportunities!I14*(1-Opportunities!J14)-Opportunities!K14)*(1+Assumptions!$B$10)^7*MAX(0,MIN(1,(8*12-(Opportunities!H14))/12)) -> 0 | K11: =(Opportunities!C14*Opportunities!D14*12*Opportunities!I14*(1-Opportunities!J14)-Opportunities!K14)*(1+Assumptions!$B$10)^8*MAX(0,MIN(1,(9*12-(Opportunities!H14))/12)) -> 0 | L11: =(Opportunities!C14*Opportunities!D14*12*Opportunities!I14*(1-Opportunities!J14)-Opportunities!K14)*(1+Assumptions!$B$10)^9*MAX(0,MIN(1,(10*12-(Opportunities!H14))/12))+MAX(0,(Opportunities!O14)/Assumptions!$B$11)*(1-Assumptions!$B$12) -> 0
A12: =Opportunities!B15 | B12: =-Opportunities!L15 -> 0 | C12: =(Opportunities!C15*Opportunities!D15*12*Opportunities!I15*(1-Opportunities!J15)-Opportunities!K15)*(1+Assumptions!$B$10)^0*MAX(0,MIN(1,(1*12-(Opportunities!H15))/12)) -> 0 | D12: =(Opportunities!C15*Opportunities!D15*12*Opportunities!I15*(1-Opportunities!J15)-Opportunities!K15)*(1+Assumptions!$B$10)^1*MAX(0,MIN(1,(2*12-(Opportunities!H15))/12)) -> 0 | E12: =(Opportunities!C15*Opportunities!D15*12*Opportunities!I15*(1-Opportunities!J15)-Opportunities!K15)*(1+Assumptions!$B$10)^2*MAX(0,MIN(1,(3*12-(Opportunities!H15))/12)) -> 0 | F12: =(Opportunities!C15*Opportunities!D15*12*Opportunities!I15*(1-Opportunities!J15)-Opportunities!K15)*(1+Assumptions!$B$10)^3*MAX(0,MIN(1,(4*12-(Opportunities!H15))/12)) -> 0 | G12: =(Opportunities!C15*Opportunities!D15*12*Opportunities!I15*(1-Opportunities!J15)-Opportunities!K15)*(1+Assumptions!$B$10)^4*MAX(0,MIN(1,(5*12-(Opportunities!H15))/12)) -> 0 | H12: =(Opportunities!C15*Opportunities!D15*12*Opportunities!I15*(1-Opportunities!J15)-Opportunities!K15)*(1+Assumptions!$B$10)^5*MAX(0,MIN(1,(6*12-(Opportunities!H15))/12)) -> 0 | I12: =(Opportunities!C15*Opportunities!D15*12*Opportunities!I15*(1-Opportunities!J15)-Opportunities!K15)*(1+Assumptions!$B$10)^6*MAX(0,MIN(1,(7*12-(Opportunities!H15))/12)) -> 0 | J12: =(Opportunities!C15*Opportunities!D15*12*Opportunities!I15*(1-Opportunities!J15)-Opportunities!K15)*(1+Assumptions!$B$10)^7*MAX(0,MIN(1,(8*12-(Opportunities!H15))/12)) -> 0 | K12: =(Opportunities!C15*Opportunities!D15*12*Opportunities!I15*(1-Opportunities!J15)-Opportunities!K15)*(1+Assumptions!$B$10)^8*MAX(0,MIN(1,(9*12-(Opportunities!H15))/12)) -> 0 | L12: =(Opportunities!C15*Opportunities!D15*12*Opportunities!I15*(1-Opportunities!J15)-Opportunities!K15)*(1+Assumptions!$B$10)^9*MAX(0,MIN(1,(10*12-(Opportunities!H15))/12))+MAX(0,(Opportunities!O15)/Assumptions!$B$11)*(1-Assumptions!$B$12) -> 0
A17: Downside | B17: Year 0 | C17: Year 1 | D17: Year 2 | E17: Year 3 | F17: Year 4 | G17: Year 5 | H17: Year 6 | I17: Year 7 | J17: Year 8 | K17: Year 9 | L17: Year 10
A18: =Opportunities!B8 -> Illustrative conversion A | B18: =-Opportunities!L8-Opportunities!F8*(1+Assumptions!$B$14)*Assumptions!$B$17 -> -922400 | C18: =(Opportunities!C8*Opportunities!D8*12*Opportunities!I8*(1-Opportunities!J8)*(1-Assumptions!$B$15)-Opportunities!K8)*(1+Assumptions!$B$10)^0*MAX(0,MIN(1,(1*12-(Opportunities!H8+Assumptions!$B$16))/12)) -> 0 | D18: =(Opportunities!C8*Opportunities!D8*12*Opportunities!I8*(1-Opportunities!J8)*(1-Assumptions!$B$15)-Opportunities!K8)*(1+Assumptions!$B$10)^1*MAX(0,MIN(1,(2*12-(Opportunities!H8+Assumptions!$B$16))/12)) -> 28491.913 | E18: =(Opportunities!C8*Opportunities!D8*12*Opportunities!I8*(1-Opportunities!J8)*(1-Assumptions!$B$15)-Opportunities!K8)*(1+Assumptions!$B$10)^2*MAX(0,MIN(1,(3*12-(Opportunities!H8+Assumptions!$B$16))/12)) -> 58123.502 | F18: =(Opportunities!C8*Opportunities!D8*12*Opportunities!I8*(1-Opportunities!J8)*(1-Assumptions!$B$15)-Opportunities!K8)*(1+Assumptions!$B$10)^3*MAX(0,MIN(1,(4*12-(Opportunities!H8+Assumptions!$B$16))/12)) -> 59285.972 | G18: =(Opportunities!C8*Opportunities!D8*12*Opportunities!I8*(1-Opportunities!J8)*(1-Assumptions!$B$15)-Opportunities!K8)*(1+Assumptions!$B$10)^4*MAX(0,MIN(1,(5*12-(Opportunities!H8+Assumptions!$B$16))/12)) -> 60471.692 | H18: =(Opportunities!C8*Opportunities!D8*12*Opportunities!I8*(1-Opportunities!J8)*(1-Assumptions!$B$15)-Opportunities!K8)*(1+Assumptions!$B$10)^5*MAX(0,MIN(1,(6*12-(Opportunities!H8+Assumptions!$B$16))/12)) -> 61681.126 | I18: =(Opportunities!C8*Opportunities!D8*12*Opportunities!I8*(1-Opportunities!J8)*(1-Assumptions!$B$15)-Opportunities!K8)*(1+Assumptions!$B$10)^6*MAX(0,MIN(1,(7*12-(Opportunities!H8+Assumptions!$B$16))/12)) -> 62914.748 | J18: =(Opportunities!C8*Opportunities!D8*12*Opportunities!I8*(1-Opportunities!J8)*(1-Assumptions!$B$15)-Opportunities!K8)*(1+Assumptions!$B$10)^7*MAX(0,MIN(1,(8*12-(Opportunities!H8+Assumptions!$B$16))/12)) -> 64173.043 | K18: =(Opportunities!C8*Opportunities!D8*12*Opportunities!I8*(1-Opportunities!J8)*(1-Assumptions!$B$15)-Opportunities!K8)*(1+Assumptions!$B$10)^8*MAX(0,MIN(1,(9*12-(Opportunities!H8+Assumptions!$B$16))/12)) -> 65456.504 | L18: =(Opportunities!C8*Opportunities!D8*12*Opportunities!I8*(1-Opportunities!J8)*(1-Assumptions!$B$15)-Opportunities!K8)*(1+Assumptions!$B$10)^9*MAX(0,MIN(1,(10*12-(Opportunities!H8+Assumptions!$B$16))/12))+MAX(0,((Opportunities!C8*Opportunities!D8*12*Opportunities!I8*(1-Opportunities!J8)*(1-Assumptions!$B$15)-Opportunities!K8)*(1+Assumptions!$B$10)^10)/Assumptions!$B$11)*(1-Assumptions!$B$12) -> 1267818.7
A19: =Opportunities!B9 -> Illustrative renovation B | B19: =-Opportunities!L9-Opportunities!F9*(1+Assumptions!$B$14)*Assumptions!$B$17 -> -617200 | C19: =(Opportunities!C9*Opportunities!D9*12*Opportunities!I9*(1-Opportunities!J9)*(1-Assumptions!$B$15)-Opportunities!K9)*(1+Assumptions!$B$10)^0*MAX(0,MIN(1,(1*12-(Opportunities!H9+Assumptions!$B$16))/12)) -> 0 | D19: =(Opportunities!C9*Opportunities!D9*12*Opportunities!I9*(1-Opportunities!J9)*(1-Assumptions!$B$15)-Opportunities!K9)*(1+Assumptions!$B$10)^1*MAX(0,MIN(1,(2*12-(Opportunities!H9+Assumptions!$B$16))/12)) -> 37953.18 | E19: =(Opportunities!C9*Opportunities!D9*12*Opportunities!I9*(1-Opportunities!J9)*(1-Assumptions!$B$15)-Opportunities!K9)*(1+Assumptions!$B$10)^2*MAX(0,MIN(1,(3*12-(Opportunities!H9+Assumptions!$B$16))/12)) -> 38712.244 | F19: =(Opportunities!C9*Opportunities!D9*12*Opportunities!I9*(1-Opportunities!J9)*(1-Assumptions!$B$15)-Opportunities!K9)*(1+Assumptions!$B$10)^3*MAX(0,MIN(1,(4*12-(Opportunities!H9+Assumptions!$B$16))/12)) -> 39486.488 | G19: =(Opportunities!C9*Opportunities!D9*12*Opportunities!I9*(1-Opportunities!J9)*(1-Assumptions!$B$15)-Opportunities!K9)*(1+Assumptions!$B$10)^4*MAX(0,MIN(1,(5*12-(Opportunities!H9+Assumptions!$B$16))/12)) -> 40276.218 | H19: =(Opportunities!C9*Opportunities!D9*12*Opportunities!I9*(1-Opportunities!J9)*(1-Assumptions!$B$15)-Opportunities!K9)*(1+Assumptions!$B$10)^5*MAX(0,MIN(1,(6*12-(Opportunities!H9+Assumptions!$B$16))/12)) -> 41081.743 | I19: =(Opportunities!C9*Opportunities!D9*12*Opportunities!I9*(1-Opportunities!J9)*(1-Assumptions!$B$15)-Opportunities!K9)*(1+Assumptions!$B$10)^6*MAX(0,MIN(1,(7*12-(Opportunities!H9+Assumptions!$B$16))/12)) -> 41903.377 | J19: =(Opportunities!C9*Opportunities!D9*12*Opportunities!I9*(1-Opportunities!J9)*(1-Assumptions!$B$15)-Opportunities!K9)*(1+Assumptions!$B$10)^7*MAX(0,MIN(1,(8*12-(Opportunities!H9+Assumptions!$B$16))/12)) -> 42741.445 | K19: =(Opportunities!C9*Opportunities!D9*12*Opportunities!I9*(1-Opportunities!J9)*(1-Assumptions!$B$15)-Opportunities!K9)*(1+Assumptions!$B$10)^8*MAX(0,MIN(1,(9*12-(Opportunities!H9+Assumptions!$B$16))/12)) -> 43596.274 | L19: =(Opportunities!C9*Opportunities!D9*12*Opportunities!I9*(1-Opportunities!J9)*(1-Assumptions!$B$15)-Opportunities!K9)*(1+Assumptions!$B$10)^9*MAX(0,MIN(1,(10*12-(Opportunities!H9+Assumptions!$B$16))/12))+MAX(0,((Opportunities!C9*Opportunities!D9*12*Opportunities!I9*(1-Opportunities!J9)*(1-Assumptions!$B$15)-Opportunities!K9)*(1+Assumptions!$B$10)^10)/Assumptions!$B$11)*(1-Assumptions!$B$12) -> 844410.68
A20: =Opportunities!B10 -> Illustrative new build C | B20: =-Opportunities!L10-Opportunities!F10*(1+Assumptions!$B$14)*Assumptions!$B$17 -> -1723600 | C20: =(Opportunities!C10*Opportunities!D10*12*Opportunities!I10*(1-Opportunities!J10)*(1-Assumptions!$B$15)-Opportunities!K10)*(1+Assumptions!$B$10)^0*MAX(0,MIN(1,(1*12-(Opportunities!H10+Assumptions!$B$16))/12)) -> 0 | D20: =(Opportunities!C10*Opportunities!D10*12*Opportunities!I10*(1-Opportunities!J10)*(1-Assumptions!$B$15)-Opportunities!K10)*(1+Assumptions!$B$10)^1*MAX(0,MIN(1,(2*12-(Opportunities!H10+Assumptions!$B$16))/12)) -> 0 | E20: =(Opportunities!C10*Opportunities!D10*12*Opportunities!I10*(1-Opportunities!J10)*(1-Assumptions!$B$15)-Opportunities!K10)*(1+Assumptions!$B$10)^2*MAX(0,MIN(1,(3*12-(Opportunities!H10+Assumptions!$B$16))/12)) -> 0 | F20: =(Opportunities!C10*Opportunities!D10*12*Opportunities!I10*(1-Opportunities!J10)*(1-Assumptions!$B$15)-Opportunities!K10)*(1+Assumptions!$B$10)^3*MAX(0,MIN(1,(4*12-(Opportunities!H10+Assumptions!$B$16))/12)) -> 110444.26 | G20: =(Opportunities!C10*Opportunities!D10*12*Opportunities!I10*(1-Opportunities!J10)*(1-Assumptions!$B$15)-Opportunities!K10)*(1+Assumptions!$B$10)^4*MAX(0,MIN(1,(5*12-(Opportunities!H10+Assumptions!$B$16))/12)) -> 112653.15 | H20: =(Opportunities!C10*Opportunities!D10*12*Opportunities!I10*(1-Opportunities!J10)*(1-Assumptions!$B$15)-Opportunities!K10)*(1+Assumptions!$B$10)^5*MAX(0,MIN(1,(6*12-(Opportunities!H10+Assumptions!$B$16))/12)) -> 114906.21 | I20: =(Opportunities!C10*Opportunities!D10*12*Opportunities!I10*(1-Opportunities!J10)*(1-Assumptions!$B$15)-Opportunities!K10)*(1+Assumptions!$B$10)^6*MAX(0,MIN(1,(7*12-(Opportunities!H10+Assumptions!$B$16))/12)) -> 117204.33 | J20: =(Opportunities!C10*Opportunities!D10*12*Opportunities!I10*(1-Opportunities!J10)*(1-Assumptions!$B$15)-Opportunities!K10)*(1+Assumptions!$B$10)^7*MAX(0,MIN(1,(8*12-(Opportunities!H10+Assumptions!$B$16))/12)) -> 119548.42 | K20: =(Opportunities!C10*Opportunities!D10*12*Opportunities!I10*(1-Opportunities!J10)*(1-Assumptions!$B$15)-Opportunities!K10)*(1+Assumptions!$B$10)^8*MAX(0,MIN(1,(9*12-(Opportunities!H10+Assumptions!$B$16))/12)) -> 121939.39 | L20: =(Opportunities!C10*Opportunities!D10*12*Opportunities!I10*(1-Opportunities!J10)*(1-Assumptions!$B$15)-Opportunities!K10)*(1+Assumptions!$B$10)^9*MAX(0,MIN(1,(10*12-(Opportunities!H10+Assumptions!$B$16))/12))+MAX(0,((Opportunities!C10*Opportunities!D10*12*Opportunities!I10*(1-Opportunities!J10)*(1-Assumptions!$B$15)-Opportunities!K10)*(1+Assumptions!$B$10)^10)/Assumptions!$B$11)*(1-Assumptions!$B$12) -> 2361828.5
A21: =Opportunities!B11 -> Illustrative small asset D | B21: =-Opportunities!L11-Opportunities!F11*(1+Assumptions!$B$14)*Assumptions!$B$17 -> -349500 | C21: =(Opportunities!C11*Opportunities!D11*12*Opportunities!I11*(1-Opportunities!J11)*(1-Assumptions!$B$15)-Opportunities!K11)*(1+Assumptions!$B$10)^0*MAX(0,MIN(1,(1*12-(Opportunities!H11+Assumptions!$B$16))/12)) -> 3265.6965 | D21: =(Opportunities!C11*Opportunities!D11*12*Opportunities!I11*(1-Opportunities!J11)*(1-Assumptions!$B$15)-Opportunities!K11)*(1+Assumptions!$B$10)^1*MAX(0,MIN(1,(2*12-(Opportunities!H11+Assumptions!$B$16))/12)) -> 19986.063 | E21: =(Opportunities!C11*Opportunities!D11*12*Opportunities!I11*(1-Opportunities!J11)*(1-Assumptions!$B$15)-Opportunities!K11)*(1+Assumptions!$B$10)^2*MAX(0,MIN(1,(3*12-(Opportunities!H11+Assumptions!$B$16))/12)) -> 20385.784 | F21: =(Opportunities!C11*Opportunities!D11*12*Opportunities!I11*(1-Opportunities!J11)*(1-Assumptions!$B$15)-Opportunities!K11)*(1+Assumptions!$B$10)^3*MAX(0,MIN(1,(4*12-(Opportunities!H11+Assumptions!$B$16))/12)) -> 20793.5 | G21: =(Opportunities!C11*Opportunities!D11*12*Opportunities!I11*(1-Opportunities!J11)*(1-Assumptions!$B$15)-Opportunities!K11)*(1+Assumptions!$B$10)^4*MAX(0,MIN(1,(5*12-(Opportunities!H11+Assumptions!$B$16))/12)) -> 21209.37 | H21: =(Opportunities!C11*Opportunities!D11*12*Opportunities!I11*(1-Opportunities!J11)*(1-Assumptions!$B$15)-Opportunities!K11)*(1+Assumptions!$B$10)^5*MAX(0,MIN(1,(6*12-(Opportunities!H11+Assumptions!$B$16))/12)) -> 21633.557 | I21: =(Opportunities!C11*Opportunities!D11*12*Opportunities!I11*(1-Opportunities!J11)*(1-Assumptions!$B$15)-Opportunities!K11)*(1+Assumptions!$B$10)^6*MAX(0,MIN(1,(7*12-(Opportunities!H11+Assumptions!$B$16))/12)) -> 22066.228 | J21: =(Opportunities!C11*Opportunities!D11*12*Opportunities!I11*(1-Opportunities!J11)*(1-Assumptions!$B$15)-Opportunities!K11)*(1+Assumptions!$B$10)^7*MAX(0,MIN(1,(8*12-(Opportunities!H11+Assumptions!$B$16))/12)) -> 22507.553 | K21: =(Opportunities!C11*Opportunities!D11*12*Opportunities!I11*(1-Opportunities!J11)*(1-Assumptions!$B$15)-Opportunities!K11)*(1+Assumptions!$B$10)^8*MAX(0,MIN(1,(9*12-(Opportunities!H11+Assumptions!$B$16))/12)) -> 22957.704 | L21: =(Opportunities!C11*Opportunities!D11*12*Opportunities!I11*(1-Opportunities!J11)*(1-Assumptions!$B$15)-Opportunities!K11)*(1+Assumptions!$B$10)^9*MAX(0,MIN(1,(10*12-(Opportunities!H11+Assumptions!$B$16))/12))+MAX(0,((Opportunities!C11*Opportunities!D11*12*Opportunities!I11*(1-Opportunities!J11)*(1-Assumptions!$B$15)-Opportunities!K11)*(1+Assumptions!$B$10)^10)/Assumptions!$B$11)*(1-Assumptions!$B$12) -> 444664.84
A22: =Opportunities!B12 -> Illustrative delayed asset E | B22: =-Opportunities!L12-Opportunities!F12*(1+Assumptions!$B$14)*Assumptions!$B$17 -> -1225800 | C22: =(Opportunities!C12*Opportunities!D12*12*Opportunities!I12*(1-Opportunities!J12)*(1-Assumptions!$B$15)-Opportunities!K12)*(1+Assumptions!$B$10)^0*MAX(0,MIN(1,(1*12-(Opportunities!H12+Assumptions!$B$16))/12)) -> 0 | D22: =(Opportunities!C12*Opportunities!D12*12*Opportunities!I12*(1-Opportunities!J12)*(1-Assumptions!$B$15)-Opportunities!K12)*(1+Assumptions!$B$10)^1*MAX(0,MIN(1,(2*12-(Opportunities!H12+Assumptions!$B$16))/12)) -> 0 | E22: =(Opportunities!C12*Opportunities!D12*12*Opportunities!I12*(1-Opportunities!J12)*(1-Assumptions!$B$15)-Opportunities!K12)*(1+Assumptions!$B$10)^2*MAX(0,MIN(1,(3*12-(Opportunities!H12+Assumptions!$B$16))/12)) -> 0 | F22: =(Opportunities!C12*Opportunities!D12*12*Opportunities!I12*(1-Opportunities!J12)*(1-Assumptions!$B$15)-Opportunities!K12)*(1+Assumptions!$B$10)^3*MAX(0,MIN(1,(4*12-(Opportunities!H12+Assumptions!$B$16))/12)) -> 0 | G22: =(Opportunities!C12*Opportunities!D12*12*Opportunities!I12*(1-Opportunities!J12)*(1-Assumptions!$B$15)-Opportunities!K12)*(1+Assumptions!$B$10)^4*MAX(0,MIN(1,(5*12-(Opportunities!H12+Assumptions!$B$16))/12)) -> 70460.965 | H22: =(Opportunities!C12*Opportunities!D12*12*Opportunities!I12*(1-Opportunities!J12)*(1-Assumptions!$B$15)-Opportunities!K12)*(1+Assumptions!$B$10)^5*MAX(0,MIN(1,(6*12-(Opportunities!H12+Assumptions!$B$16))/12)) -> 71870.184 | I22: =(Opportunities!C12*Opportunities!D12*12*Opportunities!I12*(1-Opportunities!J12)*(1-Assumptions!$B$15)-Opportunities!K12)*(1+Assumptions!$B$10)^6*MAX(0,MIN(1,(7*12-(Opportunities!H12+Assumptions!$B$16))/12)) -> 73307.588 | J22: =(Opportunities!C12*Opportunities!D12*12*Opportunities!I12*(1-Opportunities!J12)*(1-Assumptions!$B$15)-Opportunities!K12)*(1+Assumptions!$B$10)^7*MAX(0,MIN(1,(8*12-(Opportunities!H12+Assumptions!$B$16))/12)) -> 74773.739 | K22: =(Opportunities!C12*Opportunities!D12*12*Opportunities!I12*(1-Opportunities!J12)*(1-Assumptions!$B$15)-Opportunities!K12)*(1+Assumptions!$B$10)^8*MAX(0,MIN(1,(9*12-(Opportunities!H12+Assumptions!$B$16))/12)) -> 76269.214 | L22: =(Opportunities!C12*Opportunities!D12*12*Opportunities!I12*(1-Opportunities!J12)*(1-Assumptions!$B$15)-Opportunities!K12)*(1+Assumptions!$B$10)^9*MAX(0,MIN(1,(10*12-(Opportunities!H12+Assumptions!$B$16))/12))+MAX(0,((Opportunities!C12*Opportunities!D12*12*Opportunities!I12*(1-Opportunities!J12)*(1-Assumptions!$B$15)-Opportunities!K12)*(1+Assumptions!$B$10)^10)/Assumptions!$B$11)*(1-Assumptions!$B$12) -> 1477248.7
