Workbook

Sheet Executive report
A1: Brussels student accommodation | decision model | B1: Value / assessment
A2: Decision | B2: =IF(AND(B13>=0,B14>=Inputs!B22),"PASS numerical screen; verify all project inputs before commitment","DEFER: NPV / IRR fail the assumed investment hurdle") -> DEFER: NPV / IRR fail the assumed investment hurdle
A3: Evidence and scope | B3: Official regional benchmarks + explicitly marked project assumptions. Nominal EUR; unlevered, before income tax; 30 operating years.
A5: Policy affordable all-in threshold | B5: =Inputs!$B$7*Inputs!$B$8 -> 250.05
A6: Affordable rooms | B6: =Inputs!$B$2*Inputs!$B$6 -> 20
A7: Blended all-in monthly price | B7: =(1-Inputs!$B$6)*Inputs!$B$3+Inputs!$B$6*MIN(B5,Inputs!$B$3) -> 530.01
A8: Monthly rent collection incl bundled charges | B8: =B7-(1-Inputs!$B$5)*Inputs!$B$4 -> 530.01
A9: Separate monthly utility charge | B9: =(1-Inputs!$B$5)*Inputs!$B$4 -> 0
A10: Maximum deposit / market room | B10: =Inputs!$B$27*MAX(0,Inputs!$B$3-Inputs!$B$4) -> 1050
A11: Initial investment | B11: ='Development budget'!B9 -> 11538752
A12: Average base rent excluding utility charges | B12: =B7-Inputs!$B$4 -> 455.01
A13: Net present value (NPV) | B13: =NPV(Inputs!B22,'Cash flows'!L3:L33)+'Cash flows'!L2 -> -5367708.2
A14: Internal rate of return (IRR) | B14: =IFERROR(IRR('Cash flows'!L2:L33),"No IRR") -> 0.034478351
A15: Simple payback incl sale (years) | B15: =IF(SUM('Cash flows'!R3:R33)=0,"Not recovered",SUM('Cash flows'!R3:R33)) -> 27.099085
A16: Discounted payback incl sale (years) | B16: =IF(SUM('Cash flows'!S3:S33)=0,"Not recovered",SUM('Cash flows'!S3:S33)) -> Not recovered
A17: Operating-only recovery by horizon | B17: =IF('Cash flows'!Q33>=0,"Recovered","Not recovered") -> Recovered
A18: First operating-year NOI | B18: ='Cash flows'!I4 -> 352711.4
A19: NPV break-even initial spend | B19: =B11+B13 -> 6171043.8
A21: Interpretation | B21: The default case mixes 80% market rooms with 20% policy affordable rooms. Results are illustrative, not an official forecast. Negative NPV and IRR below the hurdle argue against this budget.
A22: Affordability | B22: A 30% housing share of the reported student-housing budget gives a policy ceiling of EUR250.05 including utilities. Spending budget is not income; this is a chosen policy, not a legal threshold. Compare EUR525 shared median and EUR600 all-in median (S1).
A23: Advantages | B23: Adds purpose-built beds, may reduce pressure on ordinary housing and deliver efficient, accessible accommodation. Campus proximity and transparent all-in charges can support tenant appeal. These benefits do not establish profitable occupancy.
A24: Drawbacks | B24: Land and build cost uncertainty; permits and construction delays; annual turnover and summer vacancies; affordable rents reduce receipts; energy, repair and major replacement exposure; competition and terminal valuation risk.
A25: Location recommendation | B25: Shortlist sites near target campuses and transit, then compare acquisition price, zoning, walking time, safety and local competing pipeline. Ixelles/Etterbeek, central Brussels, Alma and Erasme/CERIA are candidate campus areas, not an official location ranking (S1 p8).
A26: Investment gates | B26: Obtain site valuation, quantity-surveyor budget, tax treatment, operator cost plan, current rent comparables, vacancies, planning/fire/energy approvals and campus-specific demand evidence. Proceed only if updated NPV >= 0, IRR >= hurdle and the affordable share remains deliverable.
A27: Material limits | B27: Income tax, debt, interest, construction payment phasing, working capital and grants are excluded. Property tax is an unverified component of other operating expenses. Deposits are refundable liabilities, excluded from revenue and project returns.
A28: Timing and payback | B28: All cost at t=0; opening after one full year; first receipts at t=2; sale at t=31. Payback interpolates the crossing year and can depend on sale; operating-only recovery is separately shown. Annual timing is a simplification.
A29: Use | B29: Blue inputs are editable assumptions; green inputs are official historical benchmarks. Workbook recalculates in Excel. Operating years and opening delay are fixed to this timeline and locked by validation; change code to extend it.

Sheet Inputs
A1: Input | B1: Value | C1: Unit | D1: Classification | E1: Source / interpretation
A2: Rooms | B2: 100 | C2: rooms | D2: ASSUMPTION | E2: Design brief required
A3: Market all-in monthly price | B3: 600 | C3: EUR/room/month | D3: OFFICIAL BENCHMARK | E3: S1 p55; survey 2023–24, all typologies; not a 2026 quotation
A4: Monthly utility cost | B4: 75 | C4: EUR/occupied room/month | D4: ASSUMPTION | E4: Obtain energy/water/service quotes
A5: Utilities included? (1=yes; 0=separate) | B5: 1 | C5: binary | D5: POLICY | E5: All-in affordability is unchanged by billing mode
A6: Affordable room share | B6: 0.2 | C6: fraction | D6: POLICY | E6: 20% illustrative project commitment
A7: Housing share of student budget | B7: 0.3 | C7: fraction | D7: POLICY | E7: 30% illustrative; no official student affordability threshold found
A8: Student housing monthly budget | B8: 833.5 | C8: EUR/month | D8: OFFICIAL BENCHMARK | E8: S1 p110; mean spending budget, not household income
A9: Paid months per year | B9: 12 | C9: months | D9: ASSUMPTION | E9: S3 maximum lease 12 months does not ensure collection for 12 months
A10: Occupancy / collection factor | B10: 0.95 | C10: fraction | D10: ASSUMPTION | E10: Vacancy and nonpayment combined; not official occupancy
A11: Gross floor area per room | B11: 30 | C11: m2/room | D11: ASSUMPTION | E11: Includes common space; architect must verify
A12: Construction unit cost ex VAT | B12: 2200 | C12: EUR/m2 | D12: ASSUMPTION | E12: No official Brussels PBSA EUR/m2 quotation verified
A13: Land and acquisition all-in | B13: 1500000 | C13: EUR | D13: ASSUMPTION | E13: Include land purchase tax and fees; obtain site valuation
... A30: Include terminal sale (1/0) | B30: 1 | C30: binary | D30: INVESTOR INPUT | E30: Test zero for no-sale downside

Sheet Market evidence
A1: Measure | B1: Value | C1: Interpretation
A2: All-in median rent | B2: 600 | C2: S1 p55; 2023–24 survey
A3: Shared housing median/person | B3: 525 | C3: S1 p56; distinct product, not lower end of market range
A4: Mean student-housing monthly budget | B4: 833.5 | C4: S1 p110; includes rent and other spending
A5: Estimated housing demand | B5: 37200 | C5: S4 p26; approximation, excludes promotion sociale
A6: Dedicated housing units | B6: 11305 | C6: S4 p28; 2025 inventory; not all housing occupied by students
A7: Dedicated coverage ratio | B7: =B6/B5 -> 0.30389785 | C7: Not vacancy or occupancy
A8: Demand less dedicated inventory | B8: =B5-B6 -> 25895 | C8: NOT a measured shortage: ordinary rental housing also serves students
A9: Live available rooms | B9: Unknown | C9: Inventory does not provide current vacancies
A10: Observed average deposit | B10: Unknown | C10: Legal maximum must not be represented as an average
A11: Official affordable student threshold | B11: Not identified | C11: User policy threshold shown in Inputs
A12: Current rent distribution / range | B12: Not verified | C12: 525 and 600 are comparable benchmarks only, not minimum/maximum prices

Sheet Development budget
A1: Component | B1: EUR | C1: Method
A2: Gross floor area (m2) | B2: =Inputs!$B$2*Inputs!$B$11 -> 3000
A3: Hard construction | B3: =B2*Inputs!$B$12 -> 6600000
A4: Professional fees | B4: =B3*Inputs!$B$14 -> 792000
A5: Contingency | B5: =(B3+B4)*Inputs!$B$15 -> 739200
A6: Unrecoverable works VAT allowance | B6: =(B3+B4+B5)*Inputs!$B$16 -> 1707552
A7: Land and acquisition | B7: =Inputs!$B$13 -> 1500000
A8: Furniture | B8: =Inputs!$B$2*Inputs!$B$17 -> 200000
A9: Total initial development spend | B9: =SUM(B3:B8) -> 11538752 | C9: All paid at t=0; financing excluded. Replace budget assumptions before investment approval.

Sheet Cash flows
A1: Year t | B1: Operating year | C1: Rent collected | D1: Utility recovery | E1: Total receipts | F1: Utility expense | G1: Maintenance | H1: Other operating | I1: NOI | J1: Replacement capex | K1: Terminal net sale | L1: Project cash flow | M1: Discount factor | N1: PV | O1: Cumulative cash | P1: Cumulative PV | Q1: Operating-only cumulative | R1: PBP crossing | S1: Discounted PBP crossing
A2: 0 | B2: =MAX(0,A2-Inputs!$B$24) -> 0 | C2: =IF(B2>0,Inputs!$B$2*Inputs!$B$9*Inputs!$B$10*'Executive report'!B8*(1+Inputs!$B$20)^(B2-1),0) -> 0 | D2: =IF(B2>0,Inputs!$B$2*Inputs!$B$9*Inputs!$B$10*'Executive report'!B9*(1+Inputs!$B$20)^(B2-1),0) -> 0 | E2: =C2+D2 -> 0 | F2: =IF(B2>0,Inputs!$B$2*Inputs!$B$9*Inputs!$B$10*Inputs!$B$4*(1+Inputs!$B$21)^(B2-1),0) -> 0 | G2: =IF(B2>0,'Development budget'!B3*Inputs!$B$18*(1+Inputs!$B$21)^(B2-1),0) -> 0 | H2: =IF(B2>0,Inputs!$B$19*(1+Inputs!$B$21)^(B2-1),0) -> 0 | I2: =E2-SUM(F2:H2) -> 0 | J2: =IF(B2=Inputs!$B$28,Inputs!$B$29*(1+Inputs!$B$21)^(B2-1),0) -> 0 | K2: =IF(B2=Inputs!$B$23,(E2*(1+Inputs!$B$20)-(F2+G2+H2)*(1+Inputs!$B$21))/Inputs!$B$25*(1-Inputs!$B$26)*Inputs!$B$30,0) -> 0 | L2: =IF(A2=0,-'Development budget'!B9,I2-J2+K2) -> -11538752 | M2: =1/(1+Inputs!$B$22)^A2 -> 1 | N2: =L2*M2 -> -11538752 | O2: =SUM($L$2:L2) -> -11538752 | P2: =SUM($N$2:N2) -> -11538752 | Q2: =-'Development budget'!B9+SUM($I$2:I2)-SUM($J$2:J2) -> -11538752 | R2: 0 | S2: 0
A3: 1 | B3: =MAX(0,A3-Inputs!$B$24) -> 0 | C3: =IF(B3>0,Inputs!$B$2*Inputs!$B$9*Inputs!$B$10*'Executive report'!B8*(1+Inputs!$B$20)^(B3-1),0) -> 0 | D3: =IF(B3>0,Inputs!$B$2*Inputs!$B$9*Inputs!$B$10*'Executive report'!B9*(1+Inputs!$B$20)^(B3-1),0) -> 0 | E3: =C3+D3 -> 0 | F3: =IF(B3>0,Inputs!$B$2*Inputs!$B$9*Inputs!$B$10*Inputs!$B$4*(1+Inputs!$B$21)^(B3-1),0) -> 0 | G3: =IF(B3>0,'Development budget'!B3*Inputs!$B$18*(1+Inputs!$B$21)^(B3-1),0) -> 0 | H3: =IF(B3>0,Inputs!$B$19*(1+Inputs!$B$21)^(B3-1),0) -> 0 | I3: =E3-SUM(F3:H3) -> 0 | J3: =IF(B3=Inputs!$B$28,Inputs!$B$29*(1+Inputs!$B$21)^(B3-1),0) -> 0 | K3: =IF(B3=Inputs!$B$23,(E3*(1+Inputs!$B$20)-(F3+G3+H3)*(1+Inputs!$B$21))/Inputs!$B$25*(1-Inputs!$B$26)*Inputs!$B$30,0) -> 0 | L3: =IF(A3=0,-'Development budget'!B9,I3-J3+K3) -> 0 | M3: =1/(1+Inputs!$B$22)^A3 -> 0.93457944 | N3: =L3*M3 -> 0 | O3: =SUM($L$2:L3) -> -11538752 | P3: =SUM($N$2:N3) -> -11538752 | Q3: =-'Development budget'!B9+SUM($I$2:I3)-SUM($J$2:J3) -> -11538752 | R3: =IF(AND(O2<0,O3>=0,L3>0),A3-1-O2/L3,0) -> 0 | S3: =IF(AND(P2<0,P3>=0,N3>0),A3-1-P2/N3,0) -> 0
A4: 2 | B4: =MAX(0,A4-Inputs!$B$24) -> 1 | C4: =IF(B4>0,Inputs!$B$2*Inputs!$B$9*Inputs!$B$10*'Executive report'!B8*(1+Inputs!$B$20)^(B4-1),0) -> 604211.4 | D4: =IF(B4>0,Inputs!$B$2*Inputs!$B$9*Inputs!$B$10*'Executive report'!B9*(1+Inputs!$B$20)^(B4-1),0) -> 0 | E4: =C4+D4 -> 604211.4 | F4: =IF(B4>0,Inputs!$B$2*Inputs!$B$9*Inputs!$B$10*Inputs!$B$4*(1+Inputs!$B$21)^(B4-1),0) -> 85500 | G4: =IF(B4>0,'Development budget'!B3*Inputs!$B$18*(1+Inputs!$B$21)^(B4-1),0) -> 66000 | H4: =IF(B4>0,Inputs!$B$19*(1+Inputs!$B$21)^(B4-1),0) -> 100000 | I4: =E4-SUM(F4:H4) -> 352711.4 | J4: =IF(B4=Inputs!$B$28,Inputs!$B$29*(1+Inputs!$B$21)^(B4-1),0) -> 0 | K4: =IF(B4=Inputs!$B$23,(E4*(1+Inputs!$B$20)-(F4+G4+H4)*(1+Inputs!$B$21))/Inputs!$B$25*(1-Inputs!$B$26)*Inputs!$B$30,0) -> 0 | L4: =IF(A4=0,-'Development budget'!B9,I4-J4+K4) -> 352711.4 | M4: =1/(1+Inputs!$B$22)^A4 -> 0.87343873 | N4: =L4*M4 -> 308071.8 | O4: =SUM($L$2:L4) -> -11186041 | P4: =SUM($N$2:N4) -> -11230680 | Q4: =-'Development budget'!B9+SUM($I$2:I4)-SUM($J$2:J4) -> -11186041 | R4: =IF(AND(O3<0,O4>=0,L4>0),A4-1-O3/L4,0) -> 0 | S4: =IF(AND(P3<0,P4>=0,N4>0),A4-1-P3/N4,0) -> 0
A5: 3 | B5: =MAX(0,A5-Inputs!$B$24) -> 2 | C5: =IF(B5>0,Inputs!$B$2*Inputs!$B$9*Inputs!$B$10*'Executive report'!B8*(1+Inputs!$B$20)^(B5-1),0) -> 616295.63 | D5: =IF(B5>0,Inputs!$B$2*Inputs!$B$9*Inputs!$B$10*'Executive report'!B9*(1+Inputs!$B$20)^(B5-1),0) -> 0 | E5: =C5+D5 -> 616295.63 | F5: =IF(B5>0,Inputs!$B$2*Inputs!$B$9*Inputs!$B$10*Inputs!$B$4*(1+Inputs!$B$21)^(B5-1),0) -> 87210 | G5: =IF(B5>0,'Development budget'!B3*Inputs!$B$18*(1+Inputs!$B$21)^(B5-1),0) -> 67320 | H5: =IF(B5>0,Inputs!$B$19*(1+Inputs!$B$21)^(B5-1),0) -> 102000 | I5: =E5-SUM(F5:H5) -> 359765.63 | J5: =IF(B5=Inputs!$B$28,Inputs!$B$29*(1+Inputs!$B$21)^(B5-1),0) -> 0 | K5: =IF(B5=Inputs!$B$23,(E5*(1+Inputs!$B$20)-(F5+G5+H5)*(1+Inputs!$B$21))/Inputs!$B$25*(1-Inputs!$B$26)*Inputs!$B$30,0) -> 0 | L5: =IF(A5=0,-'Development budget'!B9,I5-J5+K5) -> 359765.63 | M5: =1/(1+Inputs!$B$22)^A5 -> 0.81629788 | N5: =L5*M5 -> 293675.92 | O5: =SUM($L$2:L5) -> -10826275 | P5: =SUM($N$2:N5) -> -10937004 | Q5: =-'Development budget'!B9+SUM($I$2:I5)-SUM($J$2:J5) -> -10826275 | R5: =IF(AND(O4<0,O5>=0,L5>0),A5-1-O4/L5,0) -> 0 | S5: =IF(AND(P4<0,P5>=0,N5>0),A5-1-P4/N5,0) -> 0
A6: 4 | B6: =MAX(0,A6-Inputs!$B$24) -> 3 | C6: =IF(B6>0,Inputs!$B$2*Inputs!$B$9*Inputs!$B$10*'Executive report'!B8*(1+Inputs!$B$20)^(B6-1),0) -> 628621.54 | D6: =IF(B6>0,Inputs!$B$2*Inputs!$B$9*Inputs!$B$10*'Executive report'!B9*(1+Inputs!$B$20)^(B6-1),0) -> 0 | E6: =C6+D6 -> 628621.54 | F6: =IF(B6>0,Inputs!$B$2*Inputs!$B$9*Inputs!$B$10*Inputs!$B$4*(1+Inputs!$B$21)^(B6-1),0) -> 88954.2 | G6: =IF(B6>0,'Development budget'!B3*Inputs!$B$18*(1+Inputs!$B$21)^(B6-1),0) -> 68666.4 | H6: =IF(B6>0,Inputs!$B$19*(1+Inputs!$B$21)^(B6-1),0) -> 104040 | I6: =E6-SUM(F6:H6) -> 366960.94 | J6: =IF(B6=Inputs!$B$28,Inputs!$B$29*(1+Inputs!$B$21)^(B6-1),0) -> 0 | K6: =IF(B6=Inputs!$B$23,(E6*(1+Inputs!$B$20)-(F6+G6+H6)*(1+Inputs!$B$21))/Inputs!$B$25*(1-Inputs!$B$26)*Inputs!$B$30,0) -> 0 | L6: =IF(A6=0,-'Development budget'!B9,I6-J6+K6) -> 366960.94 | M6: =1/(1+Inputs!$B$22)^A6 -> 0.76289521 | N6: =L6*M6 -> 279952.74 | O6: =SUM($L$2:L6) -> -10459314 | P6: =SUM($N$2:N6) -> -10657052 | Q6: =-'Development budget'!B9+SUM($I$2:I6)-SUM($J$2:J6) -> -10459314 | R6: =IF(AND(O5<0,O6>=0,L6>0),A6-1-O5/L6,0) -> 0 | S6: =IF(AND(P5<0,P6>=0,N6>0),A6-1-P5/N6,0) -> 0
A7: 5 | B7: =MAX(0,A7-Inputs!$B$24) -> 4 | C7: =IF(B7>0,Inputs!$B$2*Inputs!$B$9*Inputs!$B$10*'Executive report'!B8*(1+Inputs!$B$20)^(B7-1),0) -> 641193.97 | D7: =IF(B7>0,Inputs!$B$2*Inputs!$B$9*Inputs!$B$10*'Executive report'!B9*(1+Inputs!$B$20)^(B7-1),0) -> 0 | E7: =C7+D7 -> 641193.97 | F7: =IF(B7>0,Inputs!$B$2*Inputs!$B$9*Inputs!$B$10*Inputs!$B$4*(1+Inputs!$B$21)^(B7-1),0) -> 90733.284 | G7: =IF(B7>0,'Development budget'!B3*Inputs!$B$18*(1+Inputs!$B$21)^(B7-1),0) -> 70039.728 | H7: =IF(B7>0,Inputs!$B$19*(1+Inputs!$B$21)^(B7-1),0) -> 106120.8 | I7: =E7-SUM(F7:H7) -> 374300.16 | J7: =IF(B7=Inputs!$B$28,Inputs!$B$29*(1+Inputs!$B$21)^(B7-1),0) -> 0 | K7: =IF(B7=Inputs!$B$23,(E7*(1+Inputs!$B$20)-(F7+G7+H7)*(1+Inputs!$B$21))/Inputs!$B$25*(1-Inputs!$B$26)*Inputs!$B$30,0) -> 0 | L7: =IF(A7=0,-'Development budget'!B9,I7-J7+K7) -> 374300.16 | M7: =1/(1+Inputs!$B$22)^A7 -> 0.71298618 | N7: =L7*M7 -> 266870.84 | O7: =SUM($L$2:L7) -> -10085014 | P7: =SUM($N$2:N7) -> -10390181 | Q7: =-'Development budget'!B9+SUM($I$2:I7)-SUM($J$2:J7) -> -10085014 | R7: =IF(AND(O6<0,O7>=0,L7>0),A7-1-O6/L7,0) -> 0 | S7: =IF(AND(P6<0,P7>=0,N7>0),A7-1-P6/N7,0) -> 0
A8: 6 | B8: =MAX(0,A8-Inputs!$B$24) -> 5 | C8: =IF(B8>0,Inputs!$B$2*Inputs!$B$9*Inputs!$B$10*'Executive report'!B8*(1+Inputs!$B$20)^(B8-1),0) -> 654017.85 | D8: =IF(B8>0,Inputs!$B$2*Inputs!$B$9*Inputs!$B$10*'Executive report'!B9*(1+Inputs!$B$20)^(B8-1),0) -> 0 | E8: =C8+D8 -> 654017.85 | F8: =IF(B8>0,Inputs!$B$2*Inputs!$B$9*Inputs!$B$10*Inputs!$B$4*(1+Inputs!$B$21)^(B8-1),0) -> 92547.95 | G8: =IF(B8>0,'Development budget'!B3*Inputs!$B$18*(1+Inputs!$B$21)^(B8-1),0) -> 71440.523 | H8: =IF(B8>0,Inputs!$B$19*(1+Inputs!$B$21)^(B8-1),0) -> 108243.22 | I8: =E8-SUM(F8:H8) -> 381786.16 | J8: =IF(B8=Inputs!$B$28,Inputs!$B$29*(1+Inputs!$B$21)^(B8-1),0) -> 0 | K8: =IF(B8=Inputs!$B$23,(E8*(1+Inputs!$B$20)-(F8+G8+H8)*(1+Inputs!$B$21))/Inputs!$B$25*(1-Inputs!$B$26)*Inputs!$B$30,0) -> 0 | L8: =IF(A8=0,-'Development budget'!B9,I8-J8+K8) -> 381786.16 | M8: =1/(1+Inputs!$B$22)^A8 -> 0.66634222 | N8: =L8*M8 -> 254400.24 | O8: =SUM($L$2:L8) -> -9703227.7 | P8: =SUM($N$2:N8) -> -10135780 | Q8: =-'Development budget'!B9+SUM($I$2:I8)-SUM($J$2:J8) -> -9703227.7 | R8: =IF(AND(O7<0,O8>=0,L8>0),A8-1-O7/L8,0) -> 0 | S8: =IF(AND(P7<0,P8>=0,N8>0),A8-1-P7/N8,0) -> 0
A9: 7 | B9: =MAX(0,A9-Inputs!$B$24) -> 6 | C9: =IF(B9>0,Inputs!$B$2*Inputs!$B$9*Inputs!$B$10*'Executive report'!B8*(1+Inputs!$B$20)^(B9-1),0) -> 667098.21 | D9: =IF(B9>0,Inputs!$B$2*Inputs!$B$9*Inputs!$B$10*'Executive report'!B9*(1+Inputs!$B$20)^(B9-1),0) -> 0 | E9: =C9+D9 -> 667098.21 | F9: =IF(B9>0,Inputs!$B$2*Inputs!$B$9*Inputs!$B$10*Inputs!$B$4*(1+Inputs!$B$21)^(B9-1),0) -> 94398.909 | G9: =IF(B9>0,'Development budget'!B3*Inputs!$B$18*(1+Inputs!$B$21)^(B9-1),0) -> 72869.333 | H9: =IF(B9>0,Inputs!$B$19*(1+Inputs!$B$21)^(B9-1),0) -> 110408.08 | I9: =E9-SUM(F9:H9) -> 389421.89 | J9: =IF(B9=Inputs!$B$28,Inputs!$B$29*(1+Inputs!$B$21)^(B9-1),0) -> 0 | K9: =IF(B9=Inputs!$B$23,(E9*(1+Inputs!$B$20)-(F9+G9+H9)*(1+Inputs!$B$21))/Inputs!$B$25*(1-Inputs!$B$26)*Inputs!$B$30,0) -> 0 | L9: =IF(A9=0,-'Development budget'!B9,I9-J9+K9) -> 389421.89 | M9: =1/(1+Inputs!$B$22)^A9 -> 0.62274974 | N9: =L9*M9 -> 242512.38 | O9: =SUM($L$2:L9) -> -9313805.8 | P9: =SUM($N$2:N9) -> -9893268.1 | Q9: =-'Development budget'!B9+SUM($I$2:I9)-SUM($J$2:J9) -> -9313805.8 | R9: =IF(AND(O8<0,O9>=0,L9>0),A9-1-O8/L9,0) -> 0 | S9: =IF(AND(P8<0,P9>=0,N9>0),A9-1-P8/N9,0) -> 0
A10: 8 | B10: =MAX(0,A10-Inputs!$B$24) -> 7 | C10: =IF(B10>0,Inputs!$B$2*Inputs!$B$9*Inputs!$B$10*'Executive report'!B8*(1+Inputs!$B$20)^(B10-1),0) -> 680440.17 | D10: =IF(B10>0,Inputs!$B$2*Inputs!$B$9*Inputs!$B$10*'Executive report'!B9*(1+Inputs!$B$20)^(B10-1),0) -> 0 | E10: =C10+D10 -> 680440.17 | F10: =IF(B10>0,Inputs!$B$2*Inputs!$B$9*Inputs!$B$10*Inputs!$B$4*(1+Inputs!$B$21)^(B10-1),0) -> 96286.887 | G10: =IF(B10>0,'Development budget'!B3*Inputs!$B$18*(1+Inputs!$B$21)^(B10-1),0) -> 74326.72 | H10: =IF(B10>0,Inputs!$B$19*(1+Inputs!$B$21)^(B10-1),0) -> 112616.24 | I10: =E10-SUM(F10:H10) -> 397210.32 | J10: =IF(B10=Inputs!$B$28,Inputs!$B$29*(1+Inputs!$B$21)^(B10-1),0) -> 0 | K10: =IF(B10=Inputs!$B$23,(E10*(1+Inputs!$B$20)-(F10+G10+H10)*(1+Inputs!$B$21))/Inputs!$B$25*(1-Inputs!$B$26)*Inputs!$B$30,0) -> 0 | L10: =IF(A10=0,-'Development budget'!B9,I10-J10+K10) -> 397210.32 | M10: =1/(1+Inputs!$B$22)^A10 -> 0.5820091 | N10: =L10*M10 -> 231180.02 | O10: =SUM($L$2:L10) -> -8916595.5 | P10: =SUM($N$2:N10) -> -9662088.1 | Q10: =-'Development budget'!B9+SUM($I$2:I10)-SUM($J$2:J10) -> -8916595.5 | R10: =IF(AND(O9<0,O10>=0,L10>0),A10-1-O9/L10,0) -> 0 | S10: =IF(AND(P9<0,P10>=0,N10>0),A10-1-P9/N10,0) -> 0
A11: 9 | B11: =MAX(0,A11-Inputs!$B$24) -> 8 | C11: =IF(B11>0,Inputs!$B$2*Inputs!$B$9*Inputs!$B$10*'Executive report'!B8*(1+Inputs!$B$20)^(B11-1),0) -> 694048.98 | D11: =IF(B11>0,Inputs!$B$2*Inputs!$B$9*Inputs!$B$10*'Executive report'!B9*(1+Inputs!$B$20)^(B11-1),0) -> 0 | E11: =C11+D11 -> 694048.98 | F11: =IF(B11>0,Inputs!$B$2*Inputs!$B$9*Inputs!$B$10*Inputs!$B$4*(1+Inputs!$B$21)^(B11-1),0) -> 98212.625 | G11: =IF(B11>0,'Development budget'!B3*Inputs!$B$18*(1+Inputs!$B$21)^(B11-1),0) -> 75813.254 | H11: =IF(B11>0,Inputs!$B$19*(1+Inputs!$B$21)^(B11-1),0) -> 114868.57 | I11: =E11-SUM(F11:H11) -> 405154.53 | J11: =IF(B11=Inputs!$B$28,Inputs!$B$29*(1+Inputs!$B$21)^(B11-1),0) -> 0 | K11: =IF(B11=Inputs!$B$23,(E11*(1+Inputs!$B$20)-(F11+G11+H11)*(1+Inputs!$B$21))/Inputs!$B$25*(1-Inputs!$B$26)*Inputs!$B$30,0) -> 0 | L11: =IF(A11=0,-'Development budget'!B9,I11-J11+K11) -> 405154.53 | M11: =1/(1+Inputs!$B$22)^A11 -> 0.54393374 | N11: =L11*M11 -> 220377.22 | O11: =SUM($L$2:L11) -> -8511441 | P11: =SUM($N$2:N11) -> -9441710.8 | Q11: =-'Development budget'!B9+SUM($I$2:I11)-SUM($J$2:J11) -> -8511441 | R11: =IF(AND(O10<0,O11>=0,L11>0),A11-1-O10/L11,0) -> 0 | S11: =IF(AND(P10<0,P11>=0,N11>0),A11-1-P10/N11,0) -> 0
A12: 10 | B12: =MAX(0,A12-Inputs!$B$24) -> 9 | C12: =IF(B12>0,Inputs!$B$2*Inputs!$B$9*Inputs!$B$10*'Executive report'!B8*(1+Inputs!$B$20)^(B12-1),0) -> 707929.95 | D12: =IF(B12>0,Inputs!$B$2*Inputs!$B$9*Inputs!$B$10*'Executive report'!B9*(1+Inputs!$B$20)^(B12-1),0) -> 0 | E12: =C12+D12 -> 707929.95 | F12: =IF(B12>0,Inputs!$B$2*Inputs!$B$9*Inputs!$B$10*Inputs!$B$4*(1+Inputs!$B$21)^(B12-1),0) -> 100176.88 | G12: =IF(B12>0,'Development budget'!B3*Inputs!$B$18*(1+Inputs!$B$21)^(B12-1),0) -> 77329.519 | H12: =IF(B12>0,Inputs!$B$19*(1+Inputs!$B$21)^(B12-1),0) -> 117165.94 | I12: =E12-SUM(F12:H12) -> 413257.62 | J12: =IF(B12=Inputs!$B$28,Inputs!$B$29*(1+Inputs!$B$21)^(B12-1),0) -> 0 | K12: =IF(B12=Inputs!$B$23,(E12*(1+Inputs!$B$20)-(F12+G12+H12)*(1+Inputs!$B$21))/Inputs!$B$25*(1-Inputs!$B$26)*Inputs!$B$30,0) -> 0 | L12: =IF(A12=0,-'Development budget'!B9,I12-J12+K12) -> 413257.62 | M12: =1/(1+Inputs!$B$22)^A12 -> 0.50834929 | N12: =L12*M12 -> 210079.22 | O12: =SUM($L$2:L12) -> -8098183.3 | P12: =SUM($N$2:N12) -> -9231631.6 | Q12: =-'Development budget'!B9+SUM($I$2:I12)-SUM($J$2:J12) -> -8098183.3 | R12: =IF(AND(O11<0,O12>=0,L12>0),A12-1-O11/L12,0) -> 0 | S12: =IF(AND(P11<0,P12>=0,N12>0),A12-1-P11/N12,0) -> 0
A13: 11 | B13: =MAX(0,A13-Inputs!$B$24) -> 10 | C13: =IF(B13>0,Inputs!$B$2*Inputs!$B$9*Inputs!$B$10*'Executive report'!B8*(1+Inputs!$B$20)^(B13-1),0) -> 722088.55 | D13: =IF(B13>0,Inputs!$B$2*Inputs!$B$9*Inputs!$B$10*'Executive report'!B9*(1+Inputs!$B$20)^(B13-1),0) -> 0 | E13: =C13+D13 -> 722088.55 | F13: =IF(B13>0,Inputs!$B$2*Inputs!$B$9*Inputs!$B$10*Inputs!$B$4*(1+Inputs!$B$21)^(B13-1),0) -> 102180.41 | G13: =IF(B13>0,'Development budget'!B3*Inputs!$B$18*(1+Inputs!$B$21)^(B13-1),0) -> 78876.11 | H13: =IF(B13>0,Inputs!$B$19*(1+Inputs!$B$21)^(B13-1),0) -> 119509.26 | I13: =E13-SUM(F13:H13) -> 421522.77 | J13: =IF(B13=Inputs!$B$28,Inputs!$B$29*(1+Inputs!$B$21)^(B13-1),0) -> 0 | K13: =IF(B13=Inputs!$B$23,(E13*(1+Inputs!$B$20)-(F13+G13+H13)*(1+Inputs!$B$21))/Inputs!$B$25*(1-Inputs!$B$26)*Inputs!$B$30,0) -> 0 | L13: =IF(A13=0,-'Development budget'!B9,I13-J13+K13) -> 421522.77 | M13: =1/(1+Inputs!$B$22)^A13 -> 0.4750928 | N13: =L13*M13 -> 200262.43 | O13: =SUM($L$2:L13) -> -7676660.6 | P13: =SUM($N$2:N13) -> -9031369.2 | Q13: =-'Development budget'!B9+SUM($I$2:I13)-SUM($J$2:J13) -> -7676660.6 | R13: =IF(AND(O12<0,O13>=0,L13>0),A13-1-O12/L13,0) -> 0 | S13: =IF(AND(P12<0,P13>=0,N13>0),A13-1-P12/N13,0) -> 0
A14: 12 | B14: =MAX(0,A14-Inputs!$B$24) -> 11 | C14: =IF(B14>0,Inputs!$B$2*Inputs!$B$9*Inputs!$B$10*'Executive report'!B8*(1+Inputs!$B$20)^(B14-1),0) -> 736530.33 | D14: =IF(B14>0,Inputs!$B$2*Inputs!$B$9*Inputs!$B$10*'Executive report'!B9*(1+Inputs!$B$20)^(B14-1),0) -> 0 | E14: =C14+D14 -> 736530.33 | F14: =IF(B14>0,Inputs!$B$2*Inputs!$B$9*Inputs!$B$10*Inputs!$B$4*(1+Inputs!$B$21)^(B14-1),0) -> 104224.02 | G14: =IF(B14>0,'Development budget'!B3*Inputs!$B$18*(1+Inputs!$B$21)^(B14-1),0) -> 80453.632 | H14: =IF(B14>0,Inputs!$B$19*(1+Inputs!$B$21)^(B14-1),0) -> 121899.44 | I14: =E14-SUM(F14:H14) -> 429953.23 | J14: =IF(B14=Inputs!$B$28,Inputs!$B$29*(1+Inputs!$B$21)^(B14-1),0) -> 0 | K14: =IF(B14=Inputs!$B$23,(E14*(1+Inputs!$B$20)-(F14+G14+H14)*(1+Inputs!$B$21))/Inputs!$B$25*(1-Inputs!$B$26)*Inputs!$B$30,0) -> 0 | L14: =IF(A14=0,-'Development budget'!B9,I14-J14+K14) -> 429953.23 | M14: =1/(1+Inputs!$B$22)^A14 -> 0.44401196 | N14: =L14*M14 -> 190904.38 | O14: =SUM($L$2:L14) -> -7246707.3 | P14: =SUM($N$2:N14) -> -8840464.8 | Q14: =-'Development budget'!B9+SUM($I$2:I14)-SUM($J$2:J14) -> -7246707.3 | R14: =IF(AND(O13<0,O14>=0,L14>0),A14-1-O13/L14,0) -> 0 | S14: =IF(AND(P13<0,P14>=0,N14>0),A14-1-P13/N14,0) -> 0
A15: 13 | B15: =MAX(0,A15-Inputs!$B$24) -> 12 | C15: =IF(B15>0,Inputs!$B$2*Inputs!$B$9*Inputs!$B$10*'Executive report'!B8*(1+Inputs!$B$20)^(B15-1),0) -> 751260.93 | D15: =IF(B15>0,Inputs!$B$2*Inputs!$B$9*Inputs!$B$10*'Executive report'!B9*(1+Inputs!$B$20)^(B15-1),0) -> 0 | E15: =C15+D15 -> 751260.93 | F15: =IF(B15>0,Inputs!$B$2*Inputs!$B$9*Inputs!$B$10*Inputs!$B$4*(1+Inputs!$B$21)^(B15-1),0) -> 106308.5 | G15: =IF(B15>0,'Development budget'!B3*Inputs!$B$18*(1+Inputs!$B$21)^(B15-1),0) -> 82062.704 | H15: =IF(B15>0,Inputs!$B$19*(1+Inputs!$B$21)^(B15-1),0) -> 124337.43 | I15: =E15-SUM(F15:H15) -> 438552.29 | J15: =IF(B15=Inputs!$B$28,Inputs!$B$29*(1+Inputs!$B$21)^(B15-1),0) -> 0 | K15: =IF(B15=Inputs!$B$23,(E15*(1+Inputs!$B$20)-(F15+G15+H15)*(1+Inputs!$B$21))/Inputs!$B$25*(1-Inputs!$B$26)*Inputs!$B$30,0) -> 0 | L15: =IF(A15=0,-'Development budget'!B9,I15-J15+K15) -> 438552.29 | M15: =1/(1+Inputs!$B$22)^A15 -> 0.41496445 | N15: =L15*M15 -> 181983.61 | O15: =SUM($L$2:L15) -> -6808155.1 | P15: =SUM($N$2:N15) -> -8658481.2 | Q15: =-'Development budget'!B9+SUM($I$2:I15)-SUM($J$2:J15) -> -6808155.1 | R15: =IF(AND(O14<0,O15>=0,L15>0),A15-1-O14/L15,0) -> 0 | S15: =IF(AND(P14<0,P15>=0,N15>0),A15-1-P14/N15,0) -> 0
A16: 14 | B16: =MAX(0,A16-Inputs!$B$24) -> 13 | C16: =IF(B16>0,Inputs!$B$2*Inputs!$B$9*Inputs!$B$10*'Executive report'!B8*(1+Inputs!$B$20)^(B16-1),0) -> 766286.15 | D16: =IF(B16>0,Inputs!$B$2*Inputs!$B$9*Inputs!$B$10*'Executive report'!B9*(1+Inputs!$B$20)^(B16-1),0) -> 0 | E16: =C16+D16 -> 766286.15 | F16: =IF(B16>0,Inputs!$B$2*Inputs!$B$9*Inputs!$B$10*Inputs!$B$4*(1+Inputs!$B$21)^(B16-1),0) -> 108434.67 | G16: =IF(B16>0,'Development budget'!B3*Inputs!$B$18*(1+Inputs!$B$21)^(B16-1),0) -> 83703.958 | H16: =IF(B16>0,Inputs!$B$19*(1+Inputs!$B$21)^(B16-1),0) -> 126824.18 | I16: =E16-SUM(F16:H16) -> 447323.34 | J16: =IF(B16=Inputs!$B$28,Inputs!$B$29*(1+Inputs!$B$21)^(B16-1),0) -> 0 | K16: =IF(B16=Inputs!$B$23,(E16*(1+Inputs!$B$20)-(F16+G16+H16)*(1+Inputs!$B$21))/Inputs!$B$25*(1-Inputs!$B$26)*Inputs!$B$30,0) -> 0 | L16: =IF(A16=0,-'Development budget'!B9,I16-J16+K16) -> 447323.34 | M16: =1/(1+Inputs!$B$22)^A16 -> 0.38781724 | N16: =L16*M16 -> 173479.7 | O16: =SUM($L$2:L16) -> -6360831.7 | P16: =SUM($N$2:N16) -> -8485001.5 | Q16: =-'Development budget'!B9+SUM($I$2:I16)-SUM($J$2:J16) -> -6360831.7 | R16: =IF(AND(O15<0,O16>=0,L16>0),A16-1-O15/L16,0) -> 0 | S16: =IF(AND(P15<0,P16>=0,N16>0),A16-1-P15/N16,0) -> 0
A17: 15 | B17: =MAX(0,A17-Inputs!$B$24) -> 14 | C17: =IF(B17>0,Inputs!$B$2*Inputs!$B$9*Inputs!$B$10*'Executive report'!B8*(1+Inputs!$B$20)^(B17-1),0) -> 781611.87 | D17: =IF(B17>0,Inputs!$B$2*Inputs!$B$9*Inputs!$B$10*'Executive report'!B9*(1+Inputs!$B$20)^(B17-1),0) -> 0 | E17: =C17+D17 -> 781611.87 | F17: =IF(B17>0,Inputs!$B$2*Inputs!$B$9*Inputs!$B$10*Inputs!$B$4*(1+Inputs!$B$21)^(B17-1),0) -> 110603.37 | G17: =IF(B17>0,'Development budget'!B3*Inputs!$B$18*(1+Inputs!$B$21)^(B17-1),0) -> 85378.038 | H17: =IF(B17>0,Inputs!$B$19*(1+Inputs!$B$21)^(B17-1),0) -> 129360.66 | I17: =E17-SUM(F17:H17) -> 456269.81 | J17: =IF(B17=Inputs!$B$28,Inputs!$B$29*(1+Inputs!$B$21)^(B17-1),0) -> 0 | K17: =IF(B17=Inputs!$B$23,(E17*(1+Inputs!$B$20)-(F17+G17+H17)*(1+Inputs!$B$21))/Inputs!$B$25*(1-Inputs!$B$26)*Inputs!$B$30,0) -> 0 | L17: =IF(A17=0,-'Development budget'!B9,I17-J17+K17) -> 456269.81 | M17: =1/(1+Inputs!$B$22)^A17 -> 0.36244602 | N17: =L17*M17 -> 165373.17 | O17: =SUM($L$2:L17) -> -5904561.9 | P17: =SUM($N$2:N17) -> -8319628.3 | Q17: =-'Development budget'!B9+SUM($I$2:I17)-SUM($J$2:J17) -> -5904561.9 | R17: =IF(AND(O16<0,O17>=0,L17>0),A17-1-O16/L17,0) -> 0 | S17: =IF(AND(P16<0,P17>=0,N17>0),A17-1-P16/N17,0) -> 0
A18: 16 | B18: =MAX(0,A18-Inputs!$B$24) -> 15 | C18: =IF(B18>0,Inputs!$B$2*Inputs!$B$9*Inputs!$B$10*'Executive report'!B8*(1+Inputs!$B$20)^(B18-1),0) -> 797244.11 | D18: =IF(B18>0,Inputs!$B$2*Inputs!$B$9*Inputs!$B$10*'Executive report'!B9*(1+Inputs!$B$20)^(B18-1),0) -> 0 | E18: =C18+D18 -> 797244.11 | F18: =IF(B18>0,Inputs!$B$2*Inputs!$B$9*Inputs!$B$10*Inputs!$B$4*(1+Inputs!$B$21)^(B18-1),0) -> 112815.43 | G18: =IF(B18>0,'Development budget'!B3*Inputs!$B$18*(1+Inputs!$B$21)^(B18-1),0) -> 87085.598 | H18: =IF(B18>0,Inputs!$B$19*(1+Inputs!$B$21)^(B18-1),0) -> 131947.88 | I18: =E18-SUM(F18:H18) -> 465395.2 | J18: =IF(B18=Inputs!$B$28,Inputs!$B$29*(1+Inputs!$B$21)^(B18-1),0) -> 395843.63 | K18: =IF(B18=Inputs!$B$23,(E18*(1+Inputs!$B$20)-(F18+G18+H18)*(1+Inputs!$B$21))/Inputs!$B$25*(1-Inputs!$B$26)*Inputs!$B$30,0) -> 0 | L18: =IF(A18=0,-'Development budget'!B9,I18-J18+K18) -> 69551.573 | M18: =1/(1+Inputs!$B$22)^A18 -> 0.3387346 | N18: =L18*M18 -> 23559.524 | O18: =SUM($L$2:L18) -> -5835010.3 | P18: =SUM($N$2:N18) -> -8296068.8 | Q18: =-'Development budget'!B9+SUM($I$2:I18)-SUM($J$2:J18) -> -5835010.3 | R18: =IF(AND(O17<0,O18>=0,L18>0),A18-1-O17/L18,0) -> 0 | S18: =IF(AND(P17<0,P18>=0,N18>0),A18-1-P17/N18,0) -> 0
A19: 17 | B19: =MAX(0,A19-Inputs!$B$24) -> 16 | C19: =IF(B19>0,Inputs!$B$2*Inputs!$B$9*Inputs!$B$10*'Executive report'!B8*(1+Inputs!$B$20)^(B19-1),0) -> 813188.99 | D19: =IF(B19>0,Inputs!$B$2*Inputs!$B$9*Inputs!$B$10*'Executive report'!B9*(1+Inputs!$B$20)^(B19-1),0) -> 0 | E19: =C19+D19 -> 813188.99 | F19: =IF(B19>0,Inputs!$B$2*Inputs!$B$9*Inputs!$B$10*Inputs!$B$4*(1+Inputs!$B$21)^(B19-1),0) -> 115071.74 | G19: =IF(B19>0,'Development budget'!B3*Inputs!$B$18*(1+Inputs!$B$21)^(B19-1),0) -> 88827.31 | H19: =IF(B19>0,Inputs!$B$19*(1+Inputs!$B$21)^(B19-1),0) -> 134586.83 | I19: =E19-SUM(F19:H19) -> 474703.11 | J19: =IF(B19=Inputs!$B$28,Inputs!$B$29*(1+Inputs!$B$21)^(B19-1),0) -> 0 | K19: =IF(B19=Inputs!$B$23,(E19*(1+Inputs!$B$20)-(F19+G19+H19)*(1+Inputs!$B$21))/Inputs!$B$25*(1-Inputs!$B$26)*Inputs!$B$30,0) -> 0 | L19: =IF(A19=0,-'Development budget'!B9,I19-J19+K19) -> 474703.11 | M19: =1/(1+Inputs!$B$22)^A19 -> 0.31657439 | N19: =L19*M19 -> 150278.85 | O19: =SUM($L$2:L19) -> -5360307.2 | P19: =SUM($N$2:N19) -> -8145789.9 | Q19: =-'Development budget'!B9+SUM($I$2:I19)-SUM($J$2:J19) -> -5360307.2 | R19: =IF(AND(O18<0,O19>=0,L19>0),A19-1-O18/L19,0) -> 0 | S19: =IF(AND(P18<0,P19>=0,N19>0),A19-1-P18/N19,0) -> 0
A20: 18 | B20: =MAX(0,A20-Inputs!$B$24) -> 17 | C20: =IF(B20>0,Inputs!$B$2*Inputs!$B$9*Inputs!$B$10*'Executive report'!B8*(1+Inputs!$B$20)^(B20-1),0) -> 829452.77 | D20: =IF(B20>0,Inputs!$B$2*Inputs!$B$9*Inputs!$B$10*'Executive report'!B9*(1+Inputs!$B$20)^(B20-1),0) -> 0 | E20: =C20+D20 -> 829452.77 | F20: =IF(B20>0,Inputs!$B$2*Inputs!$B$9*Inputs!$B$10*Inputs!$B$4*(1+Inputs!$B$21)^(B20-1),0) -> 117373.18 | G20: =IF(B20>0,'Development budget'!B3*Inputs!$B$18*(1+Inputs!$B$21)^(B20-1),0) -> 90603.857 | H20: =IF(B20>0,Inputs!$B$19*(1+Inputs!$B$21)^(B20-1),0) -> 137278.57 | I20: =E20-SUM(F20:H20) -> 484197.17 | J20: =IF(B20=Inputs!$B$28,Inputs!$B$29*(1+Inputs!$B$21)^(B20-1),0) -> 0 | K20: =IF(B20=Inputs!$B$23,(E20*(1+Inputs!$B$20)-(F20+G20+H20)*(1+Inputs!$B$21))/Inputs!$B$25*(1-Inputs!$B$26)*Inputs!$B$30,0) -> 0 | L20: =IF(A20=0,-'Development budget'!B9,I20-J20+K20) -> 484197.17 | M20: =1/(1+Inputs!$B$22)^A20 -> 0.29586392 | N20: =L20*M20 -> 143256.47 | O20: =SUM($L$2:L20) -> -4876110.1 | P20: =SUM($N$2:N20) -> -8002533.5 | Q20: =-'Development budget'!B9+SUM($I$2:I20)-SUM($J$2:J20) -> -4876110.1 | R20: =IF(AND(O19<0,O20>=0,L20>0),A20-1-O19/L20,0) -> 0 | S20: =IF(AND(P19<0,P20>=0,N20>0),A20-1-P19/N20,0) -> 0
A21: 19 | B21: =MAX(0,A21-Inputs!$B$24) -> 18 | C21: =IF(B21>0,Inputs!$B$2*Inputs!$B$9*Inputs!$B$10*'Executive report'!B8*(1+Inputs!$B$20)^(B21-1),0) -> 846041.83 | D21: =IF(B21>0,Inputs!$B$2*Inputs!$B$9*Inputs!$B$10*'Executive report'!B9*(1+Inputs!$B$20)^(B21-1),0) -> 0 | E21: =C21+D21 -> 846041.83 | F21: =IF(B21>0,Inputs!$B$2*Inputs!$B$9*Inputs!$B$10*Inputs!$B$4*(1+Inputs!$B$21)^(B21-1),0) -> 119720.64 | G21: =IF(B21>0,'Development budget'!B3*Inputs!$B$18*(1+Inputs!$B$21)^(B21-1),0) -> 92415.934 | H21: =IF(B21>0,Inputs!$B$19*(1+Inputs!$B$21)^(B21-1),0) -> 140024.14 | I21: =E21-SUM(F21:H21) -> 493881.11 | J21: =IF(B21=Inputs!$B$28,Inputs!$B$29*(1+Inputs!$B$21)^(B21-1),0) -> 0 | K21: =IF(B21=Inputs!$B$23,(E21*(1+Inputs!$B$20)-(F21+G21+H21)*(1+Inputs!$B$21))/Inputs!$B$25*(1-Inputs!$B$26)*Inputs!$B$30,0) -> 0 | L21: =IF(A21=0,-'Development budget'!B9,I21-J21+K21) -> 493881.11 | M21: =1/(1+Inputs!$B$22)^A21 -> 0.27650833 | N21: =L21*M21 -> 136562.24 | O21: =SUM($L$2:L21) -> -4382229 | P21: =SUM($N$2:N21) -> -7865971.2 | Q21: =-'Development budget'!B9+SUM($I$2:I21)-SUM($J$2:J21) -> -4382229 | R21: =IF(AND(O20<0,O21>=0,L21>0),A21-1-O20/L21,0) -> 0 | S21: =IF(AND(P20<0,P21>=0,N21>0),A21-1-P20/N21,0) -> 0
A22: 20 | B22: =MAX(0,A22-Inputs!$B$24) -> 19 | C22: =IF(B22>0,Inputs!$B$2*Inputs!$B$9*Inputs!$B$10*'Executive report'!B8*(1+Inputs!$B$20)^(B22-1),0) -> 862962.66 | D22: =IF(B22>0,Inputs!$B$2*Inputs!$B$9*Inputs!$B$10*'Executive report'!B9*(1+Inputs!$B$20)^(B22-1),0) -> 0 | E22: =C22+D22 -> 862962.66 | F22: =IF(B22>0,Inputs!$B$2*Inputs!$B$9*Inputs!$B$10*Inputs!$B$4*(1+Inputs!$B$21)^(B22-1),0) -> 122115.05 | G22: =IF(B22>0,'Development budget'!B3*Inputs!$B$18*(1+Inputs!$B$21)^(B22-1),0) -> 94264.252 | H22: =IF(B22>0,Inputs!$B$19*(1+Inputs!$B$21)^(B22-1),0) -> 142824.62 | I22: =E22-SUM(F22:H22) -> 503758.73 | J22: =IF(B22=Inputs!$B$28,Inputs!$B$29*(1+Inputs!$B$21)^(B22-1),0) -> 0 | K22: =IF(B22=Inputs!$B$23,(E22*(1+Inputs!$B$20)-(F22+G22+H22)*(1+Inputs!$B$21))/Inputs!$B$25*(1-Inputs!$B$26)*Inputs!$B$30,0) -> 0 | L22: =IF(A22=0,-'Development budget'!B9,I22-J22+K22) -> 503758.73 | M22: =1/(1+Inputs!$B$22)^A22 -> 0.258419 | N22: =L22*M22 -> 130180.83 | O22: =SUM($L$2:L22) -> -3878470.2 | P22: =SUM($N$2:N22) -> -7735790.4 | Q22: =-'Development budget'!B9+SUM($I$2:I22)-SUM($J$2:J22) -> -3878470.2 | R22: =IF(AND(O21<0,O22>=0,L22>0),A22-1-O21/L22,0) -> 0 | S22: =IF(AND(P21<0,P22>=0,N22>0),A22-1-P21/N22,0) -> 0
A23: 21 | B23: =MAX(0,A23-Inputs!$B$24) -> 20 | C23: =IF(B23>0,Inputs!$B$2*Inputs!$B$9*Inputs!$B$10*'Executive report'!B8*(1+Inputs!$B$20)^(B23-1),0) -> 880221.92 | D23: =IF(B23>0,Inputs!$B$2*Inputs!$B$9*Inputs!$B$10*'Executive report'!B9*(1+Inputs!$B$20)^(B23-1),0) -> 0 | E23: =C23+D23 -> 880221.92 | F23: =IF(B23>0,Inputs!$B$2*Inputs!$B$9*Inputs!$B$10*Inputs!$B$4*(1+Inputs!$B$21)^(B23-1),0) -> 124557.36 | G23: =IF(B23>0,'Development budget'!B3*Inputs!$B$18*(1+Inputs!$B$21)^(B23-1),0) -> 96149.537 | H23: =IF(B23>0,Inputs!$B$19*(1+Inputs!$B$21)^(B23-1),0) -> 145681.12 | I23: =E23-SUM(F23:H23) -> 513833.91 | J23: =IF(B23=Inputs!$B$28,Inputs!$B$29*(1+Inputs!$B$21)^(B23-1),0) -> 0 | K23: =IF(B23=Inputs!$B$23,(E23*(1+Inputs!$B$20)-(F23+G23+H23)*(1+Inputs!$B$21))/Inputs!$B$25*(1-Inputs!$B$26)*Inputs!$B$30,0) -> 0 | L23: =IF(A23=0,-'Development budget'!B9,I23-J23+K23) -> 513833.91 | M23: =1/(1+Inputs!$B$22)^A23 -> 0.24151309 | N23: =L23*M23 -> 124097.61 | O23: =SUM($L$2:L23) -> -3364636.3 | P23: =SUM($N$2:N23) -> -7611692.8 | Q23: =-'Development budget'!B9+SUM($I$2:I23)-SUM($J$2:J23) -> -3364636.3 | R23: =IF(AND(O22<0,O23>=0,L23>0),A23-1-O22/L23,0) -> 0 | S23: =IF(AND(P22<0,P23>=0,N23>0),A23-1-P22/N23,0) -> 0
A24: 22 | B24: =MAX(0,A24-Inputs!$B$24) -> 21 | C24: =IF(B24>0,Inputs!$B$2*Inputs!$B$9*Inputs!$B$10*'Executive report'!B8*(1+Inputs!$B$20)^(B24-1),0) -> 897826.36 | D24: =IF(B24>0,Inputs!$B$2*Inputs!$B$9*Inputs!$B$10*'Executive report'!B9*(1+Inputs!$B$20)^(B24-1),0) -> 0 | E24: =C24+D24 -> 897826.36 | F24: =IF(B24>0,Inputs!$B$2*Inputs!$B$9*Inputs!$B$10*Inputs!$B$4*(1+Inputs!$B$21)^(B24-1),0) -> 127048.5 | G24: =IF(B24>0,'Development budget'!B3*Inputs!$B$18*(1+Inputs!$B$21)^(B24-1),0) -> 98072.528 | H24: =IF(B24>0,Inputs!$B$19*(1+Inputs!$B$21)^(B24-1),0) -> 148594.74 | I24: =E24-SUM(F24:H24) -> 524110.59 | J24: =IF(B24=Inputs!$B$28,Inputs!$B$29*(1+Inputs!$B$21)^(B24-1),0) -> 0 | K24: =IF(B24=Inputs!$B$23,(E24*(1+Inputs!$B$20)-(F24+G24+H24)*(1+Inputs!$B$21))/Inputs!$B$25*(1-Inputs!$B$26)*Inputs!$B$30,0) -> 0 | L24: =IF(A24=0,-'Development budget'!B9,I24-J24+K24) -> 524110.59 | M24: =1/(1+Inputs!$B$22)^A24 -> 0.22571317 | N24: =L24*M24 -> 118298.66 | O24: =SUM($L$2:L24) -> -2840525.7 | P24: =SUM($N$2:N24) -> -7493394.1 | Q24: =-'Development budget'!B9+SUM($I$2:I24)-SUM($J$2:J24) -> -2840525.7 | R24: =IF(AND(O23<0,O24>=0,L24>0),A24-1-O23/L24,0) -> 0 | S24: =IF(AND(P23<0,P24>=0,N24>0),A24-1-P23/N24,0) -> 0
A25: 23 | B25: =MAX(0,A25-Inputs!$B$24) -> 22 | C25: =IF(B25>0,Inputs!$B$2*Inputs!$B$9*Inputs!$B$10*'Executive report'!B8*(1+Inputs!$B$20)^(B25-1),0) -> 915782.88 | D25: =IF(B25>0,Inputs!$B$2*Inputs!$B$9*Inputs!$B$10*'Executive report'!B9*(1+Inputs!$B$20)^(B25-1),0) -> 0 | E25: =C25+D25 -> 915782.88 | F25: =IF(B25>0,Inputs!$B$2*Inputs!$B$9*Inputs!$B$10*Inputs!$B$4*(1+Inputs!$B$21)^(B25-1),0) -> 129589.47 | G25: =IF(B25>0,'Development budget'!B3*Inputs!$B$18*(1+Inputs!$B$21)^(B25-1),0) -> 100033.98 | H25: =IF(B25>0,Inputs!$B$19*(1+Inputs!$B$21)^(B25-1),0) -> 151566.63 | I25: =E25-SUM(F25:H25) -> 534592.8 | J25: =IF(B25=Inputs!$B$28,Inputs!$B$29*(1+Inputs!$B$21)^(B25-1),0) -> 0 | K25: =IF(B25=Inputs!$B$23,(E25*(1+Inputs!$B$20)-(F25+G25+H25)*(1+Inputs!$B$21))/Inputs!$B$25*(1-Inputs!$B$26)*Inputs!$B$30,0) -> 0 | L25: =IF(A25=0,-'Development budget'!B9,I25-J25+K25) -> 534592.8 | M25: =1/(1+Inputs!$B$22)^A25 -> 0.21094688 | N25: =L25*M25 -> 112770.68 | O25: =SUM($L$2:L25) -> -2305932.9 | P25: =SUM($N$2:N25) -> -7380623.4 | Q25: =-'Development budget'!B9+SUM($I$2:I25)-SUM($J$2:J25) -> -2305932.9 | R25: =IF(AND(O24<0,O25>=0,L25>0),A25-1-O24/L25,0) -> 0 | S25: =IF(AND(P24<0,P25>=0,N25>0),A25-1-P24/N25,0) -> 0
A26: 24 | B26: =MAX(0,A26-Inputs!$B$24) -> 23 | C26: =IF(B26>0,Inputs!$B$2*Inputs!$B$9*Inputs!$B$10*'Executive report'!B8*(1+Inputs!$B$20)^(B26-1),0) -> 934098.54 | D26: =IF(B26>0,Inputs!$B$2*Inputs!$B$9*Inputs!$B$10*'Executive report'!B9*(1+Inputs!$B$20)^(B26-1),0) -> 0 | E26: =C26+D26 -> 934098.54 | F26: =IF(B26>0,Inputs!$B$2*Inputs!$B$9*Inputs!$B$10*Inputs!$B$4*(1+Inputs!$B$21)^(B26-1),0) -> 132181.26 | G26: =IF(B26>0,'Development budget'!B3*Inputs!$B$18*(1+Inputs!$B$21)^(B26-1),0) -> 102034.66 | H26: =IF(B26>0,Inputs!$B$19*(1+Inputs!$B$21)^(B26-1),0) -> 154597.97 | I26: =E26-SUM(F26:H26) -> 545284.65 | J26: =IF(B26=Inputs!$B$28,Inputs!$B$29*(1+Inputs!$B$21)^(B26-1),0) -> 0 | K26: =IF(B26=Inputs!$B$23,(E26*(1+Inputs!$B$20)-(F26+G26+H26)*(1+Inputs!$B$21))/Inputs!$B$25*(1-Inputs!$B$26)*Inputs!$B$30,0) -> 0 | L26: =IF(A26=0,-'Development budget'!B9,I26-J26+K26) -> 545284.65 | M26: =1/(1+Inputs!$B$22)^A26 -> 0.19714662 | N26: =L26*M26 -> 107501.03 | O26: =SUM($L$2:L26) -> -1760648.3 | P26: =SUM($N$2:N26) -> -7273122.4 | Q26: =-'Development budget'!B9+SUM($I$2:I26)-SUM($J$2:J26) -> -1760648.3 | R26: =IF(AND(O25<0,O26>=0,L26>0),A26-1-O25/L26,0) -> 0 | S26: =IF(AND(P25<0,P26>=0,N26>0),A26-1-P25/N26,0) -> 0
A27: 25 | B27: =MAX(0,A27-Inputs!$B$24) -> 24 | C27: =IF(B27>0,Inputs!$B$2*Inputs!$B$9*Inputs!$B$10*'Executive report'!B8*(1+Inputs!$B$20)^(B27-1),0) -> 952780.51 | D27: =IF(B27>0,Inputs!$B$2*Inputs!$B$9*Inputs!$B$10*'Executive report'!B9*(1+Inputs!$B$20)^(B27-1),0) -> 0 | E27: =C27+D27 -> 952780.51 | F27: =IF(B27>0,Inputs!$B$2*Inputs!$B$9*Inputs!$B$10*Inputs!$B$4*(1+Inputs!$B$21)^(B27-1),0) -> 134824.89 | G27: =IF(B27>0,'Development budget'!B3*Inputs!$B$18*(1+Inputs!$B$21)^(B27-1),0) -> 104075.35 | H27: =IF(B27>0,Inputs!$B$19*(1+Inputs!$B$21)^(B27-1),0) -> 157689.93 | I27: =E27-SUM(F27:H27) -> 556190.35 | J27: =IF(B27=Inputs!$B$28,Inputs!$B$29*(1+Inputs!$B$21)^(B27-1),0) -> 0 | K27: =IF(B27=Inputs!$B$23,(E27*(1+Inputs!$B$20)-(F27+G27+H27)*(1+Inputs!$B$21))/Inputs!$B$25*(1-Inputs!$B$26)*Inputs!$B$30,0) -> 0 | L27: =IF(A27=0,-'Development budget'!B9,I27-J27+K27) -> 556190.35 | M27: =1/(1+Inputs!$B$22)^A27 -> 0.18424918 | N27: =L27*M27 -> 102477.61 | O27: =SUM($L$2:L27) -> -1204457.9 | P27: =SUM($N$2:N27) -> -7170644.8 | Q27: =-'Development budget'!B9+SUM($I$2:I27)-SUM($J$2:J27) -> -1204457.9 | R27: =IF(AND(O26<0,O27>=0,L27>0),A27-1-O26/L27,0) -> 0 | S27: =IF(AND(P26<0,P27>=0,N27>0),A27-1-P26/N27,0) -> 0
A28: 26 | B28: =MAX(0,A28-Inputs!$B$24) -> 25 | C28: =IF(B28>0,Inputs!$B$2*Inputs!$B$9*Inputs!$B$10*'Executive report'!B8*(1+Inputs!$B$20)^(B28-1),0) -> 971836.12 | D28: =IF(B28>0,Inputs!$B$2*Inputs!$B$9*Inputs!$B$10*'Executive report'!B9*(1+Inputs!$B$20)^(B28-1),0) -> 0 | E28: =C28+D28 -> 971836.12 | F28: =IF(B28>0,Inputs!$B$2*Inputs!$B$9*Inputs!$B$10*Inputs!$B$4*(1+Inputs!$B$21)^(B28-1),0) -> 137521.38 | G28: =IF(B28>0,'Development budget'!B3*Inputs!$B$18*(1+Inputs!$B$21)^(B28-1),0) -> 106156.86 | H28: =IF(B28>0,Inputs!$B$19*(1+Inputs!$B$21)^(B28-1),0) -> 160843.72 | I28: =E28-SUM(F28:H28) -> 567314.15 | J28: =IF(B28=Inputs!$B$28,Inputs!$B$29*(1+Inputs!$B$21)^(B28-1),0) -> 0 | K28: =IF(B28=Inputs!$B$23,(E28*(1+Inputs!$B$20)-(F28+G28+H28)*(1+Inputs!$B$21))/Inputs!$B$25*(1-Inputs!$B$26)*Inputs!$B$30,0) -> 0 | L28: =IF(A28=0,-'Development budget'!B9,I28-J28+K28) -> 567314.15 | M28: =1/(1+Inputs!$B$22)^A28 -> 0.17219549 | N28: =L28*M28 -> 97688.94 | O28: =SUM($L$2:L28) -> -637143.77 | P28: =SUM($N$2:N28) -> -7072955.9 | Q28: =-'Development budget'!B9+SUM($I$2:I28)-SUM($J$2:J28) -> -637143.77 | R28: =IF(AND(O27<0,O28>=0,L28>0),A28-1-O27/L28,0) -> 0 | S28: =IF(AND(P27<0,P28>=0,N28>0),A28-1-P27/N28,0) -> 0
A29: 27 | B29: =MAX(0,A29-Inputs!$B$24) -> 26 | C29: =IF(B29>0,Inputs!$B$2*Inputs!$B$9*Inputs!$B$10*'Executive report'!B8*(1+Inputs!$B$20)^(B29-1),0) -> 991272.84 | D29: =IF(B29>0,Inputs!$B$2*Inputs!$B$9*Inputs!$B$10*'Executive report'!B9*(1+Inputs!$B$20)^(B29-1),0) -> 0 | E29: =C29+D29 -> 991272.84 | F29: =IF(B29>0,Inputs!$B$2*Inputs!$B$9*Inputs!$B$10*Inputs!$B$4*(1+Inputs!$B$21)^(B29-1),0) -> 140271.81 | G29: =IF(B29>0,'Development budget'!B3*Inputs!$B$18*(1+Inputs!$B$21)^(B29-1),0) -> 108280 | H29: =IF(B29>0,Inputs!$B$19*(1+Inputs!$B$21)^(B29-1),0) -> 164060.6 | I29: =E29-SUM(F29:H29) -> 578660.44 | J29: =IF(B29=Inputs!$B$28,Inputs!$B$29*(1+Inputs!$B$21)^(B29-1),0) -> 0 | K29: =IF(B29=Inputs!$B$23,(E29*(1+Inputs!$B$20)-(F29+G29+H29)*(1+Inputs!$B$21))/Inputs!$B$25*(1-Inputs!$B$26)*Inputs!$B$30,0) -> 0 | L29: =IF(A29=0,-'Development budget'!B9,I29-J29+K29) -> 578660.44 | M29: =1/(1+Inputs!$B$22)^A29 -> 0.16093037 | N29: =L29*M29 -> 93124.037 | O29: =SUM($L$2:L29) -> -58483.334 | P29: =SUM($N$2:N29) -> -6979831.8 | Q29: =-'Development budget'!B9+SUM($I$2:I29)-SUM($J$2:J29) -> -58483.334 | R29: =IF(AND(O28<0,O29>=0,L29>0),A29-1-O28/L29,0) -> 0 | S29: =IF(AND(P28<0,P29>=0,N29>0),A29-1-P28/N29,0) -> 0
A30: 28 | B30: =MAX(0,A30-Inputs!$B$24) -> 27 | C30: =IF(B30>0,Inputs!$B$2*Inputs!$B$9*Inputs!$B$10*'Executive report'!B8*(1+Inputs!$B$20)^(B30-1),0) -> 1011098.3 | D30: =IF(B30>0,Inputs!$B$2*Inputs!$B$9*Inputs!$B$10*'Executive report'!B9*(1+Inputs!$B$20)^(B30-1),0) -> 0 | E30: =C30+D30 -> 1011098.3 | F30: =IF(B30>0,Inputs!$B$2*Inputs!$B$9*Inputs!$B$10*Inputs!$B$4*(1+Inputs!$B$21)^(B30-1),0) -> 143077.25 | G30: =IF(B30>0,'Development budget'!B3*Inputs!$B$18*(1+Inputs!$B$21)^(B30-1),0) -> 110445.6 | H30: =IF(B30>0,Inputs!$B$19*(1+Inputs!$B$21)^(B30-1),0) -> 167341.81 | I30: =E30-SUM(F30:H30) -> 590233.65 | J30: =IF(B30=Inputs!$B$28,Inputs!$B$29*(1+Inputs!$B$21)^(B30-1),0) -> 0 | K30: =IF(B30=Inputs!$B$23,(E30*(1+Inputs!$B$20)-(F30+G30+H30)*(1+Inputs!$B$21))/Inputs!$B$25*(1-Inputs!$B$26)*Inputs!$B$30,0) -> 0 | L30: =IF(A30=0,-'Development budget'!B9,I30-J30+K30) -> 590233.65 | M30: =1/(1+Inputs!$B$22)^A30 -> 0.15040221 | N30: =L30*M30 -> 88772.446 | O30: =SUM($L$2:L30) -> 531750.31 | P30: =SUM($N$2:N30) -> -6891059.4 | Q30: =-'Development budget'!B9+SUM($I$2:I30)-SUM($J$2:J30) -> 531750.31 | R30: =IF(AND(O29<0,O30>=0,L30>0),A30-1-O29/L30,0) -> 27.099085 | S30: =IF(AND(P29<0,P30>=0,N30>0),A30-1-P29/N30,0) -> 0
A31: 29 | B31: =MAX(0,A31-Inputs!$B$24) -> 28 | C31: =IF(B31>0,Inputs!$B$2*Inputs!$B$9*Inputs!$B$10*'Executive report'!B8*(1+Inputs!$B$20)^(B31-1),0) -> 1031320.3 | D31: =IF(B31>0,Inputs!$B$2*Inputs!$B$9*Inputs!$B$10*'Executive report'!B9*(1+Inputs!$B$20)^(B31-1),0) -> 0 | E31: =C31+D31 -> 1031320.3 | F31: =IF(B31>0,Inputs!$B$2*Inputs!$B$9*Inputs!$B$10*Inputs!$B$4*(1+Inputs!$B$21)^(B31-1),0) -> 145938.79 | G31: =IF(B31>0,'Development budget'!B3*Inputs!$B$18*(1+Inputs!$B$21)^(B31-1),0) -> 112654.51 | H31: =IF(B31>0,Inputs!$B$19*(1+Inputs!$B$21)^(B31-1),0) -> 170688.65 | I31: =E31-SUM(F31:H31) -> 602038.32 | J31: =IF(B31=Inputs!$B$28,Inputs!$B$29*(1+Inputs!$B$21)^(B31-1),0) -> 0 | K31: =IF(B31=Inputs!$B$23,(E31*(1+Inputs!$B$20)-(F31+G31+H31)*(1+Inputs!$B$21))/Inputs!$B$25*(1-Inputs!$B$26)*Inputs!$B$30,0) -> 0 | L31: =IF(A31=0,-'Development budget'!B9,I31-J31+K31) -> 602038.32 | M31: =1/(1+Inputs!$B$22)^A31 -> 0.14056282 | N31: =L31*M31 -> 84624.201 | O31: =SUM($L$2:L31) -> 1133788.6 | P31: =SUM($N$2:N31) -> -6806435.2 | Q31: =-'Development budget'!B9+SUM($I$2:I31)-SUM($J$2:J31) -> 1133788.6 | R31: =IF(AND(O30<0,O31>=0,L31>0),A31-1-O30/L31,0) -> 0 | S31: =IF(AND(P30<0,P31>=0,N31>0),A31-1-P30/N31,0) -> 0
A32: 30 | B32: =MAX(0,A32-Inputs!$B$24) -> 29 | C32: =IF(B32>0,Inputs!$B$2*Inputs!$B$9*Inputs!$B$10*'Executive report'!B8*(1+Inputs!$B$20)^(B32-1),0) -> 1051946.7 | D32: =IF(B32>0,Inputs!$B$2*Inputs!$B$9*Inputs!$B$10*'Executive report'!B9*(1+Inputs!$B$20)^(B32-1),0) -> 0 | E32: =C32+D32 -> 1051946.7 | F32: =IF(B32>0,Inputs!$B$2*Inputs!$B$9*Inputs!$B$10*Inputs!$B$4*(1+Inputs!$B$21)^(B32-1),0) -> 148857.57 | G32: =IF(B32>0,'Development budget'!B3*Inputs!$B$18*(1+Inputs!$B$21)^(B32-1),0) -> 114907.6 | H32: =IF(B32>0,Inputs!$B$19*(1+Inputs!$B$21)^(B32-1),0) -> 174102.42 | I32: =E32-SUM(F32:H32) -> 614079.09 | J32: =IF(B32=Inputs!$B$28,Inputs!$B$29*(1+Inputs!$B$21)^(B32-1),0) -> 0 | K32: =IF(B32=Inputs!$B$23,(E32*(1+Inputs!$B$20)-(F32+G32+H32)*(1+Inputs!$B$21))/Inputs!$B$25*(1-Inputs!$B$26)*Inputs!$B$30,0) -> 0 | L32: =IF(A32=0,-'Development budget'!B9,I32-J32+K32) -> 614079.09 | M32: =1/(1+Inputs!$B$22)^A32 -> 0.13136712 | N32: =L32*M32 -> 80669.799 | O32: =SUM($L$2:L32) -> 1747867.7 | P32: =SUM($N$2:N32) -> -6725765.4 | Q32: =-'Development budget'!B9+SUM($I$2:I32)-SUM($J$2:J32) -> 1747867.7 | R32: =IF(AND(O31<0,O32>=0,L32>0),A32-1-O31/L32,0) -> 0 | S32: =IF(AND(P31<0,P32>=0,N32>0),A32-1-P31/N32,0) -> 0
A33: 31 | B33: =MAX(0,A33-Inputs!$B$24) -> 30 | C33: =IF(B33>0,Inputs!$B$2*Inputs!$B$9*Inputs!$B$10*'Executive report'!B8*(1+Inputs!$B$20)^(B33-1),0) -> 1072985.6 | D33: =IF(B33>0,Inputs!$B$2*Inputs!$B$9*Inputs!$B$10*'Executive report'!B9*(1+Inputs!$B$20)^(B33-1),0) -> 0 | E33: =C33+D33 -> 1072985.6 | F33: =IF(B33>0,Inputs!$B$2*Inputs!$B$9*Inputs!$B$10*Inputs!$B$4*(1+Inputs!$B$21)^(B33-1),0) -> 151834.72 | G33: =IF(B33>0,'Development budget'!B3*Inputs!$B$18*(1+Inputs!$B$21)^(B33-1),0) -> 117205.75 | H33: =IF(B33>0,Inputs!$B$19*(1+Inputs!$B$21)^(B33-1),0) -> 177584.47 | I33: =E33-SUM(F33:H33) -> 626360.67 | J33: =IF(B33=Inputs!$B$28,Inputs!$B$29*(1+Inputs!$B$21)^(B33-1),0) -> 0 | K33: =IF(B33=Inputs!$B$23,(E33*(1+Inputs!$B$20)-(F33+G33+H33)*(1+Inputs!$B$21))/Inputs!$B$25*(1-Inputs!$B$26)*Inputs!$B$30,0) -> 10435169 | L33: =IF(A33=0,-'Development budget'!B9,I33-J33+K33) -> 11061529 | M33: =1/(1+Inputs!$B$22)^A33 -> 0.12277301 | N33: =L33*M33 -> 1358057.2 | O33: =SUM($L$2:L33) -> 12809397 | P33: =SUM($N$2:N33) -> -5367708.2 | Q33: =-'Development budget'!B9+SUM($I$2:I33)-SUM($J$2:J33) -> 2374228.4 | R33: =IF(AND(O32<0,O33>=0,L33>0),A33-1-O32/L33,0) -> 0 | S33: =IF(AND(P32<0,P33>=0,N33>0),A33-1-P32/N33,0) -> 0

Sheet Sensitivity
A1: Case | B1: All-in market price | C1: Occupancy | D1: Paid months | E1: Capex multiplier | F1: Terminal sale | G1: NPV EUR | H1: Interpretation
A2: Base | B2: 600 | C2: 0.95 | D2: 12 | E2: 1 | F2: 1 | G2: =NPV(Inputs!$B$22,'Scenario cash flows'!B3:B33)+'Scenario cash flows'!B2 -> -5367708.2 | H2: Benchmark / explicit stress; no forecast probability assigned
A3: Shared benchmark price | B3: 525 | C3: 0.95 | D3: 12 | E3: 1 | F3: 1 | G3: =NPV(Inputs!$B$22,'Scenario cash flows'!C3:C33)+'Scenario cash flows'!C2 -> -6590438.4 | H3: Benchmark / explicit stress; no forecast probability assigned
A4: Lower collection | B4: 600 | C4: 0.85 | D4: 12 | E4: 1 | F4: 1 | G4: =NPV(Inputs!$B$22,'Scenario cash flows'!D3:D33)+'Scenario cash flows'!D2 -> -6343768.6 | H4: Benchmark / explicit stress; no forecast probability assigned
A5: 10 paid months | B5: 600 | C5: 0.95 | D5: 10 | E5: 1 | F5: 1 | G5: =NPV(Inputs!$B$22,'Scenario cash flows'!E3:E33)+'Scenario cash flows'!E2 -> -6913137.2 | H5: Benchmark / explicit stress; no forecast probability assigned
A6: 20% development overrun | B6: 600 | C6: 0.95 | D6: 12 | E6: 1.2 | F6: 1 | G6: =NPV(Inputs!$B$22,'Scenario cash flows'!F3:F33)+'Scenario cash flows'!F2 -> -7675458.6 | H6: Benchmark / explicit stress; no forecast probability assigned
A7: No sale proceeds | B7: 600 | C7: 0.95 | D7: 12 | E7: 1 | F7: 0 | G7: =NPV(Inputs!$B$22,'Scenario cash flows'!G3:G33)+'Scenario cash flows'!G2 -> -6648865.2 | H7: Benchmark / explicit stress; no forecast probability assigned

Sheet Regulations
A1: Topic | B1: Official rule / project action | C1: Source
A2: Student lease | B2: Maximum 12 months; tenant may terminate with two months notice without penalty. Lease length is not average residence length. | C2: S3
A3: Deposit | B3: Maximum two months rent for leases concluded/renewed from 1 Nov 2024. No average deposit identified. Held for tenant; not investor revenue. | C3: S2
A4: Quality label | B4: Optional quality label lasts five years; application includes compliance declaration, student lease and valid PEB certificate. | C4: S5
A5: Site approvals | B5: Before purchase verify zoning, building permit, fire safety, habitability, accessibility and energy performance with competent authorities. No site approved by this workbook. | C5: S4 p7; site-specific review needed
A6: Utilities | B6: Show base rent and charges separately; actual billing and annual reconciliations require a compliant lease. Model assumes full cost recovery when separately billed. | C6: Model assumption; obtain lease and meter plan

Sheet Sources
A1: ID | B1: Official publisher / title | C1: URL | D1: Reference period / page | E1: Access date | F1: Use / limitation
A2: S1 | B2: Perspective — Panorama de la vie étudiante | C2: https://perspective.brussels/sites/default/files/documents/rapport_enquete_panorama_de_la_vie_etudiante.pdf | D2: Survey 2023–24; Feb 2025; pp55,56,110,8 | E2: 2026-10-14 | F2: Historical rent / student budget; no future forecast
A3: S2 | B3: Brussels Region — garantie locative | C3: https://be.brussels/fr/logement/location/bail-dhabitation/garantie-locative | D3: Effective 2024-11-01 | E3: 2026-10-14 | F3: Deposit legal cap
A4: S3 | B4: Brussels Region — contrats de bail | C4: https://be.brussels/fr/logement/location/bail-dhabitation/contrat-de-bail-modeles-et-annexe | D4: Current page | E4: 2026-10-14 | F4: Student lease term and termination
A5: S4 | B5: Perspective — Monitoring student housing no.1 | C5: https://perspective.brussels/sites/default/files/documents/fr_monitoring_logement_etudiant_final2026.pdf | D5: 2025 inventory; published 2026; pp26,28,7 | E5: 2026-10-14 | F5: Dedicated stock and estimated demand; no live vacancy or measured total shortage
A6: S5 | B6: Brussels Region — label logement étudiant | C6: https://be.brussels/fr/logement/location/conformite-logement/label-logement-etudiant | D6: Current page | E6: 2026-10-14 | F6: Quality label
A7: S6 | B7: Statbel — residential property price index | C7: https://statbel.fgov.be/fr/themes/construction-logement/indice-des-prix-des-logements | D7: Q2 2026; published 25 Sep 2026 | E7: 2026-10-14 | F7: Transaction price index is not EUR/m2 construction cost; not used as a construction quote

Sheet Methods
A1: Calculation | B1: Original formula / convention
A2: NPV | B2: NPV = CF0 + sum(CFt/(1+r)^t), t=1..31. Excel NPV excludes t=0; add it explicitly.
A3: IRR | B3: IRR solves 0 = sum(CFt/(1+IRR)^t). Excel IRR on all cash flows including t=0; equally spaced annual periods.
A4: PBP | B4: First crossing k with cumulative CFk >= 0: (k-1) + abs(cumulative CF(k-1))/CFk. Includes terminal sale; separately show operating-only recovery.
A5: Discounted PBP | B5: Same crossing formula using discounted cash flows. If no crossing within 31 years, display Not recovered.
A6: Revenue | B6: Rooms × paid months × occupancy × blended monthly price; affordable units priced at min(policy budget threshold, market price).
A7: Utility billing | B7: Included rent = all-in price. Separate mode rent = all-in price minus utility allowance; utility recovery equals allowance. Model preserves total receipts.
A8: NOI | B8: Total receipts - utility expense - maintenance - other operating costs. Cash flow = NOI - replacement capex + terminal proceeds.
A9: Terminal value | B9: Next year NOI / terminal cap rate × (1-selling cost), received at the end of final operating year; optional zero-sale stress.
A10: Threshold budget | B10: Affordable threshold = official historical student-housing spending budget × policy share. This is not an official income-based definition.
A11: Data gaps | B11: No official project-specific land, build, maintenance, utility, occupancy, discount rate, exit yield, average stay/deposit or live vacancy data verified. Those cells remain explicit assumptions or Unknown.
A12: Reproduction | B12: Run python3 build_model.py; requires openpyxl. Atomic save and cached formula values are generated. Cached values reflect the default inputs; Excel recalculates when inputs change.

Sheet Scenario cash flows
A1: Year | B1: Base | C1: Shared benchmark price | D1: Lower collection | E1: 10 paid months | F1: 20% development overrun | G1: No sale proceeds
A2: 0 | B2: =-'Development budget'!B9*Sensitivity!E2 -> -11538752 | C2: =-'Development budget'!B9*Sensitivity!E3 -> -11538752 | D2: =-'Development budget'!B9*Sensitivity!E4 -> -11538752 | E2: =-'Development budget'!B9*Sensitivity!E5 -> -11538752 | F2: =-'Development budget'!B9*Sensitivity!E6 -> -13846502 | G2: =-'Development budget'!B9*Sensitivity!E7 -> -11538752
A3: 1 | B3: =0 -> 0 | C3: =0 -> 0 | D3: =0 -> 0 | E3: =0 -> 0 | F3: =0 -> 0 | G3: =0 -> 0
A4: 2 | B4: ='Cash flows'!I4-'Cash flows'!J4+(Inputs!$B$2*Sensitivity!D2*Sensitivity!C2*((1-Inputs!$B$6)*Sensitivity!B2+Inputs!$B$6*MIN('Executive report'!B5,Sensitivity!B2))*(1+Inputs!$B$20)^('Cash flows'!B4-1)-'Cash flows'!E4-( Inputs!$B$2*Sensitivity!D2*Sensitivity!C2*Inputs!$B$4*(1+Inputs!$B$21)^('Cash flows'!B4-1)-'Cash flows'!F4)) -> 352711.4 | C4: ='Cash flows'!I4-'Cash flows'!J4+(Inputs!$B$2*Sensitivity!D3*Sensitivity!C3*((1-Inputs!$B$6)*Sensitivity!B3+Inputs!$B$6*MIN('Executive report'!B5,Sensitivity!B3))*(1+Inputs!$B$20)^('Cash flows'!B4-1)-'Cash flows'!E4-( Inputs!$B$2*Sensitivity!D3*Sensitivity!C3*Inputs!$B$4*(1+Inputs!$B$21)^('Cash flows'!B4-1)-'Cash flows'!F4)) -> 284311.4 | D4: ='Cash flows'!I4-'Cash flows'!J4+(Inputs!$B$2*Sensitivity!D4*Sensitivity!C4*((1-Inputs!$B$6)*Sensitivity!B4+Inputs!$B$6*MIN('Executive report'!B5,Sensitivity!B4))*(1+Inputs!$B$20)^('Cash flows'!B4-1)-'Cash flows'!E4-( Inputs!$B$2*Sensitivity!D4*Sensitivity!C4*Inputs!$B$4*(1+Inputs!$B$21)^('Cash flows'!B4-1)-'Cash flows'!F4)) -> 298110.2 | E4: ='Cash flows'!I4-'Cash flows'!J4+(Inputs!$B$2*Sensitivity!D5*Sensitivity!C5*((1-Inputs!$B$6)*Sensitivity!B5+Inputs!$B$6*MIN('Executive report'!B5,Sensitivity!B5))*(1+Inputs!$B$20)^('Cash flows'!B4-1)-'Cash flows'!E4-( Inputs!$B$2*Sensitivity!D5*Sensitivity!C5*Inputs!$B$4*(1+Inputs!$B$21)^('Cash flows'!B4-1)-'Cash flows'!F4)) -> 266259.5 | F4: ='Cash flows'!I4-'Cash flows'!J4+(Inputs!$B$2*Sensitivity!D6*Sensitivity!C6*((1-Inputs!$B$6)*Sensitivity!B6+Inputs!$B$6*MIN('Executive report'!B5,Sensitivity!B6))*(1+Inputs!$B$20)^('Cash flows'!B4-1)-'Cash flows'!E4-( Inputs!$B$2*Sensitivity!D6*Sensitivity!C6*Inputs!$B$4*(1+Inputs!$B$21)^('Cash flows'!B4-1)-'Cash flows'!F4)) -> 352711.4 | G4: ='Cash flows'!I4-'Cash flows'!J4+(Inputs!$B$2*Sensitivity!D7*Sensitivity!C7*((1-Inputs!$B$6)*Sensitivity!B7+Inputs!$B$6*MIN('Executive report'!B5,Sensitivity!B7))*(1+Inputs!$B$20)^('Cash flows'!B4-1)-'Cash flows'!E4-( Inputs!$B$2*Sensitivity!D7*Sensitivity!C7*Inputs!$B$4*(1+Inputs!$B$21)^('Cash flows'!B4-1)-'Cash flows'!F4)) -> 352711.4
A5: 3 | B5: ='Cash flows'!I5-'Cash flows'!J5+(Inputs!$B$2*Sensitivity!D2*Sensitivity!C2*((1-Inputs!$B$6)*Sensitivity!B2+Inputs!$B$6*MIN('Executive report'!B5,Sensitivity!B2))*(1+Inputs!$B$20)^('Cash flows'!B5-1)-'Cash flows'!E5-( Inputs!$B$2*Sensitivity!D2*Sensitivity!C2*Inputs!$B$4*(1+Inputs!$B$21)^('Cash flows'!B5-1)-'Cash flows'!F5)) -> 359765.63 | C5: ='Cash flows'!I5-'Cash flows'!J5+(Inputs!$B$2*Sensitivity!D3*Sensitivity!C3*((1-Inputs!$B$6)*Sensitivity!B3+Inputs!$B$6*MIN('Executive report'!B5,Sensitivity!B3))*(1+Inputs!$B$20)^('Cash flows'!B5-1)-'Cash flows'!E5-( Inputs!$B$2*Sensitivity!D3*Sensitivity!C3*Inputs!$B$4*(1+Inputs!$B$21)^('Cash flows'!B5-1)-'Cash flows'!F5)) -> 289997.63 | D5: ='Cash flows'!I5-'Cash flows'!J5+(Inputs!$B$2*Sensitivity!D4*Sensitivity!C4*((1-Inputs!$B$6)*Sensitivity!B4+Inputs!$B$6*MIN('Executive report'!B5,Sensitivity!B4))*(1+Inputs!$B$20)^('Cash flows'!B5-1)-'Cash flows'!E5-( Inputs!$B$2*Sensitivity!D4*Sensitivity!C4*Inputs!$B$4*(1+Inputs!$B$21)^('Cash flows'!B5-1)-'Cash flows'!F5)) -> 304072.4 | E5: ='Cash flows'!I5-'Cash flows'!J5+(Inputs!$B$2*Sensitivity!D5*Sensitivity!C5*((1-Inputs!$B$6)*Sensitivity!B5+Inputs!$B$6*MIN('Executive report'!B5,Sensitivity!B5))*(1+Inputs!$B$20)^('Cash flows'!B5-1)-'Cash flows'!E5-( Inputs!$B$2*Sensitivity!D5*Sensitivity!C5*Inputs!$B$4*(1+Inputs!$B$21)^('Cash flows'!B5-1)-'Cash flows'!F5)) -> 271584.69 | F5: ='Cash flows'!I5-'Cash flows'!J5+(Inputs!$B$2*Sensitivity!D6*Sensitivity!C6*((1-Inputs!$B$6)*Sensitivity!B6+Inputs!$B$6*MIN('Executive report'!B5,Sensitivity!B6))*(1+Inputs!$B$20)^('Cash flows'!B5-1)-'Cash flows'!E5-( Inputs!$B$2*Sensitivity!D6*Sensitivity!C6*Inputs!$B$4*(1+Inputs!$B$21)^('Cash flows'!B5-1)-'Cash flows'!F5)) -> 359765.63 | G5: ='Cash flows'!I5-'Cash flows'!J5+(Inputs!$B$2*Sensitivity!D7*Sensitivity!C7*((1-Inputs!$B$6)*Sensitivity!B7+Inputs!$B$6*MIN('Executive report'!B5,Sensitivity!B7))*(1+Inputs!$B$20)^('Cash flows'!B5-1)-'Cash flows'!E5-( Inputs!$B$2*Sensitivity!D7*Sensitivity!C7*Inputs!$B$4*(1+Inputs!$B$21)^('Cash flows'!B5-1)-'Cash flows'!F5)) -> 359765.63
A6: 4 | B6: ='Cash flows'!I6-'Cash flows'!J6+(Inputs!$B$2*Sensitivity!D2*Sensitivity!C2*((1-Inputs!$B$6)*Sensitivity!B2+Inputs!$B$6*MIN('Executive report'!B5,Sensitivity!B2))*(1+Inputs!$B$20)^('Cash flows'!B6-1)-'Cash flows'!E6-( Inputs!$B$2*Sensitivity!D2*Sensitivity!C2*Inputs!$B$4*(1+Inputs!$B$21)^('Cash flows'!B6-1)-'Cash flows'!F6)) -> 366960.94 | C6: ='Cash flows'!I6-'Cash flows'!J6+(Inputs!$B$2*Sensitivity!D3*Sensitivity!C3*((1-Inputs!$B$6)*Sensitivity!B3+Inputs!$B$6*MIN('Executive report'!B5,Sensitivity!B3))*(1+Inputs!$B$20)^('Cash flows'!B6-1)-'Cash flows'!E6-( Inputs!$B$2*Sensitivity!D3*Sensitivity!C3*Inputs!$B$4*(1+Inputs!$B$21)^('Cash flows'!B6-1)-'Cash flows'!F6)) -> 295797.58 | D6: ='Cash flows'!I6-'Cash flows'!J6+(Inputs!$B$2*Sensitivity!D4*Sensitivity!C4*((1-Inputs!$B$6)*Sensitivity!B4+Inputs!$B$6*MIN('Executive report'!B5,Sensitivity!B4))*(1+Inputs!$B$20)^('Cash flows'!B6-1)-'Cash flows'!E6-( Inputs!$B$2*Sensitivity!D4*Sensitivity!C4*Inputs!$B$4*(1+Inputs!$B$21)^('Cash flows'!B6-1)-'Cash flows'!F6)) -> 310153.85 | E6: ='Cash flows'!I6-'Cash flows'!J6+(Inputs!$B$2*Sensitivity!D5*Sensitivity!C5*((1-Inputs!$B$6)*Sensitivity!B5+Inputs!$B$6*MIN('Executive report'!B5,Sensitivity!B5))*(1+Inputs!$B$20)^('Cash flows'!B6-1)-'Cash flows'!E6-( Inputs!$B$2*Sensitivity!D5*Sensitivity!C5*Inputs!$B$4*(1+Inputs!$B$21)^('Cash flows'!B6-1)-'Cash flows'!F6)) -> 277016.38 | F6: ='Cash flows'!I6-'Cash flows'!J6+(Inputs!$B$2*Sensitivity!D6*Sensitivity!C6*((1-Inputs!$B$6)*Sensitivity!B6+Inputs!$B$6*MIN('Executive report'!B5,Sensitivity!B6))*(1+Inputs!$B$20)^('Cash flows'!B6-1)-'Cash flows'!E6-( Inputs!$B$2*Sensitivity!D6*Sensitivity!C6*Inputs!$B$4*(1+Inputs!$B$21)^('Cash flows'!B6-1)-'Cash flows'!F6)) -> 366960.94 | G6: ='Cash flows'!I6-'Cash flows'!J6+(Inputs!$B$2*Sensitivity!D7*Sensitivity!C7*((1-Inputs!$B$6)*Sensitivity!B7+Inputs!$B$6*MIN('Executive report'!B5,Sensitivity!B7))*(1+Inputs!$B$20)^('Cash flows'!B6-1)-'Cash flows'!E6-( Inputs!$B$2*Sensitivity!D7*Sensitivity!C7*Inputs!$B$4*(1+Inputs!$B$21)^('Cash flows'!B6-1)-'Cash flows'!F6)) -> 366960.94
