Workbook

Sheet Executive Report
A1: BRUSSELS STUDENT HOUSING | B1: EXECUTIVE DECISION REPORT | v2.0
A2: Recommendation | B2: Conditional shortlist: maximize affordable beds under the EUR15m planning budget.
A3: Evidence | B3: Brussels average total rent EUR695 in Kotkompas 2025–2026; designated supply is constrained (Sources).
A4: Approval gate | B4: Municipal and project policy applicability, social eligibility and quotes must be confirmed before commitment.
A5: Decision metric | B5: Affordable beds first, NPV second; no probability weighting; projects are illustrative.
A6: Feasible combinations | B6: =SUM(Portfolios!O2:O257) -> 75
A7: Recommended combination index | B7: =MATCH(MAX(Portfolios!Q2:Q257),Portfolios!Q2:Q257,0) -> 31
A8: KPI | B8: Recommended | C8: Manual selection
A9: Total investment | B9: =SUMPRODUCT(Projects!N2:N9,Projects!R2:R9) -> 14500000 | C9: =SUMPRODUCT(Projects!N2:N9,Projects!H2:H9) -> 14500000
A10: Total beds | B10: =SUMPRODUCT(Projects!C2:C9,Projects!R2:R9) -> 350 | C10: =SUMPRODUCT(Projects!C2:C9,Projects!H2:H9) -> 350
A11: Affordable beds | B11: =SUMPRODUCT(Projects!D2:D9,Projects!R2:R9) -> 172 | C11: =SUMPRODUCT(Projects!D2:D9,Projects!H2:H9) -> 172
A12: NPV incl terminal value | B12: =SUMPRODUCT(Projects!O2:O9,Projects!R2:R9) -> 11863873 | C12: =SUMPRODUCT(Projects!O2:O9,Projects!H2:H9) -> 11863873
A13: Year 1 NOI | B13: =SUMPRODUCT(Projects!M2:M9,Projects!R2:R9) -> 1216467.7 | C13: =SUMPRODUCT(Projects!M2:M9,Projects!H2:H9) -> 1216467.7
A14: Year 1 NOI yield | B14: =IFERROR(B13/B9,0) -> 0.083894324
A15: Budget headroom | B15: =Inputs!B2-B9 -> 500000
A16: Manual planning status | C16: =IF(AND(C9<=Inputs!B2,C11>=Inputs!B3,C12>=Inputs!B18,SUMPRODUCT(Projects!H2:H9,Projects!Q2:Q9)=SUM(Projects!H2:H9)),"PLANNING FEASIBLE","FAIL") -> PLANNING FEASIBLE
A18: Shortlist at saved inputs | B18: D / Etterbeek, E / Schaerbeek, F / Jette, G / Molenbeek-Saint-Jean
A19: Interpretation | B19: Recommendation updates via Projects R when inputs change; this text records the saved-input shortlist.
A20: Affordability | B20: EUR550 all-in ceiling is a course planning definition. It does not establish social-housing legal compliance.
A21: Municipal differences | B21: City Brussels policy: 20% from 30 student units. Ixelles: 15% for large projects. Other 17 minima unverified.
A22: Risk | B22: Downside: NPV about -EUR0.43m and cost EUR16.675m, exceeding the EUR15m budget. Secure contingency or reduce scope before commitment.
A23: Next agile sprint | B23: Validate thresholds and allocation with municipalities/AISE; replace costs with quotes; add delivery schedule and debt only after evidence.
A24: Decision requested | B24: Approve further feasibility work on the shortlist; capital commitment remains conditional on due diligence.

Sheet Guide
A1: HOW TO USE | B1: Decision model v2.0 | 14 October 2026
A2: 1 | B2: Read Executive Report. All eight developments are hypothetical investment opportunities.
A3: 2 | B3: Blue cells are editable assumptions; green cells hold external evidence; black cells are formulas.
A4: 3 | B4: Edit Inputs, project costs/rents/beds, municipal planning percentages and policy applicability.
A5: 4 | B5: Projects H is manual selection 0/1. Dashboard compares manual selection with the live optimal recommendation.
A6: 5 | B6: Portfolios enumerates all 256 binary combinations: maximize affordable beds, then NPV at equal beds.
A7: 6 | B7: Feasible requires budget, at least target affordable beds, nonnegative portfolio NPV and all selected projects passing planning/rent checks.
A8: 7 | B8: Municipal source evidence is distinct from verified legal approval. Unknown requirements do not mean zero requirements.
A9: 8 | B9: Change project policy applicability to 1 only when a cited policy applies; social allocation and rent must be validated separately.
A10: 9 | B10: Recommendation is conditional feasibility analysis. Obtain municipal confirmation, quotes, demand studies and due diligence before investment.
A11: 10 | B11: Reopen in Excel to recalculate edits. Run python3 build_model.py to regenerate defaults; it overwrites manual edits.
A12: Scope | B12: Unlevered pre-tax cash flow; no borrowing, grants, corporate tax, construction delays or VAT separately. Total cost inputs must include acquisition, fees, taxes and contingency.
... A15: Authors | B15: Nisa, Maite, Ilias — names supplied with uncertainty; confirm before course submission.

Sheet Inputs
A1: Parameter | B1: Value | C1: Definition / evidence
A2: Capital budget | B2: 15000000 | C2: EUR; total development outlay; illustrative
A3: Minimum affordable beds | B3: 80 | C3: Portfolio target; illustrative
A4: Base occupancy | B4: 0.95 | C4: Same for both rent classes; illustrative
A5: Months billed | B5: 12 | C5: Annual contracts; illustrative
A6: Variable operating share | B6: 0.15 | C6: Share of collected base rents; illustrative
A7: Fixed annual operating cost / bed | B7: 1600 | C7: EUR; includes reserve, insurance, maintenance; illustrative
A8: Rent and operating growth | B8: 0.02 | C8: Annual; both rent and costs grow at same rate
A9: Discount rate | B9: 0.06 | C9: Unlevered nominal annual hurdle; illustrative
A10: Exit capitalization rate | B10: 0.055 | C10: Terminal value on year 21 NOI; illustrative
A11: Sale cost share | B11: 0.02 | C11: Terminal sale proceeds haircut
A12: Hold years | B12: 20 | C12: Fixed 20-year DCF; change code to alter horizon
A13: Affordable all-in rent ceiling | B13: 550 | C13: EUR/month; course definition, not legal social-rent definition
... A18: Portfolio minimum NPV | B18: 0 | C18: Unlevered; positive-NPV requirement

Sheet Municipalities
A1: Municipality | B1: Sourced policy share | C1: Planning share (editable) | D1: Activation / scope | E1: Evidence status | F1: Source
A2: Anderlecht | C2: 0.25 | D2: Unknown; request project-specific minimum | E2: UNVERIFIED | F2: Not yet located
A3: Auderghem | C3: 0.25 | D3: Unknown; request project-specific minimum | E3: UNVERIFIED | F3: Not yet located
A4: Berchem-Sainte-Agathe | C4: 0.25 | D4: Unknown; request project-specific minimum | E4: UNVERIFIED | F4: Not yet located
A5: Bruxelles-Ville | B5: 0.2 | C5: 0.25 | D5: >=30 student units; social allocation | E5: POLICY FOUND; application not verified | F5: https://www.bruxelles.be/sites/default/files/bxl/Recommandations_logements_etudiants_VBX_17juin2021.pdf
A6: Etterbeek | C6: 0.25 | D6: Unknown; request project-specific minimum | E6: UNVERIFIED | F6: Not yet located
A7: Evere | C7: 0.25 | D7: Unknown; request project-specific minimum | E7: UNVERIFIED | F7: Not yet located
A8: Forest | C8: 0.25 | D8: Unknown; request project-specific minimum | E8: UNVERIFIED | F8: Not yet located
A9: Ganshoren | C9: 0.25 | D9: Unknown; request project-specific minimum | E9: UNVERIFIED | F9: Not yet located
A10: Ixelles | B10: 0.15 | C10: 0.25 | D10: Large kot projects; trigger needs confirmation | E10: POLICY FOUND; application not verified | F10: https://www.ixelles.be/site/downloads/publications/infoxl-2014-/infoxl20250304.pdf
A11: Jette | C11: 0.25 | D11: Unknown; request project-specific minimum | E11: UNVERIFIED | F11: Not yet located
A12: Koekelberg | C12: 0.25 | D12: Unknown; request project-specific minimum | E12: UNVERIFIED | F12: Not yet located
A13: Molenbeek-Saint-Jean | C13: 0.25 | D13: Unknown; request project-specific minimum | E13: UNVERIFIED | F13: Not yet located
A14: Saint-Gilles | C14: 0.25 | D14: Unknown; request project-specific minimum | E14: UNVERIFIED | F14: Not yet located
A15: Saint-Josse-ten-Noode | C15: 0.25 | D15: Unknown; request project-specific minimum | E15: UNVERIFIED | F15: Not yet located
A16: Schaerbeek | C16: 0.25 | D16: Unknown; request project-specific minimum | E16: UNVERIFIED | F16: Not yet located
A17: Uccle | C17: 0.25 | D17: Unknown; request project-specific minimum | E17: UNVERIFIED | F17: Not yet located
A18: Watermael-Boitsfort | C18: 0.25 | D18: Unknown; request project-specific minimum | E18: UNVERIFIED | F18: Not yet located
A19: Woluwe-Saint-Lambert | C19: 0.25 | D19: Unknown; request project-specific minimum | E19: UNVERIFIED | F19: Not yet located
A20: Woluwe-Saint-Pierre | C20: 0.25 | D20: Unknown; request project-specific minimum | E20: UNVERIFIED | F20: Not yet located

Sheet Projects
A1: ID | B1: Municipality | C1: Beds | D1: Affordable beds | E1: Affordable base rent/mo | F1: Market base rent/mo | G1: Total development cost | H1: Manual select 0/1 | I1: Policy applies 0/1 | J1: Effective planning minimum | K1: Required affordable beds | L1: Year 1 collected rent | M1: Year 1 NOI | N1: Cost with overrun | O1: NPV incl exit | P1: NOI yield | Q1: Planning & rent pass | R1: Recommended select | S1: Affordable all-in rent
A2: A | B2: Bruxelles-Ville | C2: 100 | D2: 40 | E2: 440 | F2: 680 | G2: 4800000 | H2: 0 | I2: 1 | J2: =MAX(Municipalities!C5,IF(I2=1,Municipalities!B5,0)) -> 0.25 | K2: =ROUNDUP(C2*J2,0) -> 25 | L2: =(D2*E2+(C2-D2)*F2)*Inputs!B5*Inputs!B4 -> 665760 | M2: =L2*(1-Inputs!B6)-C2*Inputs!B7 -> 405896 | N2: =G2*(1+Inputs!B17) -> 4800000 | O2: =SUM('Cash Flows'!D2:D22) -> 3996773.4 | P2: =IFERROR(M2/N2,0) -> 0.084561667 | Q2: =IF(AND(D2>=K2,D2<=C2,E2+Inputs!B14<=Inputs!B13,C2>0,D2>=0,E2>0,F2>0,G2>0),1,0) -> 1 | R2: =IF('Executive Report'!B6=0,0,INDEX(Portfolios!B$2:B$257,'Executive Report'!B7)) -> 0 | S2: =E2+Inputs!B14 -> 540
A3: B | B3: Ixelles | C3: 80 | D3: 24 | E3: 450 | F3: 730 | G3: 4300000 | H3: 0 | I3: 1 | J3: =MAX(Municipalities!C10,IF(I3=1,Municipalities!B10,0)) -> 0.25 | K3: =ROUNDUP(C3*J3,0) -> 20 | L3: =(D3*E3+(C3-D3)*F3)*Inputs!B5*Inputs!B4 -> 589152 | M3: =L3*(1-Inputs!B6)-C3*Inputs!B7 -> 372779.2 | N3: =G3*(1+Inputs!B17) -> 4300000 | O3: =SUM('Cash Flows'!D23:D43) -> 3779050.2 | P3: =IFERROR(M3/N3,0) -> 0.086692837 | Q3: =IF(AND(D3>=K3,D3<=C3,E3+Inputs!B14<=Inputs!B13,C3>0,D3>=0,E3>0,F3>0,G3>0),1,0) -> 1 | R3: =IF('Executive Report'!B6=0,0,INDEX(Portfolios!C$2:C$257,'Executive Report'!B7)) -> 0 | S3: =E3+Inputs!B14 -> 550
A4: C | B4: Anderlecht | C4: 120 | D4: 60 | E4: 400 | F4: 620 | G4: 4900000 | H4: 0 | I4: 0 | J4: =MAX(Municipalities!C2,IF(I4=1,Municipalities!B2,0)) -> 0.25 | K4: =ROUNDUP(C4*J4,0) -> 30 | L4: =(D4*E4+(C4-D4)*F4)*Inputs!B5*Inputs!B4 -> 697680 | M4: =L4*(1-Inputs!B6)-C4*Inputs!B7 -> 401028 | N4: =G4*(1+Inputs!B17) -> 4900000 | O4: =SUM('Cash Flows'!D44:D64) -> 3791271.7 | P4: =IFERROR(M4/N4,0) -> 0.081842449 | Q4: =IF(AND(D4>=K4,D4<=C4,E4+Inputs!B14<=Inputs!B13,C4>0,D4>=0,E4>0,F4>0,G4>0),1,0) -> 1 | R4: =IF('Executive Report'!B6=0,0,INDEX(Portfolios!D$2:D$257,'Executive Report'!B7)) -> 0 | S4: =E4+Inputs!B14 -> 500
A5: D | B5: Etterbeek | C5: 70 | D5: 21 | E5: 440 | F5: 700 | G5: 3400000 | H5: 1 | I5: 0 | J5: =MAX(Municipalities!C6,IF(I5=1,Municipalities!B6,0)) -> 0.25 | K5: =ROUNDUP(C5*J5,0) -> 18 | L5: =(D5*E5+(C5-D5)*F5)*Inputs!B5*Inputs!B4 -> 496356 | M5: =L5*(1-Inputs!B6)-C5*Inputs!B7 -> 309902.6 | N5: =G5*(1+Inputs!B17) -> 3400000 | O5: =SUM('Cash Flows'!D65:D85) -> 3316358.2 | P5: =IFERROR(M5/N5,0) -> 0.091147824 | Q5: =IF(AND(D5>=K5,D5<=C5,E5+Inputs!B14<=Inputs!B13,C5>0,D5>=0,E5>0,F5>0,G5>0),1,0) -> 1 | R5: =IF('Executive Report'!B6=0,0,INDEX(Portfolios!E$2:E$257,'Executive Report'!B7)) -> 1 | S5: =E5+Inputs!B14 -> 540
A6: E | B6: Schaerbeek | C6: 90 | D6: 45 | E6: 410 | F6: 640 | G6: 3800000 | H6: 1 | I6: 0 | J6: =MAX(Municipalities!C16,IF(I6=1,Municipalities!B16,0)) -> 0.25 | K6: =ROUNDUP(C6*J6,0) -> 23 | L6: =(D6*E6+(C6-D6)*F6)*Inputs!B5*Inputs!B4 -> 538650 | M6: =L6*(1-Inputs!B6)-C6*Inputs!B7 -> 313852.5 | N6: =G6*(1+Inputs!B17) -> 3800000 | O6: =SUM('Cash Flows'!D86:D106) -> 3001962.4 | P6: =IFERROR(M6/N6,0) -> 0.082592763 | Q6: =IF(AND(D6>=K6,D6<=C6,E6+Inputs!B14<=Inputs!B13,C6>0,D6>=0,E6>0,F6>0,G6>0),1,0) -> 1 | R6: =IF('Executive Report'!B6=0,0,INDEX(Portfolios!F$2:F$257,'Executive Report'!B7)) -> 1 | S6: =E6+Inputs!B14 -> 510
A7: F | B7: Jette | C7: 80 | D7: 40 | E7: 400 | F7: 610 | G7: 3200000 | H7: 1 | I7: 0 | J7: =MAX(Municipalities!C11,IF(I7=1,Municipalities!B11,0)) -> 0.25 | K7: =ROUNDUP(C7*J7,0) -> 20 | L7: =(D7*E7+(C7-D7)*F7)*Inputs!B5*Inputs!B4 -> 460560 | M7: =L7*(1-Inputs!B6)-C7*Inputs!B7 -> 263476 | N7: =G7*(1+Inputs!B17) -> 3200000 | O7: =SUM('Cash Flows'!D107:D127) -> 2510178.6 | P7: =IFERROR(M7/N7,0) -> 0.08233625 | Q7: =IF(AND(D7>=K7,D7<=C7,E7+Inputs!B14<=Inputs!B13,C7>0,D7>=0,E7>0,F7>0,G7>0),1,0) -> 1 | R7: =IF('Executive Report'!B6=0,0,INDEX(Portfolios!G$2:G$257,'Executive Report'!B7)) -> 1 | S7: =E7+Inputs!B14 -> 500
A8: G | B8: Molenbeek-Saint-Jean | C8: 110 | D8: 66 | E8: 390 | F8: 600 | G8: 4100000 | H8: 1 | I8: 0 | J8: =MAX(Municipalities!C13,IF(I8=1,Municipalities!B13,0)) -> 0.25 | K8: =ROUNDUP(C8*J8,0) -> 28 | L8: =(D8*E8+(C8-D8)*F8)*Inputs!B5*Inputs!B4 -> 594396 | M8: =L8*(1-Inputs!B6)-C8*Inputs!B7 -> 329236.6 | N8: =G8*(1+Inputs!B17) -> 4100000 | O8: =SUM('Cash Flows'!D128:D148) -> 3035374 | P8: =IFERROR(M8/N8,0) -> 0.08030161 | Q8: =IF(AND(D8>=K8,D8<=C8,E8+Inputs!B14<=Inputs!B13,C8>0,D8>=0,E8>0,F8>0,G8>0),1,0) -> 1 | R8: =IF('Executive Report'!B6=0,0,INDEX(Portfolios!H$2:H$257,'Executive Report'!B7)) -> 1 | S8: =E8+Inputs!B14 -> 490
A9: H | B9: Woluwe-Saint-Lambert | C9: 90 | D9: 27 | E9: 450 | F9: 720 | G9: 4500000 | H9: 0 | I9: 0 | J9: =MAX(Municipalities!C19,IF(I9=1,Municipalities!B19,0)) -> 0.25 | K9: =ROUNDUP(C9*J9,0) -> 23 | L9: =(D9*E9+(C9-D9)*F9)*Inputs!B5*Inputs!B4 -> 655614 | M9: =L9*(1-Inputs!B6)-C9*Inputs!B7 -> 413271.9 | N9: =G9*(1+Inputs!B17) -> 4500000 | O9: =SUM('Cash Flows'!D149:D169) -> 4456627.4 | P9: =IFERROR(M9/N9,0) -> 0.0918382 | Q9: =IF(AND(D9>=K9,D9<=C9,E9+Inputs!B14<=Inputs!B13,C9>0,D9>=0,E9>0,F9>0,G9>0),1,0) -> 1 | R9: =IF('Executive Report'!B6=0,0,INDEX(Portfolios!I$2:I$257,'Executive Report'!B7)) -> 0 | S9: =E9+Inputs!B14 -> 550

Sheet Cash Flows
A1: Project | B1: Year | C1: Unlevered cash flow | D1: Discounted cash flow
A2: A | B2: 0 | C2: =-Projects!N2 -> -4800000 | D2: =C2/(1+Inputs!B9)^B2 -> -4800000
A3: A | B3: 1 | C3: =Projects!M2*(1+Inputs!B8)^(B3-1) -> 405896 | D3: =C3/(1+Inputs!B9)^B3 -> 382920.75
A4: A | B4: 2 | C4: =Projects!M2*(1+Inputs!B8)^(B4-1) -> 414013.92 | D4: =C4/(1+Inputs!B9)^B4 -> 368470.91
A5: A | B5: 3 | C5: =Projects!M2*(1+Inputs!B8)^(B5-1) -> 422294.2 | D5: =C5/(1+Inputs!B9)^B5 -> 354566.35
A6: A | B6: 4 | C6: =Projects!M2*(1+Inputs!B8)^(B6-1) -> 430740.08 | D6: =C6/(1+Inputs!B9)^B6 -> 341186.49
A7: A | B7: 5 | C7: =Projects!M2*(1+Inputs!B8)^(B7-1) -> 439354.88 | D7: =C7/(1+Inputs!B9)^B7 -> 328311.53
A8: A | B8: 6 | C8: =Projects!M2*(1+Inputs!B8)^(B8-1) -> 448141.98 | D8: =C8/(1+Inputs!B9)^B8 -> 315922.41
A9: A | B9: 7 | C9: =Projects!M2*(1+Inputs!B8)^(B9-1) -> 457104.82 | D9: =C9/(1+Inputs!B9)^B9 -> 304000.81
A10: A | B10: 8 | C10: =Projects!M2*(1+Inputs!B8)^(B10-1) -> 466246.92 | D10: =C10/(1+Inputs!B9)^B10 -> 292529.08
A11: A | B11: 9 | C11: =Projects!M2*(1+Inputs!B8)^(B11-1) -> 475571.86 | D11: =C11/(1+Inputs!B9)^B11 -> 281490.25
A12: A | B12: 10 | C12: =Projects!M2*(1+Inputs!B8)^(B12-1) -> 485083.29 | D12: =C12/(1+Inputs!B9)^B12 -> 270867.98
A13: A | B13: 11 | C13: =Projects!M2*(1+Inputs!B8)^(B13-1) -> 494784.96 | D13: =C13/(1+Inputs!B9)^B13 -> 260646.54
A14: A | B14: 12 | C14: =Projects!M2*(1+Inputs!B8)^(B14-1) -> 504680.66 | D14: =C14/(1+Inputs!B9)^B14 -> 250810.83
A15: A | B15: 13 | C15: =Projects!M2*(1+Inputs!B8)^(B15-1) -> 514774.27 | D15: =C15/(1+Inputs!B9)^B15 -> 241346.27
A16: A | B16: 14 | C16: =Projects!M2*(1+Inputs!B8)^(B16-1) -> 525069.76 | D16: =C16/(1+Inputs!B9)^B16 -> 232238.86
A17: A | B17: 15 | C17: =Projects!M2*(1+Inputs!B8)^(B17-1) -> 535571.15 | D17: =C17/(1+Inputs!B9)^B17 -> 223475.13
A18: A | B18: 16 | C18: =Projects!M2*(1+Inputs!B8)^(B18-1) -> 546282.58 | D18: =C18/(1+Inputs!B9)^B18 -> 215042.11
A19: A | B19: 17 | C19: =Projects!M2*(1+Inputs!B8)^(B19-1) -> 557208.23 | D19: =C19/(1+Inputs!B9)^B19 -> 206927.31
A20: A | B20: 18 | C20: =Projects!M2*(1+Inputs!B8)^(B20-1) -> 568352.39 | D20: =C20/(1+Inputs!B9)^B20 -> 199118.73
A21: A | B21: 19 | C21: =Projects!M2*(1+Inputs!B8)^(B21-1) -> 579719.44 | D21: =C21/(1+Inputs!B9)^B21 -> 191604.82
A22: A | B22: 20 | C22: =Projects!M2*(1+Inputs!B8)^(B22-1)+Projects!M2*(1+Inputs!B8)^20/Inputs!B10*(1-Inputs!B11) -> 11338174 | D22: =C22/(1+Inputs!B9)^B22 -> 3535296.2
A23: B | B23: 0 | C23: =-Projects!N3 -> -4300000 | D23: =C23/(1+Inputs!B9)^B23 -> -4300000
A24: B | B24: 1 | C24: =Projects!M3*(1+Inputs!B8)^(B24-1) -> 372779.2 | D24: =C24/(1+Inputs!B9)^B24 -> 351678.49
A25: B | B25: 2 | C25: =Projects!M3*(1+Inputs!B8)^(B25-1) -> 380234.78 | D25: =C25/(1+Inputs!B9)^B25 -> 338407.6
A26: B | B26: 3 | C26: =Projects!M3*(1+Inputs!B8)^(B26-1) -> 387839.48 | D26: =C26/(1+Inputs!B9)^B26 -> 325637.51
A27: B | B27: 4 | C27: =Projects!M3*(1+Inputs!B8)^(B27-1) -> 395596.27 | D27: =C27/(1+Inputs!B9)^B27 -> 313349.3
A28: B | B28: 5 | C28: =Projects!M3*(1+Inputs!B8)^(B28-1) -> 403508.19 | D28: =C28/(1+Inputs!B9)^B28 -> 301524.8
A29: B | B29: 6 | C29: =Projects!M3*(1+Inputs!B8)^(B29-1) -> 411578.36 | D29: =C29/(1+Inputs!B9)^B29 -> 290146.5
A30: B | B30: 7 | C30: =Projects!M3*(1+Inputs!B8)^(B30-1) -> 419809.93 | D30: =C30/(1+Inputs!B9)^B30 -> 279197.58
A31: B | B31: 8 | C31: =Projects!M3*(1+Inputs!B8)^(B31-1) -> 428206.12 | D31: =C31/(1+Inputs!B9)^B31 -> 268661.82
A32: B | B32: 9 | C32: =Projects!M3*(1+Inputs!B8)^(B32-1) -> 436770.25 | D32: =C32/(1+Inputs!B9)^B32 -> 258523.64
A33: B | B33: 10 | C33: =Projects!M3*(1+Inputs!B8)^(B33-1) -> 445505.65 | D33: =C33/(1+Inputs!B9)^B33 -> 248768.03
A34: B | B34: 11 | C34: =Projects!M3*(1+Inputs!B8)^(B34-1) -> 454415.76 | D34: =C34/(1+Inputs!B9)^B34 -> 239380.56
A35: B | B35: 12 | C35: =Projects!M3*(1+Inputs!B8)^(B35-1) -> 463504.08 | D35: =C35/(1+Inputs!B9)^B35 -> 230347.33
A36: B | B36: 13 | C36: =Projects!M3*(1+Inputs!B8)^(B36-1) -> 472774.16 | D36: =C36/(1+Inputs!B9)^B36 -> 221654.98
A37: B | B37: 14 | C37: =Projects!M3*(1+Inputs!B8)^(B37-1) -> 482229.64 | D37: =C37/(1+Inputs!B9)^B37 -> 213290.64
A38: B | B38: 15 | C38: =Projects!M3*(1+Inputs!B8)^(B38-1) -> 491874.24 | D38: =C38/(1+Inputs!B9)^B38 -> 205241.93
A39: B | B39: 16 | C39: =Projects!M3*(1+Inputs!B8)^(B39-1) -> 501711.72 | D39: =C39/(1+Inputs!B9)^B39 -> 197496.96
A40: B | B40: 17 | C40: =Projects!M3*(1+Inputs!B8)^(B40-1) -> 511745.96 | D40: =C40/(1+Inputs!B9)^B40 -> 190044.24
...

Sheet Portfolios
A1: Combination | B1: A | C1: B | D1: C | E1: D | F1: E | G1: F | H1: G | I1: H | J1: Cost | K1: Beds | L1: Affordable beds | M1: NPV | N1: Selected planning failures | O1: Feasible | P1: Affordable objective | Q1: NPV tie break
A2: 0 | B2: 0 | C2: 0 | D2: 0 | E2: 0 | F2: 0 | G2: 0 | H2: 0 | I2: 0 | J2: =B2*Projects!N2+C2*Projects!N3+D2*Projects!N4+E2*Projects!N5+F2*Projects!N6+G2*Projects!N7+H2*Projects!N8+I2*Projects!N9 -> 0 | K2: =B2*Projects!C2+C2*Projects!C3+D2*Projects!C4+E2*Projects!C5+F2*Projects!C6+G2*Projects!C7+H2*Projects!C8+I2*Projects!C9 -> 0 | L2: =B2*Projects!D2+C2*Projects!D3+D2*Projects!D4+E2*Projects!D5+F2*Projects!D6+G2*Projects!D7+H2*Projects!D8+I2*Projects!D9 -> 0 | M2: =B2*Projects!O2+C2*Projects!O3+D2*Projects!O4+E2*Projects!O5+F2*Projects!O6+G2*Projects!O7+H2*Projects!O8+I2*Projects!O9 -> 0 | N2: =B2*(1-Projects!Q2)+C2*(1-Projects!Q3)+D2*(1-Projects!Q4)+E2*(1-Projects!Q5)+F2*(1-Projects!Q6)+G2*(1-Projects!Q7)+H2*(1-Projects!Q8)+I2*(1-Projects!Q9) -> 0 | O2: =IF(AND(J2<=Inputs!B2,L2>=Inputs!B3,M2>=Inputs!B18,N2=0),1,0) -> 0 | P2: =IF(O2=1,L2,-1) -> -1 | Q2: =IF(AND(O2=1,L2=MAX(P$2:P$257)),M2,-1E+99) -> -1e+99
A3: 1 | B3: 0 | C3: 0 | D3: 0 | E3: 0 | F3: 0 | G3: 0 | H3: 0 | I3: 1 | J3: =B3*Projects!N2+C3*Projects!N3+D3*Projects!N4+E3*Projects!N5+F3*Projects!N6+G3*Projects!N7+H3*Projects!N8+I3*Projects!N9 -> 4500000 | K3: =B3*Projects!C2+C3*Projects!C3+D3*Projects!C4+E3*Projects!C5+F3*Projects!C6+G3*Projects!C7+H3*Projects!C8+I3*Projects!C9 -> 90 | L3: =B3*Projects!D2+C3*Projects!D3+D3*Projects!D4+E3*Projects!D5+F3*Projects!D6+G3*Projects!D7+H3*Projects!D8+I3*Projects!D9 -> 27 | M3: =B3*Projects!O2+C3*Projects!O3+D3*Projects!O4+E3*Projects!O5+F3*Projects!O6+G3*Projects!O7+H3*Projects!O8+I3*Projects!O9 -> 4456627.4 | N3: =B3*(1-Projects!Q2)+C3*(1-Projects!Q3)+D3*(1-Projects!Q4)+E3*(1-Projects!Q5)+F3*(1-Projects!Q6)+G3*(1-Projects!Q7)+H3*(1-Projects!Q8)+I3*(1-Projects!Q9) -> 0 | O3: =IF(AND(J3<=Inputs!B2,L3>=Inputs!B3,M3>=Inputs!B18,N3=0),1,0) -> 0 | P3: =IF(O3=1,L3,-1) -> -1 | Q3: =IF(AND(O3=1,L3=MAX(P$2:P$257)),M3,-1E+99) -> -1e+99
A4: 2 | B4: 0 | C4: 0 | D4: 0 | E4: 0 | F4: 0 | G4: 0 | H4: 1 | I4: 0 | J4: =B4*Projects!N2+C4*Projects!N3+D4*Projects!N4+E4*Projects!N5+F4*Projects!N6+G4*Projects!N7+H4*Projects!N8+I4*Projects!N9 -> 4100000 | K4: =B4*Projects!C2+C4*Projects!C3+D4*Projects!C4+E4*Projects!C5+F4*Projects!C6+G4*Projects!C7+H4*Projects!C8+I4*Projects!C9 -> 110 | L4: =B4*Projects!D2+C4*Projects!D3+D4*Projects!D4+E4*Projects!D5+F4*Projects!D6+G4*Projects!D7+H4*Projects!D8+I4*Projects!D9 -> 66 | M4: =B4*Projects!O2+C4*Projects!O3+D4*Projects!O4+E4*Projects!O5+F4*Projects!O6+G4*Projects!O7+H4*Projects!O8+I4*Projects!O9 -> 3035374 | N4: =B4*(1-Projects!Q2)+C4*(1-Projects!Q3)+D4*(1-Projects!Q4)+E4*(1-Projects!Q5)+F4*(1-Projects!Q6)+G4*(1-Projects!Q7)+H4*(1-Projects!Q8)+I4*(1-Projects!Q9) -> 0 | O4: =IF(AND(J4<=Inputs!B2,L4>=Inputs!B3,M4>=Inputs!B18,N4=0),1,0) -> 0 | P4: =IF(O4=1,L4,-1) -> -1 | Q4: =IF(AND(O4=1,L4=MAX(P$2:P$257)),M4,-1E+99) -> -1e+99
A5: 3 | B5: 0 | C5: 0 | D5: 0 | E5: 0 | F5: 0 | G5: 0 | H5: 1 | I5: 1 | J5: =B5*Projects!N2+C5*Projects!N3+D5*Projects!N4+E5*Projects!N5+F5*Projects!N6+G5*Projects!N7+H5*Projects!N8+I5*Projects!N9 -> 8600000 | K5: =B5*Projects!C2+C5*Projects!C3+D5*Projects!C4+E5*Projects!C5+F5*Projects!C6+G5*Projects!C7+H5*Projects!C8+I5*Projects!C9 -> 200 | L5: =B5*Projects!D2+C5*Projects!D3+D5*Projects!D4+E5*Projects!D5+F5*Projects!D6+G5*Projects!D7+H5*Projects!D8+I5*Projects!D9 -> 93 | M5: =B5*Projects!O2+C5*Projects!O3+D5*Projects!O4+E5*Projects!O5+F5*Projects!O6+G5*Projects!O7+H5*Projects!O8+I5*Projects!O9 -> 7492001.4 | N5: =B5*(1-Projects!Q2)+C5*(1-Projects!Q3)+D5*(1-Projects!Q4)+E5*(1-Projects!Q5)+F5*(1-Projects!Q6)+G5*(1-Projects!Q7)+H5*(1-Projects!Q8)+I5*(1-Projects!Q9) -> 0 | O5: =IF(AND(J5<=Inputs!B2,L5>=Inputs!B3,M5>=Inputs!B18,N5=0),1,0) -> 1 | P5: =IF(O5=1,L5,-1) -> 93 | Q5: =IF(AND(O5=1,L5=MAX(P$2:P$257)),M5,-1E+99) -> -1e+99
A6: 4 | B6: 0 | C6: 0 | D6: 0 | E6: 0 | F6: 0 | G6: 1 | H6: 0 | I6: 0 | J6: =B6*Projects!N2+C6*Projects!N3+D6*Projects!N4+E6*Projects!N5+F6*Projects!N6+G6*Projects!N7+H6*Projects!N8+I6*Projects!N9 -> 3200000 | K6: =B6*Projects!C2+C6*Projects!C3+D6*Projects!C4+E6*Projects!C5+F6*Projects!C6+G6*Projects!C7+H6*Projects!C8+I6*Projects!C9 -> 80 | L6: =B6*Projects!D2+C6*Projects!D3+D6*Projects!D4+E6*Projects!D5+F6*Projects!D6+G6*Projects!D7+H6*Projects!D8+I6*Projects!D9 -> 40 | M6: =B6*Projects!O2+C6*Projects!O3+D6*Projects!O4+E6*Projects!O5+F6*Projects!O6+G6*Projects!O7+H6*Projects!O8+I6*Projects!O9 -> 2510178.6 | N6: =B6*(1-Projects!Q2)+C6*(1-Projects!Q3)+D6*(1-Projects!Q4)+E6*(1-Projects!Q5)+F6*(1-Projects!Q6)+G6*(1-Projects!Q7)+H6*(1-Projects!Q8)+I6*(1-Projects!Q9) -> 0 | O6: =IF(AND(J6<=Inputs!B2,L6>=Inputs!B3,M6>=Inputs!B18,N6=0),1,0) -> 0 | P6: =IF(O6=1,L6,-1) -> -1 | Q6: =IF(AND(O6=1,L6=MAX(P$2:P$257)),M6,-1E+99) -> -1e+99
A7: 5 | B7: 0 | C7: 0 | D7: 0 | E7: 0 | F7: 0 | G7: 1 | H7: 0 | I7: 1 | J7: =B7*Projects!N2+C7*Projects!N3+D7*Projects!N4+E7*Projects!N5+F7*Projects!N6+G7*Projects!N7+H7*Projects!N8+I7*Projects!N9 -> 7700000 | K7: =B7*Projects!C2+C7*Projects!C3+D7*Projects!C4+E7*Projects!C5+F7*Projects!C6+G7*Projects!C7+H7*Projects!C8+I7*Projects!C9 -> 170 | L7: =B7*Projects!D2+C7*Projects!D3+D7*Projects!D4+E7*Projects!D5+F7*Projects!D6+G7*Projects!D7+H7*Projects!D8+I7*Projects!D9 -> 67 | M7: =B7*Projects!O2+C7*Projects!O3+D7*Projects!O4+E7*Projects!O5+F7*Projects!O6+G7*Projects!O7+H7*Projects!O8+I7*Projects!O9 -> 6966806 | N7: =B7*(1-Projects!Q2)+C7*(1-Projects!Q3)+D7*(1-Projects!Q4)+E7*(1-Projects!Q5)+F7*(1-Projects!Q6)+G7*(1-Projects!Q7)+H7*(1-Projects!Q8)+I7*(1-Projects!Q9) -> 0 | O7: =IF(AND(J7<=Inputs!B2,L7>=Inputs!B3,M7>=Inputs!B18,N7=0),1,0) -> 0 | P7: =IF(O7=1,L7,-1) -> -1 | Q7: =IF(AND(O7=1,L7=MAX(P$2:P$257)),M7,-1E+99) -> -1e+99
A8: 6 | B8: 0 | C8: 0 | D8: 0 | E8: 0 | F8: 0 | G8: 1 | H8: 1 | I8: 0 | J8: =B8*Projects!N2+C8*Projects!N3+D8*Projects!N4+E8*Projects!N5+F8*Projects!N6+G8*Projects!N7+H8*Projects!N8+I8*Projects!N9 -> 7300000 | K8: =B8*Projects!C2+C8*Projects!C3+D8*Projects!C4+E8*Projects!C5+F8*Projects!C6+G8*Projects!C7+H8*Projects!C8+I8*Projects!C9 -> 190 | L8: =B8*Projects!D2+C8*Projects!D3+D8*Projects!D4+E8*Projects!D5+F8*Projects!D6+G8*Projects!D7+H8*Projects!D8+I8*Projects!D9 -> 106 | M8: =B8*Projects!O2+C8*Projects!O3+D8*Projects!O4+E8*Projects!O5+F8*Projects!O6+G8*Projects!O7+H8*Projects!O8+I8*Projects!O9 -> 5545552.6 | N8: =B8*(1-Projects!Q2)+C8*(1-Projects!Q3)+D8*(1-Projects!Q4)+E8*(1-Projects!Q5)+F8*(1-Projects!Q6)+G8*(1-Projects!Q7)+H8*(1-Projects!Q8)+I8*(1-Projects!Q9) -> 0 | O8: =IF(AND(J8<=Inputs!B2,L8>=Inputs!B3,M8>=Inputs!B18,N8=0),1,0) -> 1 | P8: =IF(O8=1,L8,-1) -> 106 | Q8: =IF(AND(O8=1,L8=MAX(P$2:P$257)),M8,-1E+99) -> -1e+99
A9: 7 | B9: 0 | C9: 0 | D9: 0 | E9: 0 | F9: 0 | G9: 1 | H9: 1 | I9: 1 | J9: =B9*Projects!N2+C9*Projects!N3+D9*Projects!N4+E9*Projects!N5+F9*Projects!N6+G9*Projects!N7+H9*Projects!N8+I9*Projects!N9 -> 11800000 | K9: =B9*Projects!C2+C9*Projects!C3+D9*Projects!C4+E9*Projects!C5+F9*Projects!C6+G9*Projects!C7+H9*Projects!C8+I9*Projects!C9 -> 280 | L9: =B9*Projects!D2+C9*Projects!D3+D9*Projects!D4+E9*Projects!D5+F9*Projects!D6+G9*Projects!D7+H9*Projects!D8+I9*Projects!D9 -> 133 | M9: =B9*Projects!O2+C9*Projects!O3+D9*Projects!O4+E9*Projects!O5+F9*Projects!O6+G9*Projects!O7+H9*Projects!O8+I9*Projects!O9 -> 10002180 | N9: =B9*(1-Projects!Q2)+C9*(1-Projects!Q3)+D9*(1-Projects!Q4)+E9*(1-Projects!Q5)+F9*(1-Projects!Q6)+G9*(1-Projects!Q7)+H9*(1-Projects!Q8)+I9*(1-Projects!Q9) -> 0 | O9: =IF(AND(J9<=Inputs!B2,L9>=Inputs!B3,M9>=Inputs!B18,N9=0),1,0) -> 1 | P9: =IF(O9=1,L9,-1) -> 133 | Q9: =IF(AND(O9=1,L9=MAX(P$2:P$257)),M9,-1E+99) -> -1e+99
A10: 8 | B10: 0 | C10: 0 | D10: 0 | E10: 0 | F10: 1 | G10: 0 | H10: 0 | I10: 0 | J10: =B10*Projects!N2+C10*Projects!N3+D10*Projects!N4+E10*Projects!N5+F10*Projects!N6+G10*Projects!N7+H10*Projects!N8+I10*Projects!N9 -> 3800000 | K10: =B10*Projects!C2+C10*Projects!C3+D10*Projects!C4+E10*Projects!C5+F10*Projects!C6+G10*Projects!C7+H10*Projects!C8+I10*Projects!C9 -> 90 | L10: =B10*Projects!D2+C10*Projects!D3+D10*Projects!D4+E10*Projects!D5+F10*Projects!D6+G10*Projects!D7+H10*Projects!D8+I10*Projects!D9 -> 45 | M10: =B10*Projects!O2+C10*Projects!O3+D10*Projects!O4+E10*Projects!O5+F10*Projects!O6+G10*Projects!O7+H10*Projects!O8+I10*Projects!O9 -> 3001962.4 | N10: =B10*(1-Projects!Q2)+C10*(1-Projects!Q3)+D10*(1-Projects!Q4)+E10*(1-Projects!Q5)+F10*(1-Projects!Q6)+G10*(1-Projects!Q7)+H10*(1-Projects!Q8)+I10*(1-Projects!Q9) -> 0 | O10: =IF(AND(J10<=Inputs!B2,L10>=Inputs!B3,M10>=Inputs!B18,N10=0),1,0) -> 0 | P10: =IF(O10=1,L10,-1) -> -1 | Q10: =IF(AND(O10=1,L10=MAX(P$2:P$257)),M10,-1E+99) -> -1e+99
A11: 9 | B11: 0 | C11: 0 | D11: 0 | E11: 0 | F11: 1 | G11: 0 | H11: 0 | I11: 1 | J11: =B11*Projects!N2+C11*Projects!N3+D11*Projects!N4+E11*Projects!N5+F11*Projects!N6+G11*Projects!N7+H11*Projects!N8+I11*Projects!N9 -> 8300000 | K11: =B11*Projects!C2+C11*Projects!C3+D11*Projects!C4+E11*Projects!C5+F11*Projects!C6+G11*Projects!C7+H11*Projects!C8+I11*Projects!C9 -> 180 | L11: =B11*Projects!D2+C11*Projects!D3+D11*Projects!D4+E11*Projects!D5+F11*Projects!D6+G11*Projects!D7+H11*Projects!D8+I11*Projects!D9 -> 72 | M11: =B11*Projects!O2+C11*Projects!O3+D11*Projects!O4+E11*Projects!O5+F11*Projects!O6+G11*Projects!O7+H11*Projects!O8+I11*Projects!O9 -> 7458589.8 | N11: =B11*(1-Projects!Q2)+C11*(1-Projects!Q3)+D11*(1-Projects!Q4)+E11*(1-Projects!Q5)+F11*(1-Projects!Q6)+G11*(1-Projects!Q7)+H11*(1-Projects!Q8)+I11*(1-Projects!Q9) -> 0 | O11: =IF(AND(J11<=Inputs!B2,L11>=Inputs!B3,M11>=Inputs!B18,N11=0),1,0) -> 0 | P11: =IF(O11=1,L11,-1) -> -1 | Q11: =IF(AND(O11=1,L11=MAX(P$2:P$257)),M11,-1E+99) -> -1e+99
A12: 10 | B12: 0 | C12: 0 | D12: 0 | E12: 0 | F12: 1 | G12: 0 | H12: 1 | I12: 0 | J12: =B12*Projects!N2+C12*Projects!N3+D12*Projects!N4+E12*Projects!N5+F12*Projects!N6+G12*Projects!N7+H12*Projects!N8+I12*Projects!N9 -> 7900000 | K12: =B12*Projects!C2+C12*Projects!C3+D12*Projects!C4+E12*Projects!C5+F12*Projects!C6+G12*Projects!C7+H12*Projects!C8+I12*Projects!C9 -> 200 | L12: =B12*Projects!D2+C12*Projects!D3+D12*Projects!D4+E12*Projects!D5+F12*Projects!D6+G12*Projects!D7+H12*Projects!D8+I12*Projects!D9 -> 111 | M12: =B12*Projects!O2+C12*Projects!O3+D12*Projects!O4+E12*Projects!O5+F12*Projects!O6+G12*Projects!O7+H12*Projects!O8+I12*Projects!O9 -> 6037336.3 | N12: =B12*(1-Projects!Q2)+C12*(1-Projects!Q3)+D12*(1-Projects!Q4)+E12*(1-Projects!Q5)+F12*(1-Projects!Q6)+G12*(1-Projects!Q7)+H12*(1-Projects!Q8)+I12*(1-Projects!Q9) -> 0 | O12: =IF(AND(J12<=Inputs!B2,L12>=Inputs!B3,M12>=Inputs!B18,N12=0),1,0) -> 1 | P12: =IF(O12=1,L12,-1) -> 111 | Q12: =IF(AND(O12=1,L12=MAX(P$2:P$257)),M12,-1E+99) -> -1e+99
A13: 11 | B13: 0 | C13: 0 | D13: 0 | E13: 0 | F13: 1 | G13: 0 | H13: 1 | I13: 1 | J13: =B13*Projects!N2+C13*Projects!N3+D13*Projects!N4+E13*Projects!N5+F13*Projects!N6+G13*Projects!N7+H13*Projects!N8+I13*Projects!N9 -> 12400000 | K13: =B13*Projects!C2+C13*Projects!C3+D13*Projects!C4+E13*Projects!C5+F13*Projects!C6+G13*Projects!C7+H13*Projects!C8+I13*Projects!C9 -> 290 | L13: =B13*Projects!D2+C13*Projects!D3+D13*Projects!D4+E13*Projects!D5+F13*Projects!D6+G13*Projects!D7+H13*Projects!D8+I13*Projects!D9 -> 138 | M13: =B13*Projects!O2+C13*Projects!O3+D13*Projects!O4+E13*Projects!O5+F13*Projects!O6+G13*Projects!O7+H13*Projects!O8+I13*Projects!O9 -> 10493964 | N13: =B13*(1-Projects!Q2)+C13*(1-Projects!Q3)+D13*(1-Projects!Q4)+E13*(1-Projects!Q5)+F13*(1-Projects!Q6)+G13*(1-Projects!Q7)+H13*(1-Projects!Q8)+I13*(1-Projects!Q9) -> 0 | O13: =IF(AND(J13<=Inputs!B2,L13>=Inputs!B3,M13>=Inputs!B18,N13=0),1,0) -> 1 | P13: =IF(O13=1,L13,-1) -> 138 | Q13: =IF(AND(O13=1,L13=MAX(P$2:P$257)),M13,-1E+99) -> -1e+99
A14: 12 | B14: 0 | C14: 0 | D14: 0 | E14: 0 | F14: 1 | G14: 1 | H14: 0 | I14: 0 | J14: =B14*Projects!N2+C14*Projects!N3+D14*Projects!N4+E14*Projects!N5+F14*Projects!N6+G14*Projects!N7+H14*Projects!N8+I14*Projects!N9 -> 7000000 | K14: =B14*Projects!C2+C14*Projects!C3+D14*Projects!C4+E14*Projects!C5+F14*Projects!C6+G14*Projects!C7+H14*Projects!C8+I14*Projects!C9 -> 170 | L14: =B14*Projects!D2+C14*Projects!D3+D14*Projects!D4+E14*Projects!D5+F14*Projects!D6+G14*Projects!D7+H14*Projects!D8+I14*Projects!D9 -> 85 | M14: =B14*Projects!O2+C14*Projects!O3+D14*Projects!O4+E14*Projects!O5+F14*Projects!O6+G14*Projects!O7+H14*Projects!O8+I14*Projects!O9 -> 5512141 | N14: =B14*(1-Projects!Q2)+C14*(1-Projects!Q3)+D14*(1-Projects!Q4)+E14*(1-Projects!Q5)+F14*(1-Projects!Q6)+G14*(1-Projects!Q7)+H14*(1-Projects!Q8)+I14*(1-Projects!Q9) -> 0 | O14: =IF(AND(J14<=Inputs!B2,L14>=Inputs!B3,M14>=Inputs!B18,N14=0),1,0) -> 1 | P14: =IF(O14=1,L14,-1) -> 85 | Q14: =IF(AND(O14=1,L14=MAX(P$2:P$257)),M14,-1E+99) -> -1e+99
A15: 13 | B15: 0 | C15: 0 | D15: 0 | E15: 0 | F15: 1 | G15: 1 | H15: 0 | I15: 1 | J15: =B15*Projects!N2+C15*Projects!N3+D15*Projects!N4+E15*Projects!N5+F15*Projects!N6+G15*Projects!N7+H15*Projects!N8+I15*Projects!N9 -> 11500000 | K15: =B15*Projects!C2+C15*Projects!C3+D15*Projects!C4+E15*Projects!C5+F15*Projects!C6+G15*Projects!C7+H15*Projects!C8+I15*Projects!C9 -> 260 | L15: =B15*Projects!D2+C15*Projects!D3+D15*Projects!D4+E15*Projects!D5+F15*Projects!D6+G15*Projects!D7+H15*Projects!D8+I15*Projects!D9 -> 112 | M15: =B15*Projects!O2+C15*Projects!O3+D15*Projects!O4+E15*Projects!O5+F15*Projects!O6+G15*Projects!O7+H15*Projects!O8+I15*Projects!O9 -> 9968768.4 | N15: =B15*(1-Projects!Q2)+C15*(1-Projects!Q3)+D15*(1-Projects!Q4)+E15*(1-Projects!Q5)+F15*(1-Projects!Q6)+G15*(1-Projects!Q7)+H15*(1-Projects!Q8)+I15*(1-Projects!Q9) -> 0 | O15: =IF(AND(J15<=Inputs!B2,L15>=Inputs!B3,M15>=Inputs!B18,N15=0),1,0) -> 1 | P15: =IF(O15=1,L15,-1) -> 112 | Q15: =IF(AND(O15=1,L15=MAX(P$2:P$257)),M15,-1E+99) -> -1e+99
A16: 14 | B16: 0 | C16: 0 | D16: 0 | E16: 0 | F16: 1 | G16: 1 | H16: 1 | I16: 0 | J16: =B16*Projects!N2+C16*Projects!N3+D16*Projects!N4+E16*Projects!N5+F16*Projects!N6+G16*Projects!N7+H16*Projects!N8+I16*Projects!N9 -> 11100000 | K16: =B16*Projects!C2+C16*Projects!C3+D16*Projects!C4+E16*Projects!C5+F16*Projects!C6+G16*Projects!C7+H16*Projects!C8+I16*Projects!C9 -> 280 | L16: =B16*Projects!D2+C16*Projects!D3+D16*Projects!D4+E16*Projects!D5+F16*Projects!D6+G16*Projects!D7+H16*Projects!D8+I16*Projects!D9 -> 151 | M16: =B16*Projects!O2+C16*Projects!O3+D16*Projects!O4+E16*Projects!O5+F16*Projects!O6+G16*Projects!O7+H16*Projects!O8+I16*Projects!O9 -> 8547515 | N16: =B16*(1-Projects!Q2)+C16*(1-Projects!Q3)+D16*(1-Projects!Q4)+E16*(1-Projects!Q5)+F16*(1-Projects!Q6)+G16*(1-Projects!Q7)+H16*(1-Projects!Q8)+I16*(1-Projects!Q9) -> 0 | O16: =IF(AND(J16<=Inputs!B2,L16>=Inputs!B3,M16>=Inputs!B18,N16=0),1,0) -> 1 | P16: =IF(O16=1,L16,-1) -> 151 | Q16: =IF(AND(O16=1,L16=MAX(P$2:P$257)),M16,-1E+99) -> -1e+99
A17: 15 | B17: 0 | C17: 0 | D17: 0 | E17: 0 | F17: 1 | G17: 1 | H17: 1 | I17: 1 | J17: =B17*Projects!N2+C17*Projects!N3+D17*Projects!N4+E17*Projects!N5+F17*Projects!N6+G17*Projects!N7+H17*Projects!N8+I17*Projects!N9 -> 15600000 | K17: =B17*Projects!C2+C17*Projects!C3+D17*Projects!C4+E17*Projects!C5+F17*Projects!C6+G17*Projects!C7+H17*Projects!C8+I17*Projects!C9 -> 370 | L17: =B17*Projects!D2+C17*Projects!D3+D17*Projects!D4+E17*Projects!D5+F17*Projects!D6+G17*Projects!D7+H17*Projects!D8+I17*Projects!D9 -> 178 | M17: =B17*Projects!O2+C17*Projects!O3+D17*Projects!O4+E17*Projects!O5+F17*Projects!O6+G17*Projects!O7+H17*Projects!O8+I17*Projects!O9 -> 13004142 | N17: =B17*(1-Projects!Q2)+C17*(1-Projects!Q3)+D17*(1-Projects!Q4)+E17*(1-Projects!Q5)+F17*(1-Projects!Q6)+G17*(1-Projects!Q7)+H17*(1-Projects!Q8)+I17*(1-Projects!Q9) -> 0 | O17: =IF(AND(J17<=Inputs!B2,L17>=Inputs!B3,M17>=Inputs!B18,N17=0),1,0) -> 0 | P17: =IF(O17=1,L17,-1) -> -1 | Q17: =IF(AND(O17=1,L17=MAX(P$2:P$257)),M17,-1E+99) -> -1e+99
A18: 16 | B18: 0 | C18: 0 | D18: 0 | E18: 1 | F18: 0 | G18: 0 | H18: 0 | I18: 0 | J18: =B18*Projects!N2+C18*Projects!N3+D18*Projects!N4+E18*Projects!N5+F18*Projects!N6+G18*Projects!N7+H18*Projects!N8+I18*Projects!N9 -> 3400000 | K18: =B18*Projects!C2+C18*Projects!C3+D18*Projects!C4+E18*Projects!C5+F18*Projects!C6+G18*Projects!C7+H18*Projects!C8+I18*Projects!C9 -> 70 | L18: =B18*Projects!D2+C18*Projects!D3+D18*Projects!D4+E18*Projects!D5+F18*Projects!D6+G18*Projects!D7+H18*Projects!D8+I18*Projects!D9 -> 21 | M18: =B18*Projects!O2+C18*Projects!O3+D18*Projects!O4+E18*Projects!O5+F18*Projects!O6+G18*Projects!O7+H18*Projects!O8+I18*Projects!O9 -> 3316358.2 | N18: =B18*(1-Projects!Q2)+C18*(1-Projects!Q3)+D18*(1-Projects!Q4)+E18*(1-Projects!Q5)+F18*(1-Projects!Q6)+G18*(1-Projects!Q7)+H18*(1-Projects!Q8)+I18*(1-Projects!Q9) -> 0 | O18: =IF(AND(J18<=Inputs!B2,L18>=Inputs!B3,M18>=Inputs!B18,N18=0),1,0) -> 0 | P18: =IF(O18=1,L18,-1) -> -1 | Q18: =IF(AND(O18=1,L18=MAX(P$2:P$257)),M18,-1E+99) -> -1e+99
A19: 17 | B19: 0 | C19: 0 | D19: 0 | E19: 1 | F19: 0 | G19: 0 | H19: 0 | I19: 1 | J19: =B19*Projects!N2+C19*Projects!N3+D19*Projects!N4+E19*Projects!N5+F19*Projects!N6+G19*Projects!N7+H19*Projects!N8+I19*Projects!N9 -> 7900000 | K19: =B19*Projects!C2+C19*Projects!C3+D19*Projects!C4+E19*Projects!C5+F19*Projects!C6+G19*Projects!C7+H19*Projects!C8+I19*Projects!C9 -> 160 | L19: =B19*Projects!D2+C19*Projects!D3+D19*Projects!D4+E19*Projects!D5+F19*Projects!D6+G19*Projects!D7+H19*Projects!D8+I19*Projects!D9 -> 48 | M19: =B19*Projects!O2+C19*Projects!O3+D19*Projects!O4+E19*Projects!O5+F19*Projects!O6+G19*Projects!O7+H19*Projects!O8+I19*Projects!O9 -> 7772985.7 | N19: =B19*(1-Projects!Q2)+C19*(1-Projects!Q3)+D19*(1-Projects!Q4)+E19*(1-Projects!Q5)+F19*(1-Projects!Q6)+G19*(1-Projects!Q7)+H19*(1-Projects!Q8)+I19*(1-Projects!Q9) -> 0 | O19: =IF(AND(J19<=Inputs!B2,L19>=Inputs!B3,M19>=Inputs!B18,N19=0),1,0) -> 0 | P19: =IF(O19=1,L19,-1) -> -1 | Q19: =IF(AND(O19=1,L19=MAX(P$2:P$257)),M19,-1E+99) -> -1e+99
A20: 18 | B20: 0 | C20: 0 | D20: 0 | E20: 1 | F20: 0 | G20: 0 | H20: 1 | I20: 0 | J20: =B20*Projects!N2+C20*Projects!N3+D20*Projects!N4+E20*Projects!N5+F20*Projects!N6+G20*Projects!N7+H20*Projects!N8+I20*Projects!N9 -> 7500000 | K20: =B20*Projects!C2+C20*Projects!C3+D20*Projects!C4+E20*Projects!C5+F20*Projects!C6+G20*Projects!C7+H20*Projects!C8+I20*Projects!C9 -> 180 | L20: =B20*Projects!D2+C20*Projects!D3+D20*Projects!D4+E20*Projects!D5+F20*Projects!D6+G20*Projects!D7+H20*Projects!D8+I20*Projects!D9 -> 87 | M20: =B20*Projects!O2+C20*Projects!O3+D20*Projects!O4+E20*Projects!O5+F20*Projects!O6+G20*Projects!O7+H20*Projects!O8+I20*Projects!O9 -> 6351732.2 | N20: =B20*(1-Projects!Q2)+C20*(1-Projects!Q3)+D20*(1-Projects!Q4)+E20*(1-Projects!Q5)+F20*(1-Projects!Q6)+G20*(1-Projects!Q7)+H20*(1-Projects!Q8)+I20*(1-Projects!Q9) -> 0 | O20: =IF(AND(J20<=Inputs!B2,L20>=Inputs!B3,M20>=Inputs!B18,N20=0),1,0) -> 1 | P20: =IF(O20=1,L20,-1) -> 87 | Q20: =IF(AND(O20=1,L20=MAX(P$2:P$257)),M20,-1E+99) -> -1e+99
A21: 19 | B21: 0 | C21: 0 | D21: 0 | E21: 1 | F21: 0 | G21: 0 | H21: 1 | I21: 1 | J21: =B21*Projects!N2+C21*Projects!N3+D21*Projects!N4+E21*Projects!N5+F21*Projects!N6+G21*Projects!N7+H21*Projects!N8+I21*Projects!N9 -> 12000000 | K21: =B21*Projects!C2+C21*Projects!C3+D21*Projects!C4+E21*Projects!C5+F21*Projects!C6+G21*Projects!C7+H21*Projects!C8+I21*Projects!C9 -> 270 | L21: =B21*Projects!D2+C21*Projects!D3+D21*Projects!D4+E21*Projects!D5+F21*Projects!D6+G21*Projects!D7+H21*Projects!D8+I21*Projects!D9 -> 114 | M21: =B21*Projects!O2+C21*Projects!O3+D21*Projects!O4+E21*Projects!O5+F21*Projects!O6+G21*Projects!O7+H21*Projects!O8+I21*Projects!O9 -> 10808360 | N21: =B21*(1-Projects!Q2)+C21*(1-Projects!Q3)+D21*(1-Projects!Q4)+E21*(1-Projects!Q5)+F21*(1-Projects!Q6)+G21*(1-Projects!Q7)+H21*(1-Projects!Q8)+I21*(1-Projects!Q9) -> 0 | O21: =IF(AND(J21<=Inputs!B2,L21>=Inputs!B3,M21>=Inputs!B18,N21=0),1,0) -> 1 | P21: =IF(O21=1,L21,-1) -> 114 | Q21: =IF(AND(O21=1,L21=MAX(P$2:P$257)),M21,-1E+99) -> -1e+99
A22: 20 | B22: 0 | C22: 0 | D22: 0 | E22: 1 | F22: 0 | G22: 1 | H22: 0 | I22: 0 | J22: =B22*Projects!N2+C22*Projects!N3+D22*Projects!N4+E22*Projects!N5+F22*Projects!N6+G22*Projects!N7+H22*Projects!N8+I22*Projects!N9 -> 6600000 | K22: =B22*Projects!C2+C22*Projects!C3+D22*Projects!C4+E22*Projects!C5+F22*Projects!C6+G22*Projects!C7+H22*Projects!C8+I22*Projects!C9 -> 150 | L22: =B22*Projects!D2+C22*Projects!D3+D22*Projects!D4+E22*Projects!D5+F22*Projects!D6+G22*Projects!D7+H22*Projects!D8+I22*Projects!D9 -> 61 | M22: =B22*Projects!O2+C22*Projects!O3+D22*Projects!O4+E22*Projects!O5+F22*Projects!O6+G22*Projects!O7+H22*Projects!O8+I22*Projects!O9 -> 5826536.8 | N22: =B22*(1-Projects!Q2)+C22*(1-Projects!Q3)+D22*(1-Projects!Q4)+E22*(1-Projects!Q5)+F22*(1-Projects!Q6)+G22*(1-Projects!Q7)+H22*(1-Projects!Q8)+I22*(1-Projects!Q9) -> 0 | O22: =IF(AND(J22<=Inputs!B2,L22>=Inputs!B3,M22>=Inputs!B18,N22=0),1,0) -> 0 | P22: =IF(O22=1,L22,-1) -> -1 | Q22: =IF(AND(O22=1,L22=MAX(P$2:P$257)),M22,-1E+99) -> -1e+99
A23: 21 | B23: 0 | C23: 0 | D23: 0 | E23: 1 | F23: 0 | G23: 1 | H23: 0 | I23: 1 | J23: =B23*Projects!N2+C23*Projects!N3+D23*Projects!N4+E23*Projects!N5+F23*Projects!N6+G23*Projects!N7+H23*Projects!N8+I23*Projects!N9 -> 11100000 | K23: =B23*Projects!C2+C23*Projects!C3+D23*Projects!C4+E23*Projects!C5+F23*Projects!C6+G23*Projects!C7+H23*Projects!C8+I23*Projects!C9 -> 240 | L23: =B23*Projects!D2+C23*Projects!D3+D23*Projects!D4+E23*Projects!D5+F23*Projects!D6+G23*Projects!D7+H23*Projects!D8+I23*Projects!D9 -> 88 | M23: =B23*Projects!O2+C23*Projects!O3+D23*Projects!O4+E23*Projects!O5+F23*Projects!O6+G23*Projects!O7+H23*Projects!O8+I23*Projects!O9 -> 10283164 | N23: =B23*(1-Projects!Q2)+C23*(1-Projects!Q3)+D23*(1-Projects!Q4)+E23*(1-Projects!Q5)+F23*(1-Projects!Q6)+G23*(1-Projects!Q7)+H23*(1-Projects!Q8)+I23*(1-Projects!Q9) -> 0 | O23: =IF(AND(J23<=Inputs!B2,L23>=Inputs!B3,M23>=Inputs!B18,N23=0),1,0) -> 1 | P23: =IF(O23=1,L23,-1) -> 88 | Q23: =IF(AND(O23=1,L23=MAX(P$2:P$257)),M23,-1E+99) -> -1e+99
A24: 22 | B24: 0 | C24: 0 | D24: 0 | E24: 1 | F24: 0 | G24: 1 | H24: 1 | I24: 0 | J24: =B24*Projects!N2+C24*Projects!N3+D24*Projects!N4+E24*Projects!N5+F24*Projects!N6+G24*Projects!N7+H24*Projects!N8+I24*Projects!N9 -> 10700000 | K24: =B24*Projects!C2+C24*Projects!C3+D24*Projects!C4+E24*Projects!C5+F24*Projects!C6+G24*Projects!C7+H24*Projects!C8+I24*Projects!C9 -> 260 | L24: =B24*Projects!D2+C24*Projects!D3+D24*Projects!D4+E24*Projects!D5+F24*Projects!D6+G24*Projects!D7+H24*Projects!D8+I24*Projects!D9 -> 127 | M24: =B24*Projects!O2+C24*Projects!O3+D24*Projects!O4+E24*Projects!O5+F24*Projects!O6+G24*Projects!O7+H24*Projects!O8+I24*Projects!O9 -> 8861910.8 | N24: =B24*(1-Projects!Q2)+C24*(1-Projects!Q3)+D24*(1-Projects!Q4)+E24*(1-Projects!Q5)+F24*(1-Projects!Q6)+G24*(1-Projects!Q7)+H24*(1-Projects!Q8)+I24*(1-Projects!Q9) -> 0 | O24: =IF(AND(J24<=Inputs!B2,L24>=Inputs!B3,M24>=Inputs!B18,N24=0),1,0) -> 1 | P24: =IF(O24=1,L24,-1) -> 127 | Q24: =IF(AND(O24=1,L24=MAX(P$2:P$257)),M24,-1E+99) -> -1e+99
A25: 23 | B25: 0 | C25: 0 | D25: 0 | E25: 1 | F25: 0 | G25: 1 | H25: 1 | I25: 1 | J25: =B25*Projects!N2+C25*Projects!N3+D25*Projects!N4+E25*Projects!N5+F25*Projects!N6+G25*Projects!N7+H25*Projects!N8+I25*Projects!N9 -> 15200000 | K25: =B25*Projects!C2+C25*Projects!C3+D25*Projects!C4+E25*Projects!C5+F25*Projects!C6+G25*Projects!C7+H25*Projects!C8+I25*Projects!C9 -> 350 | L25: =B25*Projects!D2+C25*Projects!D3+D25*Projects!D4+E25*Projects!D5+F25*Projects!D6+G25*Projects!D7+H25*Projects!D8+I25*Projects!D9 -> 154 | M25: =B25*Projects!O2+C25*Projects!O3+D25*Projects!O4+E25*Projects!O5+F25*Projects!O6+G25*Projects!O7+H25*Projects!O8+I25*Projects!O9 -> 13318538 | N25: =B25*(1-Projects!Q2)+C25*(1-Projects!Q3)+D25*(1-Projects!Q4)+E25*(1-Projects!Q5)+F25*(1-Projects!Q6)+G25*(1-Projects!Q7)+H25*(1-Projects!Q8)+I25*(1-Projects!Q9) -> 0 | O25: =IF(AND(J25<=Inputs!B2,L25>=Inputs!B3,M25>=Inputs!B18,N25=0),1,0) -> 0 | P25: =IF(O25=1,L25,-1) -> -1 | Q25: =IF(AND(O25=1,L25=MAX(P$2:P$257)),M25,-1E+99) -> -1e+99
A26: 24 | B26: 0 | C26: 0 | D26: 0 | E26: 1 | F26: 1 | G26: 0 | H26: 0 | I26: 0 | J26: =B26*Projects!N2+C26*Projects!N3+D26*Projects!N4+E26*Projects!N5+F26*Projects!N6+G26*Projects!N7+H26*Projects!N8+I26*Projects!N9 -> 7200000 | K26: =B26*Projects!C2+C26*Projects!C3+D26*Projects!C4+E26*Projects!C5+F26*Projects!C6+G26*Projects!C7+H26*Projects!C8+I26*Projects!C9 -> 160 | L26: =B26*Projects!D2+C26*Projects!D3+D26*Projects!D4+E26*Projects!D5+F26*Projects!D6+G26*Projects!D7+H26*Projects!D8+I26*Projects!D9 -> 66 | M26: =B26*Projects!O2+C26*Projects!O3+D26*Projects!O4+E26*Projects!O5+F26*Projects!O6+G26*Projects!O7+H26*Projects!O8+I26*Projects!O9 -> 6318320.6 | N26: =B26*(1-Projects!Q2)+C26*(1-Projects!Q3)+D26*(1-Projects!Q4)+E26*(1-Projects!Q5)+F26*(1-Projects!Q6)+G26*(1-Projects!Q7)+H26*(1-Projects!Q8)+I26*(1-Projects!Q9) -> 0 | O26: =IF(AND(J26<=Inputs!B2,L26>=Inputs!B3,M26>=Inputs!B18,N26=0),1,0) -> 0 | P26: =IF(O26=1,L26,-1) -> -1 | Q26: =IF(AND(O26=1,L26=MAX(P$2:P$257)),M26,-1E+99) -> -1e+99
A27: 25 | B27: 0 | C27: 0 | D27: 0 | E27: 1 | F27: 1 | G27: 0 | H27: 0 | I27: 1 | J27: =B27*Projects!N2+C27*Projects!N3+D27*Projects!N4+E27*Projects!N5+F27*Projects!N6+G27*Projects!N7+H27*Projects!N8+I27*Projects!N9 -> 11700000 | K27: =B27*Projects!C2+C27*Projects!C3+D27*Projects!C4+E27*Projects!C5+F27*Projects!C6+G27*Projects!C7+H27*Projects!C8+I27*Projects!C9 -> 250 | L27: =B27*Projects!D2+C27*Projects!D3+D27*Projects!D4+E27*Projects!D5+F27*Projects!D6+G27*Projects!D7+H27*Projects!D8+I27*Projects!D9 -> 93 | M27: =B27*Projects!O2+C27*Projects!O3+D27*Projects!O4+E27*Projects!O5+F27*Projects!O6+G27*Projects!O7+H27*Projects!O8+I27*Projects!O9 -> 10774948 | N27: =B27*(1-Projects!Q2)+C27*(1-Projects!Q3)+D27*(1-Projects!Q4)+E27*(1-Projects!Q5)+F27*(1-Projects!Q6)+G27*(1-Projects!Q7)+H27*(1-Projects!Q8)+I27*(1-Projects!Q9) -> 0 | O27: =IF(AND(J27<=Inputs!B2,L27>=Inputs!B3,M27>=Inputs!B18,N27=0),1,0) -> 1 | P27: =IF(O27=1,L27,-1) -> 93 | Q27: =IF(AND(O27=1,L27=MAX(P$2:P$257)),M27,-1E+99) -> -1e+99
A28: 26 | B28: 0 | C28: 0 | D28: 0 | E28: 1 | F28: 1 | G28: 0 | H28: 1 | I28: 0 | J28: =B28*Projects!N2+C28*Projects!N3+D28*Projects!N4+E28*Projects!N5+F28*Projects!N6+G28*Projects!N7+H28*Projects!N8+I28*Projects!N9 -> 11300000 | K28: =B28*Projects!C2+C28*Projects!C3+D28*Projects!C4+E28*Projects!C5+F28*Projects!C6+G28*Projects!C7+H28*Projects!C8+I28*Projects!C9 -> 270 | L28: =B28*Projects!D2+C28*Projects!D3+D28*Projects!D4+E28*Projects!D5+F28*Projects!D6+G28*Projects!D7+H28*Projects!D8+I28*Projects!D9 -> 132 | M28: =B28*Projects!O2+C28*Projects!O3+D28*Projects!O4+E28*Projects!O5+F28*Projects!O6+G28*Projects!O7+H28*Projects!O8+I28*Projects!O9 -> 9353694.6 | N28: =B28*(1-Projects!Q2)+C28*(1-Projects!Q3)+D28*(1-Projects!Q4)+E28*(1-Projects!Q5)+F28*(1-Projects!Q6)+G28*(1-Projects!Q7)+H28*(1-Projects!Q8)+I28*(1-Projects!Q9) -> 0 | O28: =IF(AND(J28<=Inputs!B2,L28>=Inputs!B3,M28>=Inputs!B18,N28=0),1,0) -> 1 | P28: =IF(O28=1,L28,-1) -> 132 | Q28: =IF(AND(O28=1,L28=MAX(P$2:P$257)),M28,-1E+99) -> -1e+99
A29: 27 | B29: 0 | C29: 0 | D29: 0 | E29: 1 | F29: 1 | G29: 0 | H29: 1 | I29: 1 | J29: =B29*Projects!N2+C29*Projects!N3+D29*Projects!N4+E29*Projects!N5+F29*Projects!N6+G29*Projects!N7+H29*Projects!N8+I29*Projects!N9 -> 15800000 | K29: =B29*Projects!C2+C29*Projects!C3+D29*Projects!C4+E29*Projects!C5+F29*Projects!C6+G29*Projects!C7+H29*Projects!C8+I29*Projects!C9 -> 360 | L29: =B29*Projects!D2+C29*Projects!D3+D29*Projects!D4+E29*Projects!D5+F29*Projects!D6+G29*Projects!D7+H29*Projects!D8+I29*Projects!D9 -> 159 | M29: =B29*Projects!O2+C29*Projects!O3+D29*Projects!O4+E29*Projects!O5+F29*Projects!O6+G29*Projects!O7+H29*Projects!O8+I29*Projects!O9 -> 13810322 | N29: =B29*(1-Projects!Q2)+C29*(1-Projects!Q3)+D29*(1-Projects!Q4)+E29*(1-Projects!Q5)+F29*(1-Projects!Q6)+G29*(1-Projects!Q7)+H29*(1-Projects!Q8)+I29*(1-Projects!Q9) -> 0 | O29: =IF(AND(J29<=Inputs!B2,L29>=Inputs!B3,M29>=Inputs!B18,N29=0),1,0) -> 0 | P29: =IF(O29=1,L29,-1) -> -1 | Q29: =IF(AND(O29=1,L29=MAX(P$2:P$257)),M29,-1E+99) -> -1e+99
A30: 28 | B30: 0 | C30: 0 | D30: 0 | E30: 1 | F30: 1 | G30: 1 | H30: 0 | I30: 0 | J30: =B30*Projects!N2+C30*Projects!N3+D30*Projects!N4+E30*Projects!N5+F30*Projects!N6+G30*Projects!N7+H30*Projects!N8+I30*Projects!N9 -> 10400000 | K30: =B30*Projects!C2+C30*Projects!C3+D30*Projects!C4+E30*Projects!C5+F30*Projects!C6+G30*Projects!C7+H30*Projects!C8+I30*Projects!C9 -> 240 | L30: =B30*Projects!D2+C30*Projects!D3+D30*Projects!D4+E30*Projects!D5+F30*Projects!D6+G30*Projects!D7+H30*Projects!D8+I30*Projects!D9 -> 106 | M30: =B30*Projects!O2+C30*Projects!O3+D30*Projects!O4+E30*Projects!O5+F30*Projects!O6+G30*Projects!O7+H30*Projects!O8+I30*Projects!O9 -> 8828499.2 | N30: =B30*(1-Projects!Q2)+C30*(1-Projects!Q3)+D30*(1-Projects!Q4)+E30*(1-Projects!Q5)+F30*(1-Projects!Q6)+G30*(1-Projects!Q7)+H30*(1-Projects!Q8)+I30*(1-Projects!Q9) -> 0 | O30: =IF(AND(J30<=Inputs!B2,L30>=Inputs!B3,M30>=Inputs!B18,N30=0),1,0) -> 1 | P30: =IF(O30=1,L30,-1) -> 106 | Q30: =IF(AND(O30=1,L30=MAX(P$2:P$257)),M30,-1E+99) -> -1e+99
A31: 29 | B31: 0 | C31: 0 | D31: 0 | E31: 1 | F31: 1 | G31: 1 | H31: 0 | I31: 1 | J31: =B31*Projects!N2+C31*Projects!N3+D31*Projects!N4+E31*Projects!N5+F31*Projects!N6+G31*Projects!N7+H31*Projects!N8+I31*Projects!N9 -> 14900000 | K31: =B31*Projects!C2+C31*Projects!C3+D31*Projects!C4+E31*Projects!C5+F31*Projects!C6+G31*Projects!C7+H31*Projects!C8+I31*Projects!C9 -> 330 | L31: =B31*Projects!D2+C31*Projects!D3+D31*Projects!D4+E31*Projects!D5+F31*Projects!D6+G31*Projects!D7+H31*Projects!D8+I31*Projects!D9 -> 133 | M31: =B31*Projects!O2+C31*Projects!O3+D31*Projects!O4+E31*Projects!O5+F31*Projects!O6+G31*Projects!O7+H31*Projects!O8+I31*Projects!O9 -> 13285127 | N31: =B31*(1-Projects!Q2)+C31*(1-Projects!Q3)+D31*(1-Projects!Q4)+E31*(1-Projects!Q5)+F31*(1-Projects!Q6)+G31*(1-Projects!Q7)+H31*(1-Projects!Q8)+I31*(1-Projects!Q9) -> 0 | O31: =IF(AND(J31<=Inputs!B2,L31>=Inputs!B3,M31>=Inputs!B18,N31=0),1,0) -> 1 | P31: =IF(O31=1,L31,-1) -> 133 | Q31: =IF(AND(O31=1,L31=MAX(P$2:P$257)),M31,-1E+99) -> -1e+99
A32: 30 | B32: 0 | C32: 0 | D32: 0 | E32: 1 | F32: 1 | G32: 1 | H32: 1 | I32: 0 | J32: =B32*Projects!N2+C32*Projects!N3+D32*Projects!N4+E32*Projects!N5+F32*Projects!N6+G32*Projects!N7+H32*Projects!N8+I32*Projects!N9 -> 14500000 | K32: =B32*Projects!C2+C32*Projects!C3+D32*Projects!C4+E32*Projects!C5+F32*Projects!C6+G32*Projects!C7+H32*Projects!C8+I32*Projects!C9 -> 350 | L32: =B32*Projects!D2+C32*Projects!D3+D32*Projects!D4+E32*Projects!D5+F32*Projects!D6+G32*Projects!D7+H32*Projects!D8+I32*Projects!D9 -> 172 | M32: =B32*Projects!O2+C32*Projects!O3+D32*Projects!O4+E32*Projects!O5+F32*Projects!O6+G32*Projects!O7+H32*Projects!O8+I32*Projects!O9 -> 11863873 | N32: =B32*(1-Projects!Q2)+C32*(1-Projects!Q3)+D32*(1-Projects!Q4)+E32*(1-Projects!Q5)+F32*(1-Projects!Q6)+G32*(1-Projects!Q7)+H32*(1-Projects!Q8)+I32*(1-Projects!Q9) -> 0 | O32: =IF(AND(J32<=Inputs!B2,L32>=Inputs!B3,M32>=Inputs!B18,N32=0),1,0) -> 1 | P32: =IF(O32=1,L32,-1) -> 172 | Q32: =IF(AND(O32=1,L32=MAX(P$2:P$257)),M32,-1E+99) -> 11863873
A33: 31 | B33: 0 | C33: 0 | D33: 0 | E33: 1 | F33: 1 | G33: 1 | H33: 1 | I33: 1 | J33: =B33*Projects!N2+C33*Projects!N3+D33*Projects!N4+E33*Projects!N5+F33*Projects!N6+G33*Projects!N7+H33*Projects!N8+I33*Projects!N9 -> 19000000 | K33: =B33*Projects!C2+C33*Projects!C3+D33*Projects!C4+E33*Projects!C5+F33*Projects!C6+G33*Projects!C7+H33*Projects!C8+I33*Projects!C9 -> 440 | L33: =B33*Projects!D2+C33*Projects!D3+D33*Projects!D4+E33*Projects!D5+F33*Projects!D6+G33*Projects!D7+H33*Projects!D8+I33*Projects!D9 -> 199 | M33: =B33*Projects!O2+C33*Projects!O3+D33*Projects!O4+E33*Projects!O5+F33*Projects!O6+G33*Projects!O7+H33*Projects!O8+I33*Projects!O9 -> 16320501 | N33: =B33*(1-Projects!Q2)+C33*(1-Projects!Q3)+D33*(1-Projects!Q4)+E33*(1-Projects!Q5)+F33*(1-Projects!Q6)+G33*(1-Projects!Q7)+H33*(1-Projects!Q8)+I33*(1-Projects!Q9) -> 0 | O33: =IF(AND(J33<=Inputs!B2,L33>=Inputs!B3,M33>=Inputs!B18,N33=0),1,0) -> 0 | P33: =IF(O33=1,L33,-1) -> -1 | Q33: =IF(AND(O33=1,L33=MAX(P$2:P$257)),M33,-1E+99) -> -1e+99
A34: 32 | B34: 0 | C34: 0 | D34: 1 | E34: 0 | F34: 0 | G34: 0 | H34: 0 | I34: 0 | J34: =B34*Projects!N2+C34*Projects!N3+D34*Projects!N4+E34*Projects!N5+F34*Projects!N6+G34*Projects!N7+H34*Projects!N8+I34*Projects!N9 -> 4900000 | K34: =B34*Projects!C2+C34*Projects!C3+D34*Projects!C4+E34*Projects!C5+F34*Projects!C6+G34*Projects!C7+H34*Projects!C8+I34*Projects!C9 -> 120 | L34: =B34*Projects!D2+C34*Projects!D3+D34*Projects!D4+E34*Projects!D5+F34*Projects!D6+G34*Projects!D7+H34*Projects!D8+I34*Projects!D9 -> 60 | M34: =B34*Projects!O2+C34*Projects!O3+D34*Projects!O4+E34*Projects!O5+F34*Projects!O6+G34*Projects!O7+H34*Projects!O8+I34*Projects!O9 -> 3791271.7 | N34: =B34*(1-Projects!Q2)+C34*(1-Projects!Q3)+D34*(1-Projects!Q4)+E34*(1-Projects!Q5)+F34*(1-Projects!Q6)+G34*(1-Projects!Q7)+H34*(1-Projects!Q8)+I34*(1-Projects!Q9) -> 0 | O34: =IF(AND(J34<=Inputs!B2,L34>=Inputs!B3,M34>=Inputs!B18,N34=0),1,0) -> 0 | P34: =IF(O34=1,L34,-1) -> -1 | Q34: =IF(AND(O34=1,L34=MAX(P$2:P$257)),M34,-1E+99) -> -1e+99
A35: 33 | B35: 0 | C35: 0 | D35: 1 | E35: 0 | F35: 0 | G35: 0 | H35: 0 | I35: 1 | J35: =B35*Projects!N2+C35*Projects!N3+D35*Projects!N4+E35*Projects!N5+F35*Projects!N6+G35*Projects!N7+H35*Projects!N8+I35*Projects!N9 -> 9400000 | K35: =B35*Projects!C2+C35*Projects!C3+D35*Projects!C4+E35*Projects!C5+F35*Projects!C6+G35*Projects!C7+H35*Projects!C8+I35*Projects!C9 -> 210 | L35: =B35*Projects!D2+C35*Projects!D3+D35*Projects!D4+E35*Projects!D5+F35*Projects!D6+G35*Projects!D7+H35*Projects!D8+I35*Projects!D9 -> 87 | M35: =B35*Projects!O2+C35*Projects!O3+D35*Projects!O4+E35*Projects!O5+F35*Projects!O6+G35*Projects!O7+H35*Projects!O8+I35*Projects!O9 -> 8247899.2 | N35: =B35*(1-Projects!Q2)+C35*(1-Projects!Q3)+D35*(1-Projects!Q4)+E35*(1-Projects!Q5)+F35*(1-Projects!Q6)+G35*(1-Projects!Q7)+H35*(1-Projects!Q8)+I35*(1-Projects!Q9) -> 0 | O35: =IF(AND(J35<=Inputs!B2,L35>=Inputs!B3,M35>=Inputs!B18,N35=0),1,0) -> 1 | P35: =IF(O35=1,L35,-1) -> 87 | Q35: =IF(AND(O35=1,L35=MAX(P$2:P$257)),M35,-1E+99) -> -1e+99
A36: 34 | B36: 0 | C36: 0 | D36: 1 | E36: 0 | F36: 0 | G36: 0 | H36: 1 | I36: 0 | J36: =B36*Projects!N2+C36*Projects!N3+D36*Projects!N4+E36*Projects!N5+F36*Projects!N6+G36*Projects!N7+H36*Projects!N8+I36*Projects!N9 -> 9000000 | K36: =B36*Projects!C2+C36*Projects!C3+D36*Projects!C4+E36*Projects!C5+F36*Projects!C6+G36*Projects!C7+H36*Projects!C8+I36*Projects!C9 -> 230 | L36: =B36*Projects!D2+C36*Projects!D3+D36*Projects!D4+E36*Projects!D5+F36*Projects!D6+G36*Projects!D7+H36*Projects!D8+I36*Projects!D9 -> 126 | M36: =B36*Projects!O2+C36*Projects!O3+D36*Projects!O4+E36*Projects!O5+F36*Projects!O6+G36*Projects!O7+H36*Projects!O8+I36*Projects!O9 -> 6826645.7 | N36: =B36*(1-Projects!Q2)+C36*(1-Projects!Q3)+D36*(1-Projects!Q4)+E36*(1-Projects!Q5)+F36*(1-Projects!Q6)+G36*(1-Projects!Q7)+H36*(1-Projects!Q8)+I36*(1-Projects!Q9) -> 0 | O36: =IF(AND(J36<=Inputs!B2,L36>=Inputs!B3,M36>=Inputs!B18,N36=0),1,0) -> 1 | P36: =IF(O36=1,L36,-1) -> 126 | Q36: =IF(AND(O36=1,L36=MAX(P$2:P$257)),M36,-1E+99) -> -1e+99
A37: 35 | B37: 0 | C37: 0 | D37: 1 | E37: 0 | F37: 0 | G37: 0 | H37: 1 | I37: 1 | J37: =B37*Projects!N2+C37*Projects!N3+D37*Projects!N4+E37*Projects!N5+F37*Projects!N6+G37*Projects!N7+H37*Projects!N8+I37*Projects!N9 -> 13500000 | K37: =B37*Projects!C2+C37*Projects!C3+D37*Projects!C4+E37*Projects!C5+F37*Projects!C6+G37*Projects!C7+H37*Projects!C8+I37*Projects!C9 -> 320 | L37: =B37*Projects!D2+C37*Projects!D3+D37*Projects!D4+E37*Projects!D5+F37*Projects!D6+G37*Projects!D7+H37*Projects!D8+I37*Projects!D9 -> 153 | M37: =B37*Projects!O2+C37*Projects!O3+D37*Projects!O4+E37*Projects!O5+F37*Projects!O6+G37*Projects!O7+H37*Projects!O8+I37*Projects!O9 -> 11283273 | N37: =B37*(1-Projects!Q2)+C37*(1-Projects!Q3)+D37*(1-Projects!Q4)+E37*(1-Projects!Q5)+F37*(1-Projects!Q6)+G37*(1-Projects!Q7)+H37*(1-Projects!Q8)+I37*(1-Projects!Q9) -> 0 | O37: =IF(AND(J37<=Inputs!B2,L37>=Inputs!B3,M37>=Inputs!B18,N37=0),1,0) -> 1 | P37: =IF(O37=1,L37,-1) -> 153 | Q37: =IF(AND(O37=1,L37=MAX(P$2:P$257)),M37,-1E+99) -> -1e+99
A38: 36 | B38: 0 | C38: 0 | D38: 1 | E38: 0 | F38: 0 | G38: 1 | H38: 0 | I38: 0 | J38: =B38*Projects!N2+C38*Projects!N3+D38*Projects!N4+E38*Projects!N5+F38*Projects!N6+G38*Projects!N7+H38*Projects!N8+I38*Projects!N9 -> 8100000 | K38: =B38*Projects!C2+C38*Projects!C3+D38*Projects!C4+E38*Projects!C5+F38*Projects!C6+G38*Projects!C7+H38*Projects!C8+I38*Projects!C9 -> 200 | L38: =B38*Projects!D2+C38*Projects!D3+D38*Projects!D4+E38*Projects!D5+F38*Projects!D6+G38*Projects!D7+H38*Projects!D8+I38*Projects!D9 -> 100 | M38: =B38*Projects!O2+C38*Projects!O3+D38*Projects!O4+E38*Projects!O5+F38*Projects!O6+G38*Projects!O7+H38*Projects!O8+I38*Projects!O9 -> 6301450.4 | N38: =B38*(1-Projects!Q2)+C38*(1-Projects!Q3)+D38*(1-Projects!Q4)+E38*(1-Projects!Q5)+F38*(1-Projects!Q6)+G38*(1-Projects!Q7)+H38*(1-Projects!Q8)+I38*(1-Projects!Q9) -> 0 | O38: =IF(AND(J38<=Inputs!B2,L38>=Inputs!B3,M38>=Inputs!B18,N38=0),1,0) -> 1 | P38: =IF(O38=1,L38,-1) -> 100 | Q38: =IF(AND(O38=1,L38=MAX(P$2:P$257)),M38,-1E+99) -> -1e+99
A39: 37 | B39: 0 | C39: 0 | D39: 1 | E39: 0 | F39: 0 | G39: 1 | H39: 0 | I39: 1 | J39: =B39*Projects!N2+C39*Projects!N3+D39*Projects!N4+E39*Projects!N5+F39*Projects!N6+G39*Projects!N7+H39*Projects!N8+I39*Projects!N9 -> 12600000 | K39: =B39*Projects!C2+C39*Projects!C3+D39*Projects!C4+E39*Projects!C5+F39*Projects!C6+G39*Projects!C7+H39*Projects!C8+I39*Projects!C9 -> 290 | L39: =B39*Projects!D2+C39*Projects!D3+D39*Projects!D4+E39*Projects!D5+F39*Projects!D6+G39*Projects!D7+H39*Projects!D8+I39*Projects!D9 -> 127 | M39: =B39*Projects!O2+C39*Projects!O3+D39*Projects!O4+E39*Projects!O5+F39*Projects!O6+G39*Projects!O7+H39*Projects!O8+I39*Projects!O9 -> 10758078 | N39: =B39*(1-Projects!Q2)+C39*(1-Projects!Q3)+D39*(1-Projects!Q4)+E39*(1-Projects!Q5)+F39*(1-Projects!Q6)+G39*(1-Projects!Q7)+H39*(1-Projects!Q8)+I39*(1-Projects!Q9) -> 0 | O39: =IF(AND(J39<=Inputs!B2,L39>=Inputs!B3,M39>=Inputs!B18,N39=0),1,0) -> 1 | P39: =IF(O39=1,L39,-1) -> 127 | Q39: =IF(AND(O39=1,L39=MAX(P$2:P$257)),M39,-1E+99) -> -1e+99
A40: 38 | B40: 0 | C40: 0 | D40: 1 | E40: 0 | F40: 0 | G40: 1 | H40: 1 | I40: 0 | J40: =B40*Projects!N2+C40*Projects!N3+D40*Projects!N4+E40*Projects!N5+F40*Projects!N6+G40*Projects!N7+H40*Projects!N8+I40*Projects!N9 -> 12200000 | K40: =B40*Projects!C2+C40*Projects!C3+D40*Projects!C4+E40*Projects!C5+F40*Projects!C6+G40*Projects!C7+H40*Projects!C8+I40*Projects!C9 -> 310 | L40: =B40*Projects!D2+C40*Projects!D3+D40*Projects!D4+E40*Projects!D5+F40*Projects!D6+G40*Projects!D7+H40*Projects!D8+I40*Projects!D9 -> 166 | M40: =B40*Projects!O2+C40*Projects!O3+D40*Projects!O4+E40*Projects!O5+F40*Projects!O6+G40*Projects!O7+H40*Projects!O8+I40*Projects!O9 -> 9336824.3 | N40: =B40*(1-Projects!Q2)+C40*(1-Projects!Q3)+D40*(1-Projects!Q4)+E40*(1-Projects!Q5)+F40*(1-Projects!Q6)+G40*(1-Projects!Q7)+H40*(1-Projects!Q8)+I40*(1-Projects!Q9) -> 0 | O40: =IF(AND(J40<=Inputs!B2,L40>=Inputs!B3,M40>=Inputs!B18,N40=0),1,0) -> 1 | P40: =IF(O40=1,L40,-1) -> 166 | Q40: =IF(AND(O40=1,L40=MAX(P$2:P$257)),M40,-1E+99) -> -1e+99
...

Sheet Scenarios
A1: Scenario | B1: Occupancy | C1: Capex multiplier | D1: Rent multiplier | E1: Discount rate | F1: Exit cap rate | G1: Selected investment | H1: Year 1 NOI | I1: NPV | J1: Affordable beds | K1: Planning budget check
A2: Base | B2: =Inputs!B4 -> 0.95 | C2: 1 | D2: 1 | E2: =Inputs!B9 -> 0.06 | F2: =Inputs!B10 -> 0.055 | G2: ='Executive Report'!B9*C2 -> 14500000 | H2: =(Projects!R2*(Projects!D2*Projects!E2+(Projects!C2-Projects!D2)*Projects!F2)*Inputs!B5+Projects!R3*(Projects!D3*Projects!E3+(Projects!C3-Projects!D3)*Projects!F3)*Inputs!B5+Projects!R4*(Projects!D4*Projects!E4+(Projects!C4-Projects!D4)*Projects!F4)*Inputs!B5+Projects!R5*(Projects!D5*Projects!E5+(Projects!C5-Projects!D5)*Projects!F5)*Inputs!B5+Projects!R6*(Projects!D6*Projects!E6+(Projects!C6-Projects!D6)*Projects!F6)*Inputs!B5+Projects!R7*(Projects!D7*Projects!E7+(Projects!C7-Projects!D7)*Projects!F7)*Inputs!B5+Projects!R8*(Projects!D8*Projects!E8+(Projects!C8-Projects!D8)*Projects!F8)*Inputs!B5+Projects!R9*(Projects!D9*Projects!E9+(Projects!C9-Projects!D9)*Projects!F9)*Inputs!B5)*B2*D2*(1-Inputs!B6)-'Executive Report'!B10*Inputs!B7 -> 1216467.7 | I2: =-G2+H2*(1+Inputs!B8)^0/(1+E2)^1+H2*(1+Inputs!B8)^1/(1+E2)^2+H2*(1+Inputs!B8)^2/(1+E2)^3+H2*(1+Inputs!B8)^3/(1+E2)^4+H2*(1+Inputs!B8)^4/(1+E2)^5+H2*(1+Inputs!B8)^5/(1+E2)^6+H2*(1+Inputs!B8)^6/(1+E2)^7+H2*(1+Inputs!B8)^7/(1+E2)^8+H2*(1+Inputs!B8)^8/(1+E2)^9+H2*(1+Inputs!B8)^9/(1+E2)^10+H2*(1+Inputs!B8)^10/(1+E2)^11+H2*(1+Inputs!B8)^11/(1+E2)^12+H2*(1+Inputs!B8)^12/(1+E2)^13+H2*(1+Inputs!B8)^13/(1+E2)^14+H2*(1+Inputs!B8)^14/(1+E2)^15+H2*(1+Inputs!B8)^15/(1+E2)^16+H2*(1+Inputs!B8)^16/(1+E2)^17+H2*(1+Inputs!B8)^17/(1+E2)^18+H2*(1+Inputs!B8)^18/(1+E2)^19+H2*(1+Inputs!B8)^19/(1+E2)^20+H2*(1+Inputs!B8)^20/F2*(1-Inputs!B11)/(1+E2)^20 -> 11863873 | J2: ='Executive Report'!B11 -> 172 | K2: =IF(G2<=Inputs!B2,"PASS","OVER BUDGET") -> PASS
